Workbook
Name UserName: Dashboard!$B$3
Name Method: Dashboard!$D$3
Name ExtraPayment: Dashboard!$F$3
Name PlanStart: Dashboard!$H$3
Name List_Method: Dashboard!$N$2:$N$4
Name RemainingDebt: Dashboard!$N$6
Name OriginalDebt: Dashboard!$N$7
Name ProgressPct: Dashboard!$N$8
Name DebtsLeft: Dashboard!$N$9
Name DebtsTotal: Dashboard!$N$10
Name MinTotal: Dashboard!$N$11
Name TargetDebt: Dashboard!$N$12
Name MinOnlyInt: Dashboard!$N$13
Name PlanInterest: Dashboard!$N$14
Name PayoffDate: Dashboard!$N$15
Name PayoffMonths: Dashboard!$N$16
Name InterestSaved: Dashboard!$N$17
Name ProgressBar: Dashboard!$N$18
Name DebtNames: 'Debt List'!$A$5:$A$12
Name OrderPlan: 'Debt List'!$K$5:$K$12
Name OrderSnow: 'Debt List'!$L$5:$L$12
Name OrderAval: 'Debt List'!$M$5:$M$12
Name SnowDate: '_Calc'!CC$2
Name SnowInt: '_Calc'!CD$2
Name SnowPaid: '_Calc'!CE$2
Name SnowMonths: '_Calc'!CF$2
Name AvalDate: '_Calc'!FE$2
Name AvalInt: '_Calc'!FF$2
Name AvalPaid: '_Calc'!FG$2
Name AvalMonths: '_Calc'!FH$2

Sheet Dashboard
A1: Debt Payoff Tracker & Schedule | N1: LISTS / HELPERS
A2: =IF(UserName="","Your payoff plan","Hello, "&UserName)&" · "&TEXT(TODAY(),"mmm d, yyyy")&" · "&Method&" · extra "&TEXT(ExtraPayment,"$#,##0")&"/mo" | N2: Snowball
A3: Your name | B3: Alex | C3: Method | D3: Snowball | E3: Extra / month | F3: 200 | G3: Plan start | H3: 46266 | I3: Blue settings drive the whole plan. Open Debt List to edit balances. | N3: Avalanche
N4: Custom
A5: REMAINING DEBT | D5: PROGRESS | G5: DEBT-FREE DATE | J5: INTEREST ON THIS PLAN
A6: =RemainingDebt | D6: =ProgressPct | G6: =PayoffDate | J6: =PlanInterest | N6: =SUM('Debt List'!D5:D12)
A7: ="of "&TEXT(OriginalDebt,"$#,##0")&" original" | D7: =ProgressBar | G7: ="in "&TEXT(PayoffMonths,"#,##0")&" months" | J7: ="Save "&TEXT(InterestSaved,"$#,##0")&" vs mins only" | N7: =IF('Debt List'!A5="",0,IF('Debt List'!C5="",N('Debt List'!D5),N('Debt List'!C5)))+IF('Debt List'!A6="",0,IF('Debt List'!C6="",N('Debt List'!D6),N('Debt List'!C6)))+IF('Debt List'!A7="",0,IF('Debt List'!C7="",N('Debt List'!D7),N('Debt List'!C7)))+IF('Debt List'!A8="",0,IF('Debt List'!C8="",N('Debt List'!D8),N('Debt List'!C8)))+IF('Debt List'!A9="",0,IF('Debt List'!C9="",N('Debt List'!D9),N('Debt List'!C9)))+IF('Debt List'!A10="",0,IF('Debt List'!C10="",N('Debt List'!D10),N('Debt List'!C10)))+IF('Debt List'!A11="",0,IF('Debt List'!C11="",N('Debt List'!D11),N('Debt List'!C11)))+IF('Debt List'!A12="",0,IF('Debt List'!C12="",N('Debt List'!D12),N('Debt List'!C12)))
A8: Sum of current balances | D8: Paid down vs original | G8: At this extra and method | J8: Compared with never sending extra | N8: =IF(N7=0,"",(N7-N6)/N7)
N9: =COUNTIF('Debt List'!N5:N12,"Active")
A10: DEBTS LEFT | D10: THIS MONTH’S PLAN | G10: CURRENT TARGET | J10: LOGGED THIS MONTH | N10: =COUNTA('Debt List'!A5:A12)
A11: =DebtsLeft | D11: =MinTotal+ExtraPayment | G11: =TargetDebt | J11: =SUMIFS('Payment Log'!$C$5:$C$104,'Payment Log'!$A$5:$A$104,">="&DATE(YEAR(TODAY()),MONTH(TODAY()),1)) | N11: =SUM('Debt List'!F5:F12)
A12: ="of "&TEXT(DebtsTotal,"0")&" on your list" | D12: ="Mins "&TEXT(MinTotal,"$#,##0")&" + extra" | G12: ="Order #1 under "&Method | J12: From the Payment Log | N12: =IFERROR(INDEX(DebtNames,MATCH(1,'Debt List'!K5:K12,0)),"—")
A13: Current balance above $0 | D13: Send this much to stay on track | G13: Every extra dollar goes here first | J13: Compare to This month’s plan | N13: =IF(ISNUMBER('Debt List'!S5),'Debt List'!S5,0)+IF(ISNUMBER('Debt List'!S6),'Debt List'!S6,0)+IF(ISNUMBER('Debt List'!S7),'Debt List'!S7,0)+IF(ISNUMBER('Debt List'!S8),'Debt List'!S8,0)+IF(ISNUMBER('Debt List'!S9),'Debt List'!S9,0)+IF(ISNUMBER('Debt List'!S10),'Debt List'!S10,0)+IF(ISNUMBER('Debt List'!S11),'Debt List'!S11,0)+IF(ISNUMBER('Debt List'!S12),'Debt List'!S12,0)
A14: =IF(UserName="","You","You, "&UserName)&" — "&TEXT(ProgressPct,"0%")&" of the original balance is gone. Keep the extra coming and this plan says you are done in "&TEXT(PayoffDate,"mmmm yyyy")&". That is not a slogan. It is the schedule on the next tab." | N14: ='_Calc'!B$2
N15: ='_Calc'!A$2
N16: ='_Calc'!D$2
A17: REMAINING BALANCE OVER TIME | G17: YOUR DEBTS | N17: =IF(N13=0,"",N13-N14)
G18: Debt | I18: Balance | J18: APR | K18: Min | L18: Target | N18: =IF(OR(N8="",N8<0),"",REPT("█",ROUND(MIN(1,N8)*16,0))&REPT("░",16-ROUND(MIN(1,N8)*16,0)))
G19: =IF('Debt List'!A5="","",'Debt List'!A5) | I19: =IF(G19="","",'Debt List'!D5) | J19: =IF(G19="","",'Debt List'!E5) | K19: =IF(G19="","",'Debt List'!F5) | L19: =IF(G19="","",'Debt List'!O5)
G20: =IF('Debt List'!A6="","",'Debt List'!A6) | I20: =IF(G20="","",'Debt List'!D6) | J20: =IF(G20="","",'Debt List'!E6) | K20: =IF(G20="","",'Debt List'!F6) | L20: =IF(G20="","",'Debt List'!O6)
G21: =IF('Debt List'!A7="","",'Debt List'!A7) | I21: =IF(G21="","",'Debt List'!D7) | J21: =IF(G21="","",'Debt List'!E7) | K21: =IF(G21="","",'Debt List'!F7) | L21: =IF(G21="","",'Debt List'!O7)
G22: =IF('Debt List'!A8="","",'Debt List'!A8) | I22: =IF(G22="","",'Debt List'!D8) | J22: =IF(G22="","",'Debt List'!E8) | K22: =IF(G22="","",'Debt List'!F8) | L22: =IF(G22="","",'Debt List'!O8)
G23: =IF('Debt List'!A9="","",'Debt List'!A9) | I23: =IF(G23="","",'Debt List'!D9) | J23: =IF(G23="","",'Debt List'!E9) | K23: =IF(G23="","",'Debt List'!F9) | L23: =IF(G23="","",'Debt List'!O9)
G24: =IF('Debt List'!A10="","",'Debt List'!A10) | I24: =IF(G24="","",'Debt List'!D10) | J24: =IF(G24="","",'Debt List'!E10) | K24: =IF(G24="","",'Debt List'!F10) | L24: =IF(G24="","",'Debt List'!O10)
A36: Change Extra / month and Method above — the date, the interest, this chart, and the Payoff Schedule all move. Compare Snowball and Avalanche on the next tab before you pick. See Instructions for the 5-minute start.
A70: Month | B70: Remaining
A71: =_Calc!B5 | B71: =IF(_Calc!A5="",NA(),IF(AND(0>0,_Calc!H5<=0.005,_Calc!H5<=0.005),NA(),_Calc!H5))
A72: =_Calc!B6 | B72: =IF(_Calc!A6="",NA(),IF(AND(1>0,_Calc!H6<=0.005,_Calc!H5<=0.005),NA(),_Calc!H6))
A73: =_Calc!B7 | B73: =IF(_Calc!A7="",NA(),IF(AND(2>0,_Calc!H7<=0.005,_Calc!H6<=0.005),NA(),_Calc!H7))
A74: =_Calc!B8 | B74: =IF(_Calc!A8="",NA(),IF(AND(3>0,_Calc!H8<=0.005,_Calc!H7<=0.005),NA(),_Calc!H8))
A75: =_Calc!B9 | B75: =IF(_Calc!A9="",NA(),IF(AND(4>0,_Calc!H9<=0.005,_Calc!H8<=0.005),NA(),_Calc!H9))
A76: =_Calc!B10 | B76: =IF(_Calc!A10="",NA(),IF(AND(5>0,_Calc!H10<=0.005,_Calc!H9<=0.005),NA(),_Calc!H10))
A77: =_Calc!B11 | B77: =IF(_Calc!A11="",NA(),IF(AND(6>0,_Calc!H11<=0.005,_Calc!H10<=0.005),NA(),_Calc!H11))
A78: =_Calc!B12 | B78: =IF(_Calc!A12="",NA(),IF(AND(7>0,_Calc!H12<=0.005,_Calc!H11<=0.005),NA(),_Calc!H12))
A79: =_Calc!B13 | B79: =IF(_Calc!A13="",NA(),IF(AND(8>0,_Calc!H13<=0.005,_Calc!H12<=0.005),NA(),_Calc!H13))
A80: =_Calc!B14 | B80: =IF(_Calc!A14="",NA(),IF(AND(9>0,_Calc!H14<=0.005,_Calc!H13<=0.005),NA(),_Calc!H14))
A81: =_Calc!B15 | B81: =IF(_Calc!A15="",NA(),IF(AND(10>0,_Calc!H15<=0.005,_Calc!H14<=0.005),NA(),_Calc!H15))
A82: =_Calc!B16 | B82: =IF(_Calc!A16="",NA(),IF(AND(11>0,_Calc!H16<=0.005,_Calc!H15<=0.005),NA(),_Calc!H16))
A83: =_Calc!B17 | B83: =IF(_Calc!A17="",NA(),IF(AND(12>0,_Calc!H17<=0.005,_Calc!H16<=0.005),NA(),_Calc!H17))
A84: =_Calc!B18 | B84: =IF(_Calc!A18="",NA(),IF(AND(13>0,_Calc!H18<=0.005,_Calc!H17<=0.005),NA(),_Calc!H18))
...

Sheet Debt List
A1: Debt List
A2: Blue = type. Gray = calculated. Empty name = unused slot. Update Current balance when you pay (the Payment Log is a journal, not an automatic write-down).
A3: =COUNTA(A5:A12)&" debts · Remaining "&TEXT(SUM(D5:D12),"$#,##0.00")&" · Minimums "&TEXT(SUM(F5:F12),"$#,##0.00")&" · + extra "&TEXT(ExtraPayment,"$#,##0.00")&" = "&TEXT(SUM(F5:F12)+N(ExtraPayment),"$#,##0.00")&" / month · Method: "&Method
A4: Debt name | B4: Creditor | C4: Original balance | D4: Current balance | E4: APR | F4: Min. payment | G4: Due day | H4: Opened | I4: Priority | J4: Logged payments | K4: Order | L4: Snow # | M4: Aval # | N4: Status | O4: Target?
A5: Store card | B5: Target | C5: 850 | D5: 820 | E5: 0.2499 | F5: 35 | G5: 15 | H5: 45717 | I5: 1 | J5: =IF(A5="","",SUMIFS('Payment Log'!$C$5:$C$104,'Payment Log'!$B$5:$B$104,A5)) | K5: =IF(A5="","",IF(Method="Avalanche",COUNTIF($Q$5:$Q$12,"<"&Q5)+1,IF(Method="Custom",COUNTIF($R$5:$R$12,"<"&R5)+1,COUNTIF($P$5:$P$12,"<"&P5)+1))) | L5: =IF(A5="","",COUNTIF($P$5:$P$12,"<"&P5)+1) | M5: =IF(A5="","",COUNTIF($Q$5:$Q$12,"<"&Q5)+1) | N5: =IF(A5="","",IF(N(D5)<=0.005,"Paid off","Active")) | O5: =IF(A5="","",IF(AND(N5="Active",K5=1),"Yes","")) | P5: =IF(A5="","",IF(N(D5)<=0.005,99+ROW()/100,N(D5)+ROW()/100000)) | Q5: =IF(A5="","",IF(N(D5)<=0.005,99+ROW()/100,-N(E5)+ROW()/100000)) | R5: =IF(A5="","",IF(N(D5)<=0.005,99+ROW()/100,IF(I5="",50,N(I5))+ROW()/100000)) | S5: =IF(OR(A5="",N(D5)<=0,N(F5)<=0),"",IF(N(F5)<=N(D5)*N(E5)/12,"Never",N(F5)*NPER(N(E5)/12,N(F5),-N(D5))-N(D5))) | T5: =IF(OR(A5="",S5="",S5="Never"),"",NPER(N(E5)/12,N(F5),-N(D5)))
A6: Visa | B6: Chase | C6: 3200 | D6: 3050 | E6: 0.2199 | F6: 80 | G6: 8 | H6: 45078 | I6: 2 | J6: =IF(A6="","",SUMIFS('Payment Log'!$C$5:$C$104,'Payment Log'!$B$5:$B$104,A6)) | K6: =IF(A6="","",IF(Method="Avalanche",COUNTIF($Q$5:$Q$12,"<"&Q6)+1,IF(Method="Custom",COUNTIF($R$5:$R$12,"<"&R6)+1,COUNTIF($P$5:$P$12,"<"&P6)+1))) | L6: =IF(A6="","",COUNTIF($P$5:$P$12,"<"&P6)+1) | M6: =IF(A6="","",COUNTIF($Q$5:$Q$12,"<"&Q6)+1) | N6: =IF(A6="","",IF(N(D6)<=0.005,"Paid off","Active")) | O6: =IF(A6="","",IF(AND(N6="Active",K6=1),"Yes","")) | P6: =IF(A6="","",IF(N(D6)<=0.005,99+ROW()/100,N(D6)+ROW()/100000)) | Q6: =IF(A6="","",IF(N(D6)<=0.005,99+ROW()/100,-N(E6)+ROW()/100000)) | R6: =IF(A6="","",IF(N(D6)<=0.005,99+ROW()/100,IF(I6="",50,N(I6))+ROW()/100000)) | S6: =IF(OR(A6="",N(D6)<=0,N(F6)<=0),"",IF(N(F6)<=N(D6)*N(E6)/12,"Never",N(F6)*NPER(N(E6)/12,N(F6),-N(D6))-N(D6))) | T6: =IF(OR(A6="",S6="",S6="Never"),"",NPER(N(E6)/12,N(F6),-N(D6)))
A7: Mastercard | B7: Citi | C7: 1450 | D7: 1380 | E7: 0.1999 | F7: 40 | G7: 22 | H7: 45292 | I7: 3 | J7: =IF(A7="","",SUMIFS('Payment Log'!$C$5:$C$104,'Payment Log'!$B$5:$B$104,A7)) | K7: =IF(A7="","",IF(Method="Avalanche",COUNTIF($Q$5:$Q$12,"<"&Q7)+1,IF(Method="Custom",COUNTIF($R$5:$R$12,"<"&R7)+1,COUNTIF($P$5:$P$12,"<"&P7)+1))) | L7: =IF(A7="","",COUNTIF($P$5:$P$12,"<"&P7)+1) | M7: =IF(A7="","",COUNTIF($Q$5:$Q$12,"<"&Q7)+1) | N7: =IF(A7="","",IF(N(D7)<=0.005,"Paid off","Active")) | O7: =IF(A7="","",IF(AND(N7="Active",K7=1),"Yes","")) | P7: =IF(A7="","",IF(N(D7)<=0.005,99+ROW()/100,N(D7)+ROW()/100000)) | Q7: =IF(A7="","",IF(N(D7)<=0.005,99+ROW()/100,-N(E7)+ROW()/100000)) | R7: =IF(A7="","",IF(N(D7)<=0.005,99+ROW()/100,IF(I7="",50,N(I7))+ROW()/100000)) | S7: =IF(OR(A7="",N(D7)<=0,N(F7)<=0),"",IF(N(F7)<=N(D7)*N(E7)/12,"Never",N(F7)*NPER(N(E7)/12,N(F7),-N(D7))-N(D7))) | T7: =IF(OR(A7="",S7="",S7="Never"),"",NPER(N(E7)/12,N(F7),-N(D7)))
A8: Car loan | B8: Credit union | C8: 12400 | D8: 8400 | E8: 0.065 | F8: 265 | G8: 3 | H8: 45536 | I8: 4 | J8: =IF(A8="","",SUMIFS('Payment Log'!$C$5:$C$104,'Payment Log'!$B$5:$B$104,A8)) | K8: =IF(A8="","",IF(Method="Avalanche",COUNTIF($Q$5:$Q$12,"<"&Q8)+1,IF(Method="Custom",COUNTIF($R$5:$R$12,"<"&R8)+1,COUNTIF($P$5:$P$12,"<"&P8)+1))) | L8: =IF(A8="","",COUNTIF($P$5:$P$12,"<"&P8)+1) | M8: =IF(A8="","",COUNTIF($Q$5:$Q$12,"<"&Q8)+1) | N8: =IF(A8="","",IF(N(D8)<=0.005,"Paid off","Active")) | O8: =IF(A8="","",IF(AND(N8="Active",K8=1),"Yes","")) | P8: =IF(A8="","",IF(N(D8)<=0.005,99+ROW()/100,N(D8)+ROW()/100000)) | Q8: =IF(A8="","",IF(N(D8)<=0.005,99+ROW()/100,-N(E8)+ROW()/100000)) | R8: =IF(A8="","",IF(N(D8)<=0.005,99+ROW()/100,IF(I8="",50,N(I8))+ROW()/100000)) | S8: =IF(OR(A8="",N(D8)<=0,N(F8)<=0),"",IF(N(F8)<=N(D8)*N(E8)/12,"Never",N(F8)*NPER(N(E8)/12,N(F8),-N(D8))-N(D8))) | T8: =IF(OR(A8="",S8="",S8="Never"),"",NPER(N(E8)/12,N(F8),-N(D8)))
A9: Student loan | B9: Mohela | C9: 15800 | D9: 12600 | E9: 0.055 | F9: 145 | G9: 28 | H9: 43709 | I9: 5 | J9: =IF(A9="","",SUMIFS('Payment Log'!$C$5:$C$104,'Payment Log'!$B$5:$B$104,A9)) | K9: =IF(A9="","",IF(Method="Avalanche",COUNTIF($Q$5:$Q$12,"<"&Q9)+1,IF(Method="Custom",COUNTIF($R$5:$R$12,"<"&R9)+1,COUNTIF($P$5:$P$12,"<"&P9)+1))) | L9: =IF(A9="","",COUNTIF($P$5:$P$12,"<"&P9)+1) | M9: =IF(A9="","",COUNTIF($Q$5:$Q$12,"<"&Q9)+1) | N9: =IF(A9="","",IF(N(D9)<=0.005,"Paid off","Active")) | O9: =IF(A9="","",IF(AND(N9="Active",K9=1),"Yes","")) | P9: =IF(A9="","",IF(N(D9)<=0.005,99+ROW()/100,N(D9)+ROW()/100000)) | Q9: =IF(A9="","",IF(N(D9)<=0.005,99+ROW()/100,-N(E9)+ROW()/100000)) | R9: =IF(A9="","",IF(N(D9)<=0.005,99+ROW()/100,IF(I9="",50,N(I9))+ROW()/100000)) | S9: =IF(OR(A9="",N(D9)<=0,N(F9)<=0),"",IF(N(F9)<=N(D9)*N(E9)/12,"Never",N(F9)*NPER(N(E9)/12,N(F9),-N(D9))-N(D9))) | T9: =IF(OR(A9="",S9="",S9="Never"),"",NPER(N(E9)/12,N(F9),-N(D9)))
A10: Personal loan | B10: SoFi | C10: 2500 | D10: 2100 | E10: 0.119 | F10: 75 | G10: 12 | H10: 45962 | I10: 6 | J10: =IF(A10="","",SUMIFS('Payment Log'!$C$5:$C$104,'Payment Log'!$B$5:$B$104,A10)) | K10: =IF(A10="","",IF(Method="Avalanche",COUNTIF($Q$5:$Q$12,"<"&Q10)+1,IF(Method="Custom",COUNTIF($R$5:$R$12,"<"&R10)+1,COUNTIF($P$5:$P$12,"<"&P10)+1))) | L10: =IF(A10="","",COUNTIF($P$5:$P$12,"<"&P10)+1) | M10: =IF(A10="","",COUNTIF($Q$5:$Q$12,"<"&Q10)+1) | N10: =IF(A10="","",IF(N(D10)<=0.005,"Paid off","Active")) | O10: =IF(A10="","",IF(AND(N10="Active",K10=1),"Yes","")) | P10: =IF(A10="","",IF(N(D10)<=0.005,99+ROW()/100,N(D10)+ROW()/100000)) | Q10: =IF(A10="","",IF(N(D10)<=0.005,99+ROW()/100,-N(E10)+ROW()/100000)) | R10: =IF(A10="","",IF(N(D10)<=0.005,99+ROW()/100,IF(I10="",50,N(I10))+ROW()/100000)) | S10: =IF(OR(A10="",N(D10)<=0,N(F10)<=0),"",IF(N(F10)<=N(D10)*N(E10)/12,"Never",N(F10)*NPER(N(E10)/12,N(F10),-N(D10))-N(D10))) | T10: =IF(OR(A10="",S10="",S10="Never"),"",NPER(N(E10)/12,N(F10),-N(D10)))
J11: =IF(A11="","",SUMIFS('Payment Log'!$C$5:$C$104,'Payment Log'!$B$5:$B$104,A11)) | K11: =IF(A11="","",IF(Method="Avalanche",COUNTIF($Q$5:$Q$12,"<"&Q11)+1,IF(Method="Custom",COUNTIF($R$5:$R$12,"<"&R11)+1,COUNTIF($P$5:$P$12,"<"&P11)+1))) | L11: =IF(A11="","",COUNTIF($P$5:$P$12,"<"&P11)+1) | M11: =IF(A11="","",COUNTIF($Q$5:$Q$12,"<"&Q11)+1) | N11: =IF(A11="","",IF(N(D11)<=0.005,"Paid off","Active")) | O11: =IF(A11="","",IF(AND(N11="Active",K11=1),"Yes","")) | P11: =IF(A11="","",IF(N(D11)<=0.005,99+ROW()/100,N(D11)+ROW()/100000)) | Q11: =IF(A11="","",IF(N(D11)<=0.005,99+ROW()/100,-N(E11)+ROW()/100000)) | R11: =IF(A11="","",IF(N(D11)<=0.005,99+ROW()/100,IF(I11="",50,N(I11))+ROW()/100000)) | S11: =IF(OR(A11="",N(D11)<=0,N(F11)<=0),"",IF(N(F11)<=N(D11)*N(E11)/12,"Never",N(F11)*NPER(N(E11)/12,N(F11),-N(D11))-N(D11))) | T11: =IF(OR(A11="",S11="",S11="Never"),"",NPER(N(E11)/12,N(F11),-N(D11)))
J12: =IF(A12="","",SUMIFS('Payment Log'!$C$5:$C$104,'Payment Log'!$B$5:$B$104,A12)) | K12: =IF(A12="","",IF(Method="Avalanche",COUNTIF($Q$5:$Q$12,"<"&Q12)+1,IF(Method="Custom",COUNTIF($R$5:$R$12,"<"&R12)+1,COUNTIF($P$5:$P$12,"<"&P12)+1))) | L12: =IF(A12="","",COUNTIF($P$5:$P$12,"<"&P12)+1) | M12: =IF(A12="","",COUNTIF($Q$5:$Q$12,"<"&Q12)+1) | N12: =IF(A12="","",IF(N(D12)<=0.005,"Paid off","Active")) | O12: =IF(A12="","",IF(AND(N12="Active",K12=1),"Yes","")) | P12: =IF(A12="","",IF(N(D12)<=0.005,99+ROW()/100,N(D12)+ROW()/100000)) | Q12: =IF(A12="","",IF(N(D12)<=0.005,99+ROW()/100,-N(E12)+ROW()/100000)) | R12: =IF(A12="","",IF(N(D12)<=0.005,99+ROW()/100,IF(I12="",50,N(I12))+ROW()/100000)) | S12: =IF(OR(A12="",N(D12)<=0,N(F12)<=0),"",IF(N(F12)<=N(D12)*N(E12)/12,"Never",N(F12)*NPER(N(E12)/12,N(F12),-N(D12))-N(D12))) | T12: =IF(OR(A12="",S12="",S12="Never"),"",NPER(N(E12)/12,N(F12),-N(D12)))
A13: TOTAL | C13: =SUM(C5:C12) | D13: =SUM(D5:D12) | F13: =SUM(F5:F12) | J13: =SUM(J5:J12)
A15: Snowball attacks the lowest balance first (quick wins). Avalanche attacks the highest APR first (less interest). Custom uses the Priority column. Add a debt in the next blank blue row (up to 8).

Sheet Payoff Schedule
A1: Payoff Schedule
A2: ="Method: "&Method&" · Extra "&TEXT(ExtraPayment,"$#,##0.00")&"/mo · Starting "&TEXT(PlanStart,"mmm yyyy")&" · Gray rows are calculated. This follows the Order column on Debt List."
A3: =IF(OR(PayoffDate="",PayoffDate="Beyond 120 mo"),"Not paid off within 120 months — raise Extra payment.","Debt-free "&TEXT(PayoffDate,"mmm yyyy")&" · Interest on this plan "&TEXT(PlanInterest,"$#,##0.00"))
A4: # | B4: Month | C4: Target debt | D4: Paid | E4: Interest | F4: Cum. interest | G4: Remaining | H4: Debts left | I4: =IF(INDEX(DebtNames,1)="","Debt 1",INDEX(DebtNames,1)) | J4: =IF(INDEX(DebtNames,2)="","Debt 2",INDEX(DebtNames,2)) | K4: =IF(INDEX(DebtNames,3)="","Debt 3",INDEX(DebtNames,3)) | L4: =IF(INDEX(DebtNames,4)="","Debt 4",INDEX(DebtNames,4)) | M4: =IF(INDEX(DebtNames,5)="","Debt 5",INDEX(DebtNames,5)) | N4: =IF(INDEX(DebtNames,6)="","Debt 6",INDEX(DebtNames,6)) | O4: =IF(INDEX(DebtNames,7)="","Debt 7",INDEX(DebtNames,7)) | P4: =IF(INDEX(DebtNames,8)="","Debt 8",INDEX(DebtNames,8))
A5: =_Calc!A5 | B5: =_Calc!B5 | C5: =_Calc!C5 | D5: =_Calc!E5 | E5: =_Calc!F5 | F5: =_Calc!G5 | G5: =_Calc!H5 | H5: =_Calc!I5 | I5: =IF(INDEX(DebtNames,1)="","",_Calc!M5) | J5: =IF(INDEX(DebtNames,2)="","",_Calc!Q5) | K5: =IF(INDEX(DebtNames,3)="","",_Calc!U5) | L5: =IF(INDEX(DebtNames,4)="","",_Calc!Y5) | M5: =IF(INDEX(DebtNames,5)="","",_Calc!AC5) | N5: =IF(INDEX(DebtNames,6)="","",_Calc!AG5) | O5: =IF(INDEX(DebtNames,7)="","",_Calc!AK5) | P5: =IF(INDEX(DebtNames,8)="","",_Calc!AO5)
A6: =_Calc!A6 | B6: =_Calc!B6 | C6: =_Calc!C6 | D6: =_Calc!E6 | E6: =_Calc!F6 | F6: =_Calc!G6 | G6: =_Calc!H6 | H6: =_Calc!I6 | I6: =IF(INDEX(DebtNames,1)="","",_Calc!M6) | J6: =IF(INDEX(DebtNames,2)="","",_Calc!Q6) | K6: =IF(INDEX(DebtNames,3)="","",_Calc!U6) | L6: =IF(INDEX(DebtNames,4)="","",_Calc!Y6) | M6: =IF(INDEX(DebtNames,5)="","",_Calc!AC6) | N6: =IF(INDEX(DebtNames,6)="","",_Calc!AG6) | O6: =IF(INDEX(DebtNames,7)="","",_Calc!AK6) | P6: =IF(INDEX(DebtNames,8)="","",_Calc!AO6)
A7: =_Calc!A7 | B7: =_Calc!B7 | C7: =_Calc!C7 | D7: =_Calc!E7 | E7: =_Calc!F7 | F7: =_Calc!G7 | G7: =_Calc!H7 | H7: =_Calc!I7 | I7: =IF(INDEX(DebtNames,1)="","",_Calc!M7) | J7: =IF(INDEX(DebtNames,2)="","",_Calc!Q7) | K7: =IF(INDEX(DebtNames,3)="","",_Calc!U7) | L7: =IF(INDEX(DebtNames,4)="","",_Calc!Y7) | M7: =IF(INDEX(DebtNames,5)="","",_Calc!AC7) | N7: =IF(INDEX(DebtNames,6)="","",_Calc!AG7) | O7: =IF(INDEX(DebtNames,7)="","",_Calc!AK7) | P7: =IF(INDEX(DebtNames,8)="","",_Calc!AO7)
A8: =_Calc!A8 | B8: =_Calc!B8 | C8: =_Calc!C8 | D8: =_Calc!E8 | E8: =_Calc!F8 | F8: =_Calc!G8 | G8: =_Calc!H8 | H8: =_Calc!I8 | I8: =IF(INDEX(DebtNames,1)="","",_Calc!M8) | J8: =IF(INDEX(DebtNames,2)="","",_Calc!Q8) | K8: =IF(INDEX(DebtNames,3)="","",_Calc!U8) | L8: =IF(INDEX(DebtNames,4)="","",_Calc!Y8) | M8: =IF(INDEX(DebtNames,5)="","",_Calc!AC8) | N8: =IF(INDEX(DebtNames,6)="","",_Calc!AG8) | O8: =IF(INDEX(DebtNames,7)="","",_Calc!AK8) | P8: =IF(INDEX(DebtNames,8)="","",_Calc!AO8)
A9: =_Calc!A9 | B9: =_Calc!B9 | C9: =_Calc!C9 | D9: =_Calc!E9 | E9: =_Calc!F9 | F9: =_Calc!G9 | G9: =_Calc!H9 | H9: =_Calc!I9 | I9: =IF(INDEX(DebtNames,1)="","",_Calc!M9) | J9: =IF(INDEX(DebtNames,2)="","",_Calc!Q9) | K9: =IF(INDEX(DebtNames,3)="","",_Calc!U9) | L9: =IF(INDEX(DebtNames,4)="","",_Calc!Y9) | M9: =IF(INDEX(DebtNames,5)="","",_Calc!AC9) | N9: =IF(INDEX(DebtNames,6)="","",_Calc!AG9) | O9: =IF(INDEX(DebtNames,7)="","",_Calc!AK9) | P9: =IF(INDEX(DebtNames,8)="","",_Calc!AO9)
A10: =_Calc!A10 | B10: =_Calc!B10 | C10: =_Calc!C10 | D10: =_Calc!E10 | E10: =_Calc!F10 | F10: =_Calc!G10 | G10: =_Calc!H10 | H10: =_Calc!I10 | I10: =IF(INDEX(DebtNames,1)="","",_Calc!M10) | J10: =IF(INDEX(DebtNames,2)="","",_Calc!Q10) | K10: =IF(INDEX(DebtNames,3)="","",_Calc!U10) | L10: =IF(INDEX(DebtNames,4)="","",_Calc!Y10) | M10: =IF(INDEX(DebtNames,5)="","",_Calc!AC10) | N10: =IF(INDEX(DebtNames,6)="","",_Calc!AG10) | O10: =IF(INDEX(DebtNames,7)="","",_Calc!AK10) | P10: =IF(INDEX(DebtNames,8)="","",_Calc!AO10)
A11: =_Calc!A11 | B11: =_Calc!B11 | C11: =_Calc!C11 | D11: =_Calc!E11 | E11: =_Calc!F11 | F11: =_Calc!G11 | G11: =_Calc!H11 | H11: =_Calc!I11 | I11: =IF(INDEX(DebtNames,1)="","",_Calc!M11) | J11: =IF(INDEX(DebtNames,2)="","",_Calc!Q11) | K11: =IF(INDEX(DebtNames,3)="","",_Calc!U11) | L11: =IF(INDEX(DebtNames,4)="","",_Calc!Y11) | M11: =IF(INDEX(DebtNames,5)="","",_Calc!AC11) | N11: =IF(INDEX(DebtNames,6)="","",_Calc!AG11) | O11: =IF(INDEX(DebtNames,7)="","",_Calc!AK11) | P11: =IF(INDEX(DebtNames,8)="","",_Calc!AO11)
A12: =_Calc!A12 | B12: =_Calc!B12 | C12: =_Calc!C12 | D12: =_Calc!E12 | E12: =_Calc!F12 | F12: =_Calc!G12 | G12: =_Calc!H12 | H12: =_Calc!I12 | I12: =IF(INDEX(DebtNames,1)="","",_Calc!M12) | J12: =IF(INDEX(DebtNames,2)="","",_Calc!Q12) | K12: =IF(INDEX(DebtNames,3)="","",_Calc!U12) | L12: =IF(INDEX(DebtNames,4)="","",_Calc!Y12) | M12: =IF(INDEX(DebtNames,5)="","",_Calc!AC12) | N12: =IF(INDEX(DebtNames,6)="","",_Calc!AG12) | O12: =IF(INDEX(DebtNames,7)="","",_Calc!AK12) | P12: =IF(INDEX(DebtNames,8)="","",_Calc!AO12)
A13: =_Calc!A13 | B13: =_Calc!B13 | C13: =_Calc!C13 | D13: =_Calc!E13 | E13: =_Calc!F13 | F13: =_Calc!G13 | G13: =_Calc!H13 | H13: =_Calc!I13 | I13: =IF(INDEX(DebtNames,1)="","",_Calc!M13) | J13: =IF(INDEX(DebtNames,2)="","",_Calc!Q13) | K13: =IF(INDEX(DebtNames,3)="","",_Calc!U13) | L13: =IF(INDEX(DebtNames,4)="","",_Calc!Y13) | M13: =IF(INDEX(DebtNames,5)="","",_Calc!AC13) | N13: =IF(INDEX(DebtNames,6)="","",_Calc!AG13) | O13: =IF(INDEX(DebtNames,7)="","",_Calc!AK13) | P13: =IF(INDEX(DebtNames,8)="","",_Calc!AO13)
A14: =_Calc!A14 | B14: =_Calc!B14 | C14: =_Calc!C14 | D14: =_Calc!E14 | E14: =_Calc!F14 | F14: =_Calc!G14 | G14: =_Calc!H14 | H14: =_Calc!I14 | I14: =IF(INDEX(DebtNames,1)="","",_Calc!M14) | J14: =IF(INDEX(DebtNames,2)="","",_Calc!Q14) | K14: =IF(INDEX(DebtNames,3)="","",_Calc!U14) | L14: =IF(INDEX(DebtNames,4)="","",_Calc!Y14) | M14: =IF(INDEX(DebtNames,5)="","",_Calc!AC14) | N14: =IF(INDEX(DebtNames,6)="","",_Calc!AG14) | O14: =IF(INDEX(DebtNames,7)="","",_Calc!AK14) | P14: =IF(INDEX(DebtNames,8)="","",_Calc!AO14)
A15: =_Calc!A15 | B15: =_Calc!B15 | C15: =_Calc!C15 | D15: =_Calc!E15 | E15: =_Calc!F15 | F15: =_Calc!G15 | G15: =_Calc!H15 | H15: =_Calc!I15 | I15: =IF(INDEX(DebtNames,1)="","",_Calc!M15) | J15: =IF(INDEX(DebtNames,2)="","",_Calc!Q15) | K15: =IF(INDEX(DebtNames,3)="","",_Calc!U15) | L15: =IF(INDEX(DebtNames,4)="","",_Calc!Y15) | M15: =IF(INDEX(DebtNames,5)="","",_Calc!AC15) | N15: =IF(INDEX(DebtNames,6)="","",_Calc!AG15) | O15: =IF(INDEX(DebtNames,7)="","",_Calc!AK15) | P15: =IF(INDEX(DebtNames,8)="","",_Calc!AO15)
A16: =_Calc!A16 | B16: =_Calc!B16 | C16: =_Calc!C16 | D16: =_Calc!E16 | E16: =_Calc!F16 | F16: =_Calc!G16 | G16: =_Calc!H16 | H16: =_Calc!I16 | I16: =IF(INDEX(DebtNames,1)="","",_Calc!M16) | J16: =IF(INDEX(DebtNames,2)="","",_Calc!Q16) | K16: =IF(INDEX(DebtNames,3)="","",_Calc!U16) | L16: =IF(INDEX(DebtNames,4)="","",_Calc!Y16) | M16: =IF(INDEX(DebtNames,5)="","",_Calc!AC16) | N16: =IF(INDEX(DebtNames,6)="","",_Calc!AG16) | O16: =IF(INDEX(DebtNames,7)="","",_Calc!AK16) | P16: =IF(INDEX(DebtNames,8)="","",_Calc!AO16)
... A124: =_Calc!A124 | B124: =_Calc!B124 | C124: =_Calc!C124 | D124: =_Calc!E124 | E124: =_Calc!F124 | F124: =_Calc!G124 | G124: =_Calc!H124 | H124: =_Calc!I124 | I124: =IF(INDEX(DebtNames,1)="","",_Calc!M124) | J124: =IF(INDEX(DebtNames,2)="","",_Calc!Q124) | K124: =IF(INDEX(DebtNames,3)="","",_Calc!U124) | L124: =IF(INDEX(DebtNames,4)="","",_Calc!Y124) | M124: =IF(INDEX(DebtNames,5)="","",_Calc!AC124) | N124: =IF(INDEX(DebtNames,6)="","",_Calc!AG124) | O124: =IF(INDEX(DebtNames,7)="","",_Calc!AK124) | P124: =IF(INDEX(DebtNames,8)="","",_Calc!AO124)

Sheet Payment Log
A1: Payment Log
A2: Journal of payments you actually sent. It does not change the projection — update Current balance on the Debt List after you pay. Use it to stay honest.
A3: ="Logged: "&TEXT(SUM(C5:C104),"$#,##0.00")&" · "&COUNTA(A5:A104)&" payments"
A4: Date | B4: Debt | C4: Amount | D4: Notes
A5: 46237 | B5: Store card | C5: 35 | D5: Minimum
A6: 46242 | B6: Visa | C6: 80 | D6: Minimum
A7: 46242 | B7: Mastercard | C7: 40 | D7: Minimum
A8: 46237 | B8: Car loan | C8: 265 | D8: Minimum
A9: 46246 | B9: Student loan | C9: 145 | D9: Minimum
A10: 46246 | B10: Personal loan | C10: 75 | D10: Minimum
A11: 46249 | B11: Store card | C11: 200 | D11: Extra — snowball
A105: TOTAL | C105: =SUM(C5:C104)

Sheet Snowball vs Avalanche
A1: Snowball vs Avalanche
A2: Same debts, same extra payment, two attack orders. Snowball = smallest balance first. Avalanche = highest interest rate first. Neither changes your minimums.
A3: SNOWBALL — lowest balance first | E3: AVALANCHE — highest APR first | I3: WHICH WINS?
A4: Metric | B4: Snowball | E4: Avalanche | I4: Better on this metric
A5: Debt-free date | B5: =SnowDate | E5: =AvalDate | I5: =IF(OR(SnowDate="Beyond 120 mo",AvalDate="Beyond 120 mo"),"—",IF(SnowDate<AvalDate,"Snowball",IF(AvalDate<SnowDate,"Avalanche","Tie")))
A6: Months to freedom | B6: =SnowMonths | E6: =AvalMonths | I6: =IF(N(SnowMonths)<N(AvalMonths),"Snowball",IF(N(AvalMonths)<N(SnowMonths),"Avalanche","Tie"))
A7: Total interest | B7: =SnowInt | E7: =AvalInt | I7: =IF(N(SnowInt)<N(AvalInt),"Snowball",IF(N(AvalInt)<N(SnowInt),"Avalanche","Tie"))
A8: Total paid | B8: =SnowPaid | E8: =AvalPaid | I8: =IF(N(SnowPaid)<N(AvalPaid),"Snowball",IF(N(AvalPaid)<N(SnowPaid),"Avalanche","Tie"))
A9: Interest vs minimums only | B9: =IF(MinOnlyInt="","",MinOnlyInt-SnowInt) | E9: =IF(MinOnlyInt="","",MinOnlyInt-AvalInt) | I9: =IF(OR(MinOnlyInt="",MinOnlyInt="Never"),"—",IF((MinOnlyInt-SnowInt)>(MinOnlyInt-AvalInt),"Snowball",IF((MinOnlyInt-AvalInt)>(MinOnlyInt-SnowInt),"Avalanche","Tie")))
A10: Minimums-only interest (no extra) | B10: =MinOnlyInt | E10: =MinOnlyInt | I10: Same baseline
A12: HOW TO CHOOSE
A13: Avalanche usually costs less interest because expensive debt dies first. Snowball usually clears your first account sooner, which some people find easier to stick with. The math is on this sheet. The method you can follow for years is the one that wins. Set Method on the Dashboard to the one you pick — the Payoff Schedule will follow it.
A16: INTEREST COMPARISON
A34: These two engines ignore Custom priority. They always sort by balance (Snowball) or APR (Avalanche) using today’s Current balances. If a card’s minimum does not cover the interest, minimums-only shows Never — extra payment is what makes payoff possible.
A40: Method | B40: Interest
A41: Minimums only | B41: =IF(MinOnlyInt="Never","",MinOnlyInt)
A42: Snowball | B42: =SnowInt
A43: Avalanche | B43: =AvalInt

Sheet Instructions
A1: How to use this template
B2: A payoff plan you can actually follow. Snowball or Avalanche, one extra payment, a date you can circle.
B4: 1. Five-minute start
B5: 1. Open Debt List. Replace the sample debts with yours: name, original balance, what you owe today, APR, and the minimum the lender wants.
B6: 2. Open the Dashboard. Type your name, pick Snowball or Avalanche, enter the extra you can send every month, and set Plan start (usually next month).
B7: 3. Read the four cards: remaining, progress, debt-free date, interest. That date is the schedule, not a wish.
B8: 4. Optional: open Snowball vs Avalanche before you lock a method. Avalanche usually costs less interest. Snowball usually kills the first account sooner.
B9: 5. Each month, send every minimum plus the extra to the highlighted Target. Then log the payments and lower Current balance on the Debt List.
B10: [Screenshot: Dashboard cards — remaining, progress, debt-free date]
B12: 2. Snowball vs Avalanche
B13: Snowball — pay minimums on everything, throw every extra dollar at the smallest balance. When it dies, that minimum joins the extra on the next-smallest. People like it because a debt disappears sooner.
B14: Avalanche — same extra, but the target is the highest APR. Math usually prefers this. You keep the store card longer; you keep less of your money in interest.
B15: Custom — type 1, 2, 3… in Priority on the Debt List if you have a reason the math does not know about (a card you want gone before a move, a loan with a promo rate ending).
... B38: You do not have to fill all eight slots. Empty rows are waiting, not missing.

Sheet _Calc
A1: PLAN (selected method) | CC1: SNOWBALL | FE1: AVALANCHE
A2: =IFERROR(INDEX(B5:B124,MATCH(0,I5:I124,0)),"Beyond 120 mo") | B2: =IFERROR(INDEX(G5:G124,MATCH(0,I5:I124,0)),MAX(G5:G124)) | C2: =SUM(E5:E124) | D2: =IFERROR(MATCH(0,I5:I124,0),"Beyond 120 mo") | E2: =IFERROR(MATCH(COUNTA(DebtNames)-1,I5:I124,0),"") | CC2: =IFERROR(INDEX(CD5:CD124,MATCH(0,CK5:CK124,0)),"Beyond 120 mo") | CD2: =IFERROR(INDEX(CI5:CI124,MATCH(0,CK5:CK124,0)),MAX(CI5:CI124)) | CE2: =SUM(CG5:CG124) | CF2: =IFERROR(MATCH(0,CK5:CK124,0),"Beyond 120 mo") | CG2: =IFERROR(MATCH(COUNTA(DebtNames)-1,CK5:CK124,0),"") | FE2: =IFERROR(INDEX(FF5:FF124,MATCH(0,FM5:FM124,0)),"Beyond 120 mo") | FF2: =IFERROR(INDEX(FK5:FK124,MATCH(0,FM5:FM124,0)),MAX(FK5:FK124)) | FG2: =SUM(FI5:FI124) | FH2: =IFERROR(MATCH(0,FM5:FM124,0),"Beyond 120 mo") | FI2: =IFERROR(MATCH(COUNTA(DebtNames)-1,FM5:FM124,0),"")
A3: Mo | B3: Date | C3: Target | D3: Unused extra | E3: Paid | F3: Interest | G3: Cum int | H3: Remaining | I3: Debts | J3: D1 start | K3: int | L3: pay | M3: end | N3: D2 start | O3: int | P3: pay | Q3: end | R3: D3 start | S3: int | T3: pay | U3: end | V3: D4 start | W3: int | X3: pay | Y3: end | Z3: D5 start | AA3: int | AB3: pay | AC3: end | AD3: D6 start | AE3: int | AF3: pay | AG3: end | AH3: D7 start | AI3: int | AJ3: pay | AK3: end | AL3: D8 start | AM3: int | AN3: pay | AO3: end | AP3: P1 idx | AQ3: need | AR3: ex | AS3: left | AT3: P2 idx | AU3: need | AV3: ex | AW3: left | AX3: P3 idx | AY3: need | AZ3: ex | BA3: left | BB3: P4 idx | BC3: need | BD3: ex | BE3: left | BF3: P5 idx | BG3: need | BH3: ex | BI3: left | BJ3: P6 idx | BK3: need | BL3: ex | BM3: left | BN3: P7 idx | BO3: need | BP3: ex | BQ3: left | BR3: P8 idx | BS3: need | BT3: ex | BU3: left | CC3: Mo | CD3: Date | CE3: Target | CF3: Unused extra | CG3: Paid | CH3: Interest | CI3: Cum int | CJ3: Remaining | CK3: Debts | CL3: D1 start | CM3: int | CN3: pay | CO3: end | CP3: D2 start | CQ3: int | CR3: pay | CS3: end | CT3: D3 start | CU3: int | CV3: pay | CW3: end | CX3: D4 start | CY3: int | CZ3: pay | DA3: end | DB3: D5 start | DC3: int | DD3: pay | DE3: end | DF3: D6 start | DG3: int | DH3: pay | DI3: end | DJ3: D7 start | DK3: int | DL3: pay | DM3: end | DN3: D8 start | DO3: int | DP3: pay | DQ3: end | DR3: P1 idx | DS3: need | DT3: ex | DU3: left | DV3: P2 idx | DW3: need | DX3: ex | DY3: left | DZ3: P3 idx | EA3: need | EB3: ex | EC3: left | ED3: P4 idx | EE3: need | EF3: ex | EG3: left | EH3: P5 idx | EI3: need | EJ3: ex | EK3: left | EL3: P6 idx | EM3: need | EN3: ex | EO3: left | EP3: P7 idx | EQ3: need | ER3: ex | ES3: left | ET3: P8 idx | EU3: need | EV3: ex | EW3: left | FE3: Mo | FF3: Date | FG3: Target | FH3: Unused extra | FI3: Paid | FJ3: Interest | FK3: Cum int | FL3: Remaining | FM3: Debts | FN3: D1 start | FO3: int | FP3: pay | FQ3: end | FR3: D2 start | FS3: int | FT3: pay | FU3: end | FV3: D3 start | FW3: int | FX3: pay | FY3: end | FZ3: D4 start | GA3: int | GB3: pay | GC3: end | GD3: D5 start | GE3: int | GF3: pay | GG3: end | GH3: D6 start | GI3: int | GJ3: pay | GK3: end | GL3: D7 start | GM3: int | GN3: pay | GO3: end | GP3: D8 start | GQ3: int | GR3: pay | GS3: end | GT3: P1 idx | GU3: need | GV3: ex | GW3: left | GX3: P2 idx | GY3: need | GZ3: ex | HA3: left | HB3: P3 idx | HC3: need | HD3: ex | HE3: left | HF3: P4 idx | HG3: need | HH3: ex | HI3: left | HJ3: P5 idx | HK3: need | HL3: ex | HM3: left | HN3: P6 idx | HO3: need | HP3: ex | HQ3: left | HR3: P7 idx | HS3: need | HT3: ex | HU3: left | HV3: P8 idx | HW3: need | HX3: ex | HY3: left
A5: 1 | B5: =DATE(YEAR(PlanStart),MONTH(PlanStart)+A5-1,1) | C5: =IF(AND(AP5<>"",N(CHOOSE(AP5,J5,N5,R5,V5,Z5,AD5,AH5,AL5))>0.005),INDEX(DebtNames,AP5),IF(AND(AT5<>"",N(CHOOSE(AT5,J5,N5,R5,V5,Z5,AD5,AH5,AL5))>0.005),INDEX(DebtNames,AT5),IF(AND(AX5<>"",N(CHOOSE(AX5,J5,N5,R5,V5,Z5,AD5,AH5,AL5))>0.005),INDEX(DebtNames,AX5),IF(AND(BB5<>"",N(CHOOSE(BB5,J5,N5,R5,V5,Z5,AD5,AH5,AL5))>0.005),INDEX(DebtNames,BB5),IF(AND(BF5<>"",N(CHOOSE(BF5,J5,N5,R5,V5,Z5,AD5,AH5,AL5))>0.005),INDEX(DebtNames,BF5),IF(AND(BJ5<>"",N(CHOOSE(BJ5,J5,N5,R5,V5,Z5,AD5,AH5,AL5))>0.005),INDEX(DebtNames,BJ5),IF(AND(BN5<>"",N(CHOOSE(BN5,J5,N5,R5,V5,Z5,AD5,AH5,AL5))>0.005),INDEX(DebtNames,BN5),IF(AND(BR5<>"",N(CHOOSE(BR5,J5,N5,R5,V5,Z5,AD5,AH5,AL5))>0.005),INDEX(DebtNames,BR5),"")))))))) | D5: =N(BU5) | E5: =N(L5)+N(P5)+N(T5)+N(X5)+N(AB5)+N(AF5)+N(AJ5)+N(AN5) | F5: =N(K5)+N(O5)+N(S5)+N(W5)+N(AA5)+N(AE5)+N(AI5)+N(AM5) | G5: =N(F5) | H5: =N(M5)+N(Q5)+N(U5)+N(Y5)+N(AC5)+N(AG5)+N(AK5)+N(AO5) | I5: =(M5>0.005)*1+(Q5>0.005)*1+(U5>0.005)*1+(Y5>0.005)*1+(AC5>0.005)*1+(AG5>0.005)*1+(AK5>0.005)*1+(AO5>0.005)*1 | J5: =N('Debt List'!D5) | K5: =IF(N(J5)<=0.005,0,ROUND(N(J5)*N('Debt List'!E5)/12,2)) | L5: =IF(N(J5)<=0.005,0,MIN(N('Debt List'!F5),N(J5)+N(K5)))+((AP5=1)*AR5+(AT5=1)*AV5+(AX5=1)*AZ5+(BB5=1)*BD5+(BF5=1)*BH5+(BJ5=1)*BL5+(BN5=1)*BP5+(BR5=1)*BT5) | M5: =MAX(0,ROUND(N(J5)+N(K5)-N(L5),2)) | N5: =N('Debt List'!D6) | O5: =IF(N(N5)<=0.005,0,ROUND(N(N5)*N('Debt List'!E6)/12,2)) | P5: =IF(N(N5)<=0.005,0,MIN(N('Debt List'!F6),N(N5)+N(O5)))+((AP5=2)*AR5+(AT5=2)*AV5+(AX5=2)*AZ5+(BB5=2)*BD5+(BF5=2)*BH5+(BJ5=2)*BL5+(BN5=2)*BP5+(BR5=2)*BT5) | Q5: =MAX(0,ROUND(N(N5)+N(O5)-N(P5),2)) | R5: =N('Debt List'!D7) | S5: =IF(N(R5)<=0.005,0,ROUND(N(R5)*N('Debt List'!E7)/12,2)) | T5: =IF(N(R5)<=0.005,0,MIN(N('Debt List'!F7),N(R5)+N(S5)))+((AP5=3)*AR5+(AT5=3)*AV5+(AX5=3)*AZ5+(BB5=3)*BD5+(BF5=3)*BH5+(BJ5=3)*BL5+(BN5=3)*BP5+(BR5=3)*BT5) | U5: =MAX(0,ROUND(N(R5)+N(S5)-N(T5),2)) | V5: =N('Debt List'!D8) | W5: =IF(N(V5)<=0.005,0,ROUND(N(V5)*N('Debt List'!E8)/12,2)) | X5: =IF(N(V5)<=0.005,0,MIN(N('Debt List'!F8),N(V5)+N(W5)))+((AP5=4)*AR5+(AT5=4)*AV5+(AX5=4)*AZ5+(BB5=4)*BD5+(BF5=4)*BH5+(BJ5=4)*BL5+(BN5=4)*BP5+(BR5=4)*BT5) | Y5: =MAX(0,ROUND(N(V5)+N(W5)-N(X5),2)) | Z5: =N('Debt List'!D9) | AA5: =IF(N(Z5)<=0.005,0,ROUND(N(Z5)*N('Debt List'!E9)/12,2)) | AB5: =IF(N(Z5)<=0.005,0,MIN(N('Debt List'!F9),N(Z5)+N(AA5)))+((AP5=5)*AR5+(AT5=5)*AV5+(AX5=5)*AZ5+(BB5=5)*BD5+(BF5=5)*BH5+(BJ5=5)*BL5+(BN5=5)*BP5+(BR5=5)*BT5) | AC5: =MAX(0,ROUND(N(Z5)+N(AA5)-N(AB5),2)) | AD5: =N('Debt List'!D10) | AE5: =IF(N(AD5)<=0.005,0,ROUND(N(AD5)*N('Debt List'!E10)/12,2)) | AF5: =IF(N(AD5)<=0.005,0,MIN(N('Debt List'!F10),N(AD5)+N(AE5)))+((AP5=6)*AR5+(AT5=6)*AV5+(AX5=6)*AZ5+(BB5=6)*BD5+(BF5=6)*BH5+(BJ5=6)*BL5+(BN5=6)*BP5+(BR5=6)*BT5) | AG5: =MAX(0,ROUND(N(AD5)+N(AE5)-N(AF5),2)) | AH5: =N('Debt List'!D11) | AI5: =IF(N(AH5)<=0.005,0,ROUND(N(AH5)*N('Debt List'!E11)/12,2)) | AJ5: =IF(N(AH5)<=0.005,0,MIN(N('Debt List'!F11),N(AH5)+N(AI5)))+((AP5=7)*AR5+(AT5=7)*AV5+(AX5=7)*AZ5+(BB5=7)*BD5+(BF5=7)*BH5+(BJ5=7)*BL5+(BN5=7)*BP5+(BR5=7)*BT5) | AK5: =MAX(0,ROUND(N(AH5)+N(AI5)-N(AJ5),2)) | AL5: =N('Debt List'!D12) | AM5: =IF(N(AL5)<=0.005,0,ROUND(N(AL5)*N('Debt List'!E12)/12,2)) | AN5: =IF(N(AL5)<=0.005,0,MIN(N('Debt List'!F12),N(AL5)+N(AM5)))+((AP5=8)*AR5+(AT5=8)*AV5+(AX5=8)*AZ5+(BB5=8)*BD5+(BF5=8)*BH5+(BJ5=8)*BL5+(BN5=8)*BP5+(BR5=8)*BT5) | AO5: =MAX(0,ROUND(N(AL5)+N(AM5)-N(AN5),2)) | AP5: =IFERROR(MATCH(1,OrderPlan,0),"") | AQ5: =IF(AP5="",0,IFERROR(IF(N(CHOOSE(AP5,J5,N5,R5,V5,Z5,AD5,AH5,AL5))<=0.005,0,MAX(0,N(CHOOSE(AP5,J5,N5,R5,V5,Z5,AD5,AH5,AL5))+N(CHOOSE(AP5,K5,O5,S5,W5,AA5,AE5,AI5,AM5))-MIN(N(CHOOSE(AP5,'Debt List'!$F$5,'Debt List'!$F$6,'Debt List'!$F$7,'Debt List'!$F$8,'Debt List'!$F$9,'Debt List'!$F$10,'Debt List'!$F$11,'Debt List'!$F$12)),N(CHOOSE(AP5,J5,N5,R5,V5,Z5,AD5,AH5,AL5))+N(CHOOSE(AP5,K5,O5,S5,W5,AA5,AE5,AI5,AM5))))),0)) | AR5: =MIN(N(AQ5),MAX(0,N(ExtraPayment))) | AS5: =MAX(0,N(ExtraPayment)-N(AR5)) | AT5: =IFERROR(MATCH(2,OrderPlan,0),"") | AU5: =IF(AT5="",0,IFERROR(IF(N(CHOOSE(AT5,J5,N5,R5,V5,Z5,AD5,AH5,AL5))<=0.005,0,MAX(0,N(CHOOSE(AT5,J5,N5,R5,V5,Z5,AD5,AH5,AL5))+N(CHOOSE(AT5,K5,O5,S5,W5,AA5,AE5,AI5,AM5))-MIN(N(CHOOSE(AT5,'Debt List'!$F$5,'Debt List'!$F$6,'Debt List'!$F$7,'Debt List'!$F$8,'Debt List'!$F$9,'Debt List'!$F$10,'Debt List'!$F$11,'Debt List'!$F$12)),N(CHOOSE(AT5,J5,N5,R5,V5,Z5,AD5,AH5,AL5))+N(CHOOSE(AT5,K5,O5,S5,W5,AA5,AE5,AI5,AM5))))),0)) | AV5: =MIN(N(AU5),MAX(0,N(AS5))) | AW5: =MAX(0,N(AS5)-N(AV5)) | AX5: =IFERROR(MATCH(3,OrderPlan,0),"") | AY5: =IF(AX5="",0,IFERROR(IF(N(CHOOSE(AX5,J5,N5,R5,V5,Z5,AD5,AH5,AL5))<=0.005,0,MAX(0,N(CHOOSE(AX5,J5,N5,R5,V5,Z5,AD5,AH5,AL5))+N(CHOOSE(AX5,K5,O5,S5,W5,AA5,AE5,AI5,AM5))-MIN(N(CHOOSE(AX5,'Debt List'!$F$5,'Debt List'!$F$6,'Debt List'!$F$7,'Debt List'!$F$8,'Debt List'!$F$9,'Debt List'!$F$10,'Debt List'!$F$11,'Debt List'!$F$12)),N(CHOOSE(AX5,J5,N5,R5,V5,Z5,AD5,AH5,AL5))+N(CHOOSE(AX5,K5,O5,S5,W5,AA5,AE5,AI5,AM5))))),0)) | AZ5: =MIN(N(AY5),MAX(0,N(AW5))) | BA5: =MAX(0,N(AW5)-N(AZ5)) | BB5: =IFERROR(MATCH(4,OrderPlan,0),"") | BC5: =IF(BB5="",0,IFERROR(IF(N(CHOOSE(BB5,J5,N5,R5,V5,Z5,AD5,AH5,AL5))<=0.005,0,MAX(0,N(CHOOSE(BB5,J5,N5,R5,V5,Z5,AD5,AH5,AL5))+N(CHOOSE(BB5,K5,O5,S5,W5,AA5,AE5,AI5,AM5))-MIN(N(CHOOSE(BB5,'Debt List'!$F$5,'Debt List'!$F$6,'Debt List'!$F$7,'Debt List'!$F$8,'Debt List'!$F$9,'Debt List'!$F$10,'Debt List'!$F$11,'Debt List'!$F$12)),N(CHOOSE(BB5,J5,N5,R5,V5,Z5,AD5,AH5,AL5))+N(CHOOSE(BB5,K5,O5,S5,W5,AA5,AE5,AI5,AM5))))),0)) | BD5: =MIN(N(BC5),MAX(0,N(BA5))) | BE5: =MAX(0,N(BA5)-N(BD5)) | BF5: =IFERROR(MATCH(5,OrderPlan,0),"") | BG5: =IF(BF5="",0,IFERROR(IF(N(CHOOSE(BF5,J5,N5,R5,V5,Z5,AD5,AH5,AL5))<=0.005,0,MAX(0,N(CHOOSE(BF5,J5,N5,R5,V5,Z5,AD5,AH5,AL5))+N(CHOOSE(BF5,K5,O5,S5,W5,AA5,AE5,AI5,AM5))-MIN(N(CHOOSE(BF5,'Debt List'!$F$5,'Debt List'!$F$6,'Debt List'!$F$7,'Debt List'!$F$8,'Debt List'!$F$9,'Debt List'!$F$10,'Debt List'!$F$11,'Debt List'!$F$12)),N(CHOOSE(BF5,J5,N5,R5,V5,Z5,AD5,AH5,AL5))+N(CHOOSE(BF5,K5,O5,S5,W5,AA5,AE5,AI5,AM5))))),0)) | BH5: =MIN(N(BG5),MAX(0,N(BE5))) | BI5: =MAX(0,N(BE5)-N(BH5)) | BJ5: =IFERROR(MATCH(6,OrderPlan,0),"") | BK5: =IF(BJ5="",0,IFERROR(IF(N(CHOOSE(BJ5,J5,N5,R5,V5,Z5,AD5,AH5,AL5))<=0.005,0,MAX(0,N(CHOOSE(BJ5,J5,N5,R5,V5,Z5,AD5,AH5,AL5))+N(CHOOSE(BJ5,K5,O5,S5,W5,AA5,AE5,AI5,AM5))-MIN(N(CHOOSE(BJ5,'Debt List'!$F$5,'Debt List'!$F$6,'Debt List'!$F$7,'Debt List'!$F$8,'Debt List'!$F$9,'Debt List'!$F$10,'Debt List'!$F$11,'Debt List'!$F$12)),N(CHOOSE(BJ5,J5,N5,R5,V5,Z5,AD5,AH5,AL5))+N(CHOOSE(BJ5,K5,O5,S5,W5,AA5,AE5,AI5,AM5))))),0)) | BL5: =MIN(N(BK5),MAX(0,N(BI5))) | BM5: =MAX(0,N(BI5)-N(BL5)) | BN5: =IFERROR(MATCH(7,OrderPlan,0),"") | BO5: =IF(BN5="",0,IFERROR(IF(N(CHOOSE(BN5,J5,N5,R5,V5,Z5,AD5,AH5,AL5))<=0.005,0,MAX(0,N(CHOOSE(BN5,J5,N5,R5,V5,Z5,AD5,AH5,AL5))+N(CHOOSE(BN5,K5,O5,S5,W5,AA5,AE5,AI5,AM5))-MIN(N(CHOOSE(BN5,'Debt List'!$F$5,'Debt List'!$F$6,'Debt List'!$F$7,'Debt List'!$F$8,'Debt List'!$F$9,'Debt List'!$F$10,'Debt List'!$F$11,'Debt List'!$F$12)),N(CHOOSE(BN5,J5,N5,R5,V5,Z5,AD5,AH5,AL5))+N(CHOOSE(BN5,K5,O5,S5,W5,AA5,AE5,AI5,AM5))))),0)) | BP5: =MIN(N(BO5),MAX(0,N(BM5))) | BQ5: =MAX(0,N(BM5)-N(BP5)) | BR5: =IFERROR(MATCH(8,OrderPlan,0),"") | BS5: =IF(BR5="",0,IFERROR(IF(N(CHOOSE(BR5,J5,N5,R5,V5,Z5,AD5,AH5,AL5))<=0.005,0,MAX(0,N(CHOOSE(BR5,J5,N5,R5,V5,Z5,AD5,AH5,AL5))+N(CHOOSE(BR5,K5,O5,S5,W5,AA5,AE5,AI5,AM5))-MIN(N(CHOOSE(BR5,'Debt List'!$F$5,'Debt List'!$F$6,'Debt List'!$F$7,'Debt List'!$F$8,'Debt List'!$F$9,'Debt List'!$F$10,'Debt List'!$F$11,'Debt List'!$F$12)),N(CHOOSE(BR5,J5,N5,R5,V5,Z5,AD5,AH5,AL5))+N(CHOOSE(BR5,K5,O5,S5,W5,AA5,AE5,AI5,AM5))))),0)) | BT5: =MIN(N(BS5),MAX(0,N(BQ5))) | BU5: =MAX(0,N(BQ5)-N(BT5)) | CC5: 1 | CD5: =DATE(YEAR(PlanStart),MONTH(PlanStart)+CC5-1,1) | CE5: =IF(AND(DR5<>"",N(CHOOSE(DR5,CL5,CP5,CT5,CX5,DB5,DF5,DJ5,DN5))>0.005),INDEX(DebtNames,DR5),IF(AND(DV5<>"",N(CHOOSE(DV5,CL5,CP5,CT5,CX5,DB5,DF5,DJ5,DN5))>0.005),INDEX(DebtNames,DV5),IF(AND(DZ5<>"",N(CHOOSE(DZ5,CL5,CP5,CT5,CX5,DB5,DF5,DJ5,DN5))>0.005),INDEX(DebtNames,DZ5),IF(AND(ED5<>"",N(CHOOSE(ED5,CL5,CP5,CT5,CX5,DB5,DF5,DJ5,DN5))>0.005),INDEX(DebtNames,ED5),IF(AND(EH5<>"",N(CHOOSE(EH5,CL5,CP5,CT5,CX5,DB5,DF5,DJ5,DN5))>0.005),INDEX(DebtNames,EH5),IF(AND(EL5<>"",N(CHOOSE(EL5,CL5,CP5,CT5,CX5,DB5,DF5,DJ5,DN5))>0.005),INDEX(DebtNames,EL5),IF(AND(EP5<>"",N(CHOOSE(EP5,CL5,CP5,CT5,CX5,DB5,DF5,DJ5,DN5))>0.005),INDEX(DebtNames,EP5),IF(AND(ET5<>"",N(CHOOSE(ET5,CL5,CP5,CT5,CX5,DB5,DF5,DJ5,DN5))>0.005),INDEX(DebtNames,ET5),"")))))))) | CF5: =N(EW5) | CG5: =N(CN5)+N(CR5)+N(CV5)+N(CZ5)+N(DD5)+N(DH5)+N(DL5)+N(DP5) | CH5: =N(CM5)+N(CQ5)+N(CU5)+N(CY5)+N(DC5)+N(DG5)+N(DK5)+N(DO5) | CI5: =N(CH5) | CJ5: =N(CO5)+N(CS5)+N(CW5)+N(DA5)+N(DE5)+N(DI5)+N(DM5)+N(DQ5) | CK5: =(CO5>0.005)*1+(CS5>0.005)*1+(CW5>0.005)*1+(DA5>0.005)*1+(DE5>0.005)*1+(DI5>0.005)*1+(DM5>0.005)*1+(DQ5>0.005)*1 | CL5: =N('Debt List'!D5) | CM5: =IF(N(CL5)<=0.005,0,ROUND(N(CL5)*N('Debt List'!E5)/12,2)) | CN5: =IF(N(CL5)<=0.005,0,MIN(N('Debt List'!F5),N(CL5)+N(CM5)))+((DR5=1)*DT5+(DV5=1)*DX5+(DZ5=1)*EB5+(ED5=1)*EF5+(EH5=1)*EJ5+(EL5=1)*EN5+(EP5=1)*ER5+(ET5=1)*EV5) | CO5: =MAX(0,ROUND(N(CL5)+N(CM5)-N(CN5),2)) | CP5: =N('Debt List'!D6) | CQ5: =IF(N(CP5)<=0.005,0,ROUND(N(CP5)*N('Debt List'!E6)/12,2)) | CR5: =IF(N(CP5)<=0.005,0,MIN(N('Debt List'!F6),N(CP5)+N(CQ5)))+((DR5=2)*DT5+(DV5=2)*DX5+(DZ5=2)*EB5+(ED5=2)*EF5+(EH5=2)*EJ5+(EL5=2)*EN5+(EP5=2)*ER5+(ET5=2)*EV5) | CS5: =MAX(0,ROUND(N(CP5)+N(CQ5)-N(CR5),2)) | CT5: =N('Debt List'!D7) | CU5: =IF(N(CT5)<=0.005,0,ROUND(N(CT5)*N('Debt List'!E7)/12,2)) | CV5: =IF(N(CT5)<=0.005,0,MIN(N('Debt List'!F7),N(CT5)+N(CU5)))+((DR5=3)*DT5+(DV5=3)*DX5+(DZ5=3)*EB5+(ED5=3)*EF5+(EH5=3)*EJ5+(EL5=3)*EN5+(EP5=3)*ER5+(ET5=3)*EV5) | CW5: =MAX(0,ROUND(N(CT5)+N(CU5)-N(CV5),2)) | CX5: =N('Debt List'!D8) | CY5: =IF(N(CX5)<=0.005,0,ROUND(N(CX5)*N('Debt List'!E8)/12,2)) | CZ5: =IF(N(CX5)<=0.005,0,MIN(N('Debt List'!F8),N(CX5)+N(CY5)))+((DR5=4)*DT5+(DV5=4)*DX5+(DZ5=4)*EB5+(ED5=4)*EF5+(EH5=4)*EJ5+(EL5=4)*EN5+(EP5=4)*ER5+(ET5=4)*EV5) | DA5: =MAX(0,ROUND(N(CX5)+N(CY5)-N(CZ5),2)) | DB5: =N('Debt List'!D9) | DC5: =IF(N(DB5)<=0.005,0,ROUND(N(DB5)*N('Debt List'!E9)/12,2)) | DD5: =IF(N(DB5)<=0.005,0,MIN(N('Debt List'!F9),N(DB5)+N(DC5)))+((DR5=5)*DT5+(DV5=5)*DX5+(DZ5=5)*EB5+(ED5=5)*EF5+(EH5=5)*EJ5+(EL5=5)*EN5+(EP5=5)*ER5+(ET5=5)*EV5) | DE5: =MAX(0,ROUND(N(DB5)+N(DC5)-N(DD5),2)) | DF5: =N('Debt List'!D10) | DG5: =IF(N(DF5)<=0.005,0,ROUND(N(DF5)*N('Debt List'!E10)/12,2)) | DH5: =IF(N(DF5)<=0.005,0,MIN(N('Debt List'!F10),N(DF5)+N(DG5)))+((DR5=6)*DT5+(DV5=6)*DX5+(DZ5=6)*EB5+(ED5=6)*EF5+(EH5=6)*EJ5+(EL5=6)*EN5+(EP5=6)*ER5+(ET5=6)*EV5) | DI5: =MAX(0,ROUND(N(DF5)+N(DG5)-N(DH5),2)) | DJ5: =N('Debt List'!D11) | DK5: =IF(N(DJ5)<=0.005,0,ROUND(N(DJ5)*N('Debt List'!E11)/12,2)) | DL5: =IF(N(DJ5)<=0.005,0,MIN(N('Debt List'!F11),N(DJ5)+N(DK5)))+((DR5=7)*DT5+(DV5=7)*DX5+(DZ5=7)*EB5+(ED5=7)*EF5+(EH5=7)*EJ5+(EL5=7)*EN5+(EP5=7)*ER5+(ET5=7)*EV5) | DM5: =MAX(0,ROUND(N(DJ5)+N(DK5)-N(DL5),2)) | DN5: =N('Debt List'!D12) | DO5: =IF(N(DN5)<=0.005,0,ROUND(N(DN5)*N('Debt List'!E12)/12,2)) | DP5: =IF(N(DN5)<=0.005,0,MIN(N('Debt List'!F12),N(DN5)+N(DO5)))+((DR5=8)*DT5+(DV5=8)*DX5+(DZ5=8)*EB5+(ED5=8)*EF5+(EH5=8)*EJ5+(EL5=8)*EN5+(EP5=8)*ER5+(ET5=8)*EV5) | DQ5: =MAX(0,ROUND(N(DN5)+N(DO5)-N(DP5),2)) | DR5: =IFERROR(MATCH(1,OrderSnow,0),"") | DS5: =IF(DR5="",0,IFERROR(IF(N(CHOOSE(DR5,CL5,CP5,CT5,CX5,DB5,DF5,DJ5,DN5))<=0.005,0,MAX(0,N(CHOOSE(DR5,CL5,CP5,CT5,CX5,DB5,DF5,DJ5,DN5))+N(CHOOSE(DR5,CM5,CQ5,CU5,CY5,DC5,DG5,DK5,DO5))-MIN(N(CHOOSE(DR5,'Debt List'!$F$5,'Debt List'!$F$6,'Debt List'!$F$7,'Debt List'!$F$8,'Debt List'!$F$9,'Debt List'!$F$10,'Debt List'!$F$11,'Debt List'!$F$12)),N(CHOOSE(DR5,CL5,CP5,CT5,CX5,DB5,DF5,DJ5,DN5))+N(CHOOSE(DR5,CM5,CQ5,CU5,CY5,DC5,DG5,DK5,DO5))))),0)) | DT5: =MIN(N(DS5),MAX(0,N(ExtraPayment))) | DU5: =MAX(0,N(ExtraPayment)-N(DT5)) | DV5: =IFERROR(MATCH(2,OrderSnow,0),"") | DW5: =IF(DV5="",0,IFERROR(IF(N(CHOOSE(DV5,CL5,CP5,CT5,CX5,DB5,DF5,DJ5,DN5))<=0.005,0,MAX(0,N(CHOOSE(DV5,CL5,CP5,CT5,CX5,DB5,DF5,DJ5,DN5))+N(CHOOSE(DV5,CM5,CQ5,CU5,CY5,DC5,DG5,DK5,DO5))-MIN(N(CHOOSE(DV5,'Debt List'!$F$5,'Debt List'!$F$6,'Debt List'!$F$7,'Debt List'!$F$8,'Debt List'!$F$9,'Debt List'!$F$10,'Debt List'!$F$11,'Debt List'!$F$12)),N(CHOOSE(DV5,CL5,CP5,CT5,CX5,DB5,DF5,DJ5,DN5))+N(CHOOSE(DV5,CM5,CQ5,CU5,CY5,DC5,DG5,DK5,DO5))))),0)) | DX5: =MIN(N(DW5),MAX(0,N(DU5))) | DY5: =MAX(0,N(DU5)-N(DX5)) | DZ5: =IFERROR(MATCH(3,OrderSnow,0),"") | EA5: =IF(DZ5="",0,IFERROR(IF(N(CHOOSE(DZ5,CL5,CP5,CT5,CX5,DB5,DF5,DJ5,DN5))<=0.005,0,MAX(0,N(CHOOSE(DZ5,CL5,CP5,CT5,CX5,DB5,DF5,DJ5,DN5))+N(CHOOSE(DZ5,CM5,CQ5,CU5,CY5,DC5,DG5,DK5,DO5))-MIN(N(CHOOSE(DZ5,'Debt List'!$F$5,'Debt List'!$F$6,'Debt List'!$F$7,'Debt List'!$F$8,'Debt List'!$F$9,'Debt List'!$F$10,'Debt List'!$F$11,'Debt List'!$F$12)),N(CHOOSE(DZ5,CL5,CP5,CT5,CX5,DB5,DF5,DJ5,DN5))+N(CHOOSE(DZ5,CM5,CQ5,CU5,CY5,DC5,DG5,DK5,DO5))))),0)) | EB5: =MIN(N(EA5),MAX(0,N(DY5))) | EC5: =MAX(0,N(DY5)-N(EB5)) | ED5: =IFERROR(MATCH(4,OrderSnow,0),"") | EE5: =IF(ED5="",0,IFERROR(IF(N(CHOOSE(ED5,CL5,CP5,CT5,CX5,DB5,DF5,DJ5,DN5))<=0.005,0,MAX(0,N(CHOOSE(ED5,CL5,CP5,CT5,CX5,DB5,DF5,DJ5,DN5))+N(CHOOSE(ED5,CM5,CQ5,CU5,CY5,DC5,DG5,DK5,DO5))-MIN(N(CHOOSE(ED5,'Debt List'!$F$5,'Debt List'!$F$6,'Debt List'!$F$7,'Debt List'!$F$8,'Debt List'!$F$9,'Debt List'!$F$10,'Debt List'!$F$11,'Debt List'!$F$12)),N(CHOOSE(ED5,CL5,CP5,CT5,CX5,DB5,DF5,DJ5,DN5))+N(CHOOSE(ED5,CM5,CQ5,CU5,CY5,DC5,DG5,DK5,DO5))))),0)) | EF5: =MIN(N(EE5),MAX(0,N(EC5))) | EG5: =MAX(0,N(EC5)-N(EF5)) | EH5: =IFERROR(MATCH(5,OrderSnow,0),"") | EI5: =IF(EH5="",0,IFERROR(IF(N(CHOOSE(EH5,CL5,CP5,CT5,CX5,DB5,DF5,DJ5,DN5))<=0.005,0,MAX(0,N(CHOOSE(EH5,CL5,CP5,CT5,CX5,DB5,DF5,DJ5,DN5))+N(CHOOSE(EH5,CM5,CQ5,CU5,CY5,DC5,DG5,DK5,DO5))-MIN(N(CHOOSE(EH5,'Debt List'!$F$5,'Debt List'!$F$6,'Debt List'!$F$7,'Debt List'!$F$8,'Debt List'!$F$9,'Debt List'!$F$10,'Debt List'!$F$11,'Debt List'!$F$12)),N(CHOOSE(EH5,CL5,CP5,CT5,CX5,DB5,DF5,DJ5,DN5))+N(CHOOSE(EH5,CM5,CQ5,CU5,CY5,DC5,DG5,DK5,DO5))))),0)) | EJ5: =MIN(N(EI5),MAX(0,N(EG5))) | EK5: =MAX(0,N(EG5)-N(EJ5)) | EL5: =IFERROR(MATCH(6,OrderSnow,0),"") | EM5: =IF(EL5="",0,IFERROR(IF(N(CHOOSE(EL5,CL5,CP5,CT5,CX5,DB5,DF5,DJ5,DN5))<=0.005,0,MAX(0,N(CHOOSE(EL5,CL5,CP5,CT5,CX5,DB5,DF5,DJ5,DN5))+N(CHOOSE(EL5,CM5,CQ5,CU5,CY5,DC5,DG5,DK5,DO5))-MIN(N(CHOOSE(EL5,'Debt List'!$F$5,'Debt List'!$F$6,'Debt List'!$F$7,'Debt List'!$F$8,'Debt List'!$F$9,'Debt List'!$F$10,'Debt List'!$F$11,'Debt List'!$F$12)),N(CHOOSE(EL5,CL5,CP5,CT5,CX5,DB5,DF5,DJ5,DN5))+N(CHOOSE(EL5,CM5,CQ5,CU5,CY5,DC5,DG5,DK5,DO5))))),0)) | EN5: =MIN(N(EM5),MAX(0,N(EK5))) | EO5: =MAX(0,N(EK5)-N(EN5)) | EP5: =IFERROR(MATCH(7,OrderSnow,0),"") | EQ5: =IF(EP5="",0,IFERROR(IF(N(CHOOSE(EP5,CL5,CP5,CT5,CX5,DB5,DF5,DJ5,DN5))<=0.005,0,MAX(0,N(CHOOSE(EP5,CL5,CP5,CT5,CX5,DB5,DF5,DJ5,DN5))+N(CHOOSE(EP5,CM5,CQ5,CU5,CY5,DC5,DG5,DK5,DO5))-MIN(N(CHOOSE(EP5,'Debt List'!$F$5,'Debt List'!$F$6,'Debt List'!$F$7,'Debt List'!$F$8,'Debt List'!$F$9,'Debt List'!$F$10,'Debt List'!$F$11,'Debt List'!$F$12)),N(CHOOSE(EP5,CL5,CP5,CT5,CX5,DB5,DF5,DJ5,DN5))+N(CHOOSE(EP5,CM5,CQ5,CU5,CY5,DC5,DG5,DK5,DO5))))),0)) | ER5: =MIN(N(EQ5),MAX(0,N(EO5))) | ES5: =MAX(0,N(EO5)-N(ER5)) | ET5: =IFERROR(MATCH(8,OrderSnow,0),"") | EU5: =IF(ET5="",0,IFERROR(IF(N(CHOOSE(ET5,CL5,CP5,CT5,CX5,DB5,DF5,DJ5,DN5))<=0.005,0,MAX(0,N(CHOOSE(ET5,CL5,CP5,CT5,CX5,DB5,DF5,DJ5,DN5))+N(CHOOSE(ET5,CM5,CQ5,CU5,CY5,DC5,DG5,DK5,DO5))-MIN(N(CHOOSE(ET5,'Debt List'!$F$5,'Debt List'!$F$6,'Debt List'!$F$7,'Debt List'!$F$8,'Debt List'!$F$9,'Debt List'!$F$10,'Debt List'!$F$11,'Debt List'!$F$12)),N(CHOOSE(ET5,CL5,CP5,CT5,CX5,DB5,DF5,DJ5,DN5))+N(CHOOSE(ET5,CM5,CQ5,CU5,CY5,DC5,DG5,DK5,DO5))))),0)) | EV5: =MIN(N(EU5),MAX(0,N(ES5))) | EW5: =MAX(0,N(ES5)-N(EV5)) | FE5: 1 | FF5: =DATE(YEAR(PlanStart),MONTH(PlanStart)+FE5-1,1) | FG5: =IF(AND(GT5<>"",N(CHOOSE(GT5,FN5,FR5,FV5,FZ5,GD5,GH5,GL5,GP5))>0.005),INDEX(DebtNames,GT5),IF(AND(GX5<>"",N(CHOOSE(GX5,FN5,FR5,FV5,FZ5,GD5,GH5,GL5,GP5))>0.005),INDEX(DebtNames,GX5),IF(AND(HB5<>"",N(CHOOSE(HB5,FN5,FR5,FV5,FZ5,GD5,GH5,GL5,GP5))>0.005),INDEX(DebtNames,HB5),IF(AND(HF5<>"",N(CHOOSE(HF5,FN5,FR5,FV5,FZ5,GD5,GH5,GL5,GP5))>0.005),INDEX(DebtNames,HF5),IF(AND(HJ5<>"",N(CHOOSE(HJ5,FN5,FR5,FV5,FZ5,GD5,GH5,GL5,GP5))>0.005),INDEX(DebtNames,HJ5),IF(AND(HN5<>"",N(CHOOSE(HN5,FN5,FR5,FV5,FZ5,GD5,GH5,GL5,GP5))>0.005),INDEX(DebtNames,HN5),IF(AND(HR5<>"",N(CHOOSE(HR5,FN5,FR5,FV5,FZ5,GD5,GH5,GL5,GP5))>0.005),INDEX(DebtNames,HR5),IF(AND(HV5<>"",N(CHOOSE(HV5,FN5,FR5,FV5,FZ5,GD5,GH5,GL5,GP5))>0.005),INDEX(DebtNames,HV5),"")))))))) | FH5: =N(HY5) | FI5: =N(FP5)+N(FT5)+N(FX5)+N(GB5)+N(GF5)+N(GJ5)+N(GN5)+N(GR5) | FJ5: =N(FO5)+N(FS5)+N(FW5)+N(GA5)+N(GE5)+N(GI5)+N(GM5)+N(GQ5) | FK5: =N(FJ5) | FL5: =N(FQ5)+N(FU5)+N(FY5)+N(GC5)+N(GG5)+N(GK5)+N(GO5)+N(GS5) | FM5: =(FQ5>0.005)*1+(FU5>0.005)*1+(FY5>0.005)*1+(GC5>0.005)*1+(GG5>0.005)*1+(GK5>0.005)*1+(GO5>0.005)*1+(GS5>0.005)*1 | FN5: =N('Debt List'!D5) | FO5: =IF(N(FN5)<=0.005,0,ROUND(N(FN5)*N('Debt List'!E5)/12,2)) | FP5: =IF(N(FN5)<=0.005,0,MIN(N('Debt List'!F5),N(FN5)+N(FO5)))+((GT5=1)*GV5+(GX5=1)*GZ5+(HB5=1)*HD5+(HF5=1)*HH5+(HJ5=1)*HL5+(HN5=1)*HP5+(HR5=1)*HT5+(HV5=1)*HX5) | FQ5: =MAX(0,ROUND(N(FN5)+N(FO5)-N(FP5),2)) | FR5: =N('Debt List'!D6) | FS5: =IF(N(FR5)<=0.005,0,ROUND(N(FR5)*N('Debt List'!E6)/12,2)) | FT5: =IF(N(FR5)<=0.005,0,MIN(N('Debt List'!F6),N(FR5)+N(FS5)))+((GT5=2)*GV5+(GX5=2)*GZ5+(HB5=2)*HD5+(HF5=2)*HH5+(HJ5=2)*HL5+(HN5=2)*HP5+(HR5=2)*HT5+(HV5=2)*HX5) | FU5: =MAX(0,ROUND(N(FR5)+N(FS5)-N(FT5),2)) | FV5: =N('Debt List'!D7) | FW5: =IF(N(FV5)<=0.005,0,ROUND(N(FV5)*N('Debt List'!E7)/12,2)) | FX5: =IF(N(FV5)<=0.005,0,MIN(N('Debt List'!F7),N(FV5)+N(FW5)))+((GT5=3)*GV5+(GX5=3)*GZ5+(HB5=3)*HD5+(HF5=3)*HH5+(HJ5=3)*HL5+(HN5=3)*HP5+(HR5=3)*HT5+(HV5=3)*HX5) | FY5: =MAX(0,ROUND(N(FV5)+N(FW5)-N(FX5),2)) | FZ5: =N('Debt List'!D8) | GA5: =IF(N(FZ5)<=0.005,0,ROUND(N(FZ5)*N('Debt List'!E8)/12,2)) | GB5: =IF(N(FZ5)<=0.005,0,MIN(N('Debt List'!F8),N(FZ5)+N(GA5)))+((GT5=4)*GV5+(GX5=4)*GZ5+(HB5=4)*HD5+(HF5=4)*HH5+(HJ5=4)*HL5+(HN5=4)*HP5+(HR5=4)*HT5+(HV5=4)*HX5) | GC5: =MAX(0,ROUND(N(FZ5)+N(GA5)-N(GB5),2)) | GD5: =N('Debt List'!D9) | GE5: =IF(N(GD5)<=0.005,0,ROUND(N(GD5)*N('Debt List'!E9)/12,2)) | GF5: =IF(N(GD5)<=0.005,0,MIN(N('Debt List'!F9),N(GD5)+N(GE5)))+((GT5=5)*GV5+(GX5=5)*GZ5+(HB5=5)*HD5+(HF5=5)*HH5+(HJ5=5)*HL5+(HN5=5)*HP5+(HR5=5)*HT5+(HV5=5)*HX5) | GG5: =MAX(0,ROUND(N(GD5)+N(GE5)-N(GF5),2)) | GH5: =N('Debt List'!D10) | GI5: =IF(N(GH5)<=0.005,0,ROUND(N(GH5)*N('Debt List'!E10)/12,2)) | GJ5: =IF(N(GH5)<=0.005,0,MIN(N('Debt List'!F10),N(GH5)+N(GI5)))+((GT5=6)*GV5+(GX5=6)*GZ5+(HB5=6)*HD5+(HF5=6)*HH5+(HJ5=6)*HL5+(HN5=6)*HP5+(HR5=6)*HT5+(HV5=6)*HX5) | GK5: =MAX(0,ROUND(N(GH5)+N(GI5)-N(GJ5),2)) | GL5: =N('Debt List'!D11) | GM5: =IF(N(GL5)<=0.005,0,ROUND(N(GL5)*N('Debt List'!E11)/12,2)) | GN5: =IF(N(GL5)<=0.005,0,MIN(N('Debt List'!F11),N(GL5)+N(GM5)))+((GT5=7)*GV5+(GX5=7)*GZ5+(HB5=7)*HD5+(HF5=7)*HH5+(HJ5=7)*HL5+(HN5=7)*HP5+(HR5=7)*HT5+(HV5=7)*HX5) | GO5: =MAX(0,ROUND(N(GL5)+N(GM5)-N(GN5),2)) | GP5: =N('Debt List'!D12) | GQ5: =IF(N(GP5)<=0.005,0,ROUND(N(GP5)*N('Debt List'!E12)/12,2)) | GR5: =IF(N(GP5)<=0.005,0,MIN(N('Debt List'!F12),N(GP5)+N(GQ5)))+((GT5=8)*GV5+(GX5=8)*GZ5+(HB5=8)*HD5+(HF5=8)*HH5+(HJ5=8)*HL5+(HN5=8)*HP5+(HR5=8)*HT5+(HV5=8)*HX5) | GS5: =MAX(0,ROUND(N(GP5)+N(GQ5)-N(GR5),2)) | GT5: =IFERROR(MATCH(1,OrderAval,0),"") | GU5: =IF(GT5="",0,IFERROR(IF(N(CHOOSE(GT5,FN5,FR5,FV5,FZ5,GD5,GH5,GL5,GP5))<=0.005,0,MAX(0,N(CHOOSE(GT5,FN5,FR5,FV5,FZ5,GD5,GH5,GL5,GP5))+N(CHOOSE(GT5,FO5,FS5,FW5,GA5,GE5,GI5,GM5,GQ5))-MIN(N(CHOOSE(GT5,'Debt List'!$F$5,'Debt List'!$F$6,'Debt List'!$F$7,'Debt List'!$F$8,'Debt List'!$F$9,'Debt List'!$F$10,'Debt List'!$F$11,'Debt List'!$F$12)),N(CHOOSE(GT5,FN5,FR5,FV5,FZ5,GD5,GH5,GL5,GP5))+N(CHOOSE(GT5,FO5,FS5,FW5,GA5,GE5,GI5,GM5,GQ5))))),0)) | GV5: =MIN(N(GU5),MAX(0,N(ExtraPayment))) | GW5: =MAX(0,N(ExtraPayment)-N(GV5)) | GX5: =IFERROR(MATCH(2,OrderAval,0),"") | GY5: =IF(GX5="",0,IFERROR(IF(N(CHOOSE(GX5,FN5,FR5,FV5,FZ5,GD5,GH5,GL5,GP5))<=0.005,0,MAX(0,N(CHOOSE(GX5,FN5,FR5,FV5,FZ5,GD5,GH5,GL5,GP5))+N(CHOOSE(GX5,FO5,FS5,FW5,GA5,GE5,GI5,GM5,GQ5))-MIN(N(CHOOSE(GX5,'Debt List'!$F$5,'Debt List'!$F$6,'Debt List'!$F$7,'Debt List'!$F$8,'Debt List'!$F$9,'Debt List'!$F$10,'Debt List'!$F$11,'Debt List'!$F$12)),N(CHOOSE(GX5,FN5,FR5,FV5,FZ5,GD5,GH5,GL5,GP5))+N(CHOOSE(GX5,FO5,FS5,FW5,GA5,GE5,GI5,GM5,GQ5))))),0)) | GZ5: =MIN(N(GY5),MAX(0,N(GW5))) | HA5: =MAX(0,N(GW5)-N(GZ5)) | HB5: =IFERROR(MATCH(3,OrderAval,0),"") | HC5: =IF(HB5="",0,IFERROR(IF(N(CHOOSE(HB5,FN5,FR5,FV5,FZ5,GD5,GH5,GL5,GP5))<=0.005,0,MAX(0,N(CHOOSE(HB5,FN5,FR5,FV5,FZ5,GD5,GH5,GL5,GP5))+N(CHOOSE(HB5,FO5,FS5,FW5,GA5,GE5,GI5,GM5,GQ5))-MIN(N(CHOOSE(HB5,'Debt List'!$F$5,'Debt List'!$F$6,'Debt List'!$F$7,'Debt List'!$F$8,'Debt List'!$F$9,'Debt List'!$F$10,'Debt List'!$F$11,'Debt List'!$F$12)),N(CHOOSE(HB5,FN5,FR5,FV5,FZ5,GD5,GH5,GL5,GP5))+N(CHOOSE(HB5,FO5,FS5,FW5,GA5,GE5,GI5,GM5,GQ5))))),0)) | HD5: =MIN(N(HC5),MAX(0,N(HA5))) | HE5: =MAX(0,N(HA5)-N(HD5)) | HF5: =IFERROR(MATCH(4,OrderAval,0),"") | HG5: =IF(HF5="",0,IFERROR(IF(N(CHOOSE(HF5,FN5,FR5,FV5,FZ5,GD5,GH5,GL5,GP5))<=0.005,0,MAX(0,N(CHOOSE(HF5,FN5,FR5,FV5,FZ5,GD5,GH5,GL5,GP5))+N(CHOOSE(HF5,FO5,FS5,FW5,GA5,GE5,GI5,GM5,GQ5))-MIN(N(CHOOSE(HF5,'Debt List'!$F$5,'Debt List'!$F$6,'Debt List'!$F$7,'Debt List'!$F$8,'Debt List'!$F$9,'Debt List'!$F$10,'Debt List'!$F$11,'Debt List'!$F$12)),N(CHOOSE(HF5,FN5,FR5,FV5,FZ5,GD5,GH5,GL5,GP5))+N(CHOOSE(HF5,FO5,FS5,FW5,GA5,GE5,GI5,GM5,GQ5))))),0)) | HH5: =MIN(N(HG5),MAX(0,N(HE5))) | HI5: =MAX(0,N(HE5)-N(HH5)) | HJ5: =IFERROR(MATCH(5,OrderAval,0),"") | HK5: =IF(HJ5="",0,IFERROR(IF(N(CHOOSE(HJ5,FN5,FR5,FV5,FZ5,GD5,GH5,GL5,GP5))<=0.005,0,MAX(0,N(CHOOSE(HJ5,FN5,FR5,FV5,FZ5,GD5,GH5,GL5,GP5))+N(CHOOSE(HJ5,FO5,FS5,FW5,GA5,GE5,GI5,GM5,GQ5))-MIN(N(CHOOSE(HJ5,'Debt List'!$F$5,'Debt List'!$F$6,'Debt List'!$F$7,'Debt List'!$F$8,'Debt List'!$F$9,'Debt List'!$F$10,'Debt List'!$F$11,'Debt List'!$F$12)),N(CHOOSE(HJ5,FN5,FR5,FV5,FZ5,GD5,GH5,GL5,GP5))+N(CHOOSE(HJ5,FO5,FS5,FW5,GA5,GE5,GI5,GM5,GQ5))))),0)) | HL5: =MIN(N(HK5),MAX(0,N(HI5))) | HM5: =MAX(0,N(HI5)-N(HL5)) | HN5: =IFERROR(MATCH(6,OrderAval,0),"") | HO5: =IF(HN5="",0,IFERROR(IF(N(CHOOSE(HN5,FN5,FR5,FV5,FZ5,GD5,GH5,GL5,GP5))<=0.005,0,MAX(0,N(CHOOSE(HN5,FN5,FR5,FV5,FZ5,GD5,GH5,GL5,GP5))+N(CHOOSE(HN5,FO5,FS5,FW5,GA5,GE5,GI5,GM5,GQ5))-MIN(N(CHOOSE(HN5,'Debt List'!$F$5,'Debt List'!$F$6,'Debt List'!$F$7,'Debt List'!$F$8,'Debt List'!$F$9,'Debt List'!$F$10,'Debt List'!$F$11,'Debt List'!$F$12)),N(CHOOSE(HN5,FN5,FR5,FV5,FZ5,GD5,GH5,GL5,GP5))+N(CHOOSE(HN5,FO5,FS5,FW5,GA5,GE5,GI5,GM5,GQ5))))),0)) | HP5: =MIN(N(HO5),MAX(0,N(HM5))) | HQ5: =MAX(0,N(HM5)-N(HP5)) | HR5: =IFERROR(MATCH(7,OrderAval,0),"") | HS5: =IF(HR5="",0,IFERROR(IF(N(CHOOSE(HR5,FN5,FR5,FV5,FZ5,GD5,GH5,GL5,GP5))<=0.005,0,MAX(0,N(CHOOSE(HR5,FN5,FR5,FV5,FZ5,GD5,GH5,GL5,GP5))+N(CHOOSE(HR5,FO5,FS5,FW5,GA5,GE5,GI5,GM5,GQ5))-MIN(N(CHOOSE(HR5,'Debt List'!$F$5,'Debt List'!$F$6,'Debt List'!$F$7,'Debt List'!$F$8,'Debt List'!$F$9,'Debt List'!$F$10,'Debt List'!$F$11,'Debt List'!$F$12)),N(CHOOSE(HR5,FN5,FR5,FV5,FZ5,GD5,GH5,GL5,GP5))+N(CHOOSE(HR5,FO5,FS5,FW5,GA5,GE5,GI5,GM5,GQ5))))),0)) | HT5: =MIN(N(HS5),MAX(0,N(HQ5))) | HU5: =MAX(0,N(HQ5)-N(HT5)) | HV5: =IFERROR(MATCH(8,OrderAval,0),"") | HW5: =IF(HV5="",0,IFERROR(IF(N(CHOOSE(HV5,FN5,FR5,FV5,FZ5,GD5,GH5,GL5,GP5))<=0.005,0,MAX(0,N(CHOOSE(HV5,FN5,FR5,FV5,FZ5,GD5,GH5,GL5,GP5))+N(CHOOSE(HV5,FO5,FS5,FW5,GA5,GE5,GI5,GM5,GQ5))-MIN(N(CHOOSE(HV5,'Debt List'!$F$5,'Debt List'!$F$6,'Debt List'!$F$7,'Debt List'!$F$8,'Debt List'!$F$9,'Debt List'!$F$10,'Debt List'!$F$11,'Debt List'!$F$12)),N(CHOOSE(HV5,FN5,FR5,FV5,FZ5,GD5,GH5,GL5,GP5))+N(CHOOSE(HV5,FO5,FS5,FW5,GA5,GE5,GI5,GM5,GQ5))))),0)) | HX5: =MIN(N(HW5),MAX(0,N(HU5))) | HY5: =MAX(0,N(HU5)-N(HX5))
