Workbook
Name ShopName: Products!$B$2
Name FocusMonth: Dashboard!$B$3
Name ThisMonthStart: Dashboard!$N$2
Name PriorMonthStart: Dashboard!$N$3
Name TotalRevenue: Dashboard!$N$5
Name TotalSalesProfit: Dashboard!$N$6
Name TotalExpenses: Dashboard!$N$7
Name TotalNetProfit: Dashboard!$N$8
Name TotalCOGS: Dashboard!$N$9
Name TotalFees: Dashboard!$N$10
Name TotalOrders: Dashboard!$N$11
Name TotalUnits: Dashboard!$N$12
Name AvgMargin: Dashboard!$N$13
Name FocusRevenue: Dashboard!$N$15
Name FocusSalesProfit: Dashboard!$N$16
Name FocusExpenses: Dashboard!$N$17
Name FocusNet: Dashboard!$N$18
Name FocusFees: Dashboard!$N$19
Name FocusCOGS: Dashboard!$N$20
Name FocusShip: Dashboard!$N$21
Name FocusOrders: Dashboard!$N$22
Name FocusUnits: Dashboard!$N$23
Name PriorRevenue: Dashboard!$N$25
Name PriorNet: Dashboard!$N$28
Name MoMChange: Dashboard!$N$29
Name BestSeller: Dashboard!$N$31
Name BestSellerUnits: Dashboard!$N$32
Name List_Products: Products!$A$5:$A$34
Name List_Platforms: Products!$N$2:$N$7
Name List_ExpCat: Products!$N$9:$N$16
Name List_ProdTypes: Products!$N$18:$N$20
Name ProdNames: Products!$A$5:$A$34
Name ProdCOGS: Products!$D$5:$D$34
Name ProdUnits: Products!$G$5:$G$34
Name SalesDates: 'Sales Log'!$A$5:$A$204
Name SalesProducts: 'Sales Log'!$C$5:$C$204
Name SalesQty: 'Sales Log'!$D$5:$D$204
Name SalesFees: 'Sales Log'!$H$5:$H$204
Name SalesShipPaid: 'Sales Log'!$I$5:$I$204
Name SalesCOGS: 'Sales Log'!$K$5:$K$204
Name SalesGross: 'Sales Log'!$L$5:$L$204
Name SalesNet: 'Sales Log'!$M$5:$M$204
Name SalesMonth: 'Sales Log'!$O$5:$O$204
Name SalesNewOrder: 'Sales Log'!$P$5:$P$204
Name ExpAmounts: 'Fees & Expenses'!$D$5:$D$84
Name ExpMonth: 'Fees & Expenses'!$G$5:$G$84

Sheet Dashboard
A1: Online Seller Profit Tracker | N1: HELPERS
A2: =IF(ShopName="","Your shop overview",ShopName)&" · All-time snapshot" | I2: ="As of "&TEXT(TODAY(),"mmm d, yyyy") | N2: =DATE(YEAR(FocusMonth),MONTH(FocusMonth),1)
A3: Review month | B3: 46204 | C3: ="Comparing "&TEXT(DATE(YEAR(FocusMonth),MONTH(FocusMonth),1),"mmm yyyy")&" with "&TEXT(EDATE(DATE(YEAR(FocusMonth),MONTH(FocusMonth),1),-1),"mmm yyyy")&" · Change the blue Review month to look at any period." | N3: =EDATE(N2,-1)
A5: ALL-TIME REVENUE | D5: ALL-TIME NET PROFIT | G5: PROFIT MARGIN | J5: ORDERS | N5: ='Sales Log'!L205
A6: =TotalRevenue | D6: =TotalNetProfit | G6: =AvgMargin | J6: =TotalOrders | N6: ='Sales Log'!M205
A7: ="Fees "&TEXT(TotalFees,"$#,##0.00") | D7: ="After expenses "&TEXT(TotalExpenses,"$#,##0.00") | G7: Net profit ÷ revenue | J7: ="Units "&TEXT(TotalUnits,"#,##0") | N7: ='Fees & Expenses'!D85
A8: Product sales + shipping charged | D8: Sales profit minus shop expenses | G8: All-time, after expenses | J8: Unique order IDs | N8: =N6-N7
N9: ='Sales Log'!K205
A10: =UPPER(TEXT(DATE(YEAR(FocusMonth),MONTH(FocusMonth),1),"mmm yyyy"))&" NET" | D10: =UPPER(TEXT(EDATE(DATE(YEAR(FocusMonth),MONTH(FocusMonth),1),-1),"mmm yyyy"))&" NET" | G10: MONTH-OVER-MONTH | J10: BEST SELLER | N10: =SUM('Sales Log'!H5:H204)
A11: =FocusNet | D11: =PriorNet | G11: =MoMChange | J11: =BestSeller | N11: =SUM('Sales Log'!P5:P204)
A12: ="Revenue "&TEXT(FocusRevenue,"$#,##0.00") | D12: ="Revenue "&TEXT(PriorRevenue,"$#,##0.00") | G12: =IF(N(MoMChange)<0,"Down vs prior month","Up vs prior month") | J12: ="Units "&TEXT(BestSellerUnits,"#,##0") | N12: =SUM('Sales Log'!D5:D204)
A13: Sales profit − expenses this month | D13: The month before Review month | G13: Change in net profit | J13: Most units sold, all time | N13: =IF(N5=0,"",N8/N5)
A15: REVIEW MONTH DETAIL | G15: PROFIT BY PRODUCT | N15: =SUMIFS(SalesGross,SalesMonth,N2)
A16: Orders | D16: =FocusOrders | G16: Product | I16: Units | J16: Revenue | K16: Profit | N16: =SUMIFS(SalesNet,SalesMonth,N2)
A17: Units sold | D17: =FocusUnits | G17: =IF('Products'!A5="","",'Products'!A5) | I17: =IF(G17="","",'Products'!G5) | J17: =IF(G17="","",'Products'!H5) | K17: =IF(G17="","",'Products'!I5) | N17: =SUMIFS(ExpAmounts,ExpMonth,N2)
A18: Revenue | D18: =FocusRevenue | G18: =IF('Products'!A6="","",'Products'!A6) | I18: =IF(G18="","",'Products'!G6) | J18: =IF(G18="","",'Products'!H6) | K18: =IF(G18="","",'Products'!I6) | N18: =N16-N17
A19: Platform fees | D19: =FocusFees | G19: =IF('Products'!A7="","",'Products'!A7) | I19: =IF(G19="","",'Products'!G7) | J19: =IF(G19="","",'Products'!H7) | K19: =IF(G19="","",'Products'!I7) | N19: =SUMIFS(SalesFees,SalesMonth,N2)
A20: COGS | D20: =FocusCOGS | G20: =IF('Products'!A8="","",'Products'!A8) | I20: =IF(G20="","",'Products'!G8) | J20: =IF(G20="","",'Products'!H8) | K20: =IF(G20="","",'Products'!I8) | N20: =SUMIFS(SalesCOGS,SalesMonth,N2)
A21: Shipping you paid | D21: =FocusShip | G21: =IF('Products'!A9="","",'Products'!A9) | I21: =IF(G21="","",'Products'!G9) | J21: =IF(G21="","",'Products'!H9) | K21: =IF(G21="","",'Products'!I9) | N21: =SUMIFS(SalesShipPaid,SalesMonth,N2)
A22: Sales profit | D22: =FocusSalesProfit | G22: =IF('Products'!A10="","",'Products'!A10) | I22: =IF(G22="","",'Products'!G10) | J22: =IF(G22="","",'Products'!H10) | K22: =IF(G22="","",'Products'!I10) | N22: =SUMIFS(SalesNewOrder,SalesMonth,N2)
A23: Other expenses | D23: =FocusExpenses | G23: =IF('Products'!A11="","",'Products'!A11) | I23: =IF(G23="","",'Products'!G11) | J23: =IF(G23="","",'Products'!H11) | K23: =IF(G23="","",'Products'!I11) | N23: =SUMIFS(SalesQty,SalesMonth,N2)
A24: Net profit | D24: =FocusNet | G24: =IF('Products'!A12="","",'Products'!A12) | I24: =IF(G24="","",'Products'!G12) | J24: =IF(G24="","",'Products'!H12) | K24: =IF(G24="","",'Products'!I12)
A25: Margin | D25: =IF(FocusRevenue=0,"",FocusNet/FocusRevenue) | N25: =SUMIFS(SalesGross,SalesMonth,N3)
N26: =SUMIFS(SalesNet,SalesMonth,N3)
A27: REVENUE VS PROFIT (last 12 months) | G27: PROFIT BY PRODUCT | N27: =SUMIFS(ExpAmounts,ExpMonth,N3)
N28: =N26-N27
N29: =IF(N28=0,IF(N18=0,0,1),(N18-N28)/ABS(N28))
N31: =IFERROR(INDEX(ProdNames,MATCH(MAX(ProdUnits),ProdUnits,0)),"—")
N32: =IFERROR(MAX(ProdUnits),0)
A45: MONTHLY NET PROFIT TREND (last 12 months)
A62: Blue Review month (B3) changes the comparison cards and the 12-month charts. All-time cards always include every sale and expense. Gray cells calculate. See Instructions for the 5-minute start.
A70: Month | B70: Revenue | C70: Net profit | E70: Product | F70: Profit
A71: =EDATE(DATE(YEAR(FocusMonth),MONTH(FocusMonth),1),-11) | B71: =IF(SUMIFS(SalesGross,SalesMonth,A71)+SUMIFS(ExpAmounts,ExpMonth,A71)=0,NA(),SUMIFS(SalesGross,SalesMonth,A71)) | C71: =IF(SUMIFS(SalesGross,SalesMonth,A71)+SUMIFS(ExpAmounts,ExpMonth,A71)=0,NA(),SUMIFS(SalesNet,SalesMonth,A71)-SUMIFS(ExpAmounts,ExpMonth,A71)) | E71: =IF('Products'!A5="","",'Products'!A5) | F71: =IF(OR(E71="",'Products'!I5=0),NA(),'Products'!I5)
A72: =EDATE(A71,1) | B72: =IF(SUMIFS(SalesGross,SalesMonth,A72)+SUMIFS(ExpAmounts,ExpMonth,A72)=0,NA(),SUMIFS(SalesGross,SalesMonth,A72)) | C72: =IF(SUMIFS(SalesGross,SalesMonth,A72)+SUMIFS(ExpAmounts,ExpMonth,A72)=0,NA(),SUMIFS(SalesNet,SalesMonth,A72)-SUMIFS(ExpAmounts,ExpMonth,A72)) | E72: =IF('Products'!A6="","",'Products'!A6) | F72: =IF(OR(E72="",'Products'!I6=0),NA(),'Products'!I6)
A73: =EDATE(A72,1) | B73: =IF(SUMIFS(SalesGross,SalesMonth,A73)+SUMIFS(ExpAmounts,ExpMonth,A73)=0,NA(),SUMIFS(SalesGross,SalesMonth,A73)) | C73: =IF(SUMIFS(SalesGross,SalesMonth,A73)+SUMIFS(ExpAmounts,ExpMonth,A73)=0,NA(),SUMIFS(SalesNet,SalesMonth,A73)-SUMIFS(ExpAmounts,ExpMonth,A73)) | E73: =IF('Products'!A7="","",'Products'!A7) | F73: =IF(OR(E73="",'Products'!I7=0),NA(),'Products'!I7)
A74: =EDATE(A73,1) | B74: =IF(SUMIFS(SalesGross,SalesMonth,A74)+SUMIFS(ExpAmounts,ExpMonth,A74)=0,NA(),SUMIFS(SalesGross,SalesMonth,A74)) | C74: =IF(SUMIFS(SalesGross,SalesMonth,A74)+SUMIFS(ExpAmounts,ExpMonth,A74)=0,NA(),SUMIFS(SalesNet,SalesMonth,A74)-SUMIFS(ExpAmounts,ExpMonth,A74)) | E74: =IF('Products'!A8="","",'Products'!A8) | F74: =IF(OR(E74="",'Products'!I8=0),NA(),'Products'!I8)
A75: =EDATE(A74,1) | B75: =IF(SUMIFS(SalesGross,SalesMonth,A75)+SUMIFS(ExpAmounts,ExpMonth,A75)=0,NA(),SUMIFS(SalesGross,SalesMonth,A75)) | C75: =IF(SUMIFS(SalesGross,SalesMonth,A75)+SUMIFS(ExpAmounts,ExpMonth,A75)=0,NA(),SUMIFS(SalesNet,SalesMonth,A75)-SUMIFS(ExpAmounts,ExpMonth,A75)) | E75: =IF('Products'!A9="","",'Products'!A9) | F75: =IF(OR(E75="",'Products'!I9=0),NA(),'Products'!I9)
A76: =EDATE(A75,1) | B76: =IF(SUMIFS(SalesGross,SalesMonth,A76)+SUMIFS(ExpAmounts,ExpMonth,A76)=0,NA(),SUMIFS(SalesGross,SalesMonth,A76)) | C76: =IF(SUMIFS(SalesGross,SalesMonth,A76)+SUMIFS(ExpAmounts,ExpMonth,A76)=0,NA(),SUMIFS(SalesNet,SalesMonth,A76)-SUMIFS(ExpAmounts,ExpMonth,A76)) | E76: =IF('Products'!A10="","",'Products'!A10) | F76: =IF(OR(E76="",'Products'!I10=0),NA(),'Products'!I10)
A77: =EDATE(A76,1) | B77: =IF(SUMIFS(SalesGross,SalesMonth,A77)+SUMIFS(ExpAmounts,ExpMonth,A77)=0,NA(),SUMIFS(SalesGross,SalesMonth,A77)) | C77: =IF(SUMIFS(SalesGross,SalesMonth,A77)+SUMIFS(ExpAmounts,ExpMonth,A77)=0,NA(),SUMIFS(SalesNet,SalesMonth,A77)-SUMIFS(ExpAmounts,ExpMonth,A77)) | E77: =IF('Products'!A11="","",'Products'!A11) | F77: =IF(OR(E77="",'Products'!I11=0),NA(),'Products'!I11)
A78: =EDATE(A77,1) | B78: =IF(SUMIFS(SalesGross,SalesMonth,A78)+SUMIFS(ExpAmounts,ExpMonth,A78)=0,NA(),SUMIFS(SalesGross,SalesMonth,A78)) | C78: =IF(SUMIFS(SalesGross,SalesMonth,A78)+SUMIFS(ExpAmounts,ExpMonth,A78)=0,NA(),SUMIFS(SalesNet,SalesMonth,A78)-SUMIFS(ExpAmounts,ExpMonth,A78)) | E78: =IF('Products'!A12="","",'Products'!A12) | F78: =IF(OR(E78="",'Products'!I12=0),NA(),'Products'!I12)
...

Sheet Sales Log
A1: Sales Log
A2: One row per line item. If an order has two products, use two rows and the same Order ID. Do not log ads or subscriptions here — those go on Fees & Expenses.
A3: =IF(SUM(L5:L204)=0,"Add your first sale in the blue cells below.","Lines: "&COUNTA(A5:A204)&" · Orders: "&TEXT(SUM(P5:P204),"#,##0")&" · Gross: "&TEXT(SUM(L5:L204),"$#,##0.00")&" · Sales profit: "&TEXT(SUM(M5:M204),"$#,##0.00"))
A4: Date | B4: Order ID | C4: Product | D4: Qty | E4: Unit price | F4: Shipping charged | G4: Platform | H4: Platform fees | I4: Shipping you paid | J4: COGS override | K4: COGS | L4: Gross | M4: Net profit | N4: Margin | O4: Month | P4: New order
A5: 46176 | B5: E-10201 | C5: Floral Sticker Pack | D5: 2 | E5: 8 | F5: 3.5 | G5: Etsy | H5: 2.15 | I5: 2.1 | K5: =IF(C5="","",IF(J5<>"",J5,N(D5)*IFERROR(INDEX(ProdCOGS,MATCH(C5,ProdNames,0)),0))) | L5: =IF(A5="","",N(D5)*N(E5)+N(F5)) | M5: =IF(A5="","",L5-N(H5)-N(I5)-N(K5)) | N5: =IF(OR(A5="",N(L5)=0),"",M5/L5) | O5: =IF(A5="","",DATE(YEAR(A5),MONTH(A5),1)) | P5: =IF(OR(A5="",B5=""),"",IF(COUNTIF($B$5:B5,B5)=1,1,0))
A6: 46176 | B6: E-10201 | C6: Gift Wrap Add-on | D6: 1 | E6: 4 | F6: 0 | G6: Etsy | H6: 0.45 | I6: 0 | K6: =IF(C6="","",IF(J6<>"",J6,N(D6)*IFERROR(INDEX(ProdCOGS,MATCH(C6,ProdNames,0)),0))) | L6: =IF(A6="","",N(D6)*N(E6)+N(F6)) | M6: =IF(A6="","",L6-N(H6)-N(I6)-N(K6)) | N6: =IF(OR(A6="",N(L6)=0),"",M6/L6) | O6: =IF(A6="","",DATE(YEAR(A6),MONTH(A6),1)) | P6: =IF(OR(A6="",B6=""),"",IF(COUNTIF($B$5:B6,B6)=1,1,0))
A7: 46178 | B7: E-10214 | C7: Mini Art Print | D7: 1 | E7: 12 | F7: 5 | G7: Etsy | H7: 2.05 | I7: 3.8 | K7: =IF(C7="","",IF(J7<>"",J7,N(D7)*IFERROR(INDEX(ProdCOGS,MATCH(C7,ProdNames,0)),0))) | L7: =IF(A7="","",N(D7)*N(E7)+N(F7)) | M7: =IF(A7="","",L7-N(H7)-N(I7)-N(K7)) | N7: =IF(OR(A7="",N(L7)=0),"",M7/L7) | O7: =IF(A7="","",DATE(YEAR(A7),MONTH(A7),1)) | P7: =IF(OR(A7="",B7=""),"",IF(COUNTIF($B$5:B7,B7)=1,1,0))
A8: 46180 | B8: G-4401 | C8: Digital Planner (PDF) | D8: 1 | E8: 12 | F8: 0 | G8: Gumroad | H8: 1.2 | I8: 0 | K8: =IF(C8="","",IF(J8<>"",J8,N(D8)*IFERROR(INDEX(ProdCOGS,MATCH(C8,ProdNames,0)),0))) | L8: =IF(A8="","",N(D8)*N(E8)+N(F8)) | M8: =IF(A8="","",L8-N(H8)-N(I8)-N(K8)) | N8: =IF(OR(A8="",N(L8)=0),"",M8/L8) | O8: =IF(A8="","",DATE(YEAR(A8),MONTH(A8),1)) | P8: =IF(OR(A8="",B8=""),"",IF(COUNTIF($B$5:B8,B8)=1,1,0))
A9: 46182 | B9: E-10233 | C9: Floral Sticker Pack | D9: 1 | E9: 8 | F9: 3.5 | G9: Etsy | H9: 1.55 | I9: 2.1 | K9: =IF(C9="","",IF(J9<>"",J9,N(D9)*IFERROR(INDEX(ProdCOGS,MATCH(C9,ProdNames,0)),0))) | L9: =IF(A9="","",N(D9)*N(E9)+N(F9)) | M9: =IF(A9="","",L9-N(H9)-N(I9)-N(K9)) | N9: =IF(OR(A9="",N(L9)=0),"",M9/L9) | O9: =IF(A9="","",DATE(YEAR(A9),MONTH(A9),1)) | P9: =IF(OR(A9="",B9=""),"",IF(COUNTIF($B$5:B9,B9)=1,1,0))
A10: 46185 | B10: S-881 | C10: Mini Art Print | D10: 2 | E10: 12 | F10: 6 | G10: Shopify | H10: 1.1 | I10: 4.2 | K10: =IF(C10="","",IF(J10<>"",J10,N(D10)*IFERROR(INDEX(ProdCOGS,MATCH(C10,ProdNames,0)),0))) | L10: =IF(A10="","",N(D10)*N(E10)+N(F10)) | M10: =IF(A10="","",L10-N(H10)-N(I10)-N(K10)) | N10: =IF(OR(A10="",N(L10)=0),"",M10/L10) | O10: =IF(A10="","",DATE(YEAR(A10),MONTH(A10),1)) | P10: =IF(OR(A10="",B10=""),"",IF(COUNTIF($B$5:B10,B10)=1,1,0))
A11: 46187 | B11: E-10250 | C11: Pattern Brush Set | D11: 1 | E11: 15 | F11: 0 | G11: Etsy | H11: 1.5 | I11: 0 | K11: =IF(C11="","",IF(J11<>"",J11,N(D11)*IFERROR(INDEX(ProdCOGS,MATCH(C11,ProdNames,0)),0))) | L11: =IF(A11="","",N(D11)*N(E11)+N(F11)) | M11: =IF(A11="","",L11-N(H11)-N(I11)-N(K11)) | N11: =IF(OR(A11="",N(L11)=0),"",M11/L11) | O11: =IF(A11="","",DATE(YEAR(A11),MONTH(A11),1)) | P11: =IF(OR(A11="",B11=""),"",IF(COUNTIF($B$5:B11,B11)=1,1,0))
A12: 46191 | B12: E-10261 | C12: Floral Sticker Pack | D12: 3 | E12: 8 | F12: 4 | G12: Etsy | H12: 3.1 | I12: 2.4 | K12: =IF(C12="","",IF(J12<>"",J12,N(D12)*IFERROR(INDEX(ProdCOGS,MATCH(C12,ProdNames,0)),0))) | L12: =IF(A12="","",N(D12)*N(E12)+N(F12)) | M12: =IF(A12="","",L12-N(H12)-N(I12)-N(K12)) | N12: =IF(OR(A12="",N(L12)=0),"",M12/L12) | O12: =IF(A12="","",DATE(YEAR(A12),MONTH(A12),1)) | P12: =IF(OR(A12="",B12=""),"",IF(COUNTIF($B$5:B12,B12)=1,1,0))
A13: 46194 | B13: E-10270 | C13: Minimalist Print 8x10 | D13: 1 | E13: 18 | F13: 5 | G13: Etsy | H13: 2.7 | I13: 3.8 | K13: =IF(C13="","",IF(J13<>"",J13,N(D13)*IFERROR(INDEX(ProdCOGS,MATCH(C13,ProdNames,0)),0))) | L13: =IF(A13="","",N(D13)*N(E13)+N(F13)) | M13: =IF(A13="","",L13-N(H13)-N(I13)-N(K13)) | N13: =IF(OR(A13="",N(L13)=0),"",M13/L13) | O13: =IF(A13="","",DATE(YEAR(A13),MONTH(A13),1)) | P13: =IF(OR(A13="",B13=""),"",IF(COUNTIF($B$5:B13,B13)=1,1,0))
A14: 46198 | B14: G-4418 | C14: Digital Planner (PDF) | D14: 1 | E14: 12 | F14: 0 | G14: Gumroad | H14: 1.2 | I14: 0 | K14: =IF(C14="","",IF(J14<>"",J14,N(D14)*IFERROR(INDEX(ProdCOGS,MATCH(C14,ProdNames,0)),0))) | L14: =IF(A14="","",N(D14)*N(E14)+N(F14)) | M14: =IF(A14="","",L14-N(H14)-N(I14)-N(K14)) | N14: =IF(OR(A14="",N(L14)=0),"",M14/L14) | O14: =IF(A14="","",DATE(YEAR(A14),MONTH(A14),1)) | P14: =IF(OR(A14="",B14=""),"",IF(COUNTIF($B$5:B14,B14)=1,1,0))
A15: 46201 | B15: E-10288 | C15: Floral Sticker Pack | D15: 1 | E15: 8 | F15: 3.5 | G15: Etsy | H15: 1.55 | I15: 2.1 | K15: =IF(C15="","",IF(J15<>"",J15,N(D15)*IFERROR(INDEX(ProdCOGS,MATCH(C15,ProdNames,0)),0))) | L15: =IF(A15="","",N(D15)*N(E15)+N(F15)) | M15: =IF(A15="","",L15-N(H15)-N(I15)-N(K15)) | N15: =IF(OR(A15="",N(L15)=0),"",M15/L15) | O15: =IF(A15="","",DATE(YEAR(A15),MONTH(A15),1)) | P15: =IF(OR(A15="",B15=""),"",IF(COUNTIF($B$5:B15,B15)=1,1,0))
A16: 46203 | B16: E-10295 | C16: Mini Art Print | D16: 1 | E16: 12 | F16: 5 | G16: Etsy | H16: 2.05 | I16: 3.8 | K16: =IF(C16="","",IF(J16<>"",J16,N(D16)*IFERROR(INDEX(ProdCOGS,MATCH(C16,ProdNames,0)),0))) | L16: =IF(A16="","",N(D16)*N(E16)+N(F16)) | M16: =IF(A16="","",L16-N(H16)-N(I16)-N(K16)) | N16: =IF(OR(A16="",N(L16)=0),"",M16/L16) | O16: =IF(A16="","",DATE(YEAR(A16),MONTH(A16),1)) | P16: =IF(OR(A16="",B16=""),"",IF(COUNTIF($B$5:B16,B16)=1,1,0))
... A39: 46246 | B39: E-10522 | C39: Minimalist Print 8x10 | D39: 1 | E39: 18 | F39: 5 | G39: Etsy | H39: 2.7 | I39: 3.8 | K39: =IF(C39="","",IF(J39<>"",J39,N(D39)*IFERROR(INDEX(ProdCOGS,MATCH(C39,ProdNames,0)),0))) | L39: =IF(A39="","",N(D39)*N(E39)+N(F39)) | M39: =IF(A39="","",L39-N(H39)-N(I39)-N(K39)) | N39: =IF(OR(A39="",N(L39)=0),"",M39/L39) | O39: =IF(A39="","",DATE(YEAR(A39),MONTH(A39),1)) | P39: =IF(OR(A39="",B39=""),"",IF(COUNTIF($B$5:B39,B39)=1,1,0))
K40: =IF(C40="","",IF(J40<>"",J40,N(D40)*IFERROR(INDEX(ProdCOGS,MATCH(C40,ProdNames,0)),0))) | L40: =IF(A40="","",N(D40)*N(E40)+N(F40)) | M40: =IF(A40="","",L40-N(H40)-N(I40)-N(K40)) | N40: =IF(OR(A40="",N(L40)=0),"",M40/L40) | O40: =IF(A40="","",DATE(YEAR(A40),MONTH(A40),1)) | P40: =IF(OR(A40="",B40=""),"",IF(COUNTIF($B$5:B40,B40)=1,1,0))
K41: =IF(C41="","",IF(J41<>"",J41,N(D41)*IFERROR(INDEX(ProdCOGS,MATCH(C41,ProdNames,0)),0))) | L41: =IF(A41="","",N(D41)*N(E41)+N(F41)) | M41: =IF(A41="","",L41-N(H41)-N(I41)-N(K41)) | N41: =IF(OR(A41="",N(L41)=0),"",M41/L41) | O41: =IF(A41="","",DATE(YEAR(A41),MONTH(A41),1)) | P41: =IF(OR(A41="",B41=""),"",IF(COUNTIF($B$5:B41,B41)=1,1,0))
K42: =IF(C42="","",IF(J42<>"",J42,N(D42)*IFERROR(INDEX(ProdCOGS,MATCH(C42,ProdNames,0)),0))) | L42: =IF(A42="","",N(D42)*N(E42)+N(F42)) | M42: =IF(A42="","",L42-N(H42)-N(I42)-N(K42)) | N42: =IF(OR(A42="",N(L42)=0),"",M42/L42) | O42: =IF(A42="","",DATE(YEAR(A42),MONTH(A42),1)) | P42: =IF(OR(A42="",B42=""),"",IF(COUNTIF($B$5:B42,B42)=1,1,0))
K43: =IF(C43="","",IF(J43<>"",J43,N(D43)*IFERROR(INDEX(ProdCOGS,MATCH(C43,ProdNames,0)),0))) | L43: =IF(A43="","",N(D43)*N(E43)+N(F43)) | M43: =IF(A43="","",L43-N(H43)-N(I43)-N(K43)) | N43: =IF(OR(A43="",N(L43)=0),"",M43/L43) | O43: =IF(A43="","",DATE(YEAR(A43),MONTH(A43),1)) | P43: =IF(OR(A43="",B43=""),"",IF(COUNTIF($B$5:B43,B43)=1,1,0))
K44: =IF(C44="","",IF(J44<>"",J44,N(D44)*IFERROR(INDEX(ProdCOGS,MATCH(C44,ProdNames,0)),0))) | L44: =IF(A44="","",N(D44)*N(E44)+N(F44)) | M44: =IF(A44="","",L44-N(H44)-N(I44)-N(K44)) | N44: =IF(OR(A44="",N(L44)=0),"",M44/L44) | O44: =IF(A44="","",DATE(YEAR(A44),MONTH(A44),1)) | P44: =IF(OR(A44="",B44=""),"",IF(COUNTIF($B$5:B44,B44)=1,1,0))
K45: =IF(C45="","",IF(J45<>"",J45,N(D45)*IFERROR(INDEX(ProdCOGS,MATCH(C45,ProdNames,0)),0))) | L45: =IF(A45="","",N(D45)*N(E45)+N(F45)) | M45: =IF(A45="","",L45-N(H45)-N(I45)-N(K45)) | N45: =IF(OR(A45="",N(L45)=0),"",M45/L45) | O45: =IF(A45="","",DATE(YEAR(A45),MONTH(A45),1)) | P45: =IF(OR(A45="",B45=""),"",IF(COUNTIF($B$5:B45,B45)=1,1,0))
K46: =IF(C46="","",IF(J46<>"",J46,N(D46)*IFERROR(INDEX(ProdCOGS,MATCH(C46,ProdNames,0)),0))) | L46: =IF(A46="","",N(D46)*N(E46)+N(F46)) | M46: =IF(A46="","",L46-N(H46)-N(I46)-N(K46)) | N46: =IF(OR(A46="",N(L46)=0),"",M46/L46) | O46: =IF(A46="","",DATE(YEAR(A46),MONTH(A46),1)) | P46: =IF(OR(A46="",B46=""),"",IF(COUNTIF($B$5:B46,B46)=1,1,0))
K47: =IF(C47="","",IF(J47<>"",J47,N(D47)*IFERROR(INDEX(ProdCOGS,MATCH(C47,ProdNames,0)),0))) | L47: =IF(A47="","",N(D47)*N(E47)+N(F47)) | M47: =IF(A47="","",L47-N(H47)-N(I47)-N(K47)) | N47: =IF(OR(A47="",N(L47)=0),"",M47/L47) | O47: =IF(A47="","",DATE(YEAR(A47),MONTH(A47),1)) | P47: =IF(OR(A47="",B47=""),"",IF(COUNTIF($B$5:B47,B47)=1,1,0))
K48: =IF(C48="","",IF(J48<>"",J48,N(D48)*IFERROR(INDEX(ProdCOGS,MATCH(C48,ProdNames,0)),0))) | L48: =IF(A48="","",N(D48)*N(E48)+N(F48)) | M48: =IF(A48="","",L48-N(H48)-N(I48)-N(K48)) | N48: =IF(OR(A48="",N(L48)=0),"",M48/L48) | O48: =IF(A48="","",DATE(YEAR(A48),MONTH(A48),1)) | P48: =IF(OR(A48="",B48=""),"",IF(COUNTIF($B$5:B48,B48)=1,1,0))
K49: =IF(C49="","",IF(J49<>"",J49,N(D49)*IFERROR(INDEX(ProdCOGS,MATCH(C49,ProdNames,0)),0))) | L49: =IF(A49="","",N(D49)*N(E49)+N(F49)) | M49: =IF(A49="","",L49-N(H49)-N(I49)-N(K49)) | N49: =IF(OR(A49="",N(L49)=0),"",M49/L49) | O49: =IF(A49="","",DATE(YEAR(A49),MONTH(A49),1)) | P49: =IF(OR(A49="",B49=""),"",IF(COUNTIF($B$5:B49,B49)=1,1,0))
K50: =IF(C50="","",IF(J50<>"",J50,N(D50)*IFERROR(INDEX(ProdCOGS,MATCH(C50,ProdNames,0)),0))) | L50: =IF(A50="","",N(D50)*N(E50)+N(F50)) | M50: =IF(A50="","",L50-N(H50)-N(I50)-N(K50)) | N50: =IF(OR(A50="",N(L50)=0),"",M50/L50) | O50: =IF(A50="","",DATE(YEAR(A50),MONTH(A50),1)) | P50: =IF(OR(A50="",B50=""),"",IF(COUNTIF($B$5:B50,B50)=1,1,0))
K51: =IF(C51="","",IF(J51<>"",J51,N(D51)*IFERROR(INDEX(ProdCOGS,MATCH(C51,ProdNames,0)),0))) | L51: =IF(A51="","",N(D51)*N(E51)+N(F51)) | M51: =IF(A51="","",L51-N(H51)-N(I51)-N(K51)) | N51: =IF(OR(A51="",N(L51)=0),"",M51/L51) | O51: =IF(A51="","",DATE(YEAR(A51),MONTH(A51),1)) | P51: =IF(OR(A51="",B51=""),"",IF(COUNTIF($B$5:B51,B51)=1,1,0))
... K204: =IF(C204="","",IF(J204<>"",J204,N(D204)*IFERROR(INDEX(ProdCOGS,MATCH(C204,ProdNames,0)),0))) | L204: =IF(A204="","",N(D204)*N(E204)+N(F204)) | M204: =IF(A204="","",L204-N(H204)-N(I204)-N(K204)) | N204: =IF(OR(A204="",N(L204)=0),"",M204/L204) | O204: =IF(A204="","",DATE(YEAR(A204),MONTH(A204),1)) | P204: =IF(OR(A204="",B204=""),"",IF(COUNTIF($B$5:B204,B204)=1,1,0))
A205: TOTAL | K205: =SUM(K5:K204) | L205: =SUM(L5:L204) | M205: =SUM(M5:M204) | N205: =IF(L205=0,"",M205/L205)
A207: Gross = qty × unit price + shipping charged. Net = gross − fees − shipping you paid − COGS. Same Order ID on two rows = one order (gift wrap add-on is the sample).

Sheet Products
A1: Products | N1: DROPDOWN LISTS | O1: Edit these if you need extra options.
A2: Shop name | B2: Hearth & Holly Studio | E2: Blue = type. Gray = calculated from the Sales Log. Stock is optional — update it yourself; it does not auto-decrement. | N2: Etsy | O2: Platforms
A3: =IF(ShopName="","","Catalog for "&ShopName&" · "&COUNTA(A5:A34)&" products · Units sold (all time): "&TEXT(SUM(G5:G34),"#,##0")) | N3: Shopify
A4: Product name | B4: SKU | C4: Type | D4: COGS / unit | E4: Selling price | F4: Stock (optional) | G4: Units sold | H4: Revenue | I4: Profit | J4: Margin | N4: Gumroad
A5: Floral Sticker Pack | B5: STK-01 | C5: Physical | D5: 1.2 | E5: 8 | F5: 140 | G5: =IF(A5="","",SUMIFS(SalesQty,SalesProducts,A5)) | H5: =IF(A5="","",SUMIFS(SalesGross,SalesProducts,A5)) | I5: =IF(A5="","",SUMIFS(SalesNet,SalesProducts,A5)) | J5: =IF(OR(A5="",N(H5)=0),"",I5/H5) | N5: Amazon
A6: Minimalist Print 8x10 | B6: PRT-10 | C6: Physical | D6: 3.5 | E6: 18 | F6: 45 | G6: =IF(A6="","",SUMIFS(SalesQty,SalesProducts,A6)) | H6: =IF(A6="","",SUMIFS(SalesGross,SalesProducts,A6)) | I6: =IF(A6="","",SUMIFS(SalesNet,SalesProducts,A6)) | J6: =IF(OR(A6="",N(H6)=0),"",I6/H6) | N6: eBay
A7: Digital Planner (PDF) | B7: DIG-PL | C7: Digital | D7: 0 | E7: 12 | G7: =IF(A7="","",SUMIFS(SalesQty,SalesProducts,A7)) | H7: =IF(A7="","",SUMIFS(SalesGross,SalesProducts,A7)) | I7: =IF(A7="","",SUMIFS(SalesNet,SalesProducts,A7)) | J7: =IF(OR(A7="",N(H7)=0),"",I7/H7) | N7: Other
A8: Custom Portrait | B8: ART-CP | C8: Physical | D8: 8 | E8: 45 | F8: 12 | G8: =IF(A8="","",SUMIFS(SalesQty,SalesProducts,A8)) | H8: =IF(A8="","",SUMIFS(SalesGross,SalesProducts,A8)) | I8: =IF(A8="","",SUMIFS(SalesNet,SalesProducts,A8)) | J8: =IF(OR(A8="",N(H8)=0),"",I8/H8)
A9: Everyday POD Tee | B9: POD-T1 | C9: POD | D9: 14.5 | E9: 28 | G9: =IF(A9="","",SUMIFS(SalesQty,SalesProducts,A9)) | H9: =IF(A9="","",SUMIFS(SalesGross,SalesProducts,A9)) | I9: =IF(A9="","",SUMIFS(SalesNet,SalesProducts,A9)) | J9: =IF(OR(A9="",N(H9)=0),"",I9/H9) | N9: Ads | O9: Expense categories
A10: Gift Wrap Add-on | B10: ADD-GW | C10: Physical | D10: 0.8 | E10: 4 | F10: 80 | G10: =IF(A10="","",SUMIFS(SalesQty,SalesProducts,A10)) | H10: =IF(A10="","",SUMIFS(SalesGross,SalesProducts,A10)) | I10: =IF(A10="","",SUMIFS(SalesNet,SalesProducts,A10)) | J10: =IF(OR(A10="",N(H10)=0),"",I10/H10) | N10: Packaging
A11: Pattern Brush Set | B11: DIG-BR | C11: Digital | D11: 0 | E11: 15 | G11: =IF(A11="","",SUMIFS(SalesQty,SalesProducts,A11)) | H11: =IF(A11="","",SUMIFS(SalesGross,SalesProducts,A11)) | I11: =IF(A11="","",SUMIFS(SalesNet,SalesProducts,A11)) | J11: =IF(OR(A11="",N(H11)=0),"",I11/H11) | N11: Subscriptions
A12: Mini Art Print | B12: PRT-MN | C12: Physical | D12: 2.1 | E12: 12 | F12: 60 | G12: =IF(A12="","",SUMIFS(SalesQty,SalesProducts,A12)) | H12: =IF(A12="","",SUMIFS(SalesGross,SalesProducts,A12)) | I12: =IF(A12="","",SUMIFS(SalesNet,SalesProducts,A12)) | J12: =IF(OR(A12="",N(H12)=0),"",I12/H12) | N12: Supplies
G13: =IF(A13="","",SUMIFS(SalesQty,SalesProducts,A13)) | H13: =IF(A13="","",SUMIFS(SalesGross,SalesProducts,A13)) | I13: =IF(A13="","",SUMIFS(SalesNet,SalesProducts,A13)) | J13: =IF(OR(A13="",N(H13)=0),"",I13/H13) | N13: Software
G14: =IF(A14="","",SUMIFS(SalesQty,SalesProducts,A14)) | H14: =IF(A14="","",SUMIFS(SalesGross,SalesProducts,A14)) | I14: =IF(A14="","",SUMIFS(SalesNet,SalesProducts,A14)) | J14: =IF(OR(A14="",N(H14)=0),"",I14/H14) | N14: Shipping supplies
G15: =IF(A15="","",SUMIFS(SalesQty,SalesProducts,A15)) | H15: =IF(A15="","",SUMIFS(SalesGross,SalesProducts,A15)) | I15: =IF(A15="","",SUMIFS(SalesNet,SalesProducts,A15)) | J15: =IF(OR(A15="",N(H15)=0),"",I15/H15) | N15: Taxes
G16: =IF(A16="","",SUMIFS(SalesQty,SalesProducts,A16)) | H16: =IF(A16="","",SUMIFS(SalesGross,SalesProducts,A16)) | I16: =IF(A16="","",SUMIFS(SalesNet,SalesProducts,A16)) | J16: =IF(OR(A16="",N(H16)=0),"",I16/H16) | N16: Other
G17: =IF(A17="","",SUMIFS(SalesQty,SalesProducts,A17)) | H17: =IF(A17="","",SUMIFS(SalesGross,SalesProducts,A17)) | I17: =IF(A17="","",SUMIFS(SalesNet,SalesProducts,A17)) | J17: =IF(OR(A17="",N(H17)=0),"",I17/H17)
G18: =IF(A18="","",SUMIFS(SalesQty,SalesProducts,A18)) | H18: =IF(A18="","",SUMIFS(SalesGross,SalesProducts,A18)) | I18: =IF(A18="","",SUMIFS(SalesNet,SalesProducts,A18)) | J18: =IF(OR(A18="",N(H18)=0),"",I18/H18) | N18: Physical | O18: Product types
G19: =IF(A19="","",SUMIFS(SalesQty,SalesProducts,A19)) | H19: =IF(A19="","",SUMIFS(SalesGross,SalesProducts,A19)) | I19: =IF(A19="","",SUMIFS(SalesNet,SalesProducts,A19)) | J19: =IF(OR(A19="",N(H19)=0),"",I19/H19) | N19: Digital
G20: =IF(A20="","",SUMIFS(SalesQty,SalesProducts,A20)) | H20: =IF(A20="","",SUMIFS(SalesGross,SalesProducts,A20)) | I20: =IF(A20="","",SUMIFS(SalesNet,SalesProducts,A20)) | J20: =IF(OR(A20="",N(H20)=0),"",I20/H20) | N20: POD
G21: =IF(A21="","",SUMIFS(SalesQty,SalesProducts,A21)) | H21: =IF(A21="","",SUMIFS(SalesGross,SalesProducts,A21)) | I21: =IF(A21="","",SUMIFS(SalesNet,SalesProducts,A21)) | J21: =IF(OR(A21="",N(H21)=0),"",I21/H21)
G22: =IF(A22="","",SUMIFS(SalesQty,SalesProducts,A22)) | H22: =IF(A22="","",SUMIFS(SalesGross,SalesProducts,A22)) | I22: =IF(A22="","",SUMIFS(SalesNet,SalesProducts,A22)) | J22: =IF(OR(A22="",N(H22)=0),"",I22/H22)
G23: =IF(A23="","",SUMIFS(SalesQty,SalesProducts,A23)) | H23: =IF(A23="","",SUMIFS(SalesGross,SalesProducts,A23)) | I23: =IF(A23="","",SUMIFS(SalesNet,SalesProducts,A23)) | J23: =IF(OR(A23="",N(H23)=0),"",I23/H23)
G24: =IF(A24="","",SUMIFS(SalesQty,SalesProducts,A24)) | H24: =IF(A24="","",SUMIFS(SalesGross,SalesProducts,A24)) | I24: =IF(A24="","",SUMIFS(SalesNet,SalesProducts,A24)) | J24: =IF(OR(A24="",N(H24)=0),"",I24/H24)
G25: =IF(A25="","",SUMIFS(SalesQty,SalesProducts,A25)) | H25: =IF(A25="","",SUMIFS(SalesGross,SalesProducts,A25)) | I25: =IF(A25="","",SUMIFS(SalesNet,SalesProducts,A25)) | J25: =IF(OR(A25="",N(H25)=0),"",I25/H25)
G26: =IF(A26="","",SUMIFS(SalesQty,SalesProducts,A26)) | H26: =IF(A26="","",SUMIFS(SalesGross,SalesProducts,A26)) | I26: =IF(A26="","",SUMIFS(SalesNet,SalesProducts,A26)) | J26: =IF(OR(A26="",N(H26)=0),"",I26/H26)
G27: =IF(A27="","",SUMIFS(SalesQty,SalesProducts,A27)) | H27: =IF(A27="","",SUMIFS(SalesGross,SalesProducts,A27)) | I27: =IF(A27="","",SUMIFS(SalesNet,SalesProducts,A27)) | J27: =IF(OR(A27="",N(H27)=0),"",I27/H27)
G28: =IF(A28="","",SUMIFS(SalesQty,SalesProducts,A28)) | H28: =IF(A28="","",SUMIFS(SalesGross,SalesProducts,A28)) | I28: =IF(A28="","",SUMIFS(SalesNet,SalesProducts,A28)) | J28: =IF(OR(A28="",N(H28)=0),"",I28/H28)
G29: =IF(A29="","",SUMIFS(SalesQty,SalesProducts,A29)) | H29: =IF(A29="","",SUMIFS(SalesGross,SalesProducts,A29)) | I29: =IF(A29="","",SUMIFS(SalesNet,SalesProducts,A29)) | J29: =IF(OR(A29="",N(H29)=0),"",I29/H29)
G30: =IF(A30="","",SUMIFS(SalesQty,SalesProducts,A30)) | H30: =IF(A30="","",SUMIFS(SalesGross,SalesProducts,A30)) | I30: =IF(A30="","",SUMIFS(SalesNet,SalesProducts,A30)) | J30: =IF(OR(A30="",N(H30)=0),"",I30/H30)
G31: =IF(A31="","",SUMIFS(SalesQty,SalesProducts,A31)) | H31: =IF(A31="","",SUMIFS(SalesGross,SalesProducts,A31)) | I31: =IF(A31="","",SUMIFS(SalesNet,SalesProducts,A31)) | J31: =IF(OR(A31="",N(H31)=0),"",I31/H31)
G32: =IF(A32="","",SUMIFS(SalesQty,SalesProducts,A32)) | H32: =IF(A32="","",SUMIFS(SalesGross,SalesProducts,A32)) | I32: =IF(A32="","",SUMIFS(SalesNet,SalesProducts,A32)) | J32: =IF(OR(A32="",N(H32)=0),"",I32/H32)
... G34: =IF(A34="","",SUMIFS(SalesQty,SalesProducts,A34)) | H34: =IF(A34="","",SUMIFS(SalesGross,SalesProducts,A34)) | I34: =IF(A34="","",SUMIFS(SalesNet,SalesProducts,A34)) | J34: =IF(OR(A34="",N(H34)=0),"",I34/H34)
A35: TOTAL | G35: =SUM(G5:G34) | H35: =SUM(H5:H34) | I35: =SUM(I5:I34) | J35: =IF(H35=0,"",I35/H35)
A37: Add a product: type in the next blank blue row. The Sales Log dropdown picks it up automatically. Rename a product here and update matching rows on the Sales Log so totals still match.

Sheet Fees & Expenses
A1: Fees & Expenses
A2: Shop overhead that is not tied to one order: ads, packaging stock, subscriptions, software. Per-sale platform fees and postage belong on the Sales Log.
A3: ="Operating expenses (all time): "&TEXT(SUM(D5:D84),"$#,##0.00")&" · These are subtracted from sales profit to get true net profit."
A4: Date | B4: Category | C4: Description | D4: Amount | E4: Platform | F4: Notes | G4: Month
A5: 46174 | B5: Subscriptions | C5: Etsy Plus | D5: 10 | E5: Etsy | F5: Monthly | G5: =IF(A5="","",DATE(YEAR(A5),MONTH(A5),1))
A6: 46181 | B6: Packaging | C6: Poly mailers + tissue | D6: 28.4 | F6: Stock up | G6: =IF(A6="","",DATE(YEAR(A6),MONTH(A6),1))
A7: 46188 | B7: Ads | C7: Facebook ads | D7: 35 | E7: Etsy | G7: =IF(A7="","",DATE(YEAR(A7),MONTH(A7),1))
A8: 46193 | B8: Software | C8: Canva Pro | D8: 13 | G8: =IF(A8="","",DATE(YEAR(A8),MONTH(A8),1))
A9: 46204 | B9: Subscriptions | C9: Etsy Plus | D9: 10 | E9: Etsy | F9: Monthly | G9: =IF(A9="","",DATE(YEAR(A9),MONTH(A9),1))
A10: 46209 | B10: Packaging | C10: Mailers + stickers | D10: 32.1 | G10: =IF(A10="","",DATE(YEAR(A10),MONTH(A10),1))
A11: 46215 | B11: Ads | C11: Facebook ads | D11: 48 | E11: Etsy | F11: July push | G11: =IF(A11="","",DATE(YEAR(A11),MONTH(A11),1))
A12: 46221 | B12: Ads | C12: Pinterest ads | D12: 22 | E12: Etsy | G12: =IF(A12="","",DATE(YEAR(A12),MONTH(A12),1))
A13: 46225 | B13: Supplies | C13: Cardstock restock | D13: 19.8 | G13: =IF(A13="","",DATE(YEAR(A13),MONTH(A13),1))
A14: 46235 | B14: Subscriptions | C14: Etsy Plus | D14: 10 | E14: Etsy | F14: Monthly | G14: =IF(A14="","",DATE(YEAR(A14),MONTH(A14),1))
A15: 46238 | B15: Packaging | C15: Mailers | D15: 24.5 | G15: =IF(A15="","",DATE(YEAR(A15),MONTH(A15),1))
A16: 46243 | B16: Ads | C16: Instagram ads | D16: 30 | E16: Etsy | G16: =IF(A16="","",DATE(YEAR(A16),MONTH(A16),1))
G17: =IF(A17="","",DATE(YEAR(A17),MONTH(A17),1))
G18: =IF(A18="","",DATE(YEAR(A18),MONTH(A18),1))
G19: =IF(A19="","",DATE(YEAR(A19),MONTH(A19),1))
G20: =IF(A20="","",DATE(YEAR(A20),MONTH(A20),1))
G21: =IF(A21="","",DATE(YEAR(A21),MONTH(A21),1))
G22: =IF(A22="","",DATE(YEAR(A22),MONTH(A22),1))
G23: =IF(A23="","",DATE(YEAR(A23),MONTH(A23),1))
G24: =IF(A24="","",DATE(YEAR(A24),MONTH(A24),1))
G25: =IF(A25="","",DATE(YEAR(A25),MONTH(A25),1))
G26: =IF(A26="","",DATE(YEAR(A26),MONTH(A26),1))
G27: =IF(A27="","",DATE(YEAR(A27),MONTH(A27),1))
G28: =IF(A28="","",DATE(YEAR(A28),MONTH(A28),1))
... G84: =IF(A84="","",DATE(YEAR(A84),MONTH(A84),1))
A85: TOTAL | D85: =SUM(D5:D84)
A87: At tax time, filter by Category or Month. This is a bookkeeping aid, not tax advice.

Sheet Monthly Summary
A1: Monthly Summary
A2: Auto-calculated. Jan 2025 – Dec 2028 is already here. To add 2029+, copy the last row down — the Month formula is =EDATE(cell_above,1).
A3: Sales profit is from the Sales Log. Other expenses come from Fees & Expenses. Net = sales profit − other expenses.
A4: Month | B4: Orders | C4: Units | D4: Revenue | E4: Fees | F4: COGS | G4: Ship cost | H4: Sales profit | I4: Other expenses | J4: Net profit | K4: Margin
A5: 45658 | B5: =SUMIFS(SalesNewOrder,SalesMonth,A5) | C5: =SUMIFS(SalesQty,SalesMonth,A5) | D5: =SUMIFS(SalesGross,SalesMonth,A5) | E5: =SUMIFS(SalesFees,SalesMonth,A5) | F5: =SUMIFS(SalesCOGS,SalesMonth,A5) | G5: =SUMIFS(SalesShipPaid,SalesMonth,A5) | H5: =SUMIFS(SalesNet,SalesMonth,A5) | I5: =SUMIFS(ExpAmounts,ExpMonth,A5) | J5: =H5-I5 | K5: =IF(N(D5)=0,"",J5/D5)
A6: =EDATE(A5,1) | B6: =SUMIFS(SalesNewOrder,SalesMonth,A6) | C6: =SUMIFS(SalesQty,SalesMonth,A6) | D6: =SUMIFS(SalesGross,SalesMonth,A6) | E6: =SUMIFS(SalesFees,SalesMonth,A6) | F6: =SUMIFS(SalesCOGS,SalesMonth,A6) | G6: =SUMIFS(SalesShipPaid,SalesMonth,A6) | H6: =SUMIFS(SalesNet,SalesMonth,A6) | I6: =SUMIFS(ExpAmounts,ExpMonth,A6) | J6: =H6-I6 | K6: =IF(N(D6)=0,"",J6/D6)
A7: =EDATE(A6,1) | B7: =SUMIFS(SalesNewOrder,SalesMonth,A7) | C7: =SUMIFS(SalesQty,SalesMonth,A7) | D7: =SUMIFS(SalesGross,SalesMonth,A7) | E7: =SUMIFS(SalesFees,SalesMonth,A7) | F7: =SUMIFS(SalesCOGS,SalesMonth,A7) | G7: =SUMIFS(SalesShipPaid,SalesMonth,A7) | H7: =SUMIFS(SalesNet,SalesMonth,A7) | I7: =SUMIFS(ExpAmounts,ExpMonth,A7) | J7: =H7-I7 | K7: =IF(N(D7)=0,"",J7/D7)
A8: =EDATE(A7,1) | B8: =SUMIFS(SalesNewOrder,SalesMonth,A8) | C8: =SUMIFS(SalesQty,SalesMonth,A8) | D8: =SUMIFS(SalesGross,SalesMonth,A8) | E8: =SUMIFS(SalesFees,SalesMonth,A8) | F8: =SUMIFS(SalesCOGS,SalesMonth,A8) | G8: =SUMIFS(SalesShipPaid,SalesMonth,A8) | H8: =SUMIFS(SalesNet,SalesMonth,A8) | I8: =SUMIFS(ExpAmounts,ExpMonth,A8) | J8: =H8-I8 | K8: =IF(N(D8)=0,"",J8/D8)
A9: =EDATE(A8,1) | B9: =SUMIFS(SalesNewOrder,SalesMonth,A9) | C9: =SUMIFS(SalesQty,SalesMonth,A9) | D9: =SUMIFS(SalesGross,SalesMonth,A9) | E9: =SUMIFS(SalesFees,SalesMonth,A9) | F9: =SUMIFS(SalesCOGS,SalesMonth,A9) | G9: =SUMIFS(SalesShipPaid,SalesMonth,A9) | H9: =SUMIFS(SalesNet,SalesMonth,A9) | I9: =SUMIFS(ExpAmounts,ExpMonth,A9) | J9: =H9-I9 | K9: =IF(N(D9)=0,"",J9/D9)
A10: =EDATE(A9,1) | B10: =SUMIFS(SalesNewOrder,SalesMonth,A10) | C10: =SUMIFS(SalesQty,SalesMonth,A10) | D10: =SUMIFS(SalesGross,SalesMonth,A10) | E10: =SUMIFS(SalesFees,SalesMonth,A10) | F10: =SUMIFS(SalesCOGS,SalesMonth,A10) | G10: =SUMIFS(SalesShipPaid,SalesMonth,A10) | H10: =SUMIFS(SalesNet,SalesMonth,A10) | I10: =SUMIFS(ExpAmounts,ExpMonth,A10) | J10: =H10-I10 | K10: =IF(N(D10)=0,"",J10/D10)
A11: =EDATE(A10,1) | B11: =SUMIFS(SalesNewOrder,SalesMonth,A11) | C11: =SUMIFS(SalesQty,SalesMonth,A11) | D11: =SUMIFS(SalesGross,SalesMonth,A11) | E11: =SUMIFS(SalesFees,SalesMonth,A11) | F11: =SUMIFS(SalesCOGS,SalesMonth,A11) | G11: =SUMIFS(SalesShipPaid,SalesMonth,A11) | H11: =SUMIFS(SalesNet,SalesMonth,A11) | I11: =SUMIFS(ExpAmounts,ExpMonth,A11) | J11: =H11-I11 | K11: =IF(N(D11)=0,"",J11/D11)
A12: =EDATE(A11,1) | B12: =SUMIFS(SalesNewOrder,SalesMonth,A12) | C12: =SUMIFS(SalesQty,SalesMonth,A12) | D12: =SUMIFS(SalesGross,SalesMonth,A12) | E12: =SUMIFS(SalesFees,SalesMonth,A12) | F12: =SUMIFS(SalesCOGS,SalesMonth,A12) | G12: =SUMIFS(SalesShipPaid,SalesMonth,A12) | H12: =SUMIFS(SalesNet,SalesMonth,A12) | I12: =SUMIFS(ExpAmounts,ExpMonth,A12) | J12: =H12-I12 | K12: =IF(N(D12)=0,"",J12/D12)
A13: =EDATE(A12,1) | B13: =SUMIFS(SalesNewOrder,SalesMonth,A13) | C13: =SUMIFS(SalesQty,SalesMonth,A13) | D13: =SUMIFS(SalesGross,SalesMonth,A13) | E13: =SUMIFS(SalesFees,SalesMonth,A13) | F13: =SUMIFS(SalesCOGS,SalesMonth,A13) | G13: =SUMIFS(SalesShipPaid,SalesMonth,A13) | H13: =SUMIFS(SalesNet,SalesMonth,A13) | I13: =SUMIFS(ExpAmounts,ExpMonth,A13) | J13: =H13-I13 | K13: =IF(N(D13)=0,"",J13/D13)
A14: =EDATE(A13,1) | B14: =SUMIFS(SalesNewOrder,SalesMonth,A14) | C14: =SUMIFS(SalesQty,SalesMonth,A14) | D14: =SUMIFS(SalesGross,SalesMonth,A14) | E14: =SUMIFS(SalesFees,SalesMonth,A14) | F14: =SUMIFS(SalesCOGS,SalesMonth,A14) | G14: =SUMIFS(SalesShipPaid,SalesMonth,A14) | H14: =SUMIFS(SalesNet,SalesMonth,A14) | I14: =SUMIFS(ExpAmounts,ExpMonth,A14) | J14: =H14-I14 | K14: =IF(N(D14)=0,"",J14/D14)
A15: =EDATE(A14,1) | B15: =SUMIFS(SalesNewOrder,SalesMonth,A15) | C15: =SUMIFS(SalesQty,SalesMonth,A15) | D15: =SUMIFS(SalesGross,SalesMonth,A15) | E15: =SUMIFS(SalesFees,SalesMonth,A15) | F15: =SUMIFS(SalesCOGS,SalesMonth,A15) | G15: =SUMIFS(SalesShipPaid,SalesMonth,A15) | H15: =SUMIFS(SalesNet,SalesMonth,A15) | I15: =SUMIFS(ExpAmounts,ExpMonth,A15) | J15: =H15-I15 | K15: =IF(N(D15)=0,"",J15/D15)
A16: =EDATE(A15,1) | B16: =SUMIFS(SalesNewOrder,SalesMonth,A16) | C16: =SUMIFS(SalesQty,SalesMonth,A16) | D16: =SUMIFS(SalesGross,SalesMonth,A16) | E16: =SUMIFS(SalesFees,SalesMonth,A16) | F16: =SUMIFS(SalesCOGS,SalesMonth,A16) | G16: =SUMIFS(SalesShipPaid,SalesMonth,A16) | H16: =SUMIFS(SalesNet,SalesMonth,A16) | I16: =SUMIFS(ExpAmounts,ExpMonth,A16) | J16: =H16-I16 | K16: =IF(N(D16)=0,"",J16/D16)
A17: =EDATE(A16,1) | B17: =SUMIFS(SalesNewOrder,SalesMonth,A17) | C17: =SUMIFS(SalesQty,SalesMonth,A17) | D17: =SUMIFS(SalesGross,SalesMonth,A17) | E17: =SUMIFS(SalesFees,SalesMonth,A17) | F17: =SUMIFS(SalesCOGS,SalesMonth,A17) | G17: =SUMIFS(SalesShipPaid,SalesMonth,A17) | H17: =SUMIFS(SalesNet,SalesMonth,A17) | I17: =SUMIFS(ExpAmounts,ExpMonth,A17) | J17: =H17-I17 | K17: =IF(N(D17)=0,"",J17/D17)
... A52: =EDATE(A51,1) | B52: =SUMIFS(SalesNewOrder,SalesMonth,A52) | C52: =SUMIFS(SalesQty,SalesMonth,A52) | D52: =SUMIFS(SalesGross,SalesMonth,A52) | E52: =SUMIFS(SalesFees,SalesMonth,A52) | F52: =SUMIFS(SalesCOGS,SalesMonth,A52) | G52: =SUMIFS(SalesShipPaid,SalesMonth,A52) | H52: =SUMIFS(SalesNet,SalesMonth,A52) | I52: =SUMIFS(ExpAmounts,ExpMonth,A52) | J52: =H52-I52 | K52: =IF(N(D52)=0,"",J52/D52)
A53: TOTAL | B53: =SUM(B5:B52) | C53: =SUM(C5:C52) | D53: =SUM(D5:D52) | E53: =SUM(E5:E52) | F53: =SUM(F5:F52) | G53: =SUM(G5:G52) | H53: =SUM(H5:H52) | I53: =SUM(I5:I52) | J53: =SUM(J5:J52) | K53: =IF(D53=0,"",J53/D53)

Sheet Instructions
A1: How to use this template
B2: Track every sale, fee, and expense so you know what you actually keep. Built for Etsy, Shopify, Gumroad, and similar shops.
B4: 1. Five-minute start
B5: 1. Open Products. Type your shop name, then replace the sample catalog with your items — name, cost of goods per unit, and selling price. Stock is optional.
B6: 2. Open Sales Log. Delete the sample rows (values only) or overwrite them. Each sale needs a date, order ID, product, qty, unit price, shipping charged, platform fees, and shipping you paid.
B7: 3. Open Fees & Expenses. Log ads, packaging stock, Etsy Plus / Shopify, software — anything not attached to one order.
B8: 4. Live on the Dashboard. All-time cards are your real earnings. Change Review month (blue cell) to compare any two months.
B9: 5. Monthly Summary is already calculating. Use it at month-end or tax time.
B10: [Screenshot: Dashboard cards — revenue, net profit, margin, orders]
B12: 2. What each tab does
B13: Dashboard — High-level numbers and charts. The only thing to type is Review month.
B14: Sales Log — Every order line. This is where daily selling gets recorded.
B15: Products — Your catalog and cost of goods. Sales Log picks names from here.
... B50: You do not need to fill every row. Empty blue rows are waiting for the next sale.
