Workbook
Name UserName: 'Paycheck Setup'!$C$4
Name PayFrequency: 'Paycheck Setup'!$C$5
Name PayAmount: 'Paycheck Setup'!$C$6
Name ExtraIncome: 'Paycheck Setup'!$C$7
Name LastPayDate: 'Paycheck Setup'!$C$8
Name NextPayDate: 'Paycheck Setup'!$C$11
Name PeriodStart: 'Paycheck Setup'!$C$12
Name PeriodEnd: 'Paycheck Setup'!$C$13
Name DaysInPeriod: 'Paycheck Setup'!$C$14
Name TotalAvailable: 'Paycheck Setup'!$C$15
Name TotalBillsPeriod: 'Paycheck Setup'!$C$18
Name BillsUnpaid: 'Paycheck Setup'!$C$19
Name PlannedSpending: 'Paycheck Setup'!$C$20
Name ActualSpending: 'Paycheck Setup'!$C$21
Name LeftAfterBills: 'Paycheck Setup'!$C$22
Name LeftAfterBudget: 'Paycheck Setup'!$C$23
Name LeftAfterActual: 'Paycheck Setup'!$C$24
Name List_PayFreq: 'Paycheck Setup'!$N$2:$N$4
Name List_BillFreq: 'Paycheck Setup'!$N$6:$N$11
Name List_PaidStatus: 'Paycheck Setup'!$N$13:$N$14
Name List_Categories: 'Budget Categories'!$A$5:$A$24
Name TxnDates: 'Transaction Log'!$A$5:$A$104
Name TxnCategories: 'Transaction Log'!$C$5:$C$104
Name TxnAmounts: 'Transaction Log'!$D$5:$D$104

Sheet Dashboard
A1: Paycheck Budget + Bill Tracker
A2: =IF(UserName="","Your paycheck overview","Hello, "&UserName)&IF(OR(PeriodStart="",PeriodEnd="")," · Set your pay date on Paycheck Setup"," · "&TEXT(PeriodStart,"mmm d")&" – "&TEXT(PeriodEnd,"mmm d, yyyy")&" · "&PayFrequency) | I2: ="As of "&TEXT(TODAY(),"mmm d, yyyy")
A4: NEXT PAYCHECK | D4: BILLS THIS PERIOD | G4: LEFT AFTER BILLS | J4: LEFT AFTER BILLS + BUDGET
A5: =NextPayDate | D5: =TotalBillsPeriod | G5: =LeftAfterBills | J5: =LeftAfterBudget
A6: =PayAmount | D6: =IF(N(BillsUnpaid)<=0,"All paid","Unpaid "&TEXT(BillsUnpaid,"$#,##0.00")) | G6: ="Available "&TEXT(TotalAvailable,"$#,##0.00") | J6: ="If you stick to the plan"
A7: Primary take-home on that day | D7: Due in this paycheck window | G7: Pay + extra − bills | J7: True leftover / unallocated
A9: THIS PAYCHECK AT A GLANCE | G9: BILLS DUE THIS PERIOD
A10: Total available (pay + extra) | D10: =TotalAvailable | G10: Bill | I10: Due | J10: Amount | K10: Status
A11: Bills due this period | D11: =TotalBillsPeriod | G11: =IFERROR(INDEX(Bills!$A$5:$A$34,MATCH(1,Bills!$M$5:$M$34,0)),"") | I11: =IF(G11="","",IFERROR(INDEX(Bills!$H$5:$H$34,MATCH(1,Bills!$M$5:$M$34,0)),"")) | J11: =IF(G11="","",IFERROR(INDEX(Bills!$J$5:$J$34,MATCH(1,Bills!$M$5:$M$34,0)),"")) | K11: =IF(G11="","",IFERROR(INDEX(Bills!$L$5:$L$34,MATCH(1,Bills!$M$5:$M$34,0)),""))
A12: Left after bills | D12: =LeftAfterBills | G12: =IFERROR(INDEX(Bills!$A$5:$A$34,MATCH(2,Bills!$M$5:$M$34,0)),"") | I12: =IF(G12="","",IFERROR(INDEX(Bills!$H$5:$H$34,MATCH(2,Bills!$M$5:$M$34,0)),"")) | J12: =IF(G12="","",IFERROR(INDEX(Bills!$J$5:$J$34,MATCH(2,Bills!$M$5:$M$34,0)),"")) | K12: =IF(G12="","",IFERROR(INDEX(Bills!$L$5:$L$34,MATCH(2,Bills!$M$5:$M$34,0)),""))
A13: Planned category spending | D13: =PlannedSpending | G13: =IFERROR(INDEX(Bills!$A$5:$A$34,MATCH(3,Bills!$M$5:$M$34,0)),"") | I13: =IF(G13="","",IFERROR(INDEX(Bills!$H$5:$H$34,MATCH(3,Bills!$M$5:$M$34,0)),"")) | J13: =IF(G13="","",IFERROR(INDEX(Bills!$J$5:$J$34,MATCH(3,Bills!$M$5:$M$34,0)),"")) | K13: =IF(G13="","",IFERROR(INDEX(Bills!$L$5:$L$34,MATCH(3,Bills!$M$5:$M$34,0)),""))
A14: Actual spending so far | D14: =ActualSpending | G14: =IFERROR(INDEX(Bills!$A$5:$A$34,MATCH(4,Bills!$M$5:$M$34,0)),"") | I14: =IF(G14="","",IFERROR(INDEX(Bills!$H$5:$H$34,MATCH(4,Bills!$M$5:$M$34,0)),"")) | J14: =IF(G14="","",IFERROR(INDEX(Bills!$J$5:$J$34,MATCH(4,Bills!$M$5:$M$34,0)),"")) | K14: =IF(G14="","",IFERROR(INDEX(Bills!$L$5:$L$34,MATCH(4,Bills!$M$5:$M$34,0)),""))
A15: Left after bills + budget | D15: =LeftAfterBudget | G15: =IFERROR(INDEX(Bills!$A$5:$A$34,MATCH(5,Bills!$M$5:$M$34,0)),"") | I15: =IF(G15="","",IFERROR(INDEX(Bills!$H$5:$H$34,MATCH(5,Bills!$M$5:$M$34,0)),"")) | J15: =IF(G15="","",IFERROR(INDEX(Bills!$J$5:$J$34,MATCH(5,Bills!$M$5:$M$34,0)),"")) | K15: =IF(G15="","",IFERROR(INDEX(Bills!$L$5:$L$34,MATCH(5,Bills!$M$5:$M$34,0)),""))
A16: Left after actual spending | D16: =LeftAfterActual | G16: =IFERROR(INDEX(Bills!$A$5:$A$34,MATCH(6,Bills!$M$5:$M$34,0)),"") | I16: =IF(G16="","",IFERROR(INDEX(Bills!$H$5:$H$34,MATCH(6,Bills!$M$5:$M$34,0)),"")) | J16: =IF(G16="","",IFERROR(INDEX(Bills!$J$5:$J$34,MATCH(6,Bills!$M$5:$M$34,0)),"")) | K16: =IF(G16="","",IFERROR(INDEX(Bills!$L$5:$L$34,MATCH(6,Bills!$M$5:$M$34,0)),""))
A17: Category budget used | D17: =IF(PlannedSpending=0,"",ActualSpending/PlannedSpending) | G17: =IFERROR(INDEX(Bills!$A$5:$A$34,MATCH(7,Bills!$M$5:$M$34,0)),"") | I17: =IF(G17="","",IFERROR(INDEX(Bills!$H$5:$H$34,MATCH(7,Bills!$M$5:$M$34,0)),"")) | J17: =IF(G17="","",IFERROR(INDEX(Bills!$J$5:$J$34,MATCH(7,Bills!$M$5:$M$34,0)),"")) | K17: =IF(G17="","",IFERROR(INDEX(Bills!$L$5:$L$34,MATCH(7,Bills!$M$5:$M$34,0)),""))
A18: Bills are reserved even if unpaid. Change pay info on Paycheck Setup. | G18: =IFERROR(INDEX(Bills!$A$5:$A$34,MATCH(8,Bills!$M$5:$M$34,0)),"") | I18: =IF(G18="","",IFERROR(INDEX(Bills!$H$5:$H$34,MATCH(8,Bills!$M$5:$M$34,0)),"")) | J18: =IF(G18="","",IFERROR(INDEX(Bills!$J$5:$J$34,MATCH(8,Bills!$M$5:$M$34,0)),"")) | K18: =IF(G18="","",IFERROR(INDEX(Bills!$L$5:$L$34,MATCH(8,Bills!$M$5:$M$34,0)),""))
A20: ACTUAL SPENDING BY CATEGORY | G20: PLANNED VS ACTUAL
A39: CATEGORY PROGRESS
A40: Category | B40: Planned | C40: Actual | D40: Remaining | E40: % used | F40: Progress | J40: Status
A41: =IF('Budget Categories'!A5="","",'Budget Categories'!A5) | B41: =IF(A41="","",'Budget Categories'!B5) | C41: =IF(A41="","",'Budget Categories'!C5) | D41: =IF(A41="","",'Budget Categories'!D5) | E41: =IF(A41="","",'Budget Categories'!E5) | F41: =IF(A41="","",'Budget Categories'!F5) | J41: =IF(A41="","",'Budget Categories'!G5)
A42: =IF('Budget Categories'!A6="","",'Budget Categories'!A6) | B42: =IF(A42="","",'Budget Categories'!B6) | C42: =IF(A42="","",'Budget Categories'!C6) | D42: =IF(A42="","",'Budget Categories'!D6) | E42: =IF(A42="","",'Budget Categories'!E6) | F42: =IF(A42="","",'Budget Categories'!F6) | J42: =IF(A42="","",'Budget Categories'!G6)
A43: =IF('Budget Categories'!A7="","",'Budget Categories'!A7) | B43: =IF(A43="","",'Budget Categories'!B7) | C43: =IF(A43="","",'Budget Categories'!C7) | D43: =IF(A43="","",'Budget Categories'!D7) | E43: =IF(A43="","",'Budget Categories'!E7) | F43: =IF(A43="","",'Budget Categories'!F7) | J43: =IF(A43="","",'Budget Categories'!G7)
A44: =IF('Budget Categories'!A8="","",'Budget Categories'!A8) | B44: =IF(A44="","",'Budget Categories'!B8) | C44: =IF(A44="","",'Budget Categories'!C8) | D44: =IF(A44="","",'Budget Categories'!D8) | E44: =IF(A44="","",'Budget Categories'!E8) | F44: =IF(A44="","",'Budget Categories'!F8) | J44: =IF(A44="","",'Budget Categories'!G8)
A45: =IF('Budget Categories'!A9="","",'Budget Categories'!A9) | B45: =IF(A45="","",'Budget Categories'!B9) | C45: =IF(A45="","",'Budget Categories'!C9) | D45: =IF(A45="","",'Budget Categories'!D9) | E45: =IF(A45="","",'Budget Categories'!E9) | F45: =IF(A45="","",'Budget Categories'!F9) | J45: =IF(A45="","",'Budget Categories'!G9)
A46: =IF('Budget Categories'!A10="","",'Budget Categories'!A10) | B46: =IF(A46="","",'Budget Categories'!B10) | C46: =IF(A46="","",'Budget Categories'!C10) | D46: =IF(A46="","",'Budget Categories'!D10) | E46: =IF(A46="","",'Budget Categories'!E10) | F46: =IF(A46="","",'Budget Categories'!F10) | J46: =IF(A46="","",'Budget Categories'!G10)
A47: =IF('Budget Categories'!A11="","",'Budget Categories'!A11) | B47: =IF(A47="","",'Budget Categories'!B11) | C47: =IF(A47="","",'Budget Categories'!C11) | D47: =IF(A47="","",'Budget Categories'!D11) | E47: =IF(A47="","",'Budget Categories'!E11) | F47: =IF(A47="","",'Budget Categories'!F11) | J47: =IF(A47="","",'Budget Categories'!G11)
A48: =IF('Budget Categories'!A12="","",'Budget Categories'!A12) | B48: =IF(A48="","",'Budget Categories'!B12) | C48: =IF(A48="","",'Budget Categories'!C12) | D48: =IF(A48="","",'Budget Categories'!D12) | E48: =IF(A48="","",'Budget Categories'!E12) | F48: =IF(A48="","",'Budget Categories'!F12) | J48: =IF(A48="","",'Budget Categories'!G12)
A50: Blue cells (on other tabs) are for typing. This page is a live summary — nothing to edit here. To start the next paycheck, duplicate the file and follow the checklist on Paycheck Setup. See Instructions for the 5-minute start.
A52: CHART DATA · used by the graphs above — do not edit
A53: Category | B53: Actual | C53: Planned | D53: Spent
A54: =IF('Budget Categories'!A5="","",'Budget Categories'!A5) | B54: =IF(OR(A54="",'Budget Categories'!C5=0),NA(),'Budget Categories'!C5) | C54: =IF(A54="","",'Budget Categories'!B5) | D54: =IF(A54="","",'Budget Categories'!C5)
A55: =IF('Budget Categories'!A6="","",'Budget Categories'!A6) | B55: =IF(OR(A55="",'Budget Categories'!C6=0),NA(),'Budget Categories'!C6) | C55: =IF(A55="","",'Budget Categories'!B6) | D55: =IF(A55="","",'Budget Categories'!C6)
A56: =IF('Budget Categories'!A7="","",'Budget Categories'!A7) | B56: =IF(OR(A56="",'Budget Categories'!C7=0),NA(),'Budget Categories'!C7) | C56: =IF(A56="","",'Budget Categories'!B7) | D56: =IF(A56="","",'Budget Categories'!C7)
A57: =IF('Budget Categories'!A8="","",'Budget Categories'!A8) | B57: =IF(OR(A57="",'Budget Categories'!C8=0),NA(),'Budget Categories'!C8) | C57: =IF(A57="","",'Budget Categories'!B8) | D57: =IF(A57="","",'Budget Categories'!C8)
A58: =IF('Budget Categories'!A9="","",'Budget Categories'!A9) | B58: =IF(OR(A58="",'Budget Categories'!C9=0),NA(),'Budget Categories'!C9) | C58: =IF(A58="","",'Budget Categories'!B9) | D58: =IF(A58="","",'Budget Categories'!C9)
A59: =IF('Budget Categories'!A10="","",'Budget Categories'!A10) | B59: =IF(OR(A59="",'Budget Categories'!C10=0),NA(),'Budget Categories'!C10) | C59: =IF(A59="","",'Budget Categories'!B10) | D59: =IF(A59="","",'Budget Categories'!C10)
A60: =IF('Budget Categories'!A11="","",'Budget Categories'!A11) | B60: =IF(OR(A60="",'Budget Categories'!C11=0),NA(),'Budget Categories'!C11) | C60: =IF(A60="","",'Budget Categories'!B11) | D60: =IF(A60="","",'Budget Categories'!C11)
A61: =IF('Budget Categories'!A12="","",'Budget Categories'!A12) | B61: =IF(OR(A61="",'Budget Categories'!C12=0),NA(),'Budget Categories'!C12) | C61: =IF(A61="","",'Budget Categories'!B12) | D61: =IF(A61="","",'Budget Categories'!C12)
A62: =IF('Budget Categories'!A13="","",'Budget Categories'!A13) | B62: =IF(OR(A62="",'Budget Categories'!C13=0),NA(),'Budget Categories'!C13) | C62: =IF(A62="","",'Budget Categories'!B13) | D62: =IF(A62="","",'Budget Categories'!C13)
A63: =IF('Budget Categories'!A14="","",'Budget Categories'!A14) | B63: =IF(OR(A63="",'Budget Categories'!C14=0),NA(),'Budget Categories'!C14) | C63: =IF(A63="","",'Budget Categories'!B14) | D63: =IF(A63="","",'Budget Categories'!C14)
...

Sheet Paycheck Setup
A1: Paycheck Budget + Bill Tracker | N1: DROPDOWN LISTS | O1: Edit these if you need extra options. Don't insert columns.
A2: Paycheck Setup · Enter your pay info here. Blue cells are for typing. Gray cells calculate automatically. | N2: Weekly | O2: Pay frequency list
A3: 1. YOUR PAY | N3: Bi-Weekly
A4: Your name | C4: Alex Rivera | E4: Appears at the top of the Dashboard. | N4: Monthly
A5: Pay frequency | C5: Bi-Weekly | E5: How often you get paid.
A6: Net paycheck amount | C6: 1850 | E6: Your take-home (net) amount. | N6: Weekly | O6: Bill frequency list
A7: Extra income this period | C7: 120 | E7: Optional extra money this period. | N7: Bi-Weekly
A8: Last paycheck date | C8: 46241 | E8: Date printed on this paycheck. | N8: Monthly
N9: Quarterly
A10: 2. THIS PERIOD (calculated — don't edit) | N10: Yearly
A11: Next paycheck date | C11: =IF(C8="","",IF(C5="Weekly",C8+7,IF(C5="Bi-Weekly",C8+14,IF(C5="Monthly",EDATE(C8,1),"")))) | E11: Last pay date plus 7 days, 14 days, or one month. | N11: One-Time
A12: Period start | C12: =IF(C8="","",C8) | E12: Same as last paycheck date.
A13: Period end | C13: =IF(C11="","",C11-1) | E13: The day before your next paycheck. | N13: Unpaid | O13: Paid status list
A14: Days in period | C14: =IF(OR(C12="",C13=""),"",C13-C12+1) | E14: Length of this paycheck window. | N14: Paid
A15: Total available | C15: =N(C6)+N(C7) | E15: Net paycheck + extra income.
A17: 3. THIS PERIOD TOTALS (calculated — don't edit)
A18: Bills due this period | C18: =SUM(Bills!$J$5:$J$34) | E18: Sum of Amount this period on the Bills tab.
A19: Bills still unpaid | C19: =SUMIFS(Bills!$J$5:$J$34,Bills!$F$5:$F$34,"Unpaid",Bills!$J$5:$J$34,">0") | E19: Unpaid portion of those bills.
A20: Planned category spending | C20: ='Budget Categories'!B25 | E20: Sum of planned amounts on Budget Categories.
A21: Actual spending (from log) | C21: =SUMIFS('Transaction Log'!$D$5:$D$104,'Transaction Log'!$A$5:$A$104,">="&PeriodStart,'Transaction Log'!$A$5:$A$104,"<="&PeriodEnd) | E21: Spending logged inside this period.
A22: Left after bills | C22: =C15-C18 | E22: Available minus bills. The first leftover number.
A23: Left after bills + budget | C23: =C15-C18-C20 | E23: True leftover if you stick to the plan.
A24: Left after actual spending | C24: =C15-C18-C21 | E24: Available minus bills minus what you have already spent.
A25: Category budget used | C25: =IF(C20=0,"",C21/C20) | E25: Actual spending ÷ planned categories.
A27: 4. START A NEW PAYCHECK PERIOD
A28: ☐ File → Save As (Excel) or File → Make a copy (Google Sheets). Name it with the new payday.
A29: ☐ Update Last paycheck date, Net paycheck amount, and Extra income above.
A30: ☐ On Bills, set Paid? back to Unpaid and change any amounts that moved.
A31: ☐ On Transaction Log, delete the old spending rows (keep the header and formulas in column F).
A32: ☐ Adjust category planned amounts if this paycheck needs a different plan.
A33: ☐ Open the Dashboard and confirm the four cards match the new period.
A35: COLOR KEY
A36: Type here | C36: Blue cells — the only places you type.
A37: Calculated | C37: Gray cells — formulas. Leave them alone.
A38: Over / overdue | C38: Red — overspent category or overdue unpaid bill.
A39: Due soon | C39: Amber — bill due within 7 days.
A40: Under budget | C40: Green — category still has room.

Sheet Bills
A1: Bills
A2: Recurring and one-time bills. Blue = type. Gray = calculated. A weekly bill in a 2-week period is counted twice. Use This period $ to assign part of a bill (like half of rent) to this paycheck.
A3: =IF(OR(PeriodStart="",PeriodEnd=""),"Set Last paycheck date on Paycheck Setup.","Period: "&TEXT(PeriodStart,"mmm d")&" – "&TEXT(PeriodEnd,"mmm d, yyyy")&" · Bills this period: "&TEXT(TotalBillsPeriod,"$#,##0.00")&" · Still unpaid: "&TEXT(BillsUnpaid,"$#,##0.00"))
A4: Bill name | B4: Amount | C4: Due date | D4: Frequency | E4: Category | F4: Paid? | G4: This period $ (optional) | H4: Next due | I4: Occurrences | J4: Amount this period | K4: Due this period? | L4: Status
A5: Rent | B5: 1200 | C5: 46235 | D5: Monthly | F5: Unpaid | G5: 600 | H5: =IF(OR(A5="",C5="",D5=""),"",IF(D5="One-Time",IF(AND(C5>=PeriodStart,C5<=PeriodEnd),C5,""),IF(OR(D5="Weekly",D5="Bi-Weekly"),IF(C5>PeriodEnd,"",MAX(C5,C5+IF(D5="Weekly",7,14)*CEILING(MAX(0,PeriodStart-C5)/IF(D5="Weekly",7,14),1))),IF(OR(D5="Monthly",D5="Quarterly",D5="Yearly"),IF(EDATE(C5,CEILING(MAX(0,(YEAR(PeriodStart)-YEAR(C5))*12+(MONTH(PeriodStart)-MONTH(C5)))/IF(D5="Monthly",1,IF(D5="Quarterly",3,12)),1)*IF(D5="Monthly",1,IF(D5="Quarterly",3,12)))<PeriodStart,EDATE(C5,CEILING(MAX(0,(YEAR(PeriodStart)-YEAR(C5))*12+(MONTH(PeriodStart)-MONTH(C5)))/IF(D5="Monthly",1,IF(D5="Quarterly",3,12)),1)*IF(D5="Monthly",1,IF(D5="Quarterly",3,12))+IF(D5="Monthly",1,IF(D5="Quarterly",3,12))),EDATE(C5,CEILING(MAX(0,(YEAR(PeriodStart)-YEAR(C5))*12+(MONTH(PeriodStart)-MONTH(C5)))/IF(D5="Monthly",1,IF(D5="Quarterly",3,12)),1)*IF(D5="Monthly",1,IF(D5="Quarterly",3,12)))),"")))) | I5: =IF(A5="","",IF(H5="",0,IF(OR(D5="Monthly",D5="Quarterly",D5="Yearly",D5="One-Time"),IF(AND(H5>=PeriodStart,H5<=PeriodEnd),1,0),IF(D5="Weekly",1+INT((PeriodEnd-H5)/7),IF(D5="Bi-Weekly",1+INT((PeriodEnd-H5)/14),0))))) | J5: =IF(A5="","",IF(G5<>"",G5,IF(I5=0,0,B5*I5))) | K5: =IF(A5="","",IF(N(J5)>0,"Yes","")) | L5: =IF(A5="","",IF(F5="Paid","Paid",IF(N(J5)<=0,"Not this period",IF(AND(H5<>"",H5<TODAY()),"Overdue",IF(AND(H5<>"",H5<=TODAY()+7),"Due soon","Scheduled"))))) | M5: =IF(OR(A5="",N(J5)<=0),"",COUNTIF($J$5:$J5,">0"))
A6: Electric | B6: 95 | C6: 46244 | D6: Monthly | F6: Unpaid | H6: =IF(OR(A6="",C6="",D6=""),"",IF(D6="One-Time",IF(AND(C6>=PeriodStart,C6<=PeriodEnd),C6,""),IF(OR(D6="Weekly",D6="Bi-Weekly"),IF(C6>PeriodEnd,"",MAX(C6,C6+IF(D6="Weekly",7,14)*CEILING(MAX(0,PeriodStart-C6)/IF(D6="Weekly",7,14),1))),IF(OR(D6="Monthly",D6="Quarterly",D6="Yearly"),IF(EDATE(C6,CEILING(MAX(0,(YEAR(PeriodStart)-YEAR(C6))*12+(MONTH(PeriodStart)-MONTH(C6)))/IF(D6="Monthly",1,IF(D6="Quarterly",3,12)),1)*IF(D6="Monthly",1,IF(D6="Quarterly",3,12)))<PeriodStart,EDATE(C6,CEILING(MAX(0,(YEAR(PeriodStart)-YEAR(C6))*12+(MONTH(PeriodStart)-MONTH(C6)))/IF(D6="Monthly",1,IF(D6="Quarterly",3,12)),1)*IF(D6="Monthly",1,IF(D6="Quarterly",3,12))+IF(D6="Monthly",1,IF(D6="Quarterly",3,12))),EDATE(C6,CEILING(MAX(0,(YEAR(PeriodStart)-YEAR(C6))*12+(MONTH(PeriodStart)-MONTH(C6)))/IF(D6="Monthly",1,IF(D6="Quarterly",3,12)),1)*IF(D6="Monthly",1,IF(D6="Quarterly",3,12)))),"")))) | I6: =IF(A6="","",IF(H6="",0,IF(OR(D6="Monthly",D6="Quarterly",D6="Yearly",D6="One-Time"),IF(AND(H6>=PeriodStart,H6<=PeriodEnd),1,0),IF(D6="Weekly",1+INT((PeriodEnd-H6)/7),IF(D6="Bi-Weekly",1+INT((PeriodEnd-H6)/14),0))))) | J6: =IF(A6="","",IF(G6<>"",G6,IF(I6=0,0,B6*I6))) | K6: =IF(A6="","",IF(N(J6)>0,"Yes","")) | L6: =IF(A6="","",IF(F6="Paid","Paid",IF(N(J6)<=0,"Not this period",IF(AND(H6<>"",H6<TODAY()),"Overdue",IF(AND(H6<>"",H6<=TODAY()+7),"Due soon","Scheduled"))))) | M6: =IF(OR(A6="",N(J6)<=0),"",COUNTIF($J$5:$J6,">0"))
A7: Phone | B7: 75 | C7: 46242 | D7: Monthly | F7: Paid | H7: =IF(OR(A7="",C7="",D7=""),"",IF(D7="One-Time",IF(AND(C7>=PeriodStart,C7<=PeriodEnd),C7,""),IF(OR(D7="Weekly",D7="Bi-Weekly"),IF(C7>PeriodEnd,"",MAX(C7,C7+IF(D7="Weekly",7,14)*CEILING(MAX(0,PeriodStart-C7)/IF(D7="Weekly",7,14),1))),IF(OR(D7="Monthly",D7="Quarterly",D7="Yearly"),IF(EDATE(C7,CEILING(MAX(0,(YEAR(PeriodStart)-YEAR(C7))*12+(MONTH(PeriodStart)-MONTH(C7)))/IF(D7="Monthly",1,IF(D7="Quarterly",3,12)),1)*IF(D7="Monthly",1,IF(D7="Quarterly",3,12)))<PeriodStart,EDATE(C7,CEILING(MAX(0,(YEAR(PeriodStart)-YEAR(C7))*12+(MONTH(PeriodStart)-MONTH(C7)))/IF(D7="Monthly",1,IF(D7="Quarterly",3,12)),1)*IF(D7="Monthly",1,IF(D7="Quarterly",3,12))+IF(D7="Monthly",1,IF(D7="Quarterly",3,12))),EDATE(C7,CEILING(MAX(0,(YEAR(PeriodStart)-YEAR(C7))*12+(MONTH(PeriodStart)-MONTH(C7)))/IF(D7="Monthly",1,IF(D7="Quarterly",3,12)),1)*IF(D7="Monthly",1,IF(D7="Quarterly",3,12)))),"")))) | I7: =IF(A7="","",IF(H7="",0,IF(OR(D7="Monthly",D7="Quarterly",D7="Yearly",D7="One-Time"),IF(AND(H7>=PeriodStart,H7<=PeriodEnd),1,0),IF(D7="Weekly",1+INT((PeriodEnd-H7)/7),IF(D7="Bi-Weekly",1+INT((PeriodEnd-H7)/14),0))))) | J7: =IF(A7="","",IF(G7<>"",G7,IF(I7=0,0,B7*I7))) | K7: =IF(A7="","",IF(N(J7)>0,"Yes","")) | L7: =IF(A7="","",IF(F7="Paid","Paid",IF(N(J7)<=0,"Not this period",IF(AND(H7<>"",H7<TODAY()),"Overdue",IF(AND(H7<>"",H7<=TODAY()+7),"Due soon","Scheduled"))))) | M7: =IF(OR(A7="",N(J7)<=0),"",COUNTIF($J$5:$J7,">0"))
A8: Internet | B8: 65 | C8: 46249 | D8: Monthly | F8: Unpaid | H8: =IF(OR(A8="",C8="",D8=""),"",IF(D8="One-Time",IF(AND(C8>=PeriodStart,C8<=PeriodEnd),C8,""),IF(OR(D8="Weekly",D8="Bi-Weekly"),IF(C8>PeriodEnd,"",MAX(C8,C8+IF(D8="Weekly",7,14)*CEILING(MAX(0,PeriodStart-C8)/IF(D8="Weekly",7,14),1))),IF(OR(D8="Monthly",D8="Quarterly",D8="Yearly"),IF(EDATE(C8,CEILING(MAX(0,(YEAR(PeriodStart)-YEAR(C8))*12+(MONTH(PeriodStart)-MONTH(C8)))/IF(D8="Monthly",1,IF(D8="Quarterly",3,12)),1)*IF(D8="Monthly",1,IF(D8="Quarterly",3,12)))<PeriodStart,EDATE(C8,CEILING(MAX(0,(YEAR(PeriodStart)-YEAR(C8))*12+(MONTH(PeriodStart)-MONTH(C8)))/IF(D8="Monthly",1,IF(D8="Quarterly",3,12)),1)*IF(D8="Monthly",1,IF(D8="Quarterly",3,12))+IF(D8="Monthly",1,IF(D8="Quarterly",3,12))),EDATE(C8,CEILING(MAX(0,(YEAR(PeriodStart)-YEAR(C8))*12+(MONTH(PeriodStart)-MONTH(C8)))/IF(D8="Monthly",1,IF(D8="Quarterly",3,12)),1)*IF(D8="Monthly",1,IF(D8="Quarterly",3,12)))),"")))) | I8: =IF(A8="","",IF(H8="",0,IF(OR(D8="Monthly",D8="Quarterly",D8="Yearly",D8="One-Time"),IF(AND(H8>=PeriodStart,H8<=PeriodEnd),1,0),IF(D8="Weekly",1+INT((PeriodEnd-H8)/7),IF(D8="Bi-Weekly",1+INT((PeriodEnd-H8)/14),0))))) | J8: =IF(A8="","",IF(G8<>"",G8,IF(I8=0,0,B8*I8))) | K8: =IF(A8="","",IF(N(J8)>0,"Yes","")) | L8: =IF(A8="","",IF(F8="Paid","Paid",IF(N(J8)<=0,"Not this period",IF(AND(H8<>"",H8<TODAY()),"Overdue",IF(AND(H8<>"",H8<=TODAY()+7),"Due soon","Scheduled"))))) | M8: =IF(OR(A8="",N(J8)<=0),"",COUNTIF($J$5:$J8,">0"))
A9: Car insurance | B9: 142 | C9: 46246 | D9: Monthly | F9: Unpaid | H9: =IF(OR(A9="",C9="",D9=""),"",IF(D9="One-Time",IF(AND(C9>=PeriodStart,C9<=PeriodEnd),C9,""),IF(OR(D9="Weekly",D9="Bi-Weekly"),IF(C9>PeriodEnd,"",MAX(C9,C9+IF(D9="Weekly",7,14)*CEILING(MAX(0,PeriodStart-C9)/IF(D9="Weekly",7,14),1))),IF(OR(D9="Monthly",D9="Quarterly",D9="Yearly"),IF(EDATE(C9,CEILING(MAX(0,(YEAR(PeriodStart)-YEAR(C9))*12+(MONTH(PeriodStart)-MONTH(C9)))/IF(D9="Monthly",1,IF(D9="Quarterly",3,12)),1)*IF(D9="Monthly",1,IF(D9="Quarterly",3,12)))<PeriodStart,EDATE(C9,CEILING(MAX(0,(YEAR(PeriodStart)-YEAR(C9))*12+(MONTH(PeriodStart)-MONTH(C9)))/IF(D9="Monthly",1,IF(D9="Quarterly",3,12)),1)*IF(D9="Monthly",1,IF(D9="Quarterly",3,12))+IF(D9="Monthly",1,IF(D9="Quarterly",3,12))),EDATE(C9,CEILING(MAX(0,(YEAR(PeriodStart)-YEAR(C9))*12+(MONTH(PeriodStart)-MONTH(C9)))/IF(D9="Monthly",1,IF(D9="Quarterly",3,12)),1)*IF(D9="Monthly",1,IF(D9="Quarterly",3,12)))),"")))) | I9: =IF(A9="","",IF(H9="",0,IF(OR(D9="Monthly",D9="Quarterly",D9="Yearly",D9="One-Time"),IF(AND(H9>=PeriodStart,H9<=PeriodEnd),1,0),IF(D9="Weekly",1+INT((PeriodEnd-H9)/7),IF(D9="Bi-Weekly",1+INT((PeriodEnd-H9)/14),0))))) | J9: =IF(A9="","",IF(G9<>"",G9,IF(I9=0,0,B9*I9))) | K9: =IF(A9="","",IF(N(J9)>0,"Yes","")) | L9: =IF(A9="","",IF(F9="Paid","Paid",IF(N(J9)<=0,"Not this period",IF(AND(H9<>"",H9<TODAY()),"Overdue",IF(AND(H9<>"",H9<=TODAY()+7),"Due soon","Scheduled"))))) | M9: =IF(OR(A9="",N(J9)<=0),"",COUNTIF($J$5:$J9,">0"))
A10: Credit card min. | B10: 85 | C10: 46252 | D10: Monthly | F10: Unpaid | H10: =IF(OR(A10="",C10="",D10=""),"",IF(D10="One-Time",IF(AND(C10>=PeriodStart,C10<=PeriodEnd),C10,""),IF(OR(D10="Weekly",D10="Bi-Weekly"),IF(C10>PeriodEnd,"",MAX(C10,C10+IF(D10="Weekly",7,14)*CEILING(MAX(0,PeriodStart-C10)/IF(D10="Weekly",7,14),1))),IF(OR(D10="Monthly",D10="Quarterly",D10="Yearly"),IF(EDATE(C10,CEILING(MAX(0,(YEAR(PeriodStart)-YEAR(C10))*12+(MONTH(PeriodStart)-MONTH(C10)))/IF(D10="Monthly",1,IF(D10="Quarterly",3,12)),1)*IF(D10="Monthly",1,IF(D10="Quarterly",3,12)))<PeriodStart,EDATE(C10,CEILING(MAX(0,(YEAR(PeriodStart)-YEAR(C10))*12+(MONTH(PeriodStart)-MONTH(C10)))/IF(D10="Monthly",1,IF(D10="Quarterly",3,12)),1)*IF(D10="Monthly",1,IF(D10="Quarterly",3,12))+IF(D10="Monthly",1,IF(D10="Quarterly",3,12))),EDATE(C10,CEILING(MAX(0,(YEAR(PeriodStart)-YEAR(C10))*12+(MONTH(PeriodStart)-MONTH(C10)))/IF(D10="Monthly",1,IF(D10="Quarterly",3,12)),1)*IF(D10="Monthly",1,IF(D10="Quarterly",3,12)))),"")))) | I10: =IF(A10="","",IF(H10="",0,IF(OR(D10="Monthly",D10="Quarterly",D10="Yearly",D10="One-Time"),IF(AND(H10>=PeriodStart,H10<=PeriodEnd),1,0),IF(D10="Weekly",1+INT((PeriodEnd-H10)/7),IF(D10="Bi-Weekly",1+INT((PeriodEnd-H10)/14),0))))) | J10: =IF(A10="","",IF(G10<>"",G10,IF(I10=0,0,B10*I10))) | K10: =IF(A10="","",IF(N(J10)>0,"Yes","")) | L10: =IF(A10="","",IF(F10="Paid","Paid",IF(N(J10)<=0,"Not this period",IF(AND(H10<>"",H10<TODAY()),"Overdue",IF(AND(H10<>"",H10<=TODAY()+7),"Due soon","Scheduled"))))) | M10: =IF(OR(A10="",N(J10)<=0),"",COUNTIF($J$5:$J10,">0"))
A11: Streaming | B11: 16 | C11: 46237 | D11: Monthly | F11: Paid | H11: =IF(OR(A11="",C11="",D11=""),"",IF(D11="One-Time",IF(AND(C11>=PeriodStart,C11<=PeriodEnd),C11,""),IF(OR(D11="Weekly",D11="Bi-Weekly"),IF(C11>PeriodEnd,"",MAX(C11,C11+IF(D11="Weekly",7,14)*CEILING(MAX(0,PeriodStart-C11)/IF(D11="Weekly",7,14),1))),IF(OR(D11="Monthly",D11="Quarterly",D11="Yearly"),IF(EDATE(C11,CEILING(MAX(0,(YEAR(PeriodStart)-YEAR(C11))*12+(MONTH(PeriodStart)-MONTH(C11)))/IF(D11="Monthly",1,IF(D11="Quarterly",3,12)),1)*IF(D11="Monthly",1,IF(D11="Quarterly",3,12)))<PeriodStart,EDATE(C11,CEILING(MAX(0,(YEAR(PeriodStart)-YEAR(C11))*12+(MONTH(PeriodStart)-MONTH(C11)))/IF(D11="Monthly",1,IF(D11="Quarterly",3,12)),1)*IF(D11="Monthly",1,IF(D11="Quarterly",3,12))+IF(D11="Monthly",1,IF(D11="Quarterly",3,12))),EDATE(C11,CEILING(MAX(0,(YEAR(PeriodStart)-YEAR(C11))*12+(MONTH(PeriodStart)-MONTH(C11)))/IF(D11="Monthly",1,IF(D11="Quarterly",3,12)),1)*IF(D11="Monthly",1,IF(D11="Quarterly",3,12)))),"")))) | I11: =IF(A11="","",IF(H11="",0,IF(OR(D11="Monthly",D11="Quarterly",D11="Yearly",D11="One-Time"),IF(AND(H11>=PeriodStart,H11<=PeriodEnd),1,0),IF(D11="Weekly",1+INT((PeriodEnd-H11)/7),IF(D11="Bi-Weekly",1+INT((PeriodEnd-H11)/14),0))))) | J11: =IF(A11="","",IF(G11<>"",G11,IF(I11=0,0,B11*I11))) | K11: =IF(A11="","",IF(N(J11)>0,"Yes","")) | L11: =IF(A11="","",IF(F11="Paid","Paid",IF(N(J11)<=0,"Not this period",IF(AND(H11<>"",H11<TODAY()),"Overdue",IF(AND(H11<>"",H11<=TODAY()+7),"Due soon","Scheduled"))))) | M11: =IF(OR(A11="",N(J11)<=0),"",COUNTIF($J$5:$J11,">0"))
A12: Gym (weekly) | B12: 12 | C12: 46241 | D12: Weekly | F12: Unpaid | H12: =IF(OR(A12="",C12="",D12=""),"",IF(D12="One-Time",IF(AND(C12>=PeriodStart,C12<=PeriodEnd),C12,""),IF(OR(D12="Weekly",D12="Bi-Weekly"),IF(C12>PeriodEnd,"",MAX(C12,C12+IF(D12="Weekly",7,14)*CEILING(MAX(0,PeriodStart-C12)/IF(D12="Weekly",7,14),1))),IF(OR(D12="Monthly",D12="Quarterly",D12="Yearly"),IF(EDATE(C12,CEILING(MAX(0,(YEAR(PeriodStart)-YEAR(C12))*12+(MONTH(PeriodStart)-MONTH(C12)))/IF(D12="Monthly",1,IF(D12="Quarterly",3,12)),1)*IF(D12="Monthly",1,IF(D12="Quarterly",3,12)))<PeriodStart,EDATE(C12,CEILING(MAX(0,(YEAR(PeriodStart)-YEAR(C12))*12+(MONTH(PeriodStart)-MONTH(C12)))/IF(D12="Monthly",1,IF(D12="Quarterly",3,12)),1)*IF(D12="Monthly",1,IF(D12="Quarterly",3,12))+IF(D12="Monthly",1,IF(D12="Quarterly",3,12))),EDATE(C12,CEILING(MAX(0,(YEAR(PeriodStart)-YEAR(C12))*12+(MONTH(PeriodStart)-MONTH(C12)))/IF(D12="Monthly",1,IF(D12="Quarterly",3,12)),1)*IF(D12="Monthly",1,IF(D12="Quarterly",3,12)))),"")))) | I12: =IF(A12="","",IF(H12="",0,IF(OR(D12="Monthly",D12="Quarterly",D12="Yearly",D12="One-Time"),IF(AND(H12>=PeriodStart,H12<=PeriodEnd),1,0),IF(D12="Weekly",1+INT((PeriodEnd-H12)/7),IF(D12="Bi-Weekly",1+INT((PeriodEnd-H12)/14),0))))) | J12: =IF(A12="","",IF(G12<>"",G12,IF(I12=0,0,B12*I12))) | K12: =IF(A12="","",IF(N(J12)>0,"Yes","")) | L12: =IF(A12="","",IF(F12="Paid","Paid",IF(N(J12)<=0,"Not this period",IF(AND(H12<>"",H12<TODAY()),"Overdue",IF(AND(H12<>"",H12<=TODAY()+7),"Due soon","Scheduled"))))) | M12: =IF(OR(A12="",N(J12)<=0),"",COUNTIF($J$5:$J12,">0"))
A13: Vet visit | B13: 80 | C13: 46248 | D13: One-Time | F13: Unpaid | H13: =IF(OR(A13="",C13="",D13=""),"",IF(D13="One-Time",IF(AND(C13>=PeriodStart,C13<=PeriodEnd),C13,""),IF(OR(D13="Weekly",D13="Bi-Weekly"),IF(C13>PeriodEnd,"",MAX(C13,C13+IF(D13="Weekly",7,14)*CEILING(MAX(0,PeriodStart-C13)/IF(D13="Weekly",7,14),1))),IF(OR(D13="Monthly",D13="Quarterly",D13="Yearly"),IF(EDATE(C13,CEILING(MAX(0,(YEAR(PeriodStart)-YEAR(C13))*12+(MONTH(PeriodStart)-MONTH(C13)))/IF(D13="Monthly",1,IF(D13="Quarterly",3,12)),1)*IF(D13="Monthly",1,IF(D13="Quarterly",3,12)))<PeriodStart,EDATE(C13,CEILING(MAX(0,(YEAR(PeriodStart)-YEAR(C13))*12+(MONTH(PeriodStart)-MONTH(C13)))/IF(D13="Monthly",1,IF(D13="Quarterly",3,12)),1)*IF(D13="Monthly",1,IF(D13="Quarterly",3,12))+IF(D13="Monthly",1,IF(D13="Quarterly",3,12))),EDATE(C13,CEILING(MAX(0,(YEAR(PeriodStart)-YEAR(C13))*12+(MONTH(PeriodStart)-MONTH(C13)))/IF(D13="Monthly",1,IF(D13="Quarterly",3,12)),1)*IF(D13="Monthly",1,IF(D13="Quarterly",3,12)))),"")))) | I13: =IF(A13="","",IF(H13="",0,IF(OR(D13="Monthly",D13="Quarterly",D13="Yearly",D13="One-Time"),IF(AND(H13>=PeriodStart,H13<=PeriodEnd),1,0),IF(D13="Weekly",1+INT((PeriodEnd-H13)/7),IF(D13="Bi-Weekly",1+INT((PeriodEnd-H13)/14),0))))) | J13: =IF(A13="","",IF(G13<>"",G13,IF(I13=0,0,B13*I13))) | K13: =IF(A13="","",IF(N(J13)>0,"Yes","")) | L13: =IF(A13="","",IF(F13="Paid","Paid",IF(N(J13)<=0,"Not this period",IF(AND(H13<>"",H13<TODAY()),"Overdue",IF(AND(H13<>"",H13<=TODAY()+7),"Due soon","Scheduled"))))) | M13: =IF(OR(A13="",N(J13)<=0),"",COUNTIF($J$5:$J13,">0"))
H14: =IF(OR(A14="",C14="",D14=""),"",IF(D14="One-Time",IF(AND(C14>=PeriodStart,C14<=PeriodEnd),C14,""),IF(OR(D14="Weekly",D14="Bi-Weekly"),IF(C14>PeriodEnd,"",MAX(C14,C14+IF(D14="Weekly",7,14)*CEILING(MAX(0,PeriodStart-C14)/IF(D14="Weekly",7,14),1))),IF(OR(D14="Monthly",D14="Quarterly",D14="Yearly"),IF(EDATE(C14,CEILING(MAX(0,(YEAR(PeriodStart)-YEAR(C14))*12+(MONTH(PeriodStart)-MONTH(C14)))/IF(D14="Monthly",1,IF(D14="Quarterly",3,12)),1)*IF(D14="Monthly",1,IF(D14="Quarterly",3,12)))<PeriodStart,EDATE(C14,CEILING(MAX(0,(YEAR(PeriodStart)-YEAR(C14))*12+(MONTH(PeriodStart)-MONTH(C14)))/IF(D14="Monthly",1,IF(D14="Quarterly",3,12)),1)*IF(D14="Monthly",1,IF(D14="Quarterly",3,12))+IF(D14="Monthly",1,IF(D14="Quarterly",3,12))),EDATE(C14,CEILING(MAX(0,(YEAR(PeriodStart)-YEAR(C14))*12+(MONTH(PeriodStart)-MONTH(C14)))/IF(D14="Monthly",1,IF(D14="Quarterly",3,12)),1)*IF(D14="Monthly",1,IF(D14="Quarterly",3,12)))),"")))) | I14: =IF(A14="","",IF(H14="",0,IF(OR(D14="Monthly",D14="Quarterly",D14="Yearly",D14="One-Time"),IF(AND(H14>=PeriodStart,H14<=PeriodEnd),1,0),IF(D14="Weekly",1+INT((PeriodEnd-H14)/7),IF(D14="Bi-Weekly",1+INT((PeriodEnd-H14)/14),0))))) | J14: =IF(A14="","",IF(G14<>"",G14,IF(I14=0,0,B14*I14))) | K14: =IF(A14="","",IF(N(J14)>0,"Yes","")) | L14: =IF(A14="","",IF(F14="Paid","Paid",IF(N(J14)<=0,"Not this period",IF(AND(H14<>"",H14<TODAY()),"Overdue",IF(AND(H14<>"",H14<=TODAY()+7),"Due soon","Scheduled"))))) | M14: =IF(OR(A14="",N(J14)<=0),"",COUNTIF($J$5:$J14,">0"))
H15: =IF(OR(A15="",C15="",D15=""),"",IF(D15="One-Time",IF(AND(C15>=PeriodStart,C15<=PeriodEnd),C15,""),IF(OR(D15="Weekly",D15="Bi-Weekly"),IF(C15>PeriodEnd,"",MAX(C15,C15+IF(D15="Weekly",7,14)*CEILING(MAX(0,PeriodStart-C15)/IF(D15="Weekly",7,14),1))),IF(OR(D15="Monthly",D15="Quarterly",D15="Yearly"),IF(EDATE(C15,CEILING(MAX(0,(YEAR(PeriodStart)-YEAR(C15))*12+(MONTH(PeriodStart)-MONTH(C15)))/IF(D15="Monthly",1,IF(D15="Quarterly",3,12)),1)*IF(D15="Monthly",1,IF(D15="Quarterly",3,12)))<PeriodStart,EDATE(C15,CEILING(MAX(0,(YEAR(PeriodStart)-YEAR(C15))*12+(MONTH(PeriodStart)-MONTH(C15)))/IF(D15="Monthly",1,IF(D15="Quarterly",3,12)),1)*IF(D15="Monthly",1,IF(D15="Quarterly",3,12))+IF(D15="Monthly",1,IF(D15="Quarterly",3,12))),EDATE(C15,CEILING(MAX(0,(YEAR(PeriodStart)-YEAR(C15))*12+(MONTH(PeriodStart)-MONTH(C15)))/IF(D15="Monthly",1,IF(D15="Quarterly",3,12)),1)*IF(D15="Monthly",1,IF(D15="Quarterly",3,12)))),"")))) | I15: =IF(A15="","",IF(H15="",0,IF(OR(D15="Monthly",D15="Quarterly",D15="Yearly",D15="One-Time"),IF(AND(H15>=PeriodStart,H15<=PeriodEnd),1,0),IF(D15="Weekly",1+INT((PeriodEnd-H15)/7),IF(D15="Bi-Weekly",1+INT((PeriodEnd-H15)/14),0))))) | J15: =IF(A15="","",IF(G15<>"",G15,IF(I15=0,0,B15*I15))) | K15: =IF(A15="","",IF(N(J15)>0,"Yes","")) | L15: =IF(A15="","",IF(F15="Paid","Paid",IF(N(J15)<=0,"Not this period",IF(AND(H15<>"",H15<TODAY()),"Overdue",IF(AND(H15<>"",H15<=TODAY()+7),"Due soon","Scheduled"))))) | M15: =IF(OR(A15="",N(J15)<=0),"",COUNTIF($J$5:$J15,">0"))
H16: =IF(OR(A16="",C16="",D16=""),"",IF(D16="One-Time",IF(AND(C16>=PeriodStart,C16<=PeriodEnd),C16,""),IF(OR(D16="Weekly",D16="Bi-Weekly"),IF(C16>PeriodEnd,"",MAX(C16,C16+IF(D16="Weekly",7,14)*CEILING(MAX(0,PeriodStart-C16)/IF(D16="Weekly",7,14),1))),IF(OR(D16="Monthly",D16="Quarterly",D16="Yearly"),IF(EDATE(C16,CEILING(MAX(0,(YEAR(PeriodStart)-YEAR(C16))*12+(MONTH(PeriodStart)-MONTH(C16)))/IF(D16="Monthly",1,IF(D16="Quarterly",3,12)),1)*IF(D16="Monthly",1,IF(D16="Quarterly",3,12)))<PeriodStart,EDATE(C16,CEILING(MAX(0,(YEAR(PeriodStart)-YEAR(C16))*12+(MONTH(PeriodStart)-MONTH(C16)))/IF(D16="Monthly",1,IF(D16="Quarterly",3,12)),1)*IF(D16="Monthly",1,IF(D16="Quarterly",3,12))+IF(D16="Monthly",1,IF(D16="Quarterly",3,12))),EDATE(C16,CEILING(MAX(0,(YEAR(PeriodStart)-YEAR(C16))*12+(MONTH(PeriodStart)-MONTH(C16)))/IF(D16="Monthly",1,IF(D16="Quarterly",3,12)),1)*IF(D16="Monthly",1,IF(D16="Quarterly",3,12)))),"")))) | I16: =IF(A16="","",IF(H16="",0,IF(OR(D16="Monthly",D16="Quarterly",D16="Yearly",D16="One-Time"),IF(AND(H16>=PeriodStart,H16<=PeriodEnd),1,0),IF(D16="Weekly",1+INT((PeriodEnd-H16)/7),IF(D16="Bi-Weekly",1+INT((PeriodEnd-H16)/14),0))))) | J16: =IF(A16="","",IF(G16<>"",G16,IF(I16=0,0,B16*I16))) | K16: =IF(A16="","",IF(N(J16)>0,"Yes","")) | L16: =IF(A16="","",IF(F16="Paid","Paid",IF(N(J16)<=0,"Not this period",IF(AND(H16<>"",H16<TODAY()),"Overdue",IF(AND(H16<>"",H16<=TODAY()+7),"Due soon","Scheduled"))))) | M16: =IF(OR(A16="",N(J16)<=0),"",COUNTIF($J$5:$J16,">0"))
H17: =IF(OR(A17="",C17="",D17=""),"",IF(D17="One-Time",IF(AND(C17>=PeriodStart,C17<=PeriodEnd),C17,""),IF(OR(D17="Weekly",D17="Bi-Weekly"),IF(C17>PeriodEnd,"",MAX(C17,C17+IF(D17="Weekly",7,14)*CEILING(MAX(0,PeriodStart-C17)/IF(D17="Weekly",7,14),1))),IF(OR(D17="Monthly",D17="Quarterly",D17="Yearly"),IF(EDATE(C17,CEILING(MAX(0,(YEAR(PeriodStart)-YEAR(C17))*12+(MONTH(PeriodStart)-MONTH(C17)))/IF(D17="Monthly",1,IF(D17="Quarterly",3,12)),1)*IF(D17="Monthly",1,IF(D17="Quarterly",3,12)))<PeriodStart,EDATE(C17,CEILING(MAX(0,(YEAR(PeriodStart)-YEAR(C17))*12+(MONTH(PeriodStart)-MONTH(C17)))/IF(D17="Monthly",1,IF(D17="Quarterly",3,12)),1)*IF(D17="Monthly",1,IF(D17="Quarterly",3,12))+IF(D17="Monthly",1,IF(D17="Quarterly",3,12))),EDATE(C17,CEILING(MAX(0,(YEAR(PeriodStart)-YEAR(C17))*12+(MONTH(PeriodStart)-MONTH(C17)))/IF(D17="Monthly",1,IF(D17="Quarterly",3,12)),1)*IF(D17="Monthly",1,IF(D17="Quarterly",3,12)))),"")))) | I17: =IF(A17="","",IF(H17="",0,IF(OR(D17="Monthly",D17="Quarterly",D17="Yearly",D17="One-Time"),IF(AND(H17>=PeriodStart,H17<=PeriodEnd),1,0),IF(D17="Weekly",1+INT((PeriodEnd-H17)/7),IF(D17="Bi-Weekly",1+INT((PeriodEnd-H17)/14),0))))) | J17: =IF(A17="","",IF(G17<>"",G17,IF(I17=0,0,B17*I17))) | K17: =IF(A17="","",IF(N(J17)>0,"Yes","")) | L17: =IF(A17="","",IF(F17="Paid","Paid",IF(N(J17)<=0,"Not this period",IF(AND(H17<>"",H17<TODAY()),"Overdue",IF(AND(H17<>"",H17<=TODAY()+7),"Due soon","Scheduled"))))) | M17: =IF(OR(A17="",N(J17)<=0),"",COUNTIF($J$5:$J17,">0"))
H18: =IF(OR(A18="",C18="",D18=""),"",IF(D18="One-Time",IF(AND(C18>=PeriodStart,C18<=PeriodEnd),C18,""),IF(OR(D18="Weekly",D18="Bi-Weekly"),IF(C18>PeriodEnd,"",MAX(C18,C18+IF(D18="Weekly",7,14)*CEILING(MAX(0,PeriodStart-C18)/IF(D18="Weekly",7,14),1))),IF(OR(D18="Monthly",D18="Quarterly",D18="Yearly"),IF(EDATE(C18,CEILING(MAX(0,(YEAR(PeriodStart)-YEAR(C18))*12+(MONTH(PeriodStart)-MONTH(C18)))/IF(D18="Monthly",1,IF(D18="Quarterly",3,12)),1)*IF(D18="Monthly",1,IF(D18="Quarterly",3,12)))<PeriodStart,EDATE(C18,CEILING(MAX(0,(YEAR(PeriodStart)-YEAR(C18))*12+(MONTH(PeriodStart)-MONTH(C18)))/IF(D18="Monthly",1,IF(D18="Quarterly",3,12)),1)*IF(D18="Monthly",1,IF(D18="Quarterly",3,12))+IF(D18="Monthly",1,IF(D18="Quarterly",3,12))),EDATE(C18,CEILING(MAX(0,(YEAR(PeriodStart)-YEAR(C18))*12+(MONTH(PeriodStart)-MONTH(C18)))/IF(D18="Monthly",1,IF(D18="Quarterly",3,12)),1)*IF(D18="Monthly",1,IF(D18="Quarterly",3,12)))),"")))) | I18: =IF(A18="","",IF(H18="",0,IF(OR(D18="Monthly",D18="Quarterly",D18="Yearly",D18="One-Time"),IF(AND(H18>=PeriodStart,H18<=PeriodEnd),1,0),IF(D18="Weekly",1+INT((PeriodEnd-H18)/7),IF(D18="Bi-Weekly",1+INT((PeriodEnd-H18)/14),0))))) | J18: =IF(A18="","",IF(G18<>"",G18,IF(I18=0,0,B18*I18))) | K18: =IF(A18="","",IF(N(J18)>0,"Yes","")) | L18: =IF(A18="","",IF(F18="Paid","Paid",IF(N(J18)<=0,"Not this period",IF(AND(H18<>"",H18<TODAY()),"Overdue",IF(AND(H18<>"",H18<=TODAY()+7),"Due soon","Scheduled"))))) | M18: =IF(OR(A18="",N(J18)<=0),"",COUNTIF($J$5:$J18,">0"))
H19: =IF(OR(A19="",C19="",D19=""),"",IF(D19="One-Time",IF(AND(C19>=PeriodStart,C19<=PeriodEnd),C19,""),IF(OR(D19="Weekly",D19="Bi-Weekly"),IF(C19>PeriodEnd,"",MAX(C19,C19+IF(D19="Weekly",7,14)*CEILING(MAX(0,PeriodStart-C19)/IF(D19="Weekly",7,14),1))),IF(OR(D19="Monthly",D19="Quarterly",D19="Yearly"),IF(EDATE(C19,CEILING(MAX(0,(YEAR(PeriodStart)-YEAR(C19))*12+(MONTH(PeriodStart)-MONTH(C19)))/IF(D19="Monthly",1,IF(D19="Quarterly",3,12)),1)*IF(D19="Monthly",1,IF(D19="Quarterly",3,12)))<PeriodStart,EDATE(C19,CEILING(MAX(0,(YEAR(PeriodStart)-YEAR(C19))*12+(MONTH(PeriodStart)-MONTH(C19)))/IF(D19="Monthly",1,IF(D19="Quarterly",3,12)),1)*IF(D19="Monthly",1,IF(D19="Quarterly",3,12))+IF(D19="Monthly",1,IF(D19="Quarterly",3,12))),EDATE(C19,CEILING(MAX(0,(YEAR(PeriodStart)-YEAR(C19))*12+(MONTH(PeriodStart)-MONTH(C19)))/IF(D19="Monthly",1,IF(D19="Quarterly",3,12)),1)*IF(D19="Monthly",1,IF(D19="Quarterly",3,12)))),"")))) | I19: =IF(A19="","",IF(H19="",0,IF(OR(D19="Monthly",D19="Quarterly",D19="Yearly",D19="One-Time"),IF(AND(H19>=PeriodStart,H19<=PeriodEnd),1,0),IF(D19="Weekly",1+INT((PeriodEnd-H19)/7),IF(D19="Bi-Weekly",1+INT((PeriodEnd-H19)/14),0))))) | J19: =IF(A19="","",IF(G19<>"",G19,IF(I19=0,0,B19*I19))) | K19: =IF(A19="","",IF(N(J19)>0,"Yes","")) | L19: =IF(A19="","",IF(F19="Paid","Paid",IF(N(J19)<=0,"Not this period",IF(AND(H19<>"",H19<TODAY()),"Overdue",IF(AND(H19<>"",H19<=TODAY()+7),"Due soon","Scheduled"))))) | M19: =IF(OR(A19="",N(J19)<=0),"",COUNTIF($J$5:$J19,">0"))
H20: =IF(OR(A20="",C20="",D20=""),"",IF(D20="One-Time",IF(AND(C20>=PeriodStart,C20<=PeriodEnd),C20,""),IF(OR(D20="Weekly",D20="Bi-Weekly"),IF(C20>PeriodEnd,"",MAX(C20,C20+IF(D20="Weekly",7,14)*CEILING(MAX(0,PeriodStart-C20)/IF(D20="Weekly",7,14),1))),IF(OR(D20="Monthly",D20="Quarterly",D20="Yearly"),IF(EDATE(C20,CEILING(MAX(0,(YEAR(PeriodStart)-YEAR(C20))*12+(MONTH(PeriodStart)-MONTH(C20)))/IF(D20="Monthly",1,IF(D20="Quarterly",3,12)),1)*IF(D20="Monthly",1,IF(D20="Quarterly",3,12)))<PeriodStart,EDATE(C20,CEILING(MAX(0,(YEAR(PeriodStart)-YEAR(C20))*12+(MONTH(PeriodStart)-MONTH(C20)))/IF(D20="Monthly",1,IF(D20="Quarterly",3,12)),1)*IF(D20="Monthly",1,IF(D20="Quarterly",3,12))+IF(D20="Monthly",1,IF(D20="Quarterly",3,12))),EDATE(C20,CEILING(MAX(0,(YEAR(PeriodStart)-YEAR(C20))*12+(MONTH(PeriodStart)-MONTH(C20)))/IF(D20="Monthly",1,IF(D20="Quarterly",3,12)),1)*IF(D20="Monthly",1,IF(D20="Quarterly",3,12)))),"")))) | I20: =IF(A20="","",IF(H20="",0,IF(OR(D20="Monthly",D20="Quarterly",D20="Yearly",D20="One-Time"),IF(AND(H20>=PeriodStart,H20<=PeriodEnd),1,0),IF(D20="Weekly",1+INT((PeriodEnd-H20)/7),IF(D20="Bi-Weekly",1+INT((PeriodEnd-H20)/14),0))))) | J20: =IF(A20="","",IF(G20<>"",G20,IF(I20=0,0,B20*I20))) | K20: =IF(A20="","",IF(N(J20)>0,"Yes","")) | L20: =IF(A20="","",IF(F20="Paid","Paid",IF(N(J20)<=0,"Not this period",IF(AND(H20<>"",H20<TODAY()),"Overdue",IF(AND(H20<>"",H20<=TODAY()+7),"Due soon","Scheduled"))))) | M20: =IF(OR(A20="",N(J20)<=0),"",COUNTIF($J$5:$J20,">0"))
H21: =IF(OR(A21="",C21="",D21=""),"",IF(D21="One-Time",IF(AND(C21>=PeriodStart,C21<=PeriodEnd),C21,""),IF(OR(D21="Weekly",D21="Bi-Weekly"),IF(C21>PeriodEnd,"",MAX(C21,C21+IF(D21="Weekly",7,14)*CEILING(MAX(0,PeriodStart-C21)/IF(D21="Weekly",7,14),1))),IF(OR(D21="Monthly",D21="Quarterly",D21="Yearly"),IF(EDATE(C21,CEILING(MAX(0,(YEAR(PeriodStart)-YEAR(C21))*12+(MONTH(PeriodStart)-MONTH(C21)))/IF(D21="Monthly",1,IF(D21="Quarterly",3,12)),1)*IF(D21="Monthly",1,IF(D21="Quarterly",3,12)))<PeriodStart,EDATE(C21,CEILING(MAX(0,(YEAR(PeriodStart)-YEAR(C21))*12+(MONTH(PeriodStart)-MONTH(C21)))/IF(D21="Monthly",1,IF(D21="Quarterly",3,12)),1)*IF(D21="Monthly",1,IF(D21="Quarterly",3,12))+IF(D21="Monthly",1,IF(D21="Quarterly",3,12))),EDATE(C21,CEILING(MAX(0,(YEAR(PeriodStart)-YEAR(C21))*12+(MONTH(PeriodStart)-MONTH(C21)))/IF(D21="Monthly",1,IF(D21="Quarterly",3,12)),1)*IF(D21="Monthly",1,IF(D21="Quarterly",3,12)))),"")))) | I21: =IF(A21="","",IF(H21="",0,IF(OR(D21="Monthly",D21="Quarterly",D21="Yearly",D21="One-Time"),IF(AND(H21>=PeriodStart,H21<=PeriodEnd),1,0),IF(D21="Weekly",1+INT((PeriodEnd-H21)/7),IF(D21="Bi-Weekly",1+INT((PeriodEnd-H21)/14),0))))) | J21: =IF(A21="","",IF(G21<>"",G21,IF(I21=0,0,B21*I21))) | K21: =IF(A21="","",IF(N(J21)>0,"Yes","")) | L21: =IF(A21="","",IF(F21="Paid","Paid",IF(N(J21)<=0,"Not this period",IF(AND(H21<>"",H21<TODAY()),"Overdue",IF(AND(H21<>"",H21<=TODAY()+7),"Due soon","Scheduled"))))) | M21: =IF(OR(A21="",N(J21)<=0),"",COUNTIF($J$5:$J21,">0"))
H22: =IF(OR(A22="",C22="",D22=""),"",IF(D22="One-Time",IF(AND(C22>=PeriodStart,C22<=PeriodEnd),C22,""),IF(OR(D22="Weekly",D22="Bi-Weekly"),IF(C22>PeriodEnd,"",MAX(C22,C22+IF(D22="Weekly",7,14)*CEILING(MAX(0,PeriodStart-C22)/IF(D22="Weekly",7,14),1))),IF(OR(D22="Monthly",D22="Quarterly",D22="Yearly"),IF(EDATE(C22,CEILING(MAX(0,(YEAR(PeriodStart)-YEAR(C22))*12+(MONTH(PeriodStart)-MONTH(C22)))/IF(D22="Monthly",1,IF(D22="Quarterly",3,12)),1)*IF(D22="Monthly",1,IF(D22="Quarterly",3,12)))<PeriodStart,EDATE(C22,CEILING(MAX(0,(YEAR(PeriodStart)-YEAR(C22))*12+(MONTH(PeriodStart)-MONTH(C22)))/IF(D22="Monthly",1,IF(D22="Quarterly",3,12)),1)*IF(D22="Monthly",1,IF(D22="Quarterly",3,12))+IF(D22="Monthly",1,IF(D22="Quarterly",3,12))),EDATE(C22,CEILING(MAX(0,(YEAR(PeriodStart)-YEAR(C22))*12+(MONTH(PeriodStart)-MONTH(C22)))/IF(D22="Monthly",1,IF(D22="Quarterly",3,12)),1)*IF(D22="Monthly",1,IF(D22="Quarterly",3,12)))),"")))) | I22: =IF(A22="","",IF(H22="",0,IF(OR(D22="Monthly",D22="Quarterly",D22="Yearly",D22="One-Time"),IF(AND(H22>=PeriodStart,H22<=PeriodEnd),1,0),IF(D22="Weekly",1+INT((PeriodEnd-H22)/7),IF(D22="Bi-Weekly",1+INT((PeriodEnd-H22)/14),0))))) | J22: =IF(A22="","",IF(G22<>"",G22,IF(I22=0,0,B22*I22))) | K22: =IF(A22="","",IF(N(J22)>0,"Yes","")) | L22: =IF(A22="","",IF(F22="Paid","Paid",IF(N(J22)<=0,"Not this period",IF(AND(H22<>"",H22<TODAY()),"Overdue",IF(AND(H22<>"",H22<=TODAY()+7),"Due soon","Scheduled"))))) | M22: =IF(OR(A22="",N(J22)<=0),"",COUNTIF($J$5:$J22,">0"))
H23: =IF(OR(A23="",C23="",D23=""),"",IF(D23="One-Time",IF(AND(C23>=PeriodStart,C23<=PeriodEnd),C23,""),IF(OR(D23="Weekly",D23="Bi-Weekly"),IF(C23>PeriodEnd,"",MAX(C23,C23+IF(D23="Weekly",7,14)*CEILING(MAX(0,PeriodStart-C23)/IF(D23="Weekly",7,14),1))),IF(OR(D23="Monthly",D23="Quarterly",D23="Yearly"),IF(EDATE(C23,CEILING(MAX(0,(YEAR(PeriodStart)-YEAR(C23))*12+(MONTH(PeriodStart)-MONTH(C23)))/IF(D23="Monthly",1,IF(D23="Quarterly",3,12)),1)*IF(D23="Monthly",1,IF(D23="Quarterly",3,12)))<PeriodStart,EDATE(C23,CEILING(MAX(0,(YEAR(PeriodStart)-YEAR(C23))*12+(MONTH(PeriodStart)-MONTH(C23)))/IF(D23="Monthly",1,IF(D23="Quarterly",3,12)),1)*IF(D23="Monthly",1,IF(D23="Quarterly",3,12))+IF(D23="Monthly",1,IF(D23="Quarterly",3,12))),EDATE(C23,CEILING(MAX(0,(YEAR(PeriodStart)-YEAR(C23))*12+(MONTH(PeriodStart)-MONTH(C23)))/IF(D23="Monthly",1,IF(D23="Quarterly",3,12)),1)*IF(D23="Monthly",1,IF(D23="Quarterly",3,12)))),"")))) | I23: =IF(A23="","",IF(H23="",0,IF(OR(D23="Monthly",D23="Quarterly",D23="Yearly",D23="One-Time"),IF(AND(H23>=PeriodStart,H23<=PeriodEnd),1,0),IF(D23="Weekly",1+INT((PeriodEnd-H23)/7),IF(D23="Bi-Weekly",1+INT((PeriodEnd-H23)/14),0))))) | J23: =IF(A23="","",IF(G23<>"",G23,IF(I23=0,0,B23*I23))) | K23: =IF(A23="","",IF(N(J23)>0,"Yes","")) | L23: =IF(A23="","",IF(F23="Paid","Paid",IF(N(J23)<=0,"Not this period",IF(AND(H23<>"",H23<TODAY()),"Overdue",IF(AND(H23<>"",H23<=TODAY()+7),"Due soon","Scheduled"))))) | M23: =IF(OR(A23="",N(J23)<=0),"",COUNTIF($J$5:$J23,">0"))
H24: =IF(OR(A24="",C24="",D24=""),"",IF(D24="One-Time",IF(AND(C24>=PeriodStart,C24<=PeriodEnd),C24,""),IF(OR(D24="Weekly",D24="Bi-Weekly"),IF(C24>PeriodEnd,"",MAX(C24,C24+IF(D24="Weekly",7,14)*CEILING(MAX(0,PeriodStart-C24)/IF(D24="Weekly",7,14),1))),IF(OR(D24="Monthly",D24="Quarterly",D24="Yearly"),IF(EDATE(C24,CEILING(MAX(0,(YEAR(PeriodStart)-YEAR(C24))*12+(MONTH(PeriodStart)-MONTH(C24)))/IF(D24="Monthly",1,IF(D24="Quarterly",3,12)),1)*IF(D24="Monthly",1,IF(D24="Quarterly",3,12)))<PeriodStart,EDATE(C24,CEILING(MAX(0,(YEAR(PeriodStart)-YEAR(C24))*12+(MONTH(PeriodStart)-MONTH(C24)))/IF(D24="Monthly",1,IF(D24="Quarterly",3,12)),1)*IF(D24="Monthly",1,IF(D24="Quarterly",3,12))+IF(D24="Monthly",1,IF(D24="Quarterly",3,12))),EDATE(C24,CEILING(MAX(0,(YEAR(PeriodStart)-YEAR(C24))*12+(MONTH(PeriodStart)-MONTH(C24)))/IF(D24="Monthly",1,IF(D24="Quarterly",3,12)),1)*IF(D24="Monthly",1,IF(D24="Quarterly",3,12)))),"")))) | I24: =IF(A24="","",IF(H24="",0,IF(OR(D24="Monthly",D24="Quarterly",D24="Yearly",D24="One-Time"),IF(AND(H24>=PeriodStart,H24<=PeriodEnd),1,0),IF(D24="Weekly",1+INT((PeriodEnd-H24)/7),IF(D24="Bi-Weekly",1+INT((PeriodEnd-H24)/14),0))))) | J24: =IF(A24="","",IF(G24<>"",G24,IF(I24=0,0,B24*I24))) | K24: =IF(A24="","",IF(N(J24)>0,"Yes","")) | L24: =IF(A24="","",IF(F24="Paid","Paid",IF(N(J24)<=0,"Not this period",IF(AND(H24<>"",H24<TODAY()),"Overdue",IF(AND(H24<>"",H24<=TODAY()+7),"Due soon","Scheduled"))))) | M24: =IF(OR(A24="",N(J24)<=0),"",COUNTIF($J$5:$J24,">0"))
H25: =IF(OR(A25="",C25="",D25=""),"",IF(D25="One-Time",IF(AND(C25>=PeriodStart,C25<=PeriodEnd),C25,""),IF(OR(D25="Weekly",D25="Bi-Weekly"),IF(C25>PeriodEnd,"",MAX(C25,C25+IF(D25="Weekly",7,14)*CEILING(MAX(0,PeriodStart-C25)/IF(D25="Weekly",7,14),1))),IF(OR(D25="Monthly",D25="Quarterly",D25="Yearly"),IF(EDATE(C25,CEILING(MAX(0,(YEAR(PeriodStart)-YEAR(C25))*12+(MONTH(PeriodStart)-MONTH(C25)))/IF(D25="Monthly",1,IF(D25="Quarterly",3,12)),1)*IF(D25="Monthly",1,IF(D25="Quarterly",3,12)))<PeriodStart,EDATE(C25,CEILING(MAX(0,(YEAR(PeriodStart)-YEAR(C25))*12+(MONTH(PeriodStart)-MONTH(C25)))/IF(D25="Monthly",1,IF(D25="Quarterly",3,12)),1)*IF(D25="Monthly",1,IF(D25="Quarterly",3,12))+IF(D25="Monthly",1,IF(D25="Quarterly",3,12))),EDATE(C25,CEILING(MAX(0,(YEAR(PeriodStart)-YEAR(C25))*12+(MONTH(PeriodStart)-MONTH(C25)))/IF(D25="Monthly",1,IF(D25="Quarterly",3,12)),1)*IF(D25="Monthly",1,IF(D25="Quarterly",3,12)))),"")))) | I25: =IF(A25="","",IF(H25="",0,IF(OR(D25="Monthly",D25="Quarterly",D25="Yearly",D25="One-Time"),IF(AND(H25>=PeriodStart,H25<=PeriodEnd),1,0),IF(D25="Weekly",1+INT((PeriodEnd-H25)/7),IF(D25="Bi-Weekly",1+INT((PeriodEnd-H25)/14),0))))) | J25: =IF(A25="","",IF(G25<>"",G25,IF(I25=0,0,B25*I25))) | K25: =IF(A25="","",IF(N(J25)>0,"Yes","")) | L25: =IF(A25="","",IF(F25="Paid","Paid",IF(N(J25)<=0,"Not this period",IF(AND(H25<>"",H25<TODAY()),"Overdue",IF(AND(H25<>"",H25<=TODAY()+7),"Due soon","Scheduled"))))) | M25: =IF(OR(A25="",N(J25)<=0),"",COUNTIF($J$5:$J25,">0"))
... H34: =IF(OR(A34="",C34="",D34=""),"",IF(D34="One-Time",IF(AND(C34>=PeriodStart,C34<=PeriodEnd),C34,""),IF(OR(D34="Weekly",D34="Bi-Weekly"),IF(C34>PeriodEnd,"",MAX(C34,C34+IF(D34="Weekly",7,14)*CEILING(MAX(0,PeriodStart-C34)/IF(D34="Weekly",7,14),1))),IF(OR(D34="Monthly",D34="Quarterly",D34="Yearly"),IF(EDATE(C34,CEILING(MAX(0,(YEAR(PeriodStart)-YEAR(C34))*12+(MONTH(PeriodStart)-MONTH(C34)))/IF(D34="Monthly",1,IF(D34="Quarterly",3,12)),1)*IF(D34="Monthly",1,IF(D34="Quarterly",3,12)))<PeriodStart,EDATE(C34,CEILING(MAX(0,(YEAR(PeriodStart)-YEAR(C34))*12+(MONTH(PeriodStart)-MONTH(C34)))/IF(D34="Monthly",1,IF(D34="Quarterly",3,12)),1)*IF(D34="Monthly",1,IF(D34="Quarterly",3,12))+IF(D34="Monthly",1,IF(D34="Quarterly",3,12))),EDATE(C34,CEILING(MAX(0,(YEAR(PeriodStart)-YEAR(C34))*12+(MONTH(PeriodStart)-MONTH(C34)))/IF(D34="Monthly",1,IF(D34="Quarterly",3,12)),1)*IF(D34="Monthly",1,IF(D34="Quarterly",3,12)))),"")))) | I34: =IF(A34="","",IF(H34="",0,IF(OR(D34="Monthly",D34="Quarterly",D34="Yearly",D34="One-Time"),IF(AND(H34>=PeriodStart,H34<=PeriodEnd),1,0),IF(D34="Weekly",1+INT((PeriodEnd-H34)/7),IF(D34="Bi-Weekly",1+INT((PeriodEnd-H34)/14),0))))) | J34: =IF(A34="","",IF(G34<>"",G34,IF(I34=0,0,B34*I34))) | K34: =IF(A34="","",IF(N(J34)>0,"Yes","")) | L34: =IF(A34="","",IF(F34="Paid","Paid",IF(N(J34)<=0,"Not this period",IF(AND(H34<>"",H34<TODAY()),"Overdue",IF(AND(H34<>"",H34<=TODAY()+7),"Due soon","Scheduled"))))) | M34: =IF(OR(A34="",N(J34)<=0),"",COUNTIF($J$5:$J34,">0"))
A35: TOTAL THIS PERIOD | J35: =SUM(J5:J34)
A37: Tip: Do not also log a bill payment on the Transaction Log — it would be counted twice. Mark it Paid? here instead. Streaming is a sample monthly bill whose next due date falls outside this period, so it is $0 here.

Sheet Budget Categories
A1: Budget Categories
A2: Plan how the leftover after bills gets spent. Actual fills in from the Transaction Log. Do not put rent or utilities here — those live on the Bills tab.
A3: =IF(PlannedSpending="","","Planned "&TEXT(PlannedSpending,"$#,##0.00")&" · Spent "&TEXT(ActualSpending,"$#,##0.00")&" · Remaining "&TEXT(PlannedSpending-ActualSpending,"$#,##0.00")&" · Used "&TEXT(IF(PlannedSpending=0,0,ActualSpending/PlannedSpending),"0%"))
A4: Category | B4: Planned | C4: Actual | D4: Remaining | E4: % used | F4: Progress | G4: Status
A5: Groceries | B5: 180 | C5: =IF(A5="","",SUMIFS('Transaction Log'!$D$5:$D$104,'Transaction Log'!$C$5:$C$104,A5,'Transaction Log'!$A$5:$A$104,">="&PeriodStart,'Transaction Log'!$A$5:$A$104,"<="&PeriodEnd)) | D5: =IF(A5="","",B5-C5) | E5: =IF(OR(A5="",B5=0),"",C5/B5) | F5: =IF(A5="","",REPT("█",ROUND(MIN(1,IF(B5=0,0,C5/B5))*16,0))&REPT("░",16-ROUND(MIN(1,IF(B5=0,0,C5/B5))*16,0))) | G5: =IF(A5="","",IF(B5=0,"—",IF(C5>B5,"Over",IF(C5/B5>=0.8,"On track","Under"))))
A6: Gas / Transit | B6: 70 | C6: =IF(A6="","",SUMIFS('Transaction Log'!$D$5:$D$104,'Transaction Log'!$C$5:$C$104,A6,'Transaction Log'!$A$5:$A$104,">="&PeriodStart,'Transaction Log'!$A$5:$A$104,"<="&PeriodEnd)) | D6: =IF(A6="","",B6-C6) | E6: =IF(OR(A6="",B6=0),"",C6/B6) | F6: =IF(A6="","",REPT("█",ROUND(MIN(1,IF(B6=0,0,C6/B6))*16,0))&REPT("░",16-ROUND(MIN(1,IF(B6=0,0,C6/B6))*16,0))) | G6: =IF(A6="","",IF(B6=0,"—",IF(C6>B6,"Over",IF(C6/B6>=0.8,"On track","Under"))))
A7: Dining out | B7: 60 | C7: =IF(A7="","",SUMIFS('Transaction Log'!$D$5:$D$104,'Transaction Log'!$C$5:$C$104,A7,'Transaction Log'!$A$5:$A$104,">="&PeriodStart,'Transaction Log'!$A$5:$A$104,"<="&PeriodEnd)) | D7: =IF(A7="","",B7-C7) | E7: =IF(OR(A7="",B7=0),"",C7/B7) | F7: =IF(A7="","",REPT("█",ROUND(MIN(1,IF(B7=0,0,C7/B7))*16,0))&REPT("░",16-ROUND(MIN(1,IF(B7=0,0,C7/B7))*16,0))) | G7: =IF(A7="","",IF(B7=0,"—",IF(C7>B7,"Over",IF(C7/B7>=0.8,"On track","Under"))))
A8: Personal care | B8: 30 | C8: =IF(A8="","",SUMIFS('Transaction Log'!$D$5:$D$104,'Transaction Log'!$C$5:$C$104,A8,'Transaction Log'!$A$5:$A$104,">="&PeriodStart,'Transaction Log'!$A$5:$A$104,"<="&PeriodEnd)) | D8: =IF(A8="","",B8-C8) | E8: =IF(OR(A8="",B8=0),"",C8/B8) | F8: =IF(A8="","",REPT("█",ROUND(MIN(1,IF(B8=0,0,C8/B8))*16,0))&REPT("░",16-ROUND(MIN(1,IF(B8=0,0,C8/B8))*16,0))) | G8: =IF(A8="","",IF(B8=0,"—",IF(C8>B8,"Over",IF(C8/B8>=0.8,"On track","Under"))))
A9: Fun / Entertainment | B9: 40 | C9: =IF(A9="","",SUMIFS('Transaction Log'!$D$5:$D$104,'Transaction Log'!$C$5:$C$104,A9,'Transaction Log'!$A$5:$A$104,">="&PeriodStart,'Transaction Log'!$A$5:$A$104,"<="&PeriodEnd)) | D9: =IF(A9="","",B9-C9) | E9: =IF(OR(A9="",B9=0),"",C9/B9) | F9: =IF(A9="","",REPT("█",ROUND(MIN(1,IF(B9=0,0,C9/B9))*16,0))&REPT("░",16-ROUND(MIN(1,IF(B9=0,0,C9/B9))*16,0))) | G9: =IF(A9="","",IF(B9=0,"—",IF(C9>B9,"Over",IF(C9/B9>=0.8,"On track","Under"))))
A10: Household / Misc | B10: 35 | C10: =IF(A10="","",SUMIFS('Transaction Log'!$D$5:$D$104,'Transaction Log'!$C$5:$C$104,A10,'Transaction Log'!$A$5:$A$104,">="&PeriodStart,'Transaction Log'!$A$5:$A$104,"<="&PeriodEnd)) | D10: =IF(A10="","",B10-C10) | E10: =IF(OR(A10="",B10=0),"",C10/B10) | F10: =IF(A10="","",REPT("█",ROUND(MIN(1,IF(B10=0,0,C10/B10))*16,0))&REPT("░",16-ROUND(MIN(1,IF(B10=0,0,C10/B10))*16,0))) | G10: =IF(A10="","",IF(B10=0,"—",IF(C10>B10,"Over",IF(C10/B10>=0.8,"On track","Under"))))
A11: Savings transfer | B11: 150 | C11: =IF(A11="","",SUMIFS('Transaction Log'!$D$5:$D$104,'Transaction Log'!$C$5:$C$104,A11,'Transaction Log'!$A$5:$A$104,">="&PeriodStart,'Transaction Log'!$A$5:$A$104,"<="&PeriodEnd)) | D11: =IF(A11="","",B11-C11) | E11: =IF(OR(A11="",B11=0),"",C11/B11) | F11: =IF(A11="","",REPT("█",ROUND(MIN(1,IF(B11=0,0,C11/B11))*16,0))&REPT("░",16-ROUND(MIN(1,IF(B11=0,0,C11/B11))*16,0))) | G11: =IF(A11="","",IF(B11=0,"—",IF(C11>B11,"Over",IF(C11/B11>=0.8,"On track","Under"))))
A12: Buffer | B12: 40 | C12: =IF(A12="","",SUMIFS('Transaction Log'!$D$5:$D$104,'Transaction Log'!$C$5:$C$104,A12,'Transaction Log'!$A$5:$A$104,">="&PeriodStart,'Transaction Log'!$A$5:$A$104,"<="&PeriodEnd)) | D12: =IF(A12="","",B12-C12) | E12: =IF(OR(A12="",B12=0),"",C12/B12) | F12: =IF(A12="","",REPT("█",ROUND(MIN(1,IF(B12=0,0,C12/B12))*16,0))&REPT("░",16-ROUND(MIN(1,IF(B12=0,0,C12/B12))*16,0))) | G12: =IF(A12="","",IF(B12=0,"—",IF(C12>B12,"Over",IF(C12/B12>=0.8,"On track","Under"))))
C13: =IF(A13="","",SUMIFS('Transaction Log'!$D$5:$D$104,'Transaction Log'!$C$5:$C$104,A13,'Transaction Log'!$A$5:$A$104,">="&PeriodStart,'Transaction Log'!$A$5:$A$104,"<="&PeriodEnd)) | D13: =IF(A13="","",B13-C13) | E13: =IF(OR(A13="",B13=0),"",C13/B13) | F13: =IF(A13="","",REPT("█",ROUND(MIN(1,IF(B13=0,0,C13/B13))*16,0))&REPT("░",16-ROUND(MIN(1,IF(B13=0,0,C13/B13))*16,0))) | G13: =IF(A13="","",IF(B13=0,"—",IF(C13>B13,"Over",IF(C13/B13>=0.8,"On track","Under"))))
C14: =IF(A14="","",SUMIFS('Transaction Log'!$D$5:$D$104,'Transaction Log'!$C$5:$C$104,A14,'Transaction Log'!$A$5:$A$104,">="&PeriodStart,'Transaction Log'!$A$5:$A$104,"<="&PeriodEnd)) | D14: =IF(A14="","",B14-C14) | E14: =IF(OR(A14="",B14=0),"",C14/B14) | F14: =IF(A14="","",REPT("█",ROUND(MIN(1,IF(B14=0,0,C14/B14))*16,0))&REPT("░",16-ROUND(MIN(1,IF(B14=0,0,C14/B14))*16,0))) | G14: =IF(A14="","",IF(B14=0,"—",IF(C14>B14,"Over",IF(C14/B14>=0.8,"On track","Under"))))
C15: =IF(A15="","",SUMIFS('Transaction Log'!$D$5:$D$104,'Transaction Log'!$C$5:$C$104,A15,'Transaction Log'!$A$5:$A$104,">="&PeriodStart,'Transaction Log'!$A$5:$A$104,"<="&PeriodEnd)) | D15: =IF(A15="","",B15-C15) | E15: =IF(OR(A15="",B15=0),"",C15/B15) | F15: =IF(A15="","",REPT("█",ROUND(MIN(1,IF(B15=0,0,C15/B15))*16,0))&REPT("░",16-ROUND(MIN(1,IF(B15=0,0,C15/B15))*16,0))) | G15: =IF(A15="","",IF(B15=0,"—",IF(C15>B15,"Over",IF(C15/B15>=0.8,"On track","Under"))))
C16: =IF(A16="","",SUMIFS('Transaction Log'!$D$5:$D$104,'Transaction Log'!$C$5:$C$104,A16,'Transaction Log'!$A$5:$A$104,">="&PeriodStart,'Transaction Log'!$A$5:$A$104,"<="&PeriodEnd)) | D16: =IF(A16="","",B16-C16) | E16: =IF(OR(A16="",B16=0),"",C16/B16) | F16: =IF(A16="","",REPT("█",ROUND(MIN(1,IF(B16=0,0,C16/B16))*16,0))&REPT("░",16-ROUND(MIN(1,IF(B16=0,0,C16/B16))*16,0))) | G16: =IF(A16="","",IF(B16=0,"—",IF(C16>B16,"Over",IF(C16/B16>=0.8,"On track","Under"))))
C17: =IF(A17="","",SUMIFS('Transaction Log'!$D$5:$D$104,'Transaction Log'!$C$5:$C$104,A17,'Transaction Log'!$A$5:$A$104,">="&PeriodStart,'Transaction Log'!$A$5:$A$104,"<="&PeriodEnd)) | D17: =IF(A17="","",B17-C17) | E17: =IF(OR(A17="",B17=0),"",C17/B17) | F17: =IF(A17="","",REPT("█",ROUND(MIN(1,IF(B17=0,0,C17/B17))*16,0))&REPT("░",16-ROUND(MIN(1,IF(B17=0,0,C17/B17))*16,0))) | G17: =IF(A17="","",IF(B17=0,"—",IF(C17>B17,"Over",IF(C17/B17>=0.8,"On track","Under"))))
C18: =IF(A18="","",SUMIFS('Transaction Log'!$D$5:$D$104,'Transaction Log'!$C$5:$C$104,A18,'Transaction Log'!$A$5:$A$104,">="&PeriodStart,'Transaction Log'!$A$5:$A$104,"<="&PeriodEnd)) | D18: =IF(A18="","",B18-C18) | E18: =IF(OR(A18="",B18=0),"",C18/B18) | F18: =IF(A18="","",REPT("█",ROUND(MIN(1,IF(B18=0,0,C18/B18))*16,0))&REPT("░",16-ROUND(MIN(1,IF(B18=0,0,C18/B18))*16,0))) | G18: =IF(A18="","",IF(B18=0,"—",IF(C18>B18,"Over",IF(C18/B18>=0.8,"On track","Under"))))
C19: =IF(A19="","",SUMIFS('Transaction Log'!$D$5:$D$104,'Transaction Log'!$C$5:$C$104,A19,'Transaction Log'!$A$5:$A$104,">="&PeriodStart,'Transaction Log'!$A$5:$A$104,"<="&PeriodEnd)) | D19: =IF(A19="","",B19-C19) | E19: =IF(OR(A19="",B19=0),"",C19/B19) | F19: =IF(A19="","",REPT("█",ROUND(MIN(1,IF(B19=0,0,C19/B19))*16,0))&REPT("░",16-ROUND(MIN(1,IF(B19=0,0,C19/B19))*16,0))) | G19: =IF(A19="","",IF(B19=0,"—",IF(C19>B19,"Over",IF(C19/B19>=0.8,"On track","Under"))))
C20: =IF(A20="","",SUMIFS('Transaction Log'!$D$5:$D$104,'Transaction Log'!$C$5:$C$104,A20,'Transaction Log'!$A$5:$A$104,">="&PeriodStart,'Transaction Log'!$A$5:$A$104,"<="&PeriodEnd)) | D20: =IF(A20="","",B20-C20) | E20: =IF(OR(A20="",B20=0),"",C20/B20) | F20: =IF(A20="","",REPT("█",ROUND(MIN(1,IF(B20=0,0,C20/B20))*16,0))&REPT("░",16-ROUND(MIN(1,IF(B20=0,0,C20/B20))*16,0))) | G20: =IF(A20="","",IF(B20=0,"—",IF(C20>B20,"Over",IF(C20/B20>=0.8,"On track","Under"))))
C21: =IF(A21="","",SUMIFS('Transaction Log'!$D$5:$D$104,'Transaction Log'!$C$5:$C$104,A21,'Transaction Log'!$A$5:$A$104,">="&PeriodStart,'Transaction Log'!$A$5:$A$104,"<="&PeriodEnd)) | D21: =IF(A21="","",B21-C21) | E21: =IF(OR(A21="",B21=0),"",C21/B21) | F21: =IF(A21="","",REPT("█",ROUND(MIN(1,IF(B21=0,0,C21/B21))*16,0))&REPT("░",16-ROUND(MIN(1,IF(B21=0,0,C21/B21))*16,0))) | G21: =IF(A21="","",IF(B21=0,"—",IF(C21>B21,"Over",IF(C21/B21>=0.8,"On track","Under"))))
C22: =IF(A22="","",SUMIFS('Transaction Log'!$D$5:$D$104,'Transaction Log'!$C$5:$C$104,A22,'Transaction Log'!$A$5:$A$104,">="&PeriodStart,'Transaction Log'!$A$5:$A$104,"<="&PeriodEnd)) | D22: =IF(A22="","",B22-C22) | E22: =IF(OR(A22="",B22=0),"",C22/B22) | F22: =IF(A22="","",REPT("█",ROUND(MIN(1,IF(B22=0,0,C22/B22))*16,0))&REPT("░",16-ROUND(MIN(1,IF(B22=0,0,C22/B22))*16,0))) | G22: =IF(A22="","",IF(B22=0,"—",IF(C22>B22,"Over",IF(C22/B22>=0.8,"On track","Under"))))
C23: =IF(A23="","",SUMIFS('Transaction Log'!$D$5:$D$104,'Transaction Log'!$C$5:$C$104,A23,'Transaction Log'!$A$5:$A$104,">="&PeriodStart,'Transaction Log'!$A$5:$A$104,"<="&PeriodEnd)) | D23: =IF(A23="","",B23-C23) | E23: =IF(OR(A23="",B23=0),"",C23/B23) | F23: =IF(A23="","",REPT("█",ROUND(MIN(1,IF(B23=0,0,C23/B23))*16,0))&REPT("░",16-ROUND(MIN(1,IF(B23=0,0,C23/B23))*16,0))) | G23: =IF(A23="","",IF(B23=0,"—",IF(C23>B23,"Over",IF(C23/B23>=0.8,"On track","Under"))))
C24: =IF(A24="","",SUMIFS('Transaction Log'!$D$5:$D$104,'Transaction Log'!$C$5:$C$104,A24,'Transaction Log'!$A$5:$A$104,">="&PeriodStart,'Transaction Log'!$A$5:$A$104,"<="&PeriodEnd)) | D24: =IF(A24="","",B24-C24) | E24: =IF(OR(A24="",B24=0),"",C24/B24) | F24: =IF(A24="","",REPT("█",ROUND(MIN(1,IF(B24=0,0,C24/B24))*16,0))&REPT("░",16-ROUND(MIN(1,IF(B24=0,0,C24/B24))*16,0))) | G24: =IF(A24="","",IF(B24=0,"—",IF(C24>B24,"Over",IF(C24/B24>=0.8,"On track","Under"))))
A25: TOTAL | B25: =SUM(B5:B24) | C25: =SUM(C5:C24) | D25: =B25-C25 | E25: =IF(B25=0,"",C25/B25)
A27: Status: Under = under 80% used. On track = 80–100%. Over = spent more than planned (row turns red).

Sheet Transaction Log
A1: Transaction Log
A2: Record daily spending here — not bill payments. Pick a category from the list so Budget Categories and the Dashboard stay in sync.
A3: =IF(PeriodStart="","","Period: "&TEXT(PeriodStart,"mmm d")&" – "&TEXT(PeriodEnd,"mmm d, yyyy")&" · Logged this period: "&TEXT(ActualSpending,"$#,##0.00"))
A4: Date | B4: Description | C4: Category | D4: Amount | E4: Notes | F4: In this period?
A5: 46241 | B5: Kroger | C5: Groceries | D5: 62.4 | E5: Weekly shop | F5: =IF(A5="","",IF(AND(A5>=PeriodStart,A5<=PeriodEnd),"Yes",""))
A6: 46241 | B6: Shell | C6: Gas / Transit | D6: 41.2 | E6: Fill-up | F6: =IF(A6="","",IF(AND(A6>=PeriodStart,A6<=PeriodEnd),"Yes",""))
A7: 46242 | B7: Neighborhood coffee | C7: Dining out | D7: 6.75 | F7: =IF(A7="","",IF(AND(A7>=PeriodStart,A7<=PeriodEnd),"Yes",""))
A8: 46242 | B8: Target | C8: Household / Misc | D8: 18.33 | E8: Paper goods | F8: =IF(A8="","",IF(AND(A8>=PeriodStart,A8<=PeriodEnd),"Yes",""))
A9: 46243 | B9: Trader Joe's | C9: Groceries | D9: 47.89 | F9: =IF(A9="","",IF(AND(A9>=PeriodStart,A9<=PeriodEnd),"Yes",""))
A10: 46243 | B10: Chipotle | C10: Dining out | D10: 14.5 | E10: Lunch | F10: =IF(A10="","",IF(AND(A10>=PeriodStart,A10<=PeriodEnd),"Yes",""))
A11: 46244 | B11: CVS | C11: Personal care | D11: 12.99 | F11: =IF(A11="","",IF(AND(A11>=PeriodStart,A11<=PeriodEnd),"Yes",""))
A12: 46244 | B12: Movie tickets | C12: Fun / Entertainment | D12: 28 | E12: Saturday | F12: =IF(A12="","",IF(AND(A12>=PeriodStart,A12<=PeriodEnd),"Yes",""))
A13: 46245 | B13: Aldi | C13: Groceries | D13: 38.15 | F13: =IF(A13="","",IF(AND(A13>=PeriodStart,A13<=PeriodEnd),"Yes",""))
