Workbook
Name List_Projects: Projects!$A$5:$A$24
Name List_People: Projects!$N$2:$N$6
Name List_ProjStatus: Projects!$N$8:$N$11
Name List_TaskStatus: Projects!$N$13:$N$17
Name List_Priority: Projects!$N$19:$N$21
Name List_MileStatus: Projects!$N$23:$N$25
Name TaskProjects: 'Task List'!$B$5:$B$84
Name TaskStatus: 'Task List'!$E$5:$E$84
Name TaskDue: 'Task List'!$G$5:$G$84
Name TaskOverdue: 'Task List'!$M$5:$M$84
Name TaskEffPct: 'Task List'!$P$5:$P$84
Name TimelineStart: Timeline!$D$2
Name CountProjects: Dashboard!$N$2
Name CountTasks: Dashboard!$N$3
Name OpenTasks: Dashboard!$N$4
Name OverallPct: Dashboard!$N$5
Name OverdueTasks: Dashboard!$N$6
Name UpcomingTasks: Dashboard!$N$7
Name AtRiskProjects: Dashboard!$N$8
Name ProgressBar: Dashboard!$N$9

Sheet Dashboard
A1: Project Management Tracker | N1: HELPERS
A2: ="As of "&TEXT(TODAY(),"mmm d, yyyy")&" · "&CountProjects&" projects · "&CountTasks&" tasks · Change dates on Projects and Task List — this page follows." | N2: =COUNTA(Projects!$A$5:$A$24)
N3: =COUNTA('Task List'!$A$5:$A$84)
A4: PROJECTS | D4: TASKS | G4: OVERALL PROGRESS | J4: OVERDUE TASKS | N4: =COUNTIFS('Task List'!$E$5:$E$84,"<>Completed",'Task List'!$A$5:$A$84,"<>")
A5: =CountProjects | D5: =CountTasks | G5: =OverallPct | J5: =OverdueTasks | N5: =IF(N3=0,"",AVERAGE('Task List'!$P$5:$P$84))
A6: ="In progress "&TEXT(COUNTIF('Projects'!$E$5:$E$24,"In Progress"),"0") | D6: ="Open "&TEXT(OpenTasks,"0") | G6: =ProgressBar | J6: Due date passed, not done | N6: =COUNTIF('Task List'!$M$5:$M$84,"Yes")
A7: Rows on the Projects sheet | D7: Rows on the Task List | G7: Average of task % complete | J7: Work these first | N7: =COUNTIFS('Task List'!$G$5:$G$84,">="&TODAY(),'Task List'!$G$5:$G$84,"<="&TODAY()+14,'Task List'!$E$5:$E$84,"<>Completed")
N8: =COUNTIF(Projects!$L$5:$L$24,"At risk")+COUNTIF(Projects!$L$5:$L$24,"Overdue")
A9: DUE IN 14 DAYS | D9: PROJECTS AT RISK | G9: WAITING | J9: COMPLETED | N9: =IF(OR(N5="",N5<0),"",REPT("█",ROUND(MIN(1,N5)*16,0))&REPT("░",16-ROUND(MIN(1,N5)*16,0)))
A10: =UpcomingTasks | D10: =AtRiskProjects | G10: =COUNTIF('Task List'!$E$5:$E$84,"Waiting") | J10: =COUNTIF('Task List'!$E$5:$E$84,"Completed")
A11: Not completed | D11: Overdue or due soon and behind | G11: Blocked on someone else | J11: Closed tasks
A12: Look at Upcoming below | D12: Health on Projects sheet | G12: Nudge the owner | J12: Keep this number moving
A14: UPCOMING (NEXT 14 DAYS) | G14: OVERDUE
A15: Task | B15: Project | C15: Due | D15: Owner | F15: Status | G15: Task | H15: Project | I15: Due | J15: Owner | L15: Days late
A16: =IFERROR(INDEX('Task List'!$A$5:$A$84,MATCH(1,'Task List'!$O$5:$O$84,0)),"") | B16: =IF(A16="","",IFERROR(INDEX('Task List'!$B$5:$B$84,MATCH(1,'Task List'!$O$5:$O$84,0)),"")) | C16: =IF(A16="","",IFERROR(INDEX('Task List'!$G$5:$G$84,MATCH(1,'Task List'!$O$5:$O$84,0)),"")) | D16: =IF(A16="","",IFERROR(INDEX('Task List'!$C$5:$C$84,MATCH(1,'Task List'!$O$5:$O$84,0)),"")) | F16: =IF(A16="","",IFERROR(INDEX('Task List'!$E$5:$E$84,MATCH(1,'Task List'!$O$5:$O$84,0)),"")) | G16: =IFERROR(INDEX('Task List'!$A$5:$A$84,MATCH(1,'Task List'!$N$5:$N$84,0)),"") | H16: =IF(G16="","",IFERROR(INDEX('Task List'!$B$5:$B$84,MATCH(1,'Task List'!$N$5:$N$84,0)),"")) | I16: =IF(G16="","",IFERROR(INDEX('Task List'!$G$5:$G$84,MATCH(1,'Task List'!$N$5:$N$84,0)),"")) | J16: =IF(G16="","",IFERROR(INDEX('Task List'!$C$5:$C$84,MATCH(1,'Task List'!$N$5:$N$84,0)),"")) | L16: =IF(I16="","",TODAY()-I16)
A17: =IFERROR(INDEX('Task List'!$A$5:$A$84,MATCH(2,'Task List'!$O$5:$O$84,0)),"") | B17: =IF(A17="","",IFERROR(INDEX('Task List'!$B$5:$B$84,MATCH(2,'Task List'!$O$5:$O$84,0)),"")) | C17: =IF(A17="","",IFERROR(INDEX('Task List'!$G$5:$G$84,MATCH(2,'Task List'!$O$5:$O$84,0)),"")) | D17: =IF(A17="","",IFERROR(INDEX('Task List'!$C$5:$C$84,MATCH(2,'Task List'!$O$5:$O$84,0)),"")) | F17: =IF(A17="","",IFERROR(INDEX('Task List'!$E$5:$E$84,MATCH(2,'Task List'!$O$5:$O$84,0)),"")) | G17: =IFERROR(INDEX('Task List'!$A$5:$A$84,MATCH(2,'Task List'!$N$5:$N$84,0)),"") | H17: =IF(G17="","",IFERROR(INDEX('Task List'!$B$5:$B$84,MATCH(2,'Task List'!$N$5:$N$84,0)),"")) | I17: =IF(G17="","",IFERROR(INDEX('Task List'!$G$5:$G$84,MATCH(2,'Task List'!$N$5:$N$84,0)),"")) | J17: =IF(G17="","",IFERROR(INDEX('Task List'!$C$5:$C$84,MATCH(2,'Task List'!$N$5:$N$84,0)),"")) | L17: =IF(I17="","",TODAY()-I17)
A18: =IFERROR(INDEX('Task List'!$A$5:$A$84,MATCH(3,'Task List'!$O$5:$O$84,0)),"") | B18: =IF(A18="","",IFERROR(INDEX('Task List'!$B$5:$B$84,MATCH(3,'Task List'!$O$5:$O$84,0)),"")) | C18: =IF(A18="","",IFERROR(INDEX('Task List'!$G$5:$G$84,MATCH(3,'Task List'!$O$5:$O$84,0)),"")) | D18: =IF(A18="","",IFERROR(INDEX('Task List'!$C$5:$C$84,MATCH(3,'Task List'!$O$5:$O$84,0)),"")) | F18: =IF(A18="","",IFERROR(INDEX('Task List'!$E$5:$E$84,MATCH(3,'Task List'!$O$5:$O$84,0)),"")) | G18: =IFERROR(INDEX('Task List'!$A$5:$A$84,MATCH(3,'Task List'!$N$5:$N$84,0)),"") | H18: =IF(G18="","",IFERROR(INDEX('Task List'!$B$5:$B$84,MATCH(3,'Task List'!$N$5:$N$84,0)),"")) | I18: =IF(G18="","",IFERROR(INDEX('Task List'!$G$5:$G$84,MATCH(3,'Task List'!$N$5:$N$84,0)),"")) | J18: =IF(G18="","",IFERROR(INDEX('Task List'!$C$5:$C$84,MATCH(3,'Task List'!$N$5:$N$84,0)),"")) | L18: =IF(I18="","",TODAY()-I18)
A19: =IFERROR(INDEX('Task List'!$A$5:$A$84,MATCH(4,'Task List'!$O$5:$O$84,0)),"") | B19: =IF(A19="","",IFERROR(INDEX('Task List'!$B$5:$B$84,MATCH(4,'Task List'!$O$5:$O$84,0)),"")) | C19: =IF(A19="","",IFERROR(INDEX('Task List'!$G$5:$G$84,MATCH(4,'Task List'!$O$5:$O$84,0)),"")) | D19: =IF(A19="","",IFERROR(INDEX('Task List'!$C$5:$C$84,MATCH(4,'Task List'!$O$5:$O$84,0)),"")) | F19: =IF(A19="","",IFERROR(INDEX('Task List'!$E$5:$E$84,MATCH(4,'Task List'!$O$5:$O$84,0)),"")) | G19: =IFERROR(INDEX('Task List'!$A$5:$A$84,MATCH(4,'Task List'!$N$5:$N$84,0)),"") | H19: =IF(G19="","",IFERROR(INDEX('Task List'!$B$5:$B$84,MATCH(4,'Task List'!$N$5:$N$84,0)),"")) | I19: =IF(G19="","",IFERROR(INDEX('Task List'!$G$5:$G$84,MATCH(4,'Task List'!$N$5:$N$84,0)),"")) | J19: =IF(G19="","",IFERROR(INDEX('Task List'!$C$5:$C$84,MATCH(4,'Task List'!$N$5:$N$84,0)),"")) | L19: =IF(I19="","",TODAY()-I19)
A20: =IFERROR(INDEX('Task List'!$A$5:$A$84,MATCH(5,'Task List'!$O$5:$O$84,0)),"") | B20: =IF(A20="","",IFERROR(INDEX('Task List'!$B$5:$B$84,MATCH(5,'Task List'!$O$5:$O$84,0)),"")) | C20: =IF(A20="","",IFERROR(INDEX('Task List'!$G$5:$G$84,MATCH(5,'Task List'!$O$5:$O$84,0)),"")) | D20: =IF(A20="","",IFERROR(INDEX('Task List'!$C$5:$C$84,MATCH(5,'Task List'!$O$5:$O$84,0)),"")) | F20: =IF(A20="","",IFERROR(INDEX('Task List'!$E$5:$E$84,MATCH(5,'Task List'!$O$5:$O$84,0)),"")) | G20: =IFERROR(INDEX('Task List'!$A$5:$A$84,MATCH(5,'Task List'!$N$5:$N$84,0)),"") | H20: =IF(G20="","",IFERROR(INDEX('Task List'!$B$5:$B$84,MATCH(5,'Task List'!$N$5:$N$84,0)),"")) | I20: =IF(G20="","",IFERROR(INDEX('Task List'!$G$5:$G$84,MATCH(5,'Task List'!$N$5:$N$84,0)),"")) | J20: =IF(G20="","",IFERROR(INDEX('Task List'!$C$5:$C$84,MATCH(5,'Task List'!$N$5:$N$84,0)),"")) | L20: =IF(I20="","",TODAY()-I20)
A21: =IFERROR(INDEX('Task List'!$A$5:$A$84,MATCH(6,'Task List'!$O$5:$O$84,0)),"") | B21: =IF(A21="","",IFERROR(INDEX('Task List'!$B$5:$B$84,MATCH(6,'Task List'!$O$5:$O$84,0)),"")) | C21: =IF(A21="","",IFERROR(INDEX('Task List'!$G$5:$G$84,MATCH(6,'Task List'!$O$5:$O$84,0)),"")) | D21: =IF(A21="","",IFERROR(INDEX('Task List'!$C$5:$C$84,MATCH(6,'Task List'!$O$5:$O$84,0)),"")) | F21: =IF(A21="","",IFERROR(INDEX('Task List'!$E$5:$E$84,MATCH(6,'Task List'!$O$5:$O$84,0)),"")) | G21: =IFERROR(INDEX('Task List'!$A$5:$A$84,MATCH(6,'Task List'!$N$5:$N$84,0)),"") | H21: =IF(G21="","",IFERROR(INDEX('Task List'!$B$5:$B$84,MATCH(6,'Task List'!$N$5:$N$84,0)),"")) | I21: =IF(G21="","",IFERROR(INDEX('Task List'!$G$5:$G$84,MATCH(6,'Task List'!$N$5:$N$84,0)),"")) | J21: =IF(G21="","",IFERROR(INDEX('Task List'!$C$5:$C$84,MATCH(6,'Task List'!$N$5:$N$84,0)),"")) | L21: =IF(I21="","",TODAY()-I21)
A22: =IFERROR(INDEX('Task List'!$A$5:$A$84,MATCH(7,'Task List'!$O$5:$O$84,0)),"") | B22: =IF(A22="","",IFERROR(INDEX('Task List'!$B$5:$B$84,MATCH(7,'Task List'!$O$5:$O$84,0)),"")) | C22: =IF(A22="","",IFERROR(INDEX('Task List'!$G$5:$G$84,MATCH(7,'Task List'!$O$5:$O$84,0)),"")) | D22: =IF(A22="","",IFERROR(INDEX('Task List'!$C$5:$C$84,MATCH(7,'Task List'!$O$5:$O$84,0)),"")) | F22: =IF(A22="","",IFERROR(INDEX('Task List'!$E$5:$E$84,MATCH(7,'Task List'!$O$5:$O$84,0)),"")) | G22: =IFERROR(INDEX('Task List'!$A$5:$A$84,MATCH(7,'Task List'!$N$5:$N$84,0)),"") | H22: =IF(G22="","",IFERROR(INDEX('Task List'!$B$5:$B$84,MATCH(7,'Task List'!$N$5:$N$84,0)),"")) | I22: =IF(G22="","",IFERROR(INDEX('Task List'!$G$5:$G$84,MATCH(7,'Task List'!$N$5:$N$84,0)),"")) | J22: =IF(G22="","",IFERROR(INDEX('Task List'!$C$5:$C$84,MATCH(7,'Task List'!$N$5:$N$84,0)),"")) | L22: =IF(I22="","",TODAY()-I22)
A23: =IFERROR(INDEX('Task List'!$A$5:$A$84,MATCH(8,'Task List'!$O$5:$O$84,0)),"") | B23: =IF(A23="","",IFERROR(INDEX('Task List'!$B$5:$B$84,MATCH(8,'Task List'!$O$5:$O$84,0)),"")) | C23: =IF(A23="","",IFERROR(INDEX('Task List'!$G$5:$G$84,MATCH(8,'Task List'!$O$5:$O$84,0)),"")) | D23: =IF(A23="","",IFERROR(INDEX('Task List'!$C$5:$C$84,MATCH(8,'Task List'!$O$5:$O$84,0)),"")) | F23: =IF(A23="","",IFERROR(INDEX('Task List'!$E$5:$E$84,MATCH(8,'Task List'!$O$5:$O$84,0)),"")) | G23: =IFERROR(INDEX('Task List'!$A$5:$A$84,MATCH(8,'Task List'!$N$5:$N$84,0)),"") | H23: =IF(G23="","",IFERROR(INDEX('Task List'!$B$5:$B$84,MATCH(8,'Task List'!$N$5:$N$84,0)),"")) | I23: =IF(G23="","",IFERROR(INDEX('Task List'!$G$5:$G$84,MATCH(8,'Task List'!$N$5:$N$84,0)),"")) | J23: =IF(G23="","",IFERROR(INDEX('Task List'!$C$5:$C$84,MATCH(8,'Task List'!$N$5:$N$84,0)),"")) | L23: =IF(I23="","",TODAY()-I23)
A25: PROGRESS BY PROJECT | G25: TASKS BY STATUS
A42: Start on Projects, add tasks, then live here. Overdue is red until Status is Completed. See Instructions for the 5-minute start.
A55: Project | B55: Progress | D55: Status | E55: Count
A56: =IF(Projects!A5="","",Projects!A5) | B56: =IF(OR(A56="",Projects!G5=""),NA(),Projects!G5) | D56: Not Started | E56: =COUNTIF(TaskStatus,"Not Started")
A57: =IF(Projects!A6="","",Projects!A6) | B57: =IF(OR(A57="",Projects!G6=""),NA(),Projects!G6) | D57: In Progress | E57: =COUNTIF(TaskStatus,"In Progress")
A58: =IF(Projects!A7="","",Projects!A7) | B58: =IF(OR(A58="",Projects!G7=""),NA(),Projects!G7) | D58: Waiting | E58: =COUNTIF(TaskStatus,"Waiting")
A59: =IF(Projects!A8="","",Projects!A8) | B59: =IF(OR(A59="",Projects!G8=""),NA(),Projects!G8) | D59: On Hold | E59: =COUNTIF(TaskStatus,"On Hold")
A60: =IF(Projects!A9="","",Projects!A9) | B60: =IF(OR(A60="",Projects!G9=""),NA(),Projects!G9) | D60: Completed | E60: =COUNTIF(TaskStatus,"Completed")
A61: =IF(Projects!A10="","",Projects!A10) | B61: =IF(OR(A61="",Projects!G10=""),NA(),Projects!G10)
A62: =IF(Projects!A11="","",Projects!A11) | B62: =IF(OR(A62="",Projects!G11=""),NA(),Projects!G11)
A63: =IF(Projects!A12="","",Projects!A12) | B63: =IF(OR(A63="",Projects!G12=""),NA(),Projects!G12)

Sheet Projects
A1: Projects | N1: DROPDOWN LISTS | O1: Edit these if you need extra options.
A2: One row per project. % Complete, task counts, and Health come from the Task List. Blue = type. Gray = calculated. | N2: Maya Chen | O2: People (Assigned to / Owner)
A3: =COUNTA(A5:A24)&" projects · "&COUNTIF(E5:E24,"In Progress")&" in progress · "&COUNTIF(L5:L24,"At risk")+COUNTIF(L5:L24,"Overdue")&" need attention" | N3: Jordan Blake
A4: Project name | B4: Owner / lead | C4: Start | D4: End | E4: Status | F4: Priority | G4: % Complete | H4: Tasks | I4: Open | J4: Overdue | K4: Notes | L4: Health | N4: Sam Okonkwo
A5: Website Redesign | B5: Maya Chen | C5: 46204 | D5: 46295 | E5: In Progress | F5: High | G5: =IF(A5="","",IF(COUNTIF(TaskProjects,A5)=0,"",AVERAGEIFS(TaskEffPct,TaskProjects,A5))) | H5: =IF(A5="","",COUNTIF(TaskProjects,A5)) | I5: =IF(A5="","",COUNTIFS(TaskProjects,A5,TaskStatus,"<>Completed")) | J5: =IF(A5="","",COUNTIFS(TaskProjects,A5,TaskOverdue,"Yes")) | K5: Public site + CMS | L5: =IF(A5="","",IF(E5="Completed","Done",IF(AND(D5<>"",D5<TODAY()),"Overdue",IF(AND(D5<>"",D5<=TODAY()+14,N(G5)<0.75),"At risk","On track")))) | N5: Riley Patel
A6: Q3 Client Launch | B6: Jordan Blake | C6: 46235 | D6: 46260 | E6: In Progress | F6: High | G6: =IF(A6="","",IF(COUNTIF(TaskProjects,A6)=0,"",AVERAGEIFS(TaskEffPct,TaskProjects,A6))) | H6: =IF(A6="","",COUNTIF(TaskProjects,A6)) | I6: =IF(A6="","",COUNTIFS(TaskProjects,A6,TaskStatus,"<>Completed")) | J6: =IF(A6="","",COUNTIFS(TaskProjects,A6,TaskOverdue,"Yes")) | K6: Acme Co. go-live | L6: =IF(A6="","",IF(E6="Completed","Done",IF(AND(D6<>"",D6<TODAY()),"Overdue",IF(AND(D6<>"",D6<=TODAY()+14,N(G6)<0.75),"At risk","On track")))) | N6: Alex Rivera
A7: Hiring Pipeline | B7: Sam Okonkwo | C7: 46235 | D7: 46310 | E7: On Hold | F7: Medium | G7: =IF(A7="","",IF(COUNTIF(TaskProjects,A7)=0,"",AVERAGEIFS(TaskEffPct,TaskProjects,A7))) | H7: =IF(A7="","",COUNTIF(TaskProjects,A7)) | I7: =IF(A7="","",COUNTIFS(TaskProjects,A7,TaskStatus,"<>Completed")) | J7: =IF(A7="","",COUNTIFS(TaskProjects,A7,TaskOverdue,"Yes")) | K7: Paused pending budget | L7: =IF(A7="","",IF(E7="Completed","Done",IF(AND(D7<>"",D7<TODAY()),"Overdue",IF(AND(D7<>"",D7<=TODAY()+14,N(G7)<0.75),"At risk","On track"))))
A8: Brand Guidelines | B8: Riley Patel | C8: 46266 | D8: 46326 | E8: Not Started | F8: Low | G8: =IF(A8="","",IF(COUNTIF(TaskProjects,A8)=0,"",AVERAGEIFS(TaskEffPct,TaskProjects,A8))) | H8: =IF(A8="","",COUNTIF(TaskProjects,A8)) | I8: =IF(A8="","",COUNTIFS(TaskProjects,A8,TaskStatus,"<>Completed")) | J8: =IF(A8="","",COUNTIFS(TaskProjects,A8,TaskOverdue,"Yes")) | K8: Internal + client kit | L8: =IF(A8="","",IF(E8="Completed","Done",IF(AND(D8<>"",D8<TODAY()),"Overdue",IF(AND(D8<>"",D8<=TODAY()+14,N(G8)<0.75),"At risk","On track")))) | N8: Not Started | O8: Project status
G9: =IF(A9="","",IF(COUNTIF(TaskProjects,A9)=0,"",AVERAGEIFS(TaskEffPct,TaskProjects,A9))) | H9: =IF(A9="","",COUNTIF(TaskProjects,A9)) | I9: =IF(A9="","",COUNTIFS(TaskProjects,A9,TaskStatus,"<>Completed")) | J9: =IF(A9="","",COUNTIFS(TaskProjects,A9,TaskOverdue,"Yes")) | L9: =IF(A9="","",IF(E9="Completed","Done",IF(AND(D9<>"",D9<TODAY()),"Overdue",IF(AND(D9<>"",D9<=TODAY()+14,N(G9)<0.75),"At risk","On track")))) | N9: In Progress
G10: =IF(A10="","",IF(COUNTIF(TaskProjects,A10)=0,"",AVERAGEIFS(TaskEffPct,TaskProjects,A10))) | H10: =IF(A10="","",COUNTIF(TaskProjects,A10)) | I10: =IF(A10="","",COUNTIFS(TaskProjects,A10,TaskStatus,"<>Completed")) | J10: =IF(A10="","",COUNTIFS(TaskProjects,A10,TaskOverdue,"Yes")) | L10: =IF(A10="","",IF(E10="Completed","Done",IF(AND(D10<>"",D10<TODAY()),"Overdue",IF(AND(D10<>"",D10<=TODAY()+14,N(G10)<0.75),"At risk","On track")))) | N10: On Hold
G11: =IF(A11="","",IF(COUNTIF(TaskProjects,A11)=0,"",AVERAGEIFS(TaskEffPct,TaskProjects,A11))) | H11: =IF(A11="","",COUNTIF(TaskProjects,A11)) | I11: =IF(A11="","",COUNTIFS(TaskProjects,A11,TaskStatus,"<>Completed")) | J11: =IF(A11="","",COUNTIFS(TaskProjects,A11,TaskOverdue,"Yes")) | L11: =IF(A11="","",IF(E11="Completed","Done",IF(AND(D11<>"",D11<TODAY()),"Overdue",IF(AND(D11<>"",D11<=TODAY()+14,N(G11)<0.75),"At risk","On track")))) | N11: Completed
G12: =IF(A12="","",IF(COUNTIF(TaskProjects,A12)=0,"",AVERAGEIFS(TaskEffPct,TaskProjects,A12))) | H12: =IF(A12="","",COUNTIF(TaskProjects,A12)) | I12: =IF(A12="","",COUNTIFS(TaskProjects,A12,TaskStatus,"<>Completed")) | J12: =IF(A12="","",COUNTIFS(TaskProjects,A12,TaskOverdue,"Yes")) | L12: =IF(A12="","",IF(E12="Completed","Done",IF(AND(D12<>"",D12<TODAY()),"Overdue",IF(AND(D12<>"",D12<=TODAY()+14,N(G12)<0.75),"At risk","On track"))))
G13: =IF(A13="","",IF(COUNTIF(TaskProjects,A13)=0,"",AVERAGEIFS(TaskEffPct,TaskProjects,A13))) | H13: =IF(A13="","",COUNTIF(TaskProjects,A13)) | I13: =IF(A13="","",COUNTIFS(TaskProjects,A13,TaskStatus,"<>Completed")) | J13: =IF(A13="","",COUNTIFS(TaskProjects,A13,TaskOverdue,"Yes")) | L13: =IF(A13="","",IF(E13="Completed","Done",IF(AND(D13<>"",D13<TODAY()),"Overdue",IF(AND(D13<>"",D13<=TODAY()+14,N(G13)<0.75),"At risk","On track")))) | N13: Not Started | O13: Task status
G14: =IF(A14="","",IF(COUNTIF(TaskProjects,A14)=0,"",AVERAGEIFS(TaskEffPct,TaskProjects,A14))) | H14: =IF(A14="","",COUNTIF(TaskProjects,A14)) | I14: =IF(A14="","",COUNTIFS(TaskProjects,A14,TaskStatus,"<>Completed")) | J14: =IF(A14="","",COUNTIFS(TaskProjects,A14,TaskOverdue,"Yes")) | L14: =IF(A14="","",IF(E14="Completed","Done",IF(AND(D14<>"",D14<TODAY()),"Overdue",IF(AND(D14<>"",D14<=TODAY()+14,N(G14)<0.75),"At risk","On track")))) | N14: In Progress
G15: =IF(A15="","",IF(COUNTIF(TaskProjects,A15)=0,"",AVERAGEIFS(TaskEffPct,TaskProjects,A15))) | H15: =IF(A15="","",COUNTIF(TaskProjects,A15)) | I15: =IF(A15="","",COUNTIFS(TaskProjects,A15,TaskStatus,"<>Completed")) | J15: =IF(A15="","",COUNTIFS(TaskProjects,A15,TaskOverdue,"Yes")) | L15: =IF(A15="","",IF(E15="Completed","Done",IF(AND(D15<>"",D15<TODAY()),"Overdue",IF(AND(D15<>"",D15<=TODAY()+14,N(G15)<0.75),"At risk","On track")))) | N15: Waiting
G16: =IF(A16="","",IF(COUNTIF(TaskProjects,A16)=0,"",AVERAGEIFS(TaskEffPct,TaskProjects,A16))) | H16: =IF(A16="","",COUNTIF(TaskProjects,A16)) | I16: =IF(A16="","",COUNTIFS(TaskProjects,A16,TaskStatus,"<>Completed")) | J16: =IF(A16="","",COUNTIFS(TaskProjects,A16,TaskOverdue,"Yes")) | L16: =IF(A16="","",IF(E16="Completed","Done",IF(AND(D16<>"",D16<TODAY()),"Overdue",IF(AND(D16<>"",D16<=TODAY()+14,N(G16)<0.75),"At risk","On track")))) | N16: On Hold
G17: =IF(A17="","",IF(COUNTIF(TaskProjects,A17)=0,"",AVERAGEIFS(TaskEffPct,TaskProjects,A17))) | H17: =IF(A17="","",COUNTIF(TaskProjects,A17)) | I17: =IF(A17="","",COUNTIFS(TaskProjects,A17,TaskStatus,"<>Completed")) | J17: =IF(A17="","",COUNTIFS(TaskProjects,A17,TaskOverdue,"Yes")) | L17: =IF(A17="","",IF(E17="Completed","Done",IF(AND(D17<>"",D17<TODAY()),"Overdue",IF(AND(D17<>"",D17<=TODAY()+14,N(G17)<0.75),"At risk","On track")))) | N17: Completed
G18: =IF(A18="","",IF(COUNTIF(TaskProjects,A18)=0,"",AVERAGEIFS(TaskEffPct,TaskProjects,A18))) | H18: =IF(A18="","",COUNTIF(TaskProjects,A18)) | I18: =IF(A18="","",COUNTIFS(TaskProjects,A18,TaskStatus,"<>Completed")) | J18: =IF(A18="","",COUNTIFS(TaskProjects,A18,TaskOverdue,"Yes")) | L18: =IF(A18="","",IF(E18="Completed","Done",IF(AND(D18<>"",D18<TODAY()),"Overdue",IF(AND(D18<>"",D18<=TODAY()+14,N(G18)<0.75),"At risk","On track"))))
G19: =IF(A19="","",IF(COUNTIF(TaskProjects,A19)=0,"",AVERAGEIFS(TaskEffPct,TaskProjects,A19))) | H19: =IF(A19="","",COUNTIF(TaskProjects,A19)) | I19: =IF(A19="","",COUNTIFS(TaskProjects,A19,TaskStatus,"<>Completed")) | J19: =IF(A19="","",COUNTIFS(TaskProjects,A19,TaskOverdue,"Yes")) | L19: =IF(A19="","",IF(E19="Completed","Done",IF(AND(D19<>"",D19<TODAY()),"Overdue",IF(AND(D19<>"",D19<=TODAY()+14,N(G19)<0.75),"At risk","On track")))) | N19: High | O19: Priority
G20: =IF(A20="","",IF(COUNTIF(TaskProjects,A20)=0,"",AVERAGEIFS(TaskEffPct,TaskProjects,A20))) | H20: =IF(A20="","",COUNTIF(TaskProjects,A20)) | I20: =IF(A20="","",COUNTIFS(TaskProjects,A20,TaskStatus,"<>Completed")) | J20: =IF(A20="","",COUNTIFS(TaskProjects,A20,TaskOverdue,"Yes")) | L20: =IF(A20="","",IF(E20="Completed","Done",IF(AND(D20<>"",D20<TODAY()),"Overdue",IF(AND(D20<>"",D20<=TODAY()+14,N(G20)<0.75),"At risk","On track")))) | N20: Medium
G21: =IF(A21="","",IF(COUNTIF(TaskProjects,A21)=0,"",AVERAGEIFS(TaskEffPct,TaskProjects,A21))) | H21: =IF(A21="","",COUNTIF(TaskProjects,A21)) | I21: =IF(A21="","",COUNTIFS(TaskProjects,A21,TaskStatus,"<>Completed")) | J21: =IF(A21="","",COUNTIFS(TaskProjects,A21,TaskOverdue,"Yes")) | L21: =IF(A21="","",IF(E21="Completed","Done",IF(AND(D21<>"",D21<TODAY()),"Overdue",IF(AND(D21<>"",D21<=TODAY()+14,N(G21)<0.75),"At risk","On track")))) | N21: Low
G22: =IF(A22="","",IF(COUNTIF(TaskProjects,A22)=0,"",AVERAGEIFS(TaskEffPct,TaskProjects,A22))) | H22: =IF(A22="","",COUNTIF(TaskProjects,A22)) | I22: =IF(A22="","",COUNTIFS(TaskProjects,A22,TaskStatus,"<>Completed")) | J22: =IF(A22="","",COUNTIFS(TaskProjects,A22,TaskOverdue,"Yes")) | L22: =IF(A22="","",IF(E22="Completed","Done",IF(AND(D22<>"",D22<TODAY()),"Overdue",IF(AND(D22<>"",D22<=TODAY()+14,N(G22)<0.75),"At risk","On track"))))
G23: =IF(A23="","",IF(COUNTIF(TaskProjects,A23)=0,"",AVERAGEIFS(TaskEffPct,TaskProjects,A23))) | H23: =IF(A23="","",COUNTIF(TaskProjects,A23)) | I23: =IF(A23="","",COUNTIFS(TaskProjects,A23,TaskStatus,"<>Completed")) | J23: =IF(A23="","",COUNTIFS(TaskProjects,A23,TaskOverdue,"Yes")) | L23: =IF(A23="","",IF(E23="Completed","Done",IF(AND(D23<>"",D23<TODAY()),"Overdue",IF(AND(D23<>"",D23<=TODAY()+14,N(G23)<0.75),"At risk","On track")))) | N23: Upcoming | O23: Milestone status
G24: =IF(A24="","",IF(COUNTIF(TaskProjects,A24)=0,"",AVERAGEIFS(TaskEffPct,TaskProjects,A24))) | H24: =IF(A24="","",COUNTIF(TaskProjects,A24)) | I24: =IF(A24="","",COUNTIFS(TaskProjects,A24,TaskStatus,"<>Completed")) | J24: =IF(A24="","",COUNTIFS(TaskProjects,A24,TaskOverdue,"Yes")) | L24: =IF(A24="","",IF(E24="Completed","Done",IF(AND(D24<>"",D24<TODAY()),"Overdue",IF(AND(D24<>"",D24<=TODAY()+14,N(G24)<0.75),"At risk","On track")))) | N24: Done
A25: TOTAL | H25: =SUM(H5:H24) | I25: =SUM(I5:I24) | J25: =SUM(J5:J24) | N25: Missed
A27: Add a project in the next blank blue row. Then add tasks on the Task List and pick this name from the Project dropdown.

Sheet Task List
A1: Task List
A2: One row per task. Pick the Project from the dropdown so Dashboard and project % stay in sync. Filter and sort freely.
A3: =COUNTA(A5:A84)&" tasks · "&COUNTIF(E5:E84,"Completed")&" done · "&COUNTIF(M5:M84,"Yes")&" overdue · "&COUNTIFS(G5:G84,">="&TODAY(),G5:G84,"<="&TODAY()+14,E5:E84,"<>Completed")&" due in 14 days"
A4: Task name | B4: Project | C4: Assigned to | D4: Priority | E4: Status | F4: Start | G4: Due | H4: % Complete | I4: Est. hrs | J4: Actual hrs | K4: Notes | L4: Days left | M4: Overdue?
A5: Kickoff workshop | B5: Website Redesign | C5: Maya Chen | D5: High | E5: Completed | F5: 46204 | G5: 46206 | H5: 1 | I5: 6 | J5: 5.5 | L5: =IF(OR(A5="",G5=""),"",G5-TODAY()) | M5: =IF(A5="","",IF(AND(G5<>"",G5<TODAY(),E5<>"Completed"),"Yes","")) | N5: =IF(M5<>"Yes","",COUNTIF($M$5:M5,"Yes")) | O5: =IF(OR(A5="",E5="Completed",G5="",G5<TODAY(),G5>TODAY()+14),"",COUNTIFS($G$5:G5,">="&TODAY(),$G$5:G5,"<="&TODAY()+14,$E$5:E5,"<>Completed",$A$5:A5,"<>")) | P5: =IF(A5="","",IF(E5="Completed",1,N(H5)))
A6: Sitemap and IA | B6: Website Redesign | C6: Maya Chen | D6: High | E6: Completed | F6: 46209 | G6: 46221 | H6: 1 | I6: 12 | J6: 14 | L6: =IF(OR(A6="",G6=""),"",G6-TODAY()) | M6: =IF(A6="","",IF(AND(G6<>"",G6<TODAY(),E6<>"Completed"),"Yes","")) | N6: =IF(M6<>"Yes","",COUNTIF($M$5:M6,"Yes")) | O6: =IF(OR(A6="",E6="Completed",G6="",G6<TODAY(),G6>TODAY()+14),"",COUNTIFS($G$5:G6,">="&TODAY(),$G$5:G6,"<="&TODAY()+14,$E$5:E6,"<>Completed",$A$5:A6,"<>")) | P6: =IF(A6="","",IF(E6="Completed",1,N(H6)))
A7: Visual mockups | B7: Website Redesign | C7: Riley Patel | D7: High | E7: In Progress | F7: 46223 | G7: 46249 | H7: 0.7 | I7: 24 | J7: 18 | K7: Homepage + 3 inner | L7: =IF(OR(A7="",G7=""),"",G7-TODAY()) | M7: =IF(A7="","",IF(AND(G7<>"",G7<TODAY(),E7<>"Completed"),"Yes","")) | N7: =IF(M7<>"Yes","",COUNTIF($M$5:M7,"Yes")) | O7: =IF(OR(A7="",E7="Completed",G7="",G7<TODAY(),G7>TODAY()+14),"",COUNTIFS($G$5:G7,">="&TODAY(),$G$5:G7,"<="&TODAY()+14,$E$5:E7,"<>Completed",$A$5:A7,"<>")) | P7: =IF(A7="","",IF(E7="Completed",1,N(H7)))
A8: Stakeholder review | B8: Website Redesign | C8: Maya Chen | D8: High | E8: Waiting | F8: 46239 | G8: 46246 | H8: 0.4 | I8: 3 | J8: 2 | K8: Waiting on legal | L8: =IF(OR(A8="",G8=""),"",G8-TODAY()) | M8: =IF(A8="","",IF(AND(G8<>"",G8<TODAY(),E8<>"Completed"),"Yes","")) | N8: =IF(M8<>"Yes","",COUNTIF($M$5:M8,"Yes")) | O8: =IF(OR(A8="",E8="Completed",G8="",G8<TODAY(),G8>TODAY()+14),"",COUNTIFS($G$5:G8,">="&TODAY(),$G$5:G8,"<="&TODAY()+14,$E$5:E8,"<>Completed",$A$5:A8,"<>")) | P8: =IF(A8="","",IF(E8="Completed",1,N(H8)))
A9: Homepage build | B9: Website Redesign | C9: Jordan Blake | D9: High | E9: In Progress | F9: 46238 | G9: 46256 | H9: 0.4 | I9: 20 | J9: 8 | L9: =IF(OR(A9="",G9=""),"",G9-TODAY()) | M9: =IF(A9="","",IF(AND(G9<>"",G9<TODAY(),E9<>"Completed"),"Yes","")) | N9: =IF(M9<>"Yes","",COUNTIF($M$5:M9,"Yes")) | O9: =IF(OR(A9="",E9="Completed",G9="",G9<TODAY(),G9>TODAY()+14),"",COUNTIFS($G$5:G9,">="&TODAY(),$G$5:G9,"<="&TODAY()+14,$E$5:E9,"<>Completed",$A$5:A9,"<>")) | P9: =IF(A9="","",IF(E9="Completed",1,N(H9)))
A10: Dev handoff packet | B10: Website Redesign | C10: Jordan Blake | D10: Medium | E10: Not Started | F10: 46252 | G10: 46263 | H10: 0 | I10: 6 | L10: =IF(OR(A10="",G10=""),"",G10-TODAY()) | M10: =IF(A10="","",IF(AND(G10<>"",G10<TODAY(),E10<>"Completed"),"Yes","")) | N10: =IF(M10<>"Yes","",COUNTIF($M$5:M10,"Yes")) | O10: =IF(OR(A10="",E10="Completed",G10="",G10<TODAY(),G10>TODAY()+14),"",COUNTIFS($G$5:G10,">="&TODAY(),$G$5:G10,"<="&TODAY()+14,$E$5:E10,"<>Completed",$A$5:A10,"<>")) | P10: =IF(A10="","",IF(E10="Completed",1,N(H10)))
A11: CMS training | B11: Website Redesign | C11: Maya Chen | D11: Medium | E11: Not Started | F11: 46273 | G11: 46277 | H11: 0 | I11: 4 | L11: =IF(OR(A11="",G11=""),"",G11-TODAY()) | M11: =IF(A11="","",IF(AND(G11<>"",G11<TODAY(),E11<>"Completed"),"Yes","")) | N11: =IF(M11<>"Yes","",COUNTIF($M$5:M11,"Yes")) | O11: =IF(OR(A11="",E11="Completed",G11="",G11<TODAY(),G11>TODAY()+14),"",COUNTIFS($G$5:G11,">="&TODAY(),$G$5:G11,"<="&TODAY()+14,$E$5:E11,"<>Completed",$A$5:A11,"<>")) | P11: =IF(A11="","",IF(E11="Completed",1,N(H11)))
A12: QA pass | B12: Website Redesign | C12: Sam Okonkwo | D12: High | E12: Not Started | F12: 46280 | G12: 46290 | H12: 0 | I12: 10 | L12: =IF(OR(A12="",G12=""),"",G12-TODAY()) | M12: =IF(A12="","",IF(AND(G12<>"",G12<TODAY(),E12<>"Completed"),"Yes","")) | N12: =IF(M12<>"Yes","",COUNTIF($M$5:M12,"Yes")) | O12: =IF(OR(A12="",E12="Completed",G12="",G12<TODAY(),G12>TODAY()+14),"",COUNTIFS($G$5:G12,">="&TODAY(),$G$5:G12,"<="&TODAY()+14,$E$5:E12,"<>Completed",$A$5:A12,"<>")) | P12: =IF(A12="","",IF(E12="Completed",1,N(H12)))
A13: Asset list from client | B13: Q3 Client Launch | C13: Jordan Blake | D13: High | E13: Waiting | F13: 46235 | G13: 46242 | H13: 0.5 | I13: 2 | J13: 1 | K13: Logos still missing | L13: =IF(OR(A13="",G13=""),"",G13-TODAY()) | M13: =IF(A13="","",IF(AND(G13<>"",G13<TODAY(),E13<>"Completed"),"Yes","")) | N13: =IF(M13<>"Yes","",COUNTIF($M$5:M13,"Yes")) | O13: =IF(OR(A13="",E13="Completed",G13="",G13<TODAY(),G13>TODAY()+14),"",COUNTIFS($G$5:G13,">="&TODAY(),$G$5:G13,"<="&TODAY()+14,$E$5:E13,"<>Completed",$A$5:A13,"<>")) | P13: =IF(A13="","",IF(E13="Completed",1,N(H13)))
A14: Landing page copy | B14: Q3 Client Launch | C14: Maya Chen | D14: High | E14: Completed | F14: 46235 | G14: 46244 | H14: 1 | I14: 8 | J14: 7 | L14: =IF(OR(A14="",G14=""),"",G14-TODAY()) | M14: =IF(A14="","",IF(AND(G14<>"",G14<TODAY(),E14<>"Completed"),"Yes","")) | N14: =IF(M14<>"Yes","",COUNTIF($M$5:M14,"Yes")) | O14: =IF(OR(A14="",E14="Completed",G14="",G14<TODAY(),G14>TODAY()+14),"",COUNTIFS($G$5:G14,">="&TODAY(),$G$5:G14,"<="&TODAY()+14,$E$5:E14,"<>Completed",$A$5:A14,"<>")) | P14: =IF(A14="","",IF(E14="Completed",1,N(H14)))
A15: Landing page build | B15: Q3 Client Launch | C15: Jordan Blake | D15: High | E15: In Progress | F15: 46242 | G15: 46254 | H15: 0.55 | I15: 16 | J15: 10 | L15: =IF(OR(A15="",G15=""),"",G15-TODAY()) | M15: =IF(A15="","",IF(AND(G15<>"",G15<TODAY(),E15<>"Completed"),"Yes","")) | N15: =IF(M15<>"Yes","",COUNTIF($M$5:M15,"Yes")) | O15: =IF(OR(A15="",E15="Completed",G15="",G15<TODAY(),G15>TODAY()+14),"",COUNTIFS($G$5:G15,">="&TODAY(),$G$5:G15,"<="&TODAY()+14,$E$5:E15,"<>Completed",$A$5:A15,"<>")) | P15: =IF(A15="","",IF(E15="Completed",1,N(H15)))
A16: Email sequence | B16: Q3 Client Launch | C16: Riley Patel | D16: Medium | E16: In Progress | F16: 46245 | G16: 46252 | H16: 0.3 | I16: 8 | J16: 3 | L16: =IF(OR(A16="",G16=""),"",G16-TODAY()) | M16: =IF(A16="","",IF(AND(G16<>"",G16<TODAY(),E16<>"Completed"),"Yes","")) | N16: =IF(M16<>"Yes","",COUNTIF($M$5:M16,"Yes")) | O16: =IF(OR(A16="",E16="Completed",G16="",G16<TODAY(),G16>TODAY()+14),"",COUNTIFS($G$5:G16,">="&TODAY(),$G$5:G16,"<="&TODAY()+14,$E$5:E16,"<>Completed",$A$5:A16,"<>")) | P16: =IF(A16="","",IF(E16="Completed",1,N(H16)))
A17: QA / UAT | B17: Q3 Client Launch | C17: Sam Okonkwo | D17: High | E17: Not Started | F17: 46253 | G17: 46259 | H17: 0 | I17: 6 | L17: =IF(OR(A17="",G17=""),"",G17-TODAY()) | M17: =IF(A17="","",IF(AND(G17<>"",G17<TODAY(),E17<>"Completed"),"Yes","")) | N17: =IF(M17<>"Yes","",COUNTIF($M$5:M17,"Yes")) | O17: =IF(OR(A17="",E17="Completed",G17="",G17<TODAY(),G17>TODAY()+14),"",COUNTIFS($G$5:G17,">="&TODAY(),$G$5:G17,"<="&TODAY()+14,$E$5:E17,"<>Completed",$A$5:A17,"<>")) | P17: =IF(A17="","",IF(E17="Completed",1,N(H17)))
A18: Launch checklist | B18: Q3 Client Launch | C18: Jordan Blake | D18: High | E18: Not Started | F18: 46260 | G18: 46262 | H18: 0 | I18: 3 | L18: =IF(OR(A18="",G18=""),"",G18-TODAY()) | M18: =IF(A18="","",IF(AND(G18<>"",G18<TODAY(),E18<>"Completed"),"Yes","")) | N18: =IF(M18<>"Yes","",COUNTIF($M$5:M18,"Yes")) | O18: =IF(OR(A18="",E18="Completed",G18="",G18<TODAY(),G18>TODAY()+14),"",COUNTIFS($G$5:G18,">="&TODAY(),$G$5:G18,"<="&TODAY()+14,$E$5:E18,"<>Completed",$A$5:A18,"<>")) | P18: =IF(A18="","",IF(E18="Completed",1,N(H18)))
A19: Role scorecard | B19: Hiring Pipeline | C19: Sam Okonkwo | D19: Medium | E19: Completed | F19: 46235 | G19: 46238 | H19: 1 | I19: 4 | J19: 3 | L19: =IF(OR(A19="",G19=""),"",G19-TODAY()) | M19: =IF(A19="","",IF(AND(G19<>"",G19<TODAY(),E19<>"Completed"),"Yes","")) | N19: =IF(M19<>"Yes","",COUNTIF($M$5:M19,"Yes")) | O19: =IF(OR(A19="",E19="Completed",G19="",G19<TODAY(),G19>TODAY()+14),"",COUNTIFS($G$5:G19,">="&TODAY(),$G$5:G19,"<="&TODAY()+14,$E$5:E19,"<>Completed",$A$5:A19,"<>")) | P19: =IF(A19="","",IF(E19="Completed",1,N(H19)))
A20: Post the role | B20: Hiring Pipeline | C20: Sam Okonkwo | D20: Medium | E20: Completed | F20: 46238 | G20: 46239 | H20: 1 | I20: 2 | J20: 2 | L20: =IF(OR(A20="",G20=""),"",G20-TODAY()) | M20: =IF(A20="","",IF(AND(G20<>"",G20<TODAY(),E20<>"Completed"),"Yes","")) | N20: =IF(M20<>"Yes","",COUNTIF($M$5:M20,"Yes")) | O20: =IF(OR(A20="",E20="Completed",G20="",G20<TODAY(),G20>TODAY()+14),"",COUNTIFS($G$5:G20,">="&TODAY(),$G$5:G20,"<="&TODAY()+14,$E$5:E20,"<>Completed",$A$5:A20,"<>")) | P20: =IF(A20="","",IF(E20="Completed",1,N(H20)))
A21: Screen resumes | B21: Hiring Pipeline | C21: Sam Okonkwo | D21: Medium | E21: On Hold | F21: 46240 | G21: 46254 | H21: 0.2 | I21: 8 | J21: 2 | K21: Budget hold | L21: =IF(OR(A21="",G21=""),"",G21-TODAY()) | M21: =IF(A21="","",IF(AND(G21<>"",G21<TODAY(),E21<>"Completed"),"Yes","")) | N21: =IF(M21<>"Yes","",COUNTIF($M$5:M21,"Yes")) | O21: =IF(OR(A21="",E21="Completed",G21="",G21<TODAY(),G21>TODAY()+14),"",COUNTIFS($G$5:G21,">="&TODAY(),$G$5:G21,"<="&TODAY()+14,$E$5:E21,"<>Completed",$A$5:A21,"<>")) | P21: =IF(A21="","",IF(E21="Completed",1,N(H21)))
A22: First interviews | B22: Hiring Pipeline | C22: Maya Chen | D22: Medium | E22: On Hold | F22: 46252 | G22: 46270 | H22: 0 | I22: 10 | L22: =IF(OR(A22="",G22=""),"",G22-TODAY()) | M22: =IF(A22="","",IF(AND(G22<>"",G22<TODAY(),E22<>"Completed"),"Yes","")) | N22: =IF(M22<>"Yes","",COUNTIF($M$5:M22,"Yes")) | O22: =IF(OR(A22="",E22="Completed",G22="",G22<TODAY(),G22>TODAY()+14),"",COUNTIFS($G$5:G22,">="&TODAY(),$G$5:G22,"<="&TODAY()+14,$E$5:E22,"<>Completed",$A$5:A22,"<>")) | P22: =IF(A22="","",IF(E22="Completed",1,N(H22)))
A23: Competitive scan | B23: Brand Guidelines | C23: Riley Patel | D23: Low | E23: Not Started | F23: 46266 | G23: 46277 | H23: 0 | I23: 8 | L23: =IF(OR(A23="",G23=""),"",G23-TODAY()) | M23: =IF(A23="","",IF(AND(G23<>"",G23<TODAY(),E23<>"Completed"),"Yes","")) | N23: =IF(M23<>"Yes","",COUNTIF($M$5:M23,"Yes")) | O23: =IF(OR(A23="",E23="Completed",G23="",G23<TODAY(),G23>TODAY()+14),"",COUNTIFS($G$5:G23,">="&TODAY(),$G$5:G23,"<="&TODAY()+14,$E$5:E23,"<>Completed",$A$5:A23,"<>")) | P23: =IF(A23="","",IF(E23="Completed",1,N(H23)))
A24: Type and color system | B24: Brand Guidelines | C24: Riley Patel | D24: Medium | E24: Not Started | F24: 46280 | G24: 46298 | H24: 0 | I24: 16 | L24: =IF(OR(A24="",G24=""),"",G24-TODAY()) | M24: =IF(A24="","",IF(AND(G24<>"",G24<TODAY(),E24<>"Completed"),"Yes","")) | N24: =IF(M24<>"Yes","",COUNTIF($M$5:M24,"Yes")) | O24: =IF(OR(A24="",E24="Completed",G24="",G24<TODAY(),G24>TODAY()+14),"",COUNTIFS($G$5:G24,">="&TODAY(),$G$5:G24,"<="&TODAY()+14,$E$5:E24,"<>Completed",$A$5:A24,"<>")) | P24: =IF(A24="","",IF(E24="Completed",1,N(H24)))
A25: Component examples | B25: Brand Guidelines | C25: Jordan Blake | D25: Low | E25: Not Started | F25: 46301 | G25: 46319 | H25: 0 | I25: 12 | L25: =IF(OR(A25="",G25=""),"",G25-TODAY()) | M25: =IF(A25="","",IF(AND(G25<>"",G25<TODAY(),E25<>"Completed"),"Yes","")) | N25: =IF(M25<>"Yes","",COUNTIF($M$5:M25,"Yes")) | O25: =IF(OR(A25="",E25="Completed",G25="",G25<TODAY(),G25>TODAY()+14),"",COUNTIFS($G$5:G25,">="&TODAY(),$G$5:G25,"<="&TODAY()+14,$E$5:E25,"<>Completed",$A$5:A25,"<>")) | P25: =IF(A25="","",IF(E25="Completed",1,N(H25)))
A26: Internal review deck | B26: Brand Guidelines | C26: Riley Patel | D26: Low | E26: Not Started | F26: 46315 | G26: 46326 | H26: 0 | I26: 6 | L26: =IF(OR(A26="",G26=""),"",G26-TODAY()) | M26: =IF(A26="","",IF(AND(G26<>"",G26<TODAY(),E26<>"Completed"),"Yes","")) | N26: =IF(M26<>"Yes","",COUNTIF($M$5:M26,"Yes")) | O26: =IF(OR(A26="",E26="Completed",G26="",G26<TODAY(),G26>TODAY()+14),"",COUNTIFS($G$5:G26,">="&TODAY(),$G$5:G26,"<="&TODAY()+14,$E$5:E26,"<>Completed",$A$5:A26,"<>")) | P26: =IF(A26="","",IF(E26="Completed",1,N(H26)))
L27: =IF(OR(A27="",G27=""),"",G27-TODAY()) | M27: =IF(A27="","",IF(AND(G27<>"",G27<TODAY(),E27<>"Completed"),"Yes","")) | N27: =IF(M27<>"Yes","",COUNTIF($M$5:M27,"Yes")) | O27: =IF(OR(A27="",E27="Completed",G27="",G27<TODAY(),G27>TODAY()+14),"",COUNTIFS($G$5:G27,">="&TODAY(),$G$5:G27,"<="&TODAY()+14,$E$5:E27,"<>Completed",$A$5:A27,"<>")) | P27: =IF(A27="","",IF(E27="Completed",1,N(H27)))
L28: =IF(OR(A28="",G28=""),"",G28-TODAY()) | M28: =IF(A28="","",IF(AND(G28<>"",G28<TODAY(),E28<>"Completed"),"Yes","")) | N28: =IF(M28<>"Yes","",COUNTIF($M$5:M28,"Yes")) | O28: =IF(OR(A28="",E28="Completed",G28="",G28<TODAY(),G28>TODAY()+14),"",COUNTIFS($G$5:G28,">="&TODAY(),$G$5:G28,"<="&TODAY()+14,$E$5:E28,"<>Completed",$A$5:A28,"<>")) | P28: =IF(A28="","",IF(E28="Completed",1,N(H28)))
L29: =IF(OR(A29="",G29=""),"",G29-TODAY()) | M29: =IF(A29="","",IF(AND(G29<>"",G29<TODAY(),E29<>"Completed"),"Yes","")) | N29: =IF(M29<>"Yes","",COUNTIF($M$5:M29,"Yes")) | O29: =IF(OR(A29="",E29="Completed",G29="",G29<TODAY(),G29>TODAY()+14),"",COUNTIFS($G$5:G29,">="&TODAY(),$G$5:G29,"<="&TODAY()+14,$E$5:E29,"<>Completed",$A$5:A29,"<>")) | P29: =IF(A29="","",IF(E29="Completed",1,N(H29)))
L30: =IF(OR(A30="",G30=""),"",G30-TODAY()) | M30: =IF(A30="","",IF(AND(G30<>"",G30<TODAY(),E30<>"Completed"),"Yes","")) | N30: =IF(M30<>"Yes","",COUNTIF($M$5:M30,"Yes")) | O30: =IF(OR(A30="",E30="Completed",G30="",G30<TODAY(),G30>TODAY()+14),"",COUNTIFS($G$5:G30,">="&TODAY(),$G$5:G30,"<="&TODAY()+14,$E$5:E30,"<>Completed",$A$5:A30,"<>")) | P30: =IF(A30="","",IF(E30="Completed",1,N(H30)))
L31: =IF(OR(A31="",G31=""),"",G31-TODAY()) | M31: =IF(A31="","",IF(AND(G31<>"",G31<TODAY(),E31<>"Completed"),"Yes","")) | N31: =IF(M31<>"Yes","",COUNTIF($M$5:M31,"Yes")) | O31: =IF(OR(A31="",E31="Completed",G31="",G31<TODAY(),G31>TODAY()+14),"",COUNTIFS($G$5:G31,">="&TODAY(),$G$5:G31,"<="&TODAY()+14,$E$5:E31,"<>Completed",$A$5:A31,"<>")) | P31: =IF(A31="","",IF(E31="Completed",1,N(H31)))
L32: =IF(OR(A32="",G32=""),"",G32-TODAY()) | M32: =IF(A32="","",IF(AND(G32<>"",G32<TODAY(),E32<>"Completed"),"Yes","")) | N32: =IF(M32<>"Yes","",COUNTIF($M$5:M32,"Yes")) | O32: =IF(OR(A32="",E32="Completed",G32="",G32<TODAY(),G32>TODAY()+14),"",COUNTIFS($G$5:G32,">="&TODAY(),$G$5:G32,"<="&TODAY()+14,$E$5:E32,"<>Completed",$A$5:A32,"<>")) | P32: =IF(A32="","",IF(E32="Completed",1,N(H32)))
L33: =IF(OR(A33="",G33=""),"",G33-TODAY()) | M33: =IF(A33="","",IF(AND(G33<>"",G33<TODAY(),E33<>"Completed"),"Yes","")) | N33: =IF(M33<>"Yes","",COUNTIF($M$5:M33,"Yes")) | O33: =IF(OR(A33="",E33="Completed",G33="",G33<TODAY(),G33>TODAY()+14),"",COUNTIFS($G$5:G33,">="&TODAY(),$G$5:G33,"<="&TODAY()+14,$E$5:E33,"<>Completed",$A$5:A33,"<>")) | P33: =IF(A33="","",IF(E33="Completed",1,N(H33)))
L34: =IF(OR(A34="",G34=""),"",G34-TODAY()) | M34: =IF(A34="","",IF(AND(G34<>"",G34<TODAY(),E34<>"Completed"),"Yes","")) | N34: =IF(M34<>"Yes","",COUNTIF($M$5:M34,"Yes")) | O34: =IF(OR(A34="",E34="Completed",G34="",G34<TODAY(),G34>TODAY()+14),"",COUNTIFS($G$5:G34,">="&TODAY(),$G$5:G34,"<="&TODAY()+14,$E$5:E34,"<>Completed",$A$5:A34,"<>")) | P34: =IF(A34="","",IF(E34="Completed",1,N(H34)))
L35: =IF(OR(A35="",G35=""),"",G35-TODAY()) | M35: =IF(A35="","",IF(AND(G35<>"",G35<TODAY(),E35<>"Completed"),"Yes","")) | N35: =IF(M35<>"Yes","",COUNTIF($M$5:M35,"Yes")) | O35: =IF(OR(A35="",E35="Completed",G35="",G35<TODAY(),G35>TODAY()+14),"",COUNTIFS($G$5:G35,">="&TODAY(),$G$5:G35,"<="&TODAY()+14,$E$5:E35,"<>Completed",$A$5:A35,"<>")) | P35: =IF(A35="","",IF(E35="Completed",1,N(H35)))
L36: =IF(OR(A36="",G36=""),"",G36-TODAY()) | M36: =IF(A36="","",IF(AND(G36<>"",G36<TODAY(),E36<>"Completed"),"Yes","")) | N36: =IF(M36<>"Yes","",COUNTIF($M$5:M36,"Yes")) | O36: =IF(OR(A36="",E36="Completed",G36="",G36<TODAY(),G36>TODAY()+14),"",COUNTIFS($G$5:G36,">="&TODAY(),$G$5:G36,"<="&TODAY()+14,$E$5:E36,"<>Completed",$A$5:A36,"<>")) | P36: =IF(A36="","",IF(E36="Completed",1,N(H36)))
L37: =IF(OR(A37="",G37=""),"",G37-TODAY()) | M37: =IF(A37="","",IF(AND(G37<>"",G37<TODAY(),E37<>"Completed"),"Yes","")) | N37: =IF(M37<>"Yes","",COUNTIF($M$5:M37,"Yes")) | O37: =IF(OR(A37="",E37="Completed",G37="",G37<TODAY(),G37>TODAY()+14),"",COUNTIFS($G$5:G37,">="&TODAY(),$G$5:G37,"<="&TODAY()+14,$E$5:E37,"<>Completed",$A$5:A37,"<>")) | P37: =IF(A37="","",IF(E37="Completed",1,N(H37)))
L38: =IF(OR(A38="",G38=""),"",G38-TODAY()) | M38: =IF(A38="","",IF(AND(G38<>"",G38<TODAY(),E38<>"Completed"),"Yes","")) | N38: =IF(M38<>"Yes","",COUNTIF($M$5:M38,"Yes")) | O38: =IF(OR(A38="",E38="Completed",G38="",G38<TODAY(),G38>TODAY()+14),"",COUNTIFS($G$5:G38,">="&TODAY(),$G$5:G38,"<="&TODAY()+14,$E$5:E38,"<>Completed",$A$5:A38,"<>")) | P38: =IF(A38="","",IF(E38="Completed",1,N(H38)))
... L84: =IF(OR(A84="",G84=""),"",G84-TODAY()) | M84: =IF(A84="","",IF(AND(G84<>"",G84<TODAY(),E84<>"Completed"),"Yes","")) | N84: =IF(M84<>"Yes","",COUNTIF($M$5:M84,"Yes")) | O84: =IF(OR(A84="",E84="Completed",G84="",G84<TODAY(),G84>TODAY()+14),"",COUNTIFS($G$5:G84,">="&TODAY(),$G$5:G84,"<="&TODAY()+14,$E$5:E84,"<>Completed",$A$5:A84,"<>")) | P84: =IF(A84="","",IF(E84="Completed",1,N(H84)))
A85: TOTAL | I85: =SUM(I5:I84) | J85: =SUM(J5:J84)
...

Sheet Timeline
A1: Timeline / Gantt
A2: Timeline start (Monday) | D2: 46244 | E2: Each column is one week. A block means the task is scheduled that week. Color follows Status. First 40 tasks from the Task List.
A3: ="Weeks of "&TEXT(TimelineStart,"mmm d, yyyy")&" – "&TEXT(TimelineStart+7*17,"mmm d, yyyy")
A4: Task | B4: Project | C4: Start | D4: Due | E4: Status | F4: =TimelineStart+0*7 | G4: =TimelineStart+1*7 | H4: =TimelineStart+2*7 | I4: =TimelineStart+3*7 | J4: =TimelineStart+4*7 | K4: =TimelineStart+5*7 | L4: =TimelineStart+6*7 | M4: =TimelineStart+7*7 | N4: =TimelineStart+8*7 | O4: =TimelineStart+9*7 | P4: =TimelineStart+10*7 | Q4: =TimelineStart+11*7 | R4: =TimelineStart+12*7 | S4: =TimelineStart+13*7 | T4: =TimelineStart+14*7 | U4: =TimelineStart+15*7 | V4: =TimelineStart+16*7 | W4: =TimelineStart+17*7
A5: =IF('Task List'!A5="","",'Task List'!A5) | B5: =IF(A5="","",'Task List'!B5) | C5: =IF(A5="","",'Task List'!F5) | D5: =IF(A5="","",'Task List'!G5) | E5: =IF(A5="","",'Task List'!E5) | F5: =IF(OR(A5="",C5="",D5=""),"",IF(AND(C5<=F$4+6,D5>=F$4),"█","")) | G5: =IF(OR(A5="",C5="",D5=""),"",IF(AND(C5<=G$4+6,D5>=G$4),"█","")) | H5: =IF(OR(A5="",C5="",D5=""),"",IF(AND(C5<=H$4+6,D5>=H$4),"█","")) | I5: =IF(OR(A5="",C5="",D5=""),"",IF(AND(C5<=I$4+6,D5>=I$4),"█","")) | J5: =IF(OR(A5="",C5="",D5=""),"",IF(AND(C5<=J$4+6,D5>=J$4),"█","")) | K5: =IF(OR(A5="",C5="",D5=""),"",IF(AND(C5<=K$4+6,D5>=K$4),"█","")) | L5: =IF(OR(A5="",C5="",D5=""),"",IF(AND(C5<=L$4+6,D5>=L$4),"█","")) | M5: =IF(OR(A5="",C5="",D5=""),"",IF(AND(C5<=M$4+6,D5>=M$4),"█","")) | N5: =IF(OR(A5="",C5="",D5=""),"",IF(AND(C5<=N$4+6,D5>=N$4),"█","")) | O5: =IF(OR(A5="",C5="",D5=""),"",IF(AND(C5<=O$4+6,D5>=O$4),"█","")) | P5: =IF(OR(A5="",C5="",D5=""),"",IF(AND(C5<=P$4+6,D5>=P$4),"█","")) | Q5: =IF(OR(A5="",C5="",D5=""),"",IF(AND(C5<=Q$4+6,D5>=Q$4),"█","")) | R5: =IF(OR(A5="",C5="",D5=""),"",IF(AND(C5<=R$4+6,D5>=R$4),"█","")) | S5: =IF(OR(A5="",C5="",D5=""),"",IF(AND(C5<=S$4+6,D5>=S$4),"█","")) | T5: =IF(OR(A5="",C5="",D5=""),"",IF(AND(C5<=T$4+6,D5>=T$4),"█","")) | U5: =IF(OR(A5="",C5="",D5=""),"",IF(AND(C5<=U$4+6,D5>=U$4),"█","")) | V5: =IF(OR(A5="",C5="",D5=""),"",IF(AND(C5<=V$4+6,D5>=V$4),"█","")) | W5: =IF(OR(A5="",C5="",D5=""),"",IF(AND(C5<=W$4+6,D5>=W$4),"█",""))
A6: =IF('Task List'!A6="","",'Task List'!A6) | B6: =IF(A6="","",'Task List'!B6) | C6: =IF(A6="","",'Task List'!F6) | D6: =IF(A6="","",'Task List'!G6) | E6: =IF(A6="","",'Task List'!E6) | F6: =IF(OR(A6="",C6="",D6=""),"",IF(AND(C6<=F$4+6,D6>=F$4),"█","")) | G6: =IF(OR(A6="",C6="",D6=""),"",IF(AND(C6<=G$4+6,D6>=G$4),"█","")) | H6: =IF(OR(A6="",C6="",D6=""),"",IF(AND(C6<=H$4+6,D6>=H$4),"█","")) | I6: =IF(OR(A6="",C6="",D6=""),"",IF(AND(C6<=I$4+6,D6>=I$4),"█","")) | J6: =IF(OR(A6="",C6="",D6=""),"",IF(AND(C6<=J$4+6,D6>=J$4),"█","")) | K6: =IF(OR(A6="",C6="",D6=""),"",IF(AND(C6<=K$4+6,D6>=K$4),"█","")) | L6: =IF(OR(A6="",C6="",D6=""),"",IF(AND(C6<=L$4+6,D6>=L$4),"█","")) | M6: =IF(OR(A6="",C6="",D6=""),"",IF(AND(C6<=M$4+6,D6>=M$4),"█","")) | N6: =IF(OR(A6="",C6="",D6=""),"",IF(AND(C6<=N$4+6,D6>=N$4),"█","")) | O6: =IF(OR(A6="",C6="",D6=""),"",IF(AND(C6<=O$4+6,D6>=O$4),"█","")) | P6: =IF(OR(A6="",C6="",D6=""),"",IF(AND(C6<=P$4+6,D6>=P$4),"█","")) | Q6: =IF(OR(A6="",C6="",D6=""),"",IF(AND(C6<=Q$4+6,D6>=Q$4),"█","")) | R6: =IF(OR(A6="",C6="",D6=""),"",IF(AND(C6<=R$4+6,D6>=R$4),"█","")) | S6: =IF(OR(A6="",C6="",D6=""),"",IF(AND(C6<=S$4+6,D6>=S$4),"█","")) | T6: =IF(OR(A6="",C6="",D6=""),"",IF(AND(C6<=T$4+6,D6>=T$4),"█","")) | U6: =IF(OR(A6="",C6="",D6=""),"",IF(AND(C6<=U$4+6,D6>=U$4),"█","")) | V6: =IF(OR(A6="",C6="",D6=""),"",IF(AND(C6<=V$4+6,D6>=V$4),"█","")) | W6: =IF(OR(A6="",C6="",D6=""),"",IF(AND(C6<=W$4+6,D6>=W$4),"█",""))
A7: =IF('Task List'!A7="","",'Task List'!A7) | B7: =IF(A7="","",'Task List'!B7) | C7: =IF(A7="","",'Task List'!F7) | D7: =IF(A7="","",'Task List'!G7) | E7: =IF(A7="","",'Task List'!E7) | F7: =IF(OR(A7="",C7="",D7=""),"",IF(AND(C7<=F$4+6,D7>=F$4),"█","")) | G7: =IF(OR(A7="",C7="",D7=""),"",IF(AND(C7<=G$4+6,D7>=G$4),"█","")) | H7: =IF(OR(A7="",C7="",D7=""),"",IF(AND(C7<=H$4+6,D7>=H$4),"█","")) | I7: =IF(OR(A7="",C7="",D7=""),"",IF(AND(C7<=I$4+6,D7>=I$4),"█","")) | J7: =IF(OR(A7="",C7="",D7=""),"",IF(AND(C7<=J$4+6,D7>=J$4),"█","")) | K7: =IF(OR(A7="",C7="",D7=""),"",IF(AND(C7<=K$4+6,D7>=K$4),"█","")) | L7: =IF(OR(A7="",C7="",D7=""),"",IF(AND(C7<=L$4+6,D7>=L$4),"█","")) | M7: =IF(OR(A7="",C7="",D7=""),"",IF(AND(C7<=M$4+6,D7>=M$4),"█","")) | N7: =IF(OR(A7="",C7="",D7=""),"",IF(AND(C7<=N$4+6,D7>=N$4),"█","")) | O7: =IF(OR(A7="",C7="",D7=""),"",IF(AND(C7<=O$4+6,D7>=O$4),"█","")) | P7: =IF(OR(A7="",C7="",D7=""),"",IF(AND(C7<=P$4+6,D7>=P$4),"█","")) | Q7: =IF(OR(A7="",C7="",D7=""),"",IF(AND(C7<=Q$4+6,D7>=Q$4),"█","")) | R7: =IF(OR(A7="",C7="",D7=""),"",IF(AND(C7<=R$4+6,D7>=R$4),"█","")) | S7: =IF(OR(A7="",C7="",D7=""),"",IF(AND(C7<=S$4+6,D7>=S$4),"█","")) | T7: =IF(OR(A7="",C7="",D7=""),"",IF(AND(C7<=T$4+6,D7>=T$4),"█","")) | U7: =IF(OR(A7="",C7="",D7=""),"",IF(AND(C7<=U$4+6,D7>=U$4),"█","")) | V7: =IF(OR(A7="",C7="",D7=""),"",IF(AND(C7<=V$4+6,D7>=V$4),"█","")) | W7: =IF(OR(A7="",C7="",D7=""),"",IF(AND(C7<=W$4+6,D7>=W$4),"█",""))
A8: =IF('Task List'!A8="","",'Task List'!A8) | B8: =IF(A8="","",'Task List'!B8) | C8: =IF(A8="","",'Task List'!F8) | D8: =IF(A8="","",'Task List'!G8) | E8: =IF(A8="","",'Task List'!E8) | F8: =IF(OR(A8="",C8="",D8=""),"",IF(AND(C8<=F$4+6,D8>=F$4),"█","")) | G8: =IF(OR(A8="",C8="",D8=""),"",IF(AND(C8<=G$4+6,D8>=G$4),"█","")) | H8: =IF(OR(A8="",C8="",D8=""),"",IF(AND(C8<=H$4+6,D8>=H$4),"█","")) | I8: =IF(OR(A8="",C8="",D8=""),"",IF(AND(C8<=I$4+6,D8>=I$4),"█","")) | J8: =IF(OR(A8="",C8="",D8=""),"",IF(AND(C8<=J$4+6,D8>=J$4),"█","")) | K8: =IF(OR(A8="",C8="",D8=""),"",IF(AND(C8<=K$4+6,D8>=K$4),"█","")) | L8: =IF(OR(A8="",C8="",D8=""),"",IF(AND(C8<=L$4+6,D8>=L$4),"█","")) | M8: =IF(OR(A8="",C8="",D8=""),"",IF(AND(C8<=M$4+6,D8>=M$4),"█","")) | N8: =IF(OR(A8="",C8="",D8=""),"",IF(AND(C8<=N$4+6,D8>=N$4),"█","")) | O8: =IF(OR(A8="",C8="",D8=""),"",IF(AND(C8<=O$4+6,D8>=O$4),"█","")) | P8: =IF(OR(A8="",C8="",D8=""),"",IF(AND(C8<=P$4+6,D8>=P$4),"█","")) | Q8: =IF(OR(A8="",C8="",D8=""),"",IF(AND(C8<=Q$4+6,D8>=Q$4),"█","")) | R8: =IF(OR(A8="",C8="",D8=""),"",IF(AND(C8<=R$4+6,D8>=R$4),"█","")) | S8: =IF(OR(A8="",C8="",D8=""),"",IF(AND(C8<=S$4+6,D8>=S$4),"█","")) | T8: =IF(OR(A8="",C8="",D8=""),"",IF(AND(C8<=T$4+6,D8>=T$4),"█","")) | U8: =IF(OR(A8="",C8="",D8=""),"",IF(AND(C8<=U$4+6,D8>=U$4),"█","")) | V8: =IF(OR(A8="",C8="",D8=""),"",IF(AND(C8<=V$4+6,D8>=V$4),"█","")) | W8: =IF(OR(A8="",C8="",D8=""),"",IF(AND(C8<=W$4+6,D8>=W$4),"█",""))
A9: =IF('Task List'!A9="","",'Task List'!A9) | B9: =IF(A9="","",'Task List'!B9) | C9: =IF(A9="","",'Task List'!F9) | D9: =IF(A9="","",'Task List'!G9) | E9: =IF(A9="","",'Task List'!E9) | F9: =IF(OR(A9="",C9="",D9=""),"",IF(AND(C9<=F$4+6,D9>=F$4),"█","")) | G9: =IF(OR(A9="",C9="",D9=""),"",IF(AND(C9<=G$4+6,D9>=G$4),"█","")) | H9: =IF(OR(A9="",C9="",D9=""),"",IF(AND(C9<=H$4+6,D9>=H$4),"█","")) | I9: =IF(OR(A9="",C9="",D9=""),"",IF(AND(C9<=I$4+6,D9>=I$4),"█","")) | J9: =IF(OR(A9="",C9="",D9=""),"",IF(AND(C9<=J$4+6,D9>=J$4),"█","")) | K9: =IF(OR(A9="",C9="",D9=""),"",IF(AND(C9<=K$4+6,D9>=K$4),"█","")) | L9: =IF(OR(A9="",C9="",D9=""),"",IF(AND(C9<=L$4+6,D9>=L$4),"█","")) | M9: =IF(OR(A9="",C9="",D9=""),"",IF(AND(C9<=M$4+6,D9>=M$4),"█","")) | N9: =IF(OR(A9="",C9="",D9=""),"",IF(AND(C9<=N$4+6,D9>=N$4),"█","")) | O9: =IF(OR(A9="",C9="",D9=""),"",IF(AND(C9<=O$4+6,D9>=O$4),"█","")) | P9: =IF(OR(A9="",C9="",D9=""),"",IF(AND(C9<=P$4+6,D9>=P$4),"█","")) | Q9: =IF(OR(A9="",C9="",D9=""),"",IF(AND(C9<=Q$4+6,D9>=Q$4),"█","")) | R9: =IF(OR(A9="",C9="",D9=""),"",IF(AND(C9<=R$4+6,D9>=R$4),"█","")) | S9: =IF(OR(A9="",C9="",D9=""),"",IF(AND(C9<=S$4+6,D9>=S$4),"█","")) | T9: =IF(OR(A9="",C9="",D9=""),"",IF(AND(C9<=T$4+6,D9>=T$4),"█","")) | U9: =IF(OR(A9="",C9="",D9=""),"",IF(AND(C9<=U$4+6,D9>=U$4),"█","")) | V9: =IF(OR(A9="",C9="",D9=""),"",IF(AND(C9<=V$4+6,D9>=V$4),"█","")) | W9: =IF(OR(A9="",C9="",D9=""),"",IF(AND(C9<=W$4+6,D9>=W$4),"█",""))
A10: =IF('Task List'!A10="","",'Task List'!A10) | B10: =IF(A10="","",'Task List'!B10) | C10: =IF(A10="","",'Task List'!F10) | D10: =IF(A10="","",'Task List'!G10) | E10: =IF(A10="","",'Task List'!E10) | F10: =IF(OR(A10="",C10="",D10=""),"",IF(AND(C10<=F$4+6,D10>=F$4),"█","")) | G10: =IF(OR(A10="",C10="",D10=""),"",IF(AND(C10<=G$4+6,D10>=G$4),"█","")) | H10: =IF(OR(A10="",C10="",D10=""),"",IF(AND(C10<=H$4+6,D10>=H$4),"█","")) | I10: =IF(OR(A10="",C10="",D10=""),"",IF(AND(C10<=I$4+6,D10>=I$4),"█","")) | J10: =IF(OR(A10="",C10="",D10=""),"",IF(AND(C10<=J$4+6,D10>=J$4),"█","")) | K10: =IF(OR(A10="",C10="",D10=""),"",IF(AND(C10<=K$4+6,D10>=K$4),"█","")) | L10: =IF(OR(A10="",C10="",D10=""),"",IF(AND(C10<=L$4+6,D10>=L$4),"█","")) | M10: =IF(OR(A10="",C10="",D10=""),"",IF(AND(C10<=M$4+6,D10>=M$4),"█","")) | N10: =IF(OR(A10="",C10="",D10=""),"",IF(AND(C10<=N$4+6,D10>=N$4),"█","")) | O10: =IF(OR(A10="",C10="",D10=""),"",IF(AND(C10<=O$4+6,D10>=O$4),"█","")) | P10: =IF(OR(A10="",C10="",D10=""),"",IF(AND(C10<=P$4+6,D10>=P$4),"█","")) | Q10: =IF(OR(A10="",C10="",D10=""),"",IF(AND(C10<=Q$4+6,D10>=Q$4),"█","")) | R10: =IF(OR(A10="",C10="",D10=""),"",IF(AND(C10<=R$4+6,D10>=R$4),"█","")) | S10: =IF(OR(A10="",C10="",D10=""),"",IF(AND(C10<=S$4+6,D10>=S$4),"█","")) | T10: =IF(OR(A10="",C10="",D10=""),"",IF(AND(C10<=T$4+6,D10>=T$4),"█","")) | U10: =IF(OR(A10="",C10="",D10=""),"",IF(AND(C10<=U$4+6,D10>=U$4),"█","")) | V10: =IF(OR(A10="",C10="",D10=""),"",IF(AND(C10<=V$4+6,D10>=V$4),"█","")) | W10: =IF(OR(A10="",C10="",D10=""),"",IF(AND(C10<=W$4+6,D10>=W$4),"█",""))
A11: =IF('Task List'!A11="","",'Task List'!A11) | B11: =IF(A11="","",'Task List'!B11) | C11: =IF(A11="","",'Task List'!F11) | D11: =IF(A11="","",'Task List'!G11) | E11: =IF(A11="","",'Task List'!E11) | F11: =IF(OR(A11="",C11="",D11=""),"",IF(AND(C11<=F$4+6,D11>=F$4),"█","")) | G11: =IF(OR(A11="",C11="",D11=""),"",IF(AND(C11<=G$4+6,D11>=G$4),"█","")) | H11: =IF(OR(A11="",C11="",D11=""),"",IF(AND(C11<=H$4+6,D11>=H$4),"█","")) | I11: =IF(OR(A11="",C11="",D11=""),"",IF(AND(C11<=I$4+6,D11>=I$4),"█","")) | J11: =IF(OR(A11="",C11="",D11=""),"",IF(AND(C11<=J$4+6,D11>=J$4),"█","")) | K11: =IF(OR(A11="",C11="",D11=""),"",IF(AND(C11<=K$4+6,D11>=K$4),"█","")) | L11: =IF(OR(A11="",C11="",D11=""),"",IF(AND(C11<=L$4+6,D11>=L$4),"█","")) | M11: =IF(OR(A11="",C11="",D11=""),"",IF(AND(C11<=M$4+6,D11>=M$4),"█","")) | N11: =IF(OR(A11="",C11="",D11=""),"",IF(AND(C11<=N$4+6,D11>=N$4),"█","")) | O11: =IF(OR(A11="",C11="",D11=""),"",IF(AND(C11<=O$4+6,D11>=O$4),"█","")) | P11: =IF(OR(A11="",C11="",D11=""),"",IF(AND(C11<=P$4+6,D11>=P$4),"█","")) | Q11: =IF(OR(A11="",C11="",D11=""),"",IF(AND(C11<=Q$4+6,D11>=Q$4),"█","")) | R11: =IF(OR(A11="",C11="",D11=""),"",IF(AND(C11<=R$4+6,D11>=R$4),"█","")) | S11: =IF(OR(A11="",C11="",D11=""),"",IF(AND(C11<=S$4+6,D11>=S$4),"█","")) | T11: =IF(OR(A11="",C11="",D11=""),"",IF(AND(C11<=T$4+6,D11>=T$4),"█","")) | U11: =IF(OR(A11="",C11="",D11=""),"",IF(AND(C11<=U$4+6,D11>=U$4),"█","")) | V11: =IF(OR(A11="",C11="",D11=""),"",IF(AND(C11<=V$4+6,D11>=V$4),"█","")) | W11: =IF(OR(A11="",C11="",D11=""),"",IF(AND(C11<=W$4+6,D11>=W$4),"█",""))
A12: =IF('Task List'!A12="","",'Task List'!A12) | B12: =IF(A12="","",'Task List'!B12) | C12: =IF(A12="","",'Task List'!F12) | D12: =IF(A12="","",'Task List'!G12) | E12: =IF(A12="","",'Task List'!E12) | F12: =IF(OR(A12="",C12="",D12=""),"",IF(AND(C12<=F$4+6,D12>=F$4),"█","")) | G12: =IF(OR(A12="",C12="",D12=""),"",IF(AND(C12<=G$4+6,D12>=G$4),"█","")) | H12: =IF(OR(A12="",C12="",D12=""),"",IF(AND(C12<=H$4+6,D12>=H$4),"█","")) | I12: =IF(OR(A12="",C12="",D12=""),"",IF(AND(C12<=I$4+6,D12>=I$4),"█","")) | J12: =IF(OR(A12="",C12="",D12=""),"",IF(AND(C12<=J$4+6,D12>=J$4),"█","")) | K12: =IF(OR(A12="",C12="",D12=""),"",IF(AND(C12<=K$4+6,D12>=K$4),"█","")) | L12: =IF(OR(A12="",C12="",D12=""),"",IF(AND(C12<=L$4+6,D12>=L$4),"█","")) | M12: =IF(OR(A12="",C12="",D12=""),"",IF(AND(C12<=M$4+6,D12>=M$4),"█","")) | N12: =IF(OR(A12="",C12="",D12=""),"",IF(AND(C12<=N$4+6,D12>=N$4),"█","")) | O12: =IF(OR(A12="",C12="",D12=""),"",IF(AND(C12<=O$4+6,D12>=O$4),"█","")) | P12: =IF(OR(A12="",C12="",D12=""),"",IF(AND(C12<=P$4+6,D12>=P$4),"█","")) | Q12: =IF(OR(A12="",C12="",D12=""),"",IF(AND(C12<=Q$4+6,D12>=Q$4),"█","")) | R12: =IF(OR(A12="",C12="",D12=""),"",IF(AND(C12<=R$4+6,D12>=R$4),"█","")) | S12: =IF(OR(A12="",C12="",D12=""),"",IF(AND(C12<=S$4+6,D12>=S$4),"█","")) | T12: =IF(OR(A12="",C12="",D12=""),"",IF(AND(C12<=T$4+6,D12>=T$4),"█","")) | U12: =IF(OR(A12="",C12="",D12=""),"",IF(AND(C12<=U$4+6,D12>=U$4),"█","")) | V12: =IF(OR(A12="",C12="",D12=""),"",IF(AND(C12<=V$4+6,D12>=V$4),"█","")) | W12: =IF(OR(A12="",C12="",D12=""),"",IF(AND(C12<=W$4+6,D12>=W$4),"█",""))
A13: =IF('Task List'!A13="","",'Task List'!A13) | B13: =IF(A13="","",'Task List'!B13) | C13: =IF(A13="","",'Task List'!F13) | D13: =IF(A13="","",'Task List'!G13) | E13: =IF(A13="","",'Task List'!E13) | F13: =IF(OR(A13="",C13="",D13=""),"",IF(AND(C13<=F$4+6,D13>=F$4),"█","")) | G13: =IF(OR(A13="",C13="",D13=""),"",IF(AND(C13<=G$4+6,D13>=G$4),"█","")) | H13: =IF(OR(A13="",C13="",D13=""),"",IF(AND(C13<=H$4+6,D13>=H$4),"█","")) | I13: =IF(OR(A13="",C13="",D13=""),"",IF(AND(C13<=I$4+6,D13>=I$4),"█","")) | J13: =IF(OR(A13="",C13="",D13=""),"",IF(AND(C13<=J$4+6,D13>=J$4),"█","")) | K13: =IF(OR(A13="",C13="",D13=""),"",IF(AND(C13<=K$4+6,D13>=K$4),"█","")) | L13: =IF(OR(A13="",C13="",D13=""),"",IF(AND(C13<=L$4+6,D13>=L$4),"█","")) | M13: =IF(OR(A13="",C13="",D13=""),"",IF(AND(C13<=M$4+6,D13>=M$4),"█","")) | N13: =IF(OR(A13="",C13="",D13=""),"",IF(AND(C13<=N$4+6,D13>=N$4),"█","")) | O13: =IF(OR(A13="",C13="",D13=""),"",IF(AND(C13<=O$4+6,D13>=O$4),"█","")) | P13: =IF(OR(A13="",C13="",D13=""),"",IF(AND(C13<=P$4+6,D13>=P$4),"█","")) | Q13: =IF(OR(A13="",C13="",D13=""),"",IF(AND(C13<=Q$4+6,D13>=Q$4),"█","")) | R13: =IF(OR(A13="",C13="",D13=""),"",IF(AND(C13<=R$4+6,D13>=R$4),"█","")) | S13: =IF(OR(A13="",C13="",D13=""),"",IF(AND(C13<=S$4+6,D13>=S$4),"█","")) | T13: =IF(OR(A13="",C13="",D13=""),"",IF(AND(C13<=T$4+6,D13>=T$4),"█","")) | U13: =IF(OR(A13="",C13="",D13=""),"",IF(AND(C13<=U$4+6,D13>=U$4),"█","")) | V13: =IF(OR(A13="",C13="",D13=""),"",IF(AND(C13<=V$4+6,D13>=V$4),"█","")) | W13: =IF(OR(A13="",C13="",D13=""),"",IF(AND(C13<=W$4+6,D13>=W$4),"█",""))
A14: =IF('Task List'!A14="","",'Task List'!A14) | B14: =IF(A14="","",'Task List'!B14) | C14: =IF(A14="","",'Task List'!F14) | D14: =IF(A14="","",'Task List'!G14) | E14: =IF(A14="","",'Task List'!E14) | F14: =IF(OR(A14="",C14="",D14=""),"",IF(AND(C14<=F$4+6,D14>=F$4),"█","")) | G14: =IF(OR(A14="",C14="",D14=""),"",IF(AND(C14<=G$4+6,D14>=G$4),"█","")) | H14: =IF(OR(A14="",C14="",D14=""),"",IF(AND(C14<=H$4+6,D14>=H$4),"█","")) | I14: =IF(OR(A14="",C14="",D14=""),"",IF(AND(C14<=I$4+6,D14>=I$4),"█","")) | J14: =IF(OR(A14="",C14="",D14=""),"",IF(AND(C14<=J$4+6,D14>=J$4),"█","")) | K14: =IF(OR(A14="",C14="",D14=""),"",IF(AND(C14<=K$4+6,D14>=K$4),"█","")) | L14: =IF(OR(A14="",C14="",D14=""),"",IF(AND(C14<=L$4+6,D14>=L$4),"█","")) | M14: =IF(OR(A14="",C14="",D14=""),"",IF(AND(C14<=M$4+6,D14>=M$4),"█","")) | N14: =IF(OR(A14="",C14="",D14=""),"",IF(AND(C14<=N$4+6,D14>=N$4),"█","")) | O14: =IF(OR(A14="",C14="",D14=""),"",IF(AND(C14<=O$4+6,D14>=O$4),"█","")) | P14: =IF(OR(A14="",C14="",D14=""),"",IF(AND(C14<=P$4+6,D14>=P$4),"█","")) | Q14: =IF(OR(A14="",C14="",D14=""),"",IF(AND(C14<=Q$4+6,D14>=Q$4),"█","")) | R14: =IF(OR(A14="",C14="",D14=""),"",IF(AND(C14<=R$4+6,D14>=R$4),"█","")) | S14: =IF(OR(A14="",C14="",D14=""),"",IF(AND(C14<=S$4+6,D14>=S$4),"█","")) | T14: =IF(OR(A14="",C14="",D14=""),"",IF(AND(C14<=T$4+6,D14>=T$4),"█","")) | U14: =IF(OR(A14="",C14="",D14=""),"",IF(AND(C14<=U$4+6,D14>=U$4),"█","")) | V14: =IF(OR(A14="",C14="",D14=""),"",IF(AND(C14<=V$4+6,D14>=V$4),"█","")) | W14: =IF(OR(A14="",C14="",D14=""),"",IF(AND(C14<=W$4+6,D14>=W$4),"█",""))
A15: =IF('Task List'!A15="","",'Task List'!A15) | B15: =IF(A15="","",'Task List'!B15) | C15: =IF(A15="","",'Task List'!F15) | D15: =IF(A15="","",'Task List'!G15) | E15: =IF(A15="","",'Task List'!E15) | F15: =IF(OR(A15="",C15="",D15=""),"",IF(AND(C15<=F$4+6,D15>=F$4),"█","")) | G15: =IF(OR(A15="",C15="",D15=""),"",IF(AND(C15<=G$4+6,D15>=G$4),"█","")) | H15: =IF(OR(A15="",C15="",D15=""),"",IF(AND(C15<=H$4+6,D15>=H$4),"█","")) | I15: =IF(OR(A15="",C15="",D15=""),"",IF(AND(C15<=I$4+6,D15>=I$4),"█","")) | J15: =IF(OR(A15="",C15="",D15=""),"",IF(AND(C15<=J$4+6,D15>=J$4),"█","")) | K15: =IF(OR(A15="",C15="",D15=""),"",IF(AND(C15<=K$4+6,D15>=K$4),"█","")) | L15: =IF(OR(A15="",C15="",D15=""),"",IF(AND(C15<=L$4+6,D15>=L$4),"█","")) | M15: =IF(OR(A15="",C15="",D15=""),"",IF(AND(C15<=M$4+6,D15>=M$4),"█","")) | N15: =IF(OR(A15="",C15="",D15=""),"",IF(AND(C15<=N$4+6,D15>=N$4),"█","")) | O15: =IF(OR(A15="",C15="",D15=""),"",IF(AND(C15<=O$4+6,D15>=O$4),"█","")) | P15: =IF(OR(A15="",C15="",D15=""),"",IF(AND(C15<=P$4+6,D15>=P$4),"█","")) | Q15: =IF(OR(A15="",C15="",D15=""),"",IF(AND(C15<=Q$4+6,D15>=Q$4),"█","")) | R15: =IF(OR(A15="",C15="",D15=""),"",IF(AND(C15<=R$4+6,D15>=R$4),"█","")) | S15: =IF(OR(A15="",C15="",D15=""),"",IF(AND(C15<=S$4+6,D15>=S$4),"█","")) | T15: =IF(OR(A15="",C15="",D15=""),"",IF(AND(C15<=T$4+6,D15>=T$4),"█","")) | U15: =IF(OR(A15="",C15="",D15=""),"",IF(AND(C15<=U$4+6,D15>=U$4),"█","")) | V15: =IF(OR(A15="",C15="",D15=""),"",IF(AND(C15<=V$4+6,D15>=V$4),"█","")) | W15: =IF(OR(A15="",C15="",D15=""),"",IF(AND(C15<=W$4+6,D15>=W$4),"█",""))
A16: =IF('Task List'!A16="","",'Task List'!A16) | B16: =IF(A16="","",'Task List'!B16) | C16: =IF(A16="","",'Task List'!F16) | D16: =IF(A16="","",'Task List'!G16) | E16: =IF(A16="","",'Task List'!E16) | F16: =IF(OR(A16="",C16="",D16=""),"",IF(AND(C16<=F$4+6,D16>=F$4),"█","")) | G16: =IF(OR(A16="",C16="",D16=""),"",IF(AND(C16<=G$4+6,D16>=G$4),"█","")) | H16: =IF(OR(A16="",C16="",D16=""),"",IF(AND(C16<=H$4+6,D16>=H$4),"█","")) | I16: =IF(OR(A16="",C16="",D16=""),"",IF(AND(C16<=I$4+6,D16>=I$4),"█","")) | J16: =IF(OR(A16="",C16="",D16=""),"",IF(AND(C16<=J$4+6,D16>=J$4),"█","")) | K16: =IF(OR(A16="",C16="",D16=""),"",IF(AND(C16<=K$4+6,D16>=K$4),"█","")) | L16: =IF(OR(A16="",C16="",D16=""),"",IF(AND(C16<=L$4+6,D16>=L$4),"█","")) | M16: =IF(OR(A16="",C16="",D16=""),"",IF(AND(C16<=M$4+6,D16>=M$4),"█","")) | N16: =IF(OR(A16="",C16="",D16=""),"",IF(AND(C16<=N$4+6,D16>=N$4),"█","")) | O16: =IF(OR(A16="",C16="",D16=""),"",IF(AND(C16<=O$4+6,D16>=O$4),"█","")) | P16: =IF(OR(A16="",C16="",D16=""),"",IF(AND(C16<=P$4+6,D16>=P$4),"█","")) | Q16: =IF(OR(A16="",C16="",D16=""),"",IF(AND(C16<=Q$4+6,D16>=Q$4),"█","")) | R16: =IF(OR(A16="",C16="",D16=""),"",IF(AND(C16<=R$4+6,D16>=R$4),"█","")) | S16: =IF(OR(A16="",C16="",D16=""),"",IF(AND(C16<=S$4+6,D16>=S$4),"█","")) | T16: =IF(OR(A16="",C16="",D16=""),"",IF(AND(C16<=T$4+6,D16>=T$4),"█","")) | U16: =IF(OR(A16="",C16="",D16=""),"",IF(AND(C16<=U$4+6,D16>=U$4),"█","")) | V16: =IF(OR(A16="",C16="",D16=""),"",IF(AND(C16<=V$4+6,D16>=V$4),"█","")) | W16: =IF(OR(A16="",C16="",D16=""),"",IF(AND(C16<=W$4+6,D16>=W$4),"█",""))
... A44: =IF('Task List'!A44="","",'Task List'!A44) | B44: =IF(A44="","",'Task List'!B44) | C44: =IF(A44="","",'Task List'!F44) | D44: =IF(A44="","",'Task List'!G44) | E44: =IF(A44="","",'Task List'!E44) | F44: =IF(OR(A44="",C44="",D44=""),"",IF(AND(C44<=F$4+6,D44>=F$4),"█","")) | G44: =IF(OR(A44="",C44="",D44=""),"",IF(AND(C44<=G$4+6,D44>=G$4),"█","")) | H44: =IF(OR(A44="",C44="",D44=""),"",IF(AND(C44<=H$4+6,D44>=H$4),"█","")) | I44: =IF(OR(A44="",C44="",D44=""),"",IF(AND(C44<=I$4+6,D44>=I$4),"█","")) | J44: =IF(OR(A44="",C44="",D44=""),"",IF(AND(C44<=J$4+6,D44>=J$4),"█","")) | K44: =IF(OR(A44="",C44="",D44=""),"",IF(AND(C44<=K$4+6,D44>=K$4),"█","")) | L44: =IF(OR(A44="",C44="",D44=""),"",IF(AND(C44<=L$4+6,D44>=L$4),"█","")) | M44: =IF(OR(A44="",C44="",D44=""),"",IF(AND(C44<=M$4+6,D44>=M$4),"█","")) | N44: =IF(OR(A44="",C44="",D44=""),"",IF(AND(C44<=N$4+6,D44>=N$4),"█","")) | O44: =IF(OR(A44="",C44="",D44=""),"",IF(AND(C44<=O$4+6,D44>=O$4),"█","")) | P44: =IF(OR(A44="",C44="",D44=""),"",IF(AND(C44<=P$4+6,D44>=P$4),"█","")) | Q44: =IF(OR(A44="",C44="",D44=""),"",IF(AND(C44<=Q$4+6,D44>=Q$4),"█","")) | R44: =IF(OR(A44="",C44="",D44=""),"",IF(AND(C44<=R$4+6,D44>=R$4),"█","")) | S44: =IF(OR(A44="",C44="",D44=""),"",IF(AND(C44<=S$4+6,D44>=S$4),"█","")) | T44: =IF(OR(A44="",C44="",D44=""),"",IF(AND(C44<=T$4+6,D44>=T$4),"█","")) | U44: =IF(OR(A44="",C44="",D44=""),"",IF(AND(C44<=U$4+6,D44>=U$4),"█","")) | V44: =IF(OR(A44="",C44="",D44=""),"",IF(AND(C44<=V$4+6,D44>=V$4),"█","")) | W44: =IF(OR(A44="",C44="",D44=""),"",IF(AND(C44<=W$4+6,D44>=W$4),"█",""))
A46: Slide the window by changing Timeline start. Overlaps are expected — that is the point. Empty task rows stay blank.

Sheet Milestones
A1: Milestones
A2: Key dates only — not every task. Mark Done when it ships. Missed is for a date that passed without a finish.
A3: =COUNTA(A5:A34)&" milestones · "&COUNTIF(D5:D34,"Done")&" done · "&COUNTIF(D5:D34,"Missed")&" missed"
A4: Milestone | B4: Project | C4: Due | D4: Status | E4: Owner | F4: Notes | G4: Days left
A5: Design approval | B5: Website Redesign | C5: 46249 | D5: Upcoming | E5: Maya Chen | F5: Sign-off on mockups | G5: =IF(OR(A5="",C5=""),"",C5-TODAY())
