Workbook
Name ListAName: Dashboard!$B$3
Name ListBName: Dashboard!$D$3
Name MatchMode: Dashboard!$F$3
Name Tolerance: Dashboard!$H$3
Name List_MatchMode: Dashboard!$N$2:$N$7
Name List_Reviewed: Dashboard!$N$9
Name CountA: Dashboard!$N$11
Name CountB: Dashboard!$N$12
Name MatchedCount: Dashboard!$N$13
Name DiffCount: Dashboard!$N$14
Name UnmatchA: Dashboard!$N$15
Name UnmatchB: Dashboard!$N$16
Name TotalA: Dashboard!$N$17
Name TotalB: Dashboard!$N$18
Name Variance: Dashboard!$N$19
Name Progress: Dashboard!$N$20
Name UnmatchAAbs: Dashboard!$N$21
Name UnmatchBAbs: Dashboard!$N$22
Name DiffAbs: Dashboard!$N$23
Name ReviewedCount: Dashboard!$N$24
Name ListA_Combo: 'List A'!$P$5:$P$204
Name ListB_Combo: 'List B'!$P$5:$P$204
Name ListA_Amt: 'List A'!$C$5:$C$204
Name ListB_Amt: 'List B'!$C$5:$C$204
Name ListA_Status: 'List A'!$L$5:$L$204
Name ListB_Status: 'List B'!$L$5:$L$204

Sheet Dashboard
A1: Transaction Reconciliation Matcher | N1: HELPERS / LISTS
A2: ="As of "&TEXT(TODAY(),"mmm d, yyyy")&" · "&ListAName&" vs "&ListBName | N2: Date + amount
A3: List A name | B3: Bank statement | C3: List B name | D3: Books | E3: Match method | F3: Date + amount | G3: Tolerance $ | H3: 0.05 | I3: IDs and Manual pair override the method. | N3: Amount only
A4: Blue settings change how every row pairs. Default method is Date + amount. A Transaction ID on a row is used first. | N4: Date + amount (tolerance)
A5: =UPPER(ListAName) | D5: =UPPER(ListBName) | G5: MATCHED PAIRS | J5: PROGRESS | N5: Amount (tolerance)
A6: =CountA | D6: =CountB | G6: =MatchedCount | J6: =Progress | N6: Description (exact)
A7: ="Total "&TEXT(TotalA,"$#,##0.00") | D7: ="Total "&TEXT(TotalB,"$#,##0.00") | G7: ="Differences "&TEXT(DiffCount,"#,##0") | J7: 2 × paired ÷ all items | N7: Reference / ID only
A8: Items pasted on List A | D8: Items pasted on List B | G8: Paired with equal amounts | J8: Includes differences as paired
N9: Reviewed
A10: UNMATCHED A | D10: UNMATCHED B | G10: AMOUNT DIFFERENCES | J10: NET VARIANCE A − B
A11: =UnmatchA | D11: =UnmatchB | G11: =DiffCount | J11: =Variance | N11: =COUNTA('List A'!$A$5:$A$204)
A12: ="Value "&TEXT(UnmatchAAbs,"$#,##0.00") | D12: ="Value "&TEXT(UnmatchBAbs,"$#,##0.00") | G12: ="Abs. "&TEXT(DiffAbs,"$#,##0.00") | J12: Sum of List A minus List B | N12: =COUNTA('List B'!$A$5:$A$204)
A13: On List A only | D13: On List B only | G13: Paired, amounts disagree | J13: Should be 0 when fully reconciled | N13: =COUNTIF('List A'!$L$5:$L$204,"Matched")
N14: =COUNTIF('List A'!$L$5:$L$204,"Difference")
A15: RECONCILIATION AT A GLANCE | G15: WHAT TO DO NEXT | N15: =COUNTIF('List A'!$L$5:$L$204,"Unmatched")
A16: Items on List A | D16: =CountA | G16: 1. Open Unmatched A — typical bank fees, interest, or missing books entries. | N16: =COUNTIF('List B'!$L$5:$L$204,"Unmatched")
A17: Items on List B | D17: =CountB | G17: 2. Open Unmatched B — typical outstanding checks or items not cleared. | N17: ='List A'!C205
A18: Matched pairs (amounts agree) | D18: =MatchedCount | G18: 3. Open Differences — paired by ID/manual but amounts disagree. Fix a typo or accept the variance. | N18: ='List B'!C205
A19: Paired with a difference | D19: =DiffCount | G19: 4. Force a pair: type the same Manual pair code (M1) on one A row and one B row. | N19: =N17-N18
A20: Unmatched on A | D20: =UnmatchA | G20: 5. Mark leftovers Reviewed when you have explained them. | N20: =IF(N11+N12=0,"",2*(N13+N14)/(N11+N12))
A21: Unmatched on B | D21: =UnmatchB | G21: 6. Change Match method if too many unmatched (try Amount only, or fill Transaction IDs). | N21: =SUMPRODUCT(('List A'!$L$5:$L$204="Unmatched")*ABS('List A'!$C$5:$C$204))
A22: Reviewed (either list) | D22: =ReviewedCount | G22: 7. Progress at 100% means every row is either matched or paired as a difference. | N22: =SUMPRODUCT(('List B'!$L$5:$L$204="Unmatched")*ABS('List B'!$C$5:$C$204))
A23: Sum of List A | D23: =TotalA | N23: =SUM('List A'!$T$5:$T$204)
A24: Sum of List B | D24: =TotalB | N24: =COUNTIF('List A'!$G$5:$G$204,"Reviewed")+COUNTIF('List B'!$G$5:$G$204,"Reviewed")
A25: Net variance (A − B) | D25: =Variance
A27: STATUS MIX
A45: START A NEW RECONCILIATION
A46: ☐ File → Save As (Excel) or File → Make a copy (Google Sheets) if you want to keep this period.
A47: ☐ On List A and List B, delete values in columns A–H only. Leave every gray column alone.
A48: ☐ Paste the new statement into List A and the new book export into List B (same columns).
A49: ☐ Confirm Match method and Tolerance above. Set List A / List B names.
A50: ☐ Check this Dashboard, then work Unmatched and Differences left to right.
A52: Green = fully matched. Amber = paired with an amount difference. Red = unmatched. See Instructions for how keys work.
A55: Status | B55: Count
A56: Matched | B56: =MatchedCount
A57: Differences | B57: =DiffCount
A58: Unmatched A | B58: =UnmatchA
A59: Unmatched B | B59: =UnmatchB

Sheet List A
A1: List A
A2: =IF(ListAName="","Paste or type transactions here.",ListAName&" · Blue = paste or type. Gray = match result. Withdrawals negative, deposits positive — same convention on both lists.")
A3: =COUNTA(A5:A204)&" items · "&COUNTIF(L5:L204,"Matched")&" matched · "&COUNTIF(L5:L204,"Difference")&" differences · "&COUNTIF(L5:L204,"Unmatched")&" unmatched · Total "&TEXT(SUM(C5:C204),"$#,##0.00")
A4: Date | B4: Description | C4: Amount | D4: Transaction ID | E4: Category | F4: Notes | G4: Reviewed? | H4: Manual pair | I4: Match key | J4: Occ. | K4: Match row | L4: Status | M4: List B amount | N4: Difference | O4: How matched
A5: 46235 | B5: Deposit — customer ACH | C5: 2500 | E5: Income | I5: =IF(A5="","",IF(H5<>"","M|"&TRIM(H5),IF(AND(MatchMode="Reference / ID only",D5=""),"U|"&ROW(),IF(D5<>"","R|"&TRIM(D5),IF(MatchMode="Amount only","A|"&TEXT(ROUND(C5,2),"0.00"),IF(MatchMode="Amount (tolerance)","T|"&TEXT(ROUND(C5/MAX(N(Tolerance),0.0001),0),"0"),IF(MatchMode="Date + amount (tolerance)","DT|"&TEXT(A5,"yyyy-mm-dd")&"|"&TEXT(ROUND(C5/MAX(N(Tolerance),0.0001),0),"0"),IF(MatchMode="Description (exact)","S|"&LOWER(TRIM(B5)),IF(MatchMode="Reference / ID only","U|"&ROW(),"DA|"&TEXT(A5,"yyyy-mm-dd")&"|"&TEXT(ROUND(C5,2),"0.00")))))))))) | J5: =IF(I5="","",COUNTIF($I$5:I5,I5)) | K5: =IF(P5="","",IFERROR(MATCH(P5,ListB_Combo,0)+4,"")) | L5: =IF(A5="","",IF(K5="","Unmatched",IF(ABS(C5-M5)<=MAX(N(Tolerance),0),"Matched","Difference"))) | M5: =IF(K5="","",INDEX('List B'!$C$5:$C$204,K5-4)) | N5: =IF(K5="","",C5-M5) | O5: =IF(OR(A5="",K5=""),"",IF(H5<>"","Manual pair",IF(D5<>"","Reference / ID",MatchMode))) | P5: =IF(I5="","",I5&"|"&J5) | Q5: =IF(L5="Matched",COUNTIF($L$5:L5,"Matched"),"") | R5: =IF(L5="Unmatched",COUNTIF($L$5:L5,"Unmatched"),"") | S5: =IF(L5="Difference",COUNTIF($L$5:L5,"Difference"),"") | T5: =IF(L5="Difference",ABS(N5),0)
A6: 46237 | B6: Check 1041 Office Depot | C6: -185 | D6: 1041 | E6: Supplies | I6: =IF(A6="","",IF(H6<>"","M|"&TRIM(H6),IF(AND(MatchMode="Reference / ID only",D6=""),"U|"&ROW(),IF(D6<>"","R|"&TRIM(D6),IF(MatchMode="Amount only","A|"&TEXT(ROUND(C6,2),"0.00"),IF(MatchMode="Amount (tolerance)","T|"&TEXT(ROUND(C6/MAX(N(Tolerance),0.0001),0),"0"),IF(MatchMode="Date + amount (tolerance)","DT|"&TEXT(A6,"yyyy-mm-dd")&"|"&TEXT(ROUND(C6/MAX(N(Tolerance),0.0001),0),"0"),IF(MatchMode="Description (exact)","S|"&LOWER(TRIM(B6)),IF(MatchMode="Reference / ID only","U|"&ROW(),"DA|"&TEXT(A6,"yyyy-mm-dd")&"|"&TEXT(ROUND(C6,2),"0.00")))))))))) | J6: =IF(I6="","",COUNTIF($I$5:I6,I6)) | K6: =IF(P6="","",IFERROR(MATCH(P6,ListB_Combo,0)+4,"")) | L6: =IF(A6="","",IF(K6="","Unmatched",IF(ABS(C6-M6)<=MAX(N(Tolerance),0),"Matched","Difference"))) | M6: =IF(K6="","",INDEX('List B'!$C$5:$C$204,K6-4)) | N6: =IF(K6="","",C6-M6) | O6: =IF(OR(A6="",K6=""),"",IF(H6<>"","Manual pair",IF(D6<>"","Reference / ID",MatchMode))) | P6: =IF(I6="","",I6&"|"&J6) | Q6: =IF(L6="Matched",COUNTIF($L$5:L6,"Matched"),"") | R6: =IF(L6="Unmatched",COUNTIF($L$5:L6,"Unmatched"),"") | S6: =IF(L6="Difference",COUNTIF($L$5:L6,"Difference"),"") | T6: =IF(L6="Difference",ABS(N6),0)
A7: 46238 | B7: ACH Payroll | C7: -2100 | E7: Payroll | I7: =IF(A7="","",IF(H7<>"","M|"&TRIM(H7),IF(AND(MatchMode="Reference / ID only",D7=""),"U|"&ROW(),IF(D7<>"","R|"&TRIM(D7),IF(MatchMode="Amount only","A|"&TEXT(ROUND(C7,2),"0.00"),IF(MatchMode="Amount (tolerance)","T|"&TEXT(ROUND(C7/MAX(N(Tolerance),0.0001),0),"0"),IF(MatchMode="Date + amount (tolerance)","DT|"&TEXT(A7,"yyyy-mm-dd")&"|"&TEXT(ROUND(C7/MAX(N(Tolerance),0.0001),0),"0"),IF(MatchMode="Description (exact)","S|"&LOWER(TRIM(B7)),IF(MatchMode="Reference / ID only","U|"&ROW(),"DA|"&TEXT(A7,"yyyy-mm-dd")&"|"&TEXT(ROUND(C7,2),"0.00")))))))))) | J7: =IF(I7="","",COUNTIF($I$5:I7,I7)) | K7: =IF(P7="","",IFERROR(MATCH(P7,ListB_Combo,0)+4,"")) | L7: =IF(A7="","",IF(K7="","Unmatched",IF(ABS(C7-M7)<=MAX(N(Tolerance),0),"Matched","Difference"))) | M7: =IF(K7="","",INDEX('List B'!$C$5:$C$204,K7-4)) | N7: =IF(K7="","",C7-M7) | O7: =IF(OR(A7="",K7=""),"",IF(H7<>"","Manual pair",IF(D7<>"","Reference / ID",MatchMode))) | P7: =IF(I7="","",I7&"|"&J7) | Q7: =IF(L7="Matched",COUNTIF($L$5:L7,"Matched"),"") | R7: =IF(L7="Unmatched",COUNTIF($L$5:L7,"Unmatched"),"") | S7: =IF(L7="Difference",COUNTIF($L$5:L7,"Difference"),"") | T7: =IF(L7="Difference",ABS(N7),0)
A8: 46239 | B8: Stripe payout | C8: 842.16 | D8: po_8f21 | E8: Income | I8: =IF(A8="","",IF(H8<>"","M|"&TRIM(H8),IF(AND(MatchMode="Reference / ID only",D8=""),"U|"&ROW(),IF(D8<>"","R|"&TRIM(D8),IF(MatchMode="Amount only","A|"&TEXT(ROUND(C8,2),"0.00"),IF(MatchMode="Amount (tolerance)","T|"&TEXT(ROUND(C8/MAX(N(Tolerance),0.0001),0),"0"),IF(MatchMode="Date + amount (tolerance)","DT|"&TEXT(A8,"yyyy-mm-dd")&"|"&TEXT(ROUND(C8/MAX(N(Tolerance),0.0001),0),"0"),IF(MatchMode="Description (exact)","S|"&LOWER(TRIM(B8)),IF(MatchMode="Reference / ID only","U|"&ROW(),"DA|"&TEXT(A8,"yyyy-mm-dd")&"|"&TEXT(ROUND(C8,2),"0.00")))))))))) | J8: =IF(I8="","",COUNTIF($I$5:I8,I8)) | K8: =IF(P8="","",IFERROR(MATCH(P8,ListB_Combo,0)+4,"")) | L8: =IF(A8="","",IF(K8="","Unmatched",IF(ABS(C8-M8)<=MAX(N(Tolerance),0),"Matched","Difference"))) | M8: =IF(K8="","",INDEX('List B'!$C$5:$C$204,K8-4)) | N8: =IF(K8="","",C8-M8) | O8: =IF(OR(A8="",K8=""),"",IF(H8<>"","Manual pair",IF(D8<>"","Reference / ID",MatchMode))) | P8: =IF(I8="","",I8&"|"&J8) | Q8: =IF(L8="Matched",COUNTIF($L$5:L8,"Matched"),"") | R8: =IF(L8="Unmatched",COUNTIF($L$5:L8,"Unmatched"),"") | S8: =IF(L8="Difference",COUNTIF($L$5:L8,"Difference"),"") | T8: =IF(L8="Difference",ABS(N8),0)
A9: 46240 | B9: Check 1043 Rent | C9: -1400 | D9: 1043 | E9: Rent | I9: =IF(A9="","",IF(H9<>"","M|"&TRIM(H9),IF(AND(MatchMode="Reference / ID only",D9=""),"U|"&ROW(),IF(D9<>"","R|"&TRIM(D9),IF(MatchMode="Amount only","A|"&TEXT(ROUND(C9,2),"0.00"),IF(MatchMode="Amount (tolerance)","T|"&TEXT(ROUND(C9/MAX(N(Tolerance),0.0001),0),"0"),IF(MatchMode="Date + amount (tolerance)","DT|"&TEXT(A9,"yyyy-mm-dd")&"|"&TEXT(ROUND(C9/MAX(N(Tolerance),0.0001),0),"0"),IF(MatchMode="Description (exact)","S|"&LOWER(TRIM(B9)),IF(MatchMode="Reference / ID only","U|"&ROW(),"DA|"&TEXT(A9,"yyyy-mm-dd")&"|"&TEXT(ROUND(C9,2),"0.00")))))))))) | J9: =IF(I9="","",COUNTIF($I$5:I9,I9)) | K9: =IF(P9="","",IFERROR(MATCH(P9,ListB_Combo,0)+4,"")) | L9: =IF(A9="","",IF(K9="","Unmatched",IF(ABS(C9-M9)<=MAX(N(Tolerance),0),"Matched","Difference"))) | M9: =IF(K9="","",INDEX('List B'!$C$5:$C$204,K9-4)) | N9: =IF(K9="","",C9-M9) | O9: =IF(OR(A9="",K9=""),"",IF(H9<>"","Manual pair",IF(D9<>"","Reference / ID",MatchMode))) | P9: =IF(I9="","",I9&"|"&J9) | Q9: =IF(L9="Matched",COUNTIF($L$5:L9,"Matched"),"") | R9: =IF(L9="Unmatched",COUNTIF($L$5:L9,"Unmatched"),"") | S9: =IF(L9="Difference",COUNTIF($L$5:L9,"Difference"),"") | T9: =IF(L9="Difference",ABS(N9),0)
A10: 46241 | B10: Card Adobe CC | C10: -54.99 | E10: Software | I10: =IF(A10="","",IF(H10<>"","M|"&TRIM(H10),IF(AND(MatchMode="Reference / ID only",D10=""),"U|"&ROW(),IF(D10<>"","R|"&TRIM(D10),IF(MatchMode="Amount only","A|"&TEXT(ROUND(C10,2),"0.00"),IF(MatchMode="Amount (tolerance)","T|"&TEXT(ROUND(C10/MAX(N(Tolerance),0.0001),0),"0"),IF(MatchMode="Date + amount (tolerance)","DT|"&TEXT(A10,"yyyy-mm-dd")&"|"&TEXT(ROUND(C10/MAX(N(Tolerance),0.0001),0),"0"),IF(MatchMode="Description (exact)","S|"&LOWER(TRIM(B10)),IF(MatchMode="Reference / ID only","U|"&ROW(),"DA|"&TEXT(A10,"yyyy-mm-dd")&"|"&TEXT(ROUND(C10,2),"0.00")))))))))) | J10: =IF(I10="","",COUNTIF($I$5:I10,I10)) | K10: =IF(P10="","",IFERROR(MATCH(P10,ListB_Combo,0)+4,"")) | L10: =IF(A10="","",IF(K10="","Unmatched",IF(ABS(C10-M10)<=MAX(N(Tolerance),0),"Matched","Difference"))) | M10: =IF(K10="","",INDEX('List B'!$C$5:$C$204,K10-4)) | N10: =IF(K10="","",C10-M10) | O10: =IF(OR(A10="",K10=""),"",IF(H10<>"","Manual pair",IF(D10<>"","Reference / ID",MatchMode))) | P10: =IF(I10="","",I10&"|"&J10) | Q10: =IF(L10="Matched",COUNTIF($L$5:L10,"Matched"),"") | R10: =IF(L10="Unmatched",COUNTIF($L$5:L10,"Unmatched"),"") | S10: =IF(L10="Difference",COUNTIF($L$5:L10,"Difference"),"") | T10: =IF(L10="Difference",ABS(N10),0)
A11: 46242 | B11: Bank service fee | C11: -12 | E11: Bank fees | G11: Reviewed | I11: =IF(A11="","",IF(H11<>"","M|"&TRIM(H11),IF(AND(MatchMode="Reference / ID only",D11=""),"U|"&ROW(),IF(D11<>"","R|"&TRIM(D11),IF(MatchMode="Amount only","A|"&TEXT(ROUND(C11,2),"0.00"),IF(MatchMode="Amount (tolerance)","T|"&TEXT(ROUND(C11/MAX(N(Tolerance),0.0001),0),"0"),IF(MatchMode="Date + amount (tolerance)","DT|"&TEXT(A11,"yyyy-mm-dd")&"|"&TEXT(ROUND(C11/MAX(N(Tolerance),0.0001),0),"0"),IF(MatchMode="Description (exact)","S|"&LOWER(TRIM(B11)),IF(MatchMode="Reference / ID only","U|"&ROW(),"DA|"&TEXT(A11,"yyyy-mm-dd")&"|"&TEXT(ROUND(C11,2),"0.00")))))))))) | J11: =IF(I11="","",COUNTIF($I$5:I11,I11)) | K11: =IF(P11="","",IFERROR(MATCH(P11,ListB_Combo,0)+4,"")) | L11: =IF(A11="","",IF(K11="","Unmatched",IF(ABS(C11-M11)<=MAX(N(Tolerance),0),"Matched","Difference"))) | M11: =IF(K11="","",INDEX('List B'!$C$5:$C$204,K11-4)) | N11: =IF(K11="","",C11-M11) | O11: =IF(OR(A11="",K11=""),"",IF(H11<>"","Manual pair",IF(D11<>"","Reference / ID",MatchMode))) | P11: =IF(I11="","",I11&"|"&J11) | Q11: =IF(L11="Matched",COUNTIF($L$5:L11,"Matched"),"") | R11: =IF(L11="Unmatched",COUNTIF($L$5:L11,"Unmatched"),"") | S11: =IF(L11="Difference",COUNTIF($L$5:L11,"Difference"),"") | T11: =IF(L11="Difference",ABS(N11),0)
A12: 46244 | B12: ACH Staples | C12: -326.4 | E12: Supplies | I12: =IF(A12="","",IF(H12<>"","M|"&TRIM(H12),IF(AND(MatchMode="Reference / ID only",D12=""),"U|"&ROW(),IF(D12<>"","R|"&TRIM(D12),IF(MatchMode="Amount only","A|"&TEXT(ROUND(C12,2),"0.00"),IF(MatchMode="Amount (tolerance)","T|"&TEXT(ROUND(C12/MAX(N(Tolerance),0.0001),0),"0"),IF(MatchMode="Date + amount (tolerance)","DT|"&TEXT(A12,"yyyy-mm-dd")&"|"&TEXT(ROUND(C12/MAX(N(Tolerance),0.0001),0),"0"),IF(MatchMode="Description (exact)","S|"&LOWER(TRIM(B12)),IF(MatchMode="Reference / ID only","U|"&ROW(),"DA|"&TEXT(A12,"yyyy-mm-dd")&"|"&TEXT(ROUND(C12,2),"0.00")))))))))) | J12: =IF(I12="","",COUNTIF($I$5:I12,I12)) | K12: =IF(P12="","",IFERROR(MATCH(P12,ListB_Combo,0)+4,"")) | L12: =IF(A12="","",IF(K12="","Unmatched",IF(ABS(C12-M12)<=MAX(N(Tolerance),0),"Matched","Difference"))) | M12: =IF(K12="","",INDEX('List B'!$C$5:$C$204,K12-4)) | N12: =IF(K12="","",C12-M12) | O12: =IF(OR(A12="",K12=""),"",IF(H12<>"","Manual pair",IF(D12<>"","Reference / ID",MatchMode))) | P12: =IF(I12="","",I12&"|"&J12) | Q12: =IF(L12="Matched",COUNTIF($L$5:L12,"Matched"),"") | R12: =IF(L12="Unmatched",COUNTIF($L$5:L12,"Unmatched"),"") | S12: =IF(L12="Difference",COUNTIF($L$5:L12,"Difference"),"") | T12: =IF(L12="Difference",ABS(N12),0)
A13: 46245 | B13: Deposit — invoice 1882 | C13: 750 | D13: INV-1882 | E13: Income | I13: =IF(A13="","",IF(H13<>"","M|"&TRIM(H13),IF(AND(MatchMode="Reference / ID only",D13=""),"U|"&ROW(),IF(D13<>"","R|"&TRIM(D13),IF(MatchMode="Amount only","A|"&TEXT(ROUND(C13,2),"0.00"),IF(MatchMode="Amount (tolerance)","T|"&TEXT(ROUND(C13/MAX(N(Tolerance),0.0001),0),"0"),IF(MatchMode="Date + amount (tolerance)","DT|"&TEXT(A13,"yyyy-mm-dd")&"|"&TEXT(ROUND(C13/MAX(N(Tolerance),0.0001),0),"0"),IF(MatchMode="Description (exact)","S|"&LOWER(TRIM(B13)),IF(MatchMode="Reference / ID only","U|"&ROW(),"DA|"&TEXT(A13,"yyyy-mm-dd")&"|"&TEXT(ROUND(C13,2),"0.00")))))))))) | J13: =IF(I13="","",COUNTIF($I$5:I13,I13)) | K13: =IF(P13="","",IFERROR(MATCH(P13,ListB_Combo,0)+4,"")) | L13: =IF(A13="","",IF(K13="","Unmatched",IF(ABS(C13-M13)<=MAX(N(Tolerance),0),"Matched","Difference"))) | M13: =IF(K13="","",INDEX('List B'!$C$5:$C$204,K13-4)) | N13: =IF(K13="","",C13-M13) | O13: =IF(OR(A13="",K13=""),"",IF(H13<>"","Manual pair",IF(D13<>"","Reference / ID",MatchMode))) | P13: =IF(I13="","",I13&"|"&J13) | Q13: =IF(L13="Matched",COUNTIF($L$5:L13,"Matched"),"") | R13: =IF(L13="Unmatched",COUNTIF($L$5:L13,"Unmatched"),"") | S13: =IF(L13="Difference",COUNTIF($L$5:L13,"Difference"),"") | T13: =IF(L13="Difference",ABS(N13),0)
A14: 46246 | B14: Wire vendor | C14: -1200 | D14: INV-2291 | E14: COGS | F14: Bank posted $1,200.00 | I14: =IF(A14="","",IF(H14<>"","M|"&TRIM(H14),IF(AND(MatchMode="Reference / ID only",D14=""),"U|"&ROW(),IF(D14<>"","R|"&TRIM(D14),IF(MatchMode="Amount only","A|"&TEXT(ROUND(C14,2),"0.00"),IF(MatchMode="Amount (tolerance)","T|"&TEXT(ROUND(C14/MAX(N(Tolerance),0.0001),0),"0"),IF(MatchMode="Date + amount (tolerance)","DT|"&TEXT(A14,"yyyy-mm-dd")&"|"&TEXT(ROUND(C14/MAX(N(Tolerance),0.0001),0),"0"),IF(MatchMode="Description (exact)","S|"&LOWER(TRIM(B14)),IF(MatchMode="Reference / ID only","U|"&ROW(),"DA|"&TEXT(A14,"yyyy-mm-dd")&"|"&TEXT(ROUND(C14,2),"0.00")))))))))) | J14: =IF(I14="","",COUNTIF($I$5:I14,I14)) | K14: =IF(P14="","",IFERROR(MATCH(P14,ListB_Combo,0)+4,"")) | L14: =IF(A14="","",IF(K14="","Unmatched",IF(ABS(C14-M14)<=MAX(N(Tolerance),0),"Matched","Difference"))) | M14: =IF(K14="","",INDEX('List B'!$C$5:$C$204,K14-4)) | N14: =IF(K14="","",C14-M14) | O14: =IF(OR(A14="",K14=""),"",IF(H14<>"","Manual pair",IF(D14<>"","Reference / ID",MatchMode))) | P14: =IF(I14="","",I14&"|"&J14) | Q14: =IF(L14="Matched",COUNTIF($L$5:L14,"Matched"),"") | R14: =IF(L14="Unmatched",COUNTIF($L$5:L14,"Unmatched"),"") | S14: =IF(L14="Difference",COUNTIF($L$5:L14,"Difference"),"") | T14: =IF(L14="Difference",ABS(N14),0)
A15: 46247 | B15: Card AWS | C15: -87.23 | E15: Software | I15: =IF(A15="","",IF(H15<>"","M|"&TRIM(H15),IF(AND(MatchMode="Reference / ID only",D15=""),"U|"&ROW(),IF(D15<>"","R|"&TRIM(D15),IF(MatchMode="Amount only","A|"&TEXT(ROUND(C15,2),"0.00"),IF(MatchMode="Amount (tolerance)","T|"&TEXT(ROUND(C15/MAX(N(Tolerance),0.0001),0),"0"),IF(MatchMode="Date + amount (tolerance)","DT|"&TEXT(A15,"yyyy-mm-dd")&"|"&TEXT(ROUND(C15/MAX(N(Tolerance),0.0001),0),"0"),IF(MatchMode="Description (exact)","S|"&LOWER(TRIM(B15)),IF(MatchMode="Reference / ID only","U|"&ROW(),"DA|"&TEXT(A15,"yyyy-mm-dd")&"|"&TEXT(ROUND(C15,2),"0.00")))))))))) | J15: =IF(I15="","",COUNTIF($I$5:I15,I15)) | K15: =IF(P15="","",IFERROR(MATCH(P15,ListB_Combo,0)+4,"")) | L15: =IF(A15="","",IF(K15="","Unmatched",IF(ABS(C15-M15)<=MAX(N(Tolerance),0),"Matched","Difference"))) | M15: =IF(K15="","",INDEX('List B'!$C$5:$C$204,K15-4)) | N15: =IF(K15="","",C15-M15) | O15: =IF(OR(A15="",K15=""),"",IF(H15<>"","Manual pair",IF(D15<>"","Reference / ID",MatchMode))) | P15: =IF(I15="","",I15&"|"&J15) | Q15: =IF(L15="Matched",COUNTIF($L$5:L15,"Matched"),"") | R15: =IF(L15="Unmatched",COUNTIF($L$5:L15,"Unmatched"),"") | S15: =IF(L15="Difference",COUNTIF($L$5:L15,"Difference"),"") | T15: =IF(L15="Difference",ABS(N15),0)
A16: 46248 | B16: Check 1044 Insurance | C16: -245 | D16: 1044 | E16: Insurance | I16: =IF(A16="","",IF(H16<>"","M|"&TRIM(H16),IF(AND(MatchMode="Reference / ID only",D16=""),"U|"&ROW(),IF(D16<>"","R|"&TRIM(D16),IF(MatchMode="Amount only","A|"&TEXT(ROUND(C16,2),"0.00"),IF(MatchMode="Amount (tolerance)","T|"&TEXT(ROUND(C16/MAX(N(Tolerance),0.0001),0),"0"),IF(MatchMode="Date + amount (tolerance)","DT|"&TEXT(A16,"yyyy-mm-dd")&"|"&TEXT(ROUND(C16/MAX(N(Tolerance),0.0001),0),"0"),IF(MatchMode="Description (exact)","S|"&LOWER(TRIM(B16)),IF(MatchMode="Reference / ID only","U|"&ROW(),"DA|"&TEXT(A16,"yyyy-mm-dd")&"|"&TEXT(ROUND(C16,2),"0.00")))))))))) | J16: =IF(I16="","",COUNTIF($I$5:I16,I16)) | K16: =IF(P16="","",IFERROR(MATCH(P16,ListB_Combo,0)+4,"")) | L16: =IF(A16="","",IF(K16="","Unmatched",IF(ABS(C16-M16)<=MAX(N(Tolerance),0),"Matched","Difference"))) | M16: =IF(K16="","",INDEX('List B'!$C$5:$C$204,K16-4)) | N16: =IF(K16="","",C16-M16) | O16: =IF(OR(A16="",K16=""),"",IF(H16<>"","Manual pair",IF(D16<>"","Reference / ID",MatchMode))) | P16: =IF(I16="","",I16&"|"&J16) | Q16: =IF(L16="Matched",COUNTIF($L$5:L16,"Matched"),"") | R16: =IF(L16="Unmatched",COUNTIF($L$5:L16,"Unmatched"),"") | S16: =IF(L16="Difference",COUNTIF($L$5:L16,"Difference"),"") | T16: =IF(L16="Difference",ABS(N16),0)
A17: 46249 | B17: Deposit — customer | C17: 1800 | E17: Income | I17: =IF(A17="","",IF(H17<>"","M|"&TRIM(H17),IF(AND(MatchMode="Reference / ID only",D17=""),"U|"&ROW(),IF(D17<>"","R|"&TRIM(D17),IF(MatchMode="Amount only","A|"&TEXT(ROUND(C17,2),"0.00"),IF(MatchMode="Amount (tolerance)","T|"&TEXT(ROUND(C17/MAX(N(Tolerance),0.0001),0),"0"),IF(MatchMode="Date + amount (tolerance)","DT|"&TEXT(A17,"yyyy-mm-dd")&"|"&TEXT(ROUND(C17/MAX(N(Tolerance),0.0001),0),"0"),IF(MatchMode="Description (exact)","S|"&LOWER(TRIM(B17)),IF(MatchMode="Reference / ID only","U|"&ROW(),"DA|"&TEXT(A17,"yyyy-mm-dd")&"|"&TEXT(ROUND(C17,2),"0.00")))))))))) | J17: =IF(I17="","",COUNTIF($I$5:I17,I17)) | K17: =IF(P17="","",IFERROR(MATCH(P17,ListB_Combo,0)+4,"")) | L17: =IF(A17="","",IF(K17="","Unmatched",IF(ABS(C17-M17)<=MAX(N(Tolerance),0),"Matched","Difference"))) | M17: =IF(K17="","",INDEX('List B'!$C$5:$C$204,K17-4)) | N17: =IF(K17="","",C17-M17) | O17: =IF(OR(A17="",K17=""),"",IF(H17<>"","Manual pair",IF(D17<>"","Reference / ID",MatchMode))) | P17: =IF(I17="","",I17&"|"&J17) | Q17: =IF(L17="Matched",COUNTIF($L$5:L17,"Matched"),"") | R17: =IF(L17="Unmatched",COUNTIF($L$5:L17,"Unmatched"),"") | S17: =IF(L17="Difference",COUNTIF($L$5:L17,"Difference"),"") | T17: =IF(L17="Difference",ABS(N17),0)
A18: 46251 | B18: Card coffee meeting | C18: -18.4 | E18: Meals | I18: =IF(A18="","",IF(H18<>"","M|"&TRIM(H18),IF(AND(MatchMode="Reference / ID only",D18=""),"U|"&ROW(),IF(D18<>"","R|"&TRIM(D18),IF(MatchMode="Amount only","A|"&TEXT(ROUND(C18,2),"0.00"),IF(MatchMode="Amount (tolerance)","T|"&TEXT(ROUND(C18/MAX(N(Tolerance),0.0001),0),"0"),IF(MatchMode="Date + amount (tolerance)","DT|"&TEXT(A18,"yyyy-mm-dd")&"|"&TEXT(ROUND(C18/MAX(N(Tolerance),0.0001),0),"0"),IF(MatchMode="Description (exact)","S|"&LOWER(TRIM(B18)),IF(MatchMode="Reference / ID only","U|"&ROW(),"DA|"&TEXT(A18,"yyyy-mm-dd")&"|"&TEXT(ROUND(C18,2),"0.00")))))))))) | J18: =IF(I18="","",COUNTIF($I$5:I18,I18)) | K18: =IF(P18="","",IFERROR(MATCH(P18,ListB_Combo,0)+4,"")) | L18: =IF(A18="","",IF(K18="","Unmatched",IF(ABS(C18-M18)<=MAX(N(Tolerance),0),"Matched","Difference"))) | M18: =IF(K18="","",INDEX('List B'!$C$5:$C$204,K18-4)) | N18: =IF(K18="","",C18-M18) | O18: =IF(OR(A18="",K18=""),"",IF(H18<>"","Manual pair",IF(D18<>"","Reference / ID",MatchMode))) | P18: =IF(I18="","",I18&"|"&J18) | Q18: =IF(L18="Matched",COUNTIF($L$5:L18,"Matched"),"") | R18: =IF(L18="Unmatched",COUNTIF($L$5:L18,"Unmatched"),"") | S18: =IF(L18="Difference",COUNTIF($L$5:L18,"Difference"),"") | T18: =IF(L18="Difference",ABS(N18),0)
A19: 46252 | B19: ACH electric | C19: -163.55 | E19: Utilities | I19: =IF(A19="","",IF(H19<>"","M|"&TRIM(H19),IF(AND(MatchMode="Reference / ID only",D19=""),"U|"&ROW(),IF(D19<>"","R|"&TRIM(D19),IF(MatchMode="Amount only","A|"&TEXT(ROUND(C19,2),"0.00"),IF(MatchMode="Amount (tolerance)","T|"&TEXT(ROUND(C19/MAX(N(Tolerance),0.0001),0),"0"),IF(MatchMode="Date + amount (tolerance)","DT|"&TEXT(A19,"yyyy-mm-dd")&"|"&TEXT(ROUND(C19/MAX(N(Tolerance),0.0001),0),"0"),IF(MatchMode="Description (exact)","S|"&LOWER(TRIM(B19)),IF(MatchMode="Reference / ID only","U|"&ROW(),"DA|"&TEXT(A19,"yyyy-mm-dd")&"|"&TEXT(ROUND(C19,2),"0.00")))))))))) | J19: =IF(I19="","",COUNTIF($I$5:I19,I19)) | K19: =IF(P19="","",IFERROR(MATCH(P19,ListB_Combo,0)+4,"")) | L19: =IF(A19="","",IF(K19="","Unmatched",IF(ABS(C19-M19)<=MAX(N(Tolerance),0),"Matched","Difference"))) | M19: =IF(K19="","",INDEX('List B'!$C$5:$C$204,K19-4)) | N19: =IF(K19="","",C19-M19) | O19: =IF(OR(A19="",K19=""),"",IF(H19<>"","Manual pair",IF(D19<>"","Reference / ID",MatchMode))) | P19: =IF(I19="","",I19&"|"&J19) | Q19: =IF(L19="Matched",COUNTIF($L$5:L19,"Matched"),"") | R19: =IF(L19="Unmatched",COUNTIF($L$5:L19,"Unmatched"),"") | S19: =IF(L19="Difference",COUNTIF($L$5:L19,"Difference"),"") | T19: =IF(L19="Difference",ABS(N19),0)
A20: 46254 | B20: Interest earned | C20: 2.14 | E20: Interest | I20: =IF(A20="","",IF(H20<>"","M|"&TRIM(H20),IF(AND(MatchMode="Reference / ID only",D20=""),"U|"&ROW(),IF(D20<>"","R|"&TRIM(D20),IF(MatchMode="Amount only","A|"&TEXT(ROUND(C20,2),"0.00"),IF(MatchMode="Amount (tolerance)","T|"&TEXT(ROUND(C20/MAX(N(Tolerance),0.0001),0),"0"),IF(MatchMode="Date + amount (tolerance)","DT|"&TEXT(A20,"yyyy-mm-dd")&"|"&TEXT(ROUND(C20/MAX(N(Tolerance),0.0001),0),"0"),IF(MatchMode="Description (exact)","S|"&LOWER(TRIM(B20)),IF(MatchMode="Reference / ID only","U|"&ROW(),"DA|"&TEXT(A20,"yyyy-mm-dd")&"|"&TEXT(ROUND(C20,2),"0.00")))))))))) | J20: =IF(I20="","",COUNTIF($I$5:I20,I20)) | K20: =IF(P20="","",IFERROR(MATCH(P20,ListB_Combo,0)+4,"")) | L20: =IF(A20="","",IF(K20="","Unmatched",IF(ABS(C20-M20)<=MAX(N(Tolerance),0),"Matched","Difference"))) | M20: =IF(K20="","",INDEX('List B'!$C$5:$C$204,K20-4)) | N20: =IF(K20="","",C20-M20) | O20: =IF(OR(A20="",K20=""),"",IF(H20<>"","Manual pair",IF(D20<>"","Reference / ID",MatchMode))) | P20: =IF(I20="","",I20&"|"&J20) | Q20: =IF(L20="Matched",COUNTIF($L$5:L20,"Matched"),"") | R20: =IF(L20="Unmatched",COUNTIF($L$5:L20,"Unmatched"),"") | S20: =IF(L20="Difference",COUNTIF($L$5:L20,"Difference"),"") | T20: =IF(L20="Difference",ABS(N20),0)
A21: 46255 | B21: Check 1045 Contractor | C21: -600 | D21: 1045 | E21: Contractors | I21: =IF(A21="","",IF(H21<>"","M|"&TRIM(H21),IF(AND(MatchMode="Reference / ID only",D21=""),"U|"&ROW(),IF(D21<>"","R|"&TRIM(D21),IF(MatchMode="Amount only","A|"&TEXT(ROUND(C21,2),"0.00"),IF(MatchMode="Amount (tolerance)","T|"&TEXT(ROUND(C21/MAX(N(Tolerance),0.0001),0),"0"),IF(MatchMode="Date + amount (tolerance)","DT|"&TEXT(A21,"yyyy-mm-dd")&"|"&TEXT(ROUND(C21/MAX(N(Tolerance),0.0001),0),"0"),IF(MatchMode="Description (exact)","S|"&LOWER(TRIM(B21)),IF(MatchMode="Reference / ID only","U|"&ROW(),"DA|"&TEXT(A21,"yyyy-mm-dd")&"|"&TEXT(ROUND(C21,2),"0.00")))))))))) | J21: =IF(I21="","",COUNTIF($I$5:I21,I21)) | K21: =IF(P21="","",IFERROR(MATCH(P21,ListB_Combo,0)+4,"")) | L21: =IF(A21="","",IF(K21="","Unmatched",IF(ABS(C21-M21)<=MAX(N(Tolerance),0),"Matched","Difference"))) | M21: =IF(K21="","",INDEX('List B'!$C$5:$C$204,K21-4)) | N21: =IF(K21="","",C21-M21) | O21: =IF(OR(A21="",K21=""),"",IF(H21<>"","Manual pair",IF(D21<>"","Reference / ID",MatchMode))) | P21: =IF(I21="","",I21&"|"&J21) | Q21: =IF(L21="Matched",COUNTIF($L$5:L21,"Matched"),"") | R21: =IF(L21="Unmatched",COUNTIF($L$5:L21,"Unmatched"),"") | S21: =IF(L21="Difference",COUNTIF($L$5:L21,"Difference"),"") | T21: =IF(L21="Difference",ABS(N21),0)
A22: 46258 | B22: Card Notion | C22: -29 | E22: Software | I22: =IF(A22="","",IF(H22<>"","M|"&TRIM(H22),IF(AND(MatchMode="Reference / ID only",D22=""),"U|"&ROW(),IF(D22<>"","R|"&TRIM(D22),IF(MatchMode="Amount only","A|"&TEXT(ROUND(C22,2),"0.00"),IF(MatchMode="Amount (tolerance)","T|"&TEXT(ROUND(C22/MAX(N(Tolerance),0.0001),0),"0"),IF(MatchMode="Date + amount (tolerance)","DT|"&TEXT(A22,"yyyy-mm-dd")&"|"&TEXT(ROUND(C22/MAX(N(Tolerance),0.0001),0),"0"),IF(MatchMode="Description (exact)","S|"&LOWER(TRIM(B22)),IF(MatchMode="Reference / ID only","U|"&ROW(),"DA|"&TEXT(A22,"yyyy-mm-dd")&"|"&TEXT(ROUND(C22,2),"0.00")))))))))) | J22: =IF(I22="","",COUNTIF($I$5:I22,I22)) | K22: =IF(P22="","",IFERROR(MATCH(P22,ListB_Combo,0)+4,"")) | L22: =IF(A22="","",IF(K22="","Unmatched",IF(ABS(C22-M22)<=MAX(N(Tolerance),0),"Matched","Difference"))) | M22: =IF(K22="","",INDEX('List B'!$C$5:$C$204,K22-4)) | N22: =IF(K22="","",C22-M22) | O22: =IF(OR(A22="",K22=""),"",IF(H22<>"","Manual pair",IF(D22<>"","Reference / ID",MatchMode))) | P22: =IF(I22="","",I22&"|"&J22) | Q22: =IF(L22="Matched",COUNTIF($L$5:L22,"Matched"),"") | R22: =IF(L22="Unmatched",COUNTIF($L$5:L22,"Unmatched"),"") | S22: =IF(L22="Difference",COUNTIF($L$5:L22,"Difference"),"") | T22: =IF(L22="Difference",ABS(N22),0)
A23: 46260 | B23: Deposit — customer | C23: 950 | E23: Income | I23: =IF(A23="","",IF(H23<>"","M|"&TRIM(H23),IF(AND(MatchMode="Reference / ID only",D23=""),"U|"&ROW(),IF(D23<>"","R|"&TRIM(D23),IF(MatchMode="Amount only","A|"&TEXT(ROUND(C23,2),"0.00"),IF(MatchMode="Amount (tolerance)","T|"&TEXT(ROUND(C23/MAX(N(Tolerance),0.0001),0),"0"),IF(MatchMode="Date + amount (tolerance)","DT|"&TEXT(A23,"yyyy-mm-dd")&"|"&TEXT(ROUND(C23/MAX(N(Tolerance),0.0001),0),"0"),IF(MatchMode="Description (exact)","S|"&LOWER(TRIM(B23)),IF(MatchMode="Reference / ID only","U|"&ROW(),"DA|"&TEXT(A23,"yyyy-mm-dd")&"|"&TEXT(ROUND(C23,2),"0.00")))))))))) | J23: =IF(I23="","",COUNTIF($I$5:I23,I23)) | K23: =IF(P23="","",IFERROR(MATCH(P23,ListB_Combo,0)+4,"")) | L23: =IF(A23="","",IF(K23="","Unmatched",IF(ABS(C23-M23)<=MAX(N(Tolerance),0),"Matched","Difference"))) | M23: =IF(K23="","",INDEX('List B'!$C$5:$C$204,K23-4)) | N23: =IF(K23="","",C23-M23) | O23: =IF(OR(A23="",K23=""),"",IF(H23<>"","Manual pair",IF(D23<>"","Reference / ID",MatchMode))) | P23: =IF(I23="","",I23&"|"&J23) | Q23: =IF(L23="Matched",COUNTIF($L$5:L23,"Matched"),"") | R23: =IF(L23="Unmatched",COUNTIF($L$5:L23,"Unmatched"),"") | S23: =IF(L23="Difference",COUNTIF($L$5:L23,"Difference"),"") | T23: =IF(L23="Difference",ABS(N23),0)
A24: 46262 | B24: ACH phone | C24: -86 | E24: Utilities | I24: =IF(A24="","",IF(H24<>"","M|"&TRIM(H24),IF(AND(MatchMode="Reference / ID only",D24=""),"U|"&ROW(),IF(D24<>"","R|"&TRIM(D24),IF(MatchMode="Amount only","A|"&TEXT(ROUND(C24,2),"0.00"),IF(MatchMode="Amount (tolerance)","T|"&TEXT(ROUND(C24/MAX(N(Tolerance),0.0001),0),"0"),IF(MatchMode="Date + amount (tolerance)","DT|"&TEXT(A24,"yyyy-mm-dd")&"|"&TEXT(ROUND(C24/MAX(N(Tolerance),0.0001),0),"0"),IF(MatchMode="Description (exact)","S|"&LOWER(TRIM(B24)),IF(MatchMode="Reference / ID only","U|"&ROW(),"DA|"&TEXT(A24,"yyyy-mm-dd")&"|"&TEXT(ROUND(C24,2),"0.00")))))))))) | J24: =IF(I24="","",COUNTIF($I$5:I24,I24)) | K24: =IF(P24="","",IFERROR(MATCH(P24,ListB_Combo,0)+4,"")) | L24: =IF(A24="","",IF(K24="","Unmatched",IF(ABS(C24-M24)<=MAX(N(Tolerance),0),"Matched","Difference"))) | M24: =IF(K24="","",INDEX('List B'!$C$5:$C$204,K24-4)) | N24: =IF(K24="","",C24-M24) | O24: =IF(OR(A24="",K24=""),"",IF(H24<>"","Manual pair",IF(D24<>"","Reference / ID",MatchMode))) | P24: =IF(I24="","",I24&"|"&J24) | Q24: =IF(L24="Matched",COUNTIF($L$5:L24,"Matched"),"") | R24: =IF(L24="Unmatched",COUNTIF($L$5:L24,"Unmatched"),"") | S24: =IF(L24="Difference",COUNTIF($L$5:L24,"Difference"),"") | T24: =IF(L24="Difference",ABS(N24),0)
I25: =IF(A25="","",IF(H25<>"","M|"&TRIM(H25),IF(AND(MatchMode="Reference / ID only",D25=""),"U|"&ROW(),IF(D25<>"","R|"&TRIM(D25),IF(MatchMode="Amount only","A|"&TEXT(ROUND(C25,2),"0.00"),IF(MatchMode="Amount (tolerance)","T|"&TEXT(ROUND(C25/MAX(N(Tolerance),0.0001),0),"0"),IF(MatchMode="Date + amount (tolerance)","DT|"&TEXT(A25,"yyyy-mm-dd")&"|"&TEXT(ROUND(C25/MAX(N(Tolerance),0.0001),0),"0"),IF(MatchMode="Description (exact)","S|"&LOWER(TRIM(B25)),IF(MatchMode="Reference / ID only","U|"&ROW(),"DA|"&TEXT(A25,"yyyy-mm-dd")&"|"&TEXT(ROUND(C25,2),"0.00")))))))))) | J25: =IF(I25="","",COUNTIF($I$5:I25,I25)) | K25: =IF(P25="","",IFERROR(MATCH(P25,ListB_Combo,0)+4,"")) | L25: =IF(A25="","",IF(K25="","Unmatched",IF(ABS(C25-M25)<=MAX(N(Tolerance),0),"Matched","Difference"))) | M25: =IF(K25="","",INDEX('List B'!$C$5:$C$204,K25-4)) | N25: =IF(K25="","",C25-M25) | O25: =IF(OR(A25="",K25=""),"",IF(H25<>"","Manual pair",IF(D25<>"","Reference / ID",MatchMode))) | P25: =IF(I25="","",I25&"|"&J25) | Q25: =IF(L25="Matched",COUNTIF($L$5:L25,"Matched"),"") | R25: =IF(L25="Unmatched",COUNTIF($L$5:L25,"Unmatched"),"") | S25: =IF(L25="Difference",COUNTIF($L$5:L25,"Difference"),"") | T25: =IF(L25="Difference",ABS(N25),0)
I26: =IF(A26="","",IF(H26<>"","M|"&TRIM(H26),IF(AND(MatchMode="Reference / ID only",D26=""),"U|"&ROW(),IF(D26<>"","R|"&TRIM(D26),IF(MatchMode="Amount only","A|"&TEXT(ROUND(C26,2),"0.00"),IF(MatchMode="Amount (tolerance)","T|"&TEXT(ROUND(C26/MAX(N(Tolerance),0.0001),0),"0"),IF(MatchMode="Date + amount (tolerance)","DT|"&TEXT(A26,"yyyy-mm-dd")&"|"&TEXT(ROUND(C26/MAX(N(Tolerance),0.0001),0),"0"),IF(MatchMode="Description (exact)","S|"&LOWER(TRIM(B26)),IF(MatchMode="Reference / ID only","U|"&ROW(),"DA|"&TEXT(A26,"yyyy-mm-dd")&"|"&TEXT(ROUND(C26,2),"0.00")))))))))) | J26: =IF(I26="","",COUNTIF($I$5:I26,I26)) | K26: =IF(P26="","",IFERROR(MATCH(P26,ListB_Combo,0)+4,"")) | L26: =IF(A26="","",IF(K26="","Unmatched",IF(ABS(C26-M26)<=MAX(N(Tolerance),0),"Matched","Difference"))) | M26: =IF(K26="","",INDEX('List B'!$C$5:$C$204,K26-4)) | N26: =IF(K26="","",C26-M26) | O26: =IF(OR(A26="",K26=""),"",IF(H26<>"","Manual pair",IF(D26<>"","Reference / ID",MatchMode))) | P26: =IF(I26="","",I26&"|"&J26) | Q26: =IF(L26="Matched",COUNTIF($L$5:L26,"Matched"),"") | R26: =IF(L26="Unmatched",COUNTIF($L$5:L26,"Unmatched"),"") | S26: =IF(L26="Difference",COUNTIF($L$5:L26,"Difference"),"") | T26: =IF(L26="Difference",ABS(N26),0)
I27: =IF(A27="","",IF(H27<>"","M|"&TRIM(H27),IF(AND(MatchMode="Reference / ID only",D27=""),"U|"&ROW(),IF(D27<>"","R|"&TRIM(D27),IF(MatchMode="Amount only","A|"&TEXT(ROUND(C27,2),"0.00"),IF(MatchMode="Amount (tolerance)","T|"&TEXT(ROUND(C27/MAX(N(Tolerance),0.0001),0),"0"),IF(MatchMode="Date + amount (tolerance)","DT|"&TEXT(A27,"yyyy-mm-dd")&"|"&TEXT(ROUND(C27/MAX(N(Tolerance),0.0001),0),"0"),IF(MatchMode="Description (exact)","S|"&LOWER(TRIM(B27)),IF(MatchMode="Reference / ID only","U|"&ROW(),"DA|"&TEXT(A27,"yyyy-mm-dd")&"|"&TEXT(ROUND(C27,2),"0.00")))))))))) | J27: =IF(I27="","",COUNTIF($I$5:I27,I27)) | K27: =IF(P27="","",IFERROR(MATCH(P27,ListB_Combo,0)+4,"")) | L27: =IF(A27="","",IF(K27="","Unmatched",IF(ABS(C27-M27)<=MAX(N(Tolerance),0),"Matched","Difference"))) | M27: =IF(K27="","",INDEX('List B'!$C$5:$C$204,K27-4)) | N27: =IF(K27="","",C27-M27) | O27: =IF(OR(A27="",K27=""),"",IF(H27<>"","Manual pair",IF(D27<>"","Reference / ID",MatchMode))) | P27: =IF(I27="","",I27&"|"&J27) | Q27: =IF(L27="Matched",COUNTIF($L$5:L27,"Matched"),"") | R27: =IF(L27="Unmatched",COUNTIF($L$5:L27,"Unmatched"),"") | S27: =IF(L27="Difference",COUNTIF($L$5:L27,"Difference"),"") | T27: =IF(L27="Difference",ABS(N27),0)
I28: =IF(A28="","",IF(H28<>"","M|"&TRIM(H28),IF(AND(MatchMode="Reference / ID only",D28=""),"U|"&ROW(),IF(D28<>"","R|"&TRIM(D28),IF(MatchMode="Amount only","A|"&TEXT(ROUND(C28,2),"0.00"),IF(MatchMode="Amount (tolerance)","T|"&TEXT(ROUND(C28/MAX(N(Tolerance),0.0001),0),"0"),IF(MatchMode="Date + amount (tolerance)","DT|"&TEXT(A28,"yyyy-mm-dd")&"|"&TEXT(ROUND(C28/MAX(N(Tolerance),0.0001),0),"0"),IF(MatchMode="Description (exact)","S|"&LOWER(TRIM(B28)),IF(MatchMode="Reference / ID only","U|"&ROW(),"DA|"&TEXT(A28,"yyyy-mm-dd")&"|"&TEXT(ROUND(C28,2),"0.00")))))))))) | J28: =IF(I28="","",COUNTIF($I$5:I28,I28)) | K28: =IF(P28="","",IFERROR(MATCH(P28,ListB_Combo,0)+4,"")) | L28: =IF(A28="","",IF(K28="","Unmatched",IF(ABS(C28-M28)<=MAX(N(Tolerance),0),"Matched","Difference"))) | M28: =IF(K28="","",INDEX('List B'!$C$5:$C$204,K28-4)) | N28: =IF(K28="","",C28-M28) | O28: =IF(OR(A28="",K28=""),"",IF(H28<>"","Manual pair",IF(D28<>"","Reference / ID",MatchMode))) | P28: =IF(I28="","",I28&"|"&J28) | Q28: =IF(L28="Matched",COUNTIF($L$5:L28,"Matched"),"") | R28: =IF(L28="Unmatched",COUNTIF($L$5:L28,"Unmatched"),"") | S28: =IF(L28="Difference",COUNTIF($L$5:L28,"Difference"),"") | T28: =IF(L28="Difference",ABS(N28),0)
I29: =IF(A29="","",IF(H29<>"","M|"&TRIM(H29),IF(AND(MatchMode="Reference / ID only",D29=""),"U|"&ROW(),IF(D29<>"","R|"&TRIM(D29),IF(MatchMode="Amount only","A|"&TEXT(ROUND(C29,2),"0.00"),IF(MatchMode="Amount (tolerance)","T|"&TEXT(ROUND(C29/MAX(N(Tolerance),0.0001),0),"0"),IF(MatchMode="Date + amount (tolerance)","DT|"&TEXT(A29,"yyyy-mm-dd")&"|"&TEXT(ROUND(C29/MAX(N(Tolerance),0.0001),0),"0"),IF(MatchMode="Description (exact)","S|"&LOWER(TRIM(B29)),IF(MatchMode="Reference / ID only","U|"&ROW(),"DA|"&TEXT(A29,"yyyy-mm-dd")&"|"&TEXT(ROUND(C29,2),"0.00")))))))))) | J29: =IF(I29="","",COUNTIF($I$5:I29,I29)) | K29: =IF(P29="","",IFERROR(MATCH(P29,ListB_Combo,0)+4,"")) | L29: =IF(A29="","",IF(K29="","Unmatched",IF(ABS(C29-M29)<=MAX(N(Tolerance),0),"Matched","Difference"))) | M29: =IF(K29="","",INDEX('List B'!$C$5:$C$204,K29-4)) | N29: =IF(K29="","",C29-M29) | O29: =IF(OR(A29="",K29=""),"",IF(H29<>"","Manual pair",IF(D29<>"","Reference / ID",MatchMode))) | P29: =IF(I29="","",I29&"|"&J29) | Q29: =IF(L29="Matched",COUNTIF($L$5:L29,"Matched"),"") | R29: =IF(L29="Unmatched",COUNTIF($L$5:L29,"Unmatched"),"") | S29: =IF(L29="Difference",COUNTIF($L$5:L29,"Difference"),"") | T29: =IF(L29="Difference",ABS(N29),0)
I30: =IF(A30="","",IF(H30<>"","M|"&TRIM(H30),IF(AND(MatchMode="Reference / ID only",D30=""),"U|"&ROW(),IF(D30<>"","R|"&TRIM(D30),IF(MatchMode="Amount only","A|"&TEXT(ROUND(C30,2),"0.00"),IF(MatchMode="Amount (tolerance)","T|"&TEXT(ROUND(C30/MAX(N(Tolerance),0.0001),0),"0"),IF(MatchMode="Date + amount (tolerance)","DT|"&TEXT(A30,"yyyy-mm-dd")&"|"&TEXT(ROUND(C30/MAX(N(Tolerance),0.0001),0),"0"),IF(MatchMode="Description (exact)","S|"&LOWER(TRIM(B30)),IF(MatchMode="Reference / ID only","U|"&ROW(),"DA|"&TEXT(A30,"yyyy-mm-dd")&"|"&TEXT(ROUND(C30,2),"0.00")))))))))) | J30: =IF(I30="","",COUNTIF($I$5:I30,I30)) | K30: =IF(P30="","",IFERROR(MATCH(P30,ListB_Combo,0)+4,"")) | L30: =IF(A30="","",IF(K30="","Unmatched",IF(ABS(C30-M30)<=MAX(N(Tolerance),0),"Matched","Difference"))) | M30: =IF(K30="","",INDEX('List B'!$C$5:$C$204,K30-4)) | N30: =IF(K30="","",C30-M30) | O30: =IF(OR(A30="",K30=""),"",IF(H30<>"","Manual pair",IF(D30<>"","Reference / ID",MatchMode))) | P30: =IF(I30="","",I30&"|"&J30) | Q30: =IF(L30="Matched",COUNTIF($L$5:L30,"Matched"),"") | R30: =IF(L30="Unmatched",COUNTIF($L$5:L30,"Unmatched"),"") | S30: =IF(L30="Difference",COUNTIF($L$5:L30,"Difference"),"") | T30: =IF(L30="Difference",ABS(N30),0)
I31: =IF(A31="","",IF(H31<>"","M|"&TRIM(H31),IF(AND(MatchMode="Reference / ID only",D31=""),"U|"&ROW(),IF(D31<>"","R|"&TRIM(D31),IF(MatchMode="Amount only","A|"&TEXT(ROUND(C31,2),"0.00"),IF(MatchMode="Amount (tolerance)","T|"&TEXT(ROUND(C31/MAX(N(Tolerance),0.0001),0),"0"),IF(MatchMode="Date + amount (tolerance)","DT|"&TEXT(A31,"yyyy-mm-dd")&"|"&TEXT(ROUND(C31/MAX(N(Tolerance),0.0001),0),"0"),IF(MatchMode="Description (exact)","S|"&LOWER(TRIM(B31)),IF(MatchMode="Reference / ID only","U|"&ROW(),"DA|"&TEXT(A31,"yyyy-mm-dd")&"|"&TEXT(ROUND(C31,2),"0.00")))))))))) | J31: =IF(I31="","",COUNTIF($I$5:I31,I31)) | K31: =IF(P31="","",IFERROR(MATCH(P31,ListB_Combo,0)+4,"")) | L31: =IF(A31="","",IF(K31="","Unmatched",IF(ABS(C31-M31)<=MAX(N(Tolerance),0),"Matched","Difference"))) | M31: =IF(K31="","",INDEX('List B'!$C$5:$C$204,K31-4)) | N31: =IF(K31="","",C31-M31) | O31: =IF(OR(A31="",K31=""),"",IF(H31<>"","Manual pair",IF(D31<>"","Reference / ID",MatchMode))) | P31: =IF(I31="","",I31&"|"&J31) | Q31: =IF(L31="Matched",COUNTIF($L$5:L31,"Matched"),"") | R31: =IF(L31="Unmatched",COUNTIF($L$5:L31,"Unmatched"),"") | S31: =IF(L31="Difference",COUNTIF($L$5:L31,"Difference"),"") | T31: =IF(L31="Difference",ABS(N31),0)
I32: =IF(A32="","",IF(H32<>"","M|"&TRIM(H32),IF(AND(MatchMode="Reference / ID only",D32=""),"U|"&ROW(),IF(D32<>"","R|"&TRIM(D32),IF(MatchMode="Amount only","A|"&TEXT(ROUND(C32,2),"0.00"),IF(MatchMode="Amount (tolerance)","T|"&TEXT(ROUND(C32/MAX(N(Tolerance),0.0001),0),"0"),IF(MatchMode="Date + amount (tolerance)","DT|"&TEXT(A32,"yyyy-mm-dd")&"|"&TEXT(ROUND(C32/MAX(N(Tolerance),0.0001),0),"0"),IF(MatchMode="Description (exact)","S|"&LOWER(TRIM(B32)),IF(MatchMode="Reference / ID only","U|"&ROW(),"DA|"&TEXT(A32,"yyyy-mm-dd")&"|"&TEXT(ROUND(C32,2),"0.00")))))))))) | J32: =IF(I32="","",COUNTIF($I$5:I32,I32)) | K32: =IF(P32="","",IFERROR(MATCH(P32,ListB_Combo,0)+4,"")) | L32: =IF(A32="","",IF(K32="","Unmatched",IF(ABS(C32-M32)<=MAX(N(Tolerance),0),"Matched","Difference"))) | M32: =IF(K32="","",INDEX('List B'!$C$5:$C$204,K32-4)) | N32: =IF(K32="","",C32-M32) | O32: =IF(OR(A32="",K32=""),"",IF(H32<>"","Manual pair",IF(D32<>"","Reference / ID",MatchMode))) | P32: =IF(I32="","",I32&"|"&J32) | Q32: =IF(L32="Matched",COUNTIF($L$5:L32,"Matched"),"") | R32: =IF(L32="Unmatched",COUNTIF($L$5:L32,"Unmatched"),"") | S32: =IF(L32="Difference",COUNTIF($L$5:L32,"Difference"),"") | T32: =IF(L32="Difference",ABS(N32),0)
I33: =IF(A33="","",IF(H33<>"","M|"&TRIM(H33),IF(AND(MatchMode="Reference / ID only",D33=""),"U|"&ROW(),IF(D33<>"","R|"&TRIM(D33),IF(MatchMode="Amount only","A|"&TEXT(ROUND(C33,2),"0.00"),IF(MatchMode="Amount (tolerance)","T|"&TEXT(ROUND(C33/MAX(N(Tolerance),0.0001),0),"0"),IF(MatchMode="Date + amount (tolerance)","DT|"&TEXT(A33,"yyyy-mm-dd")&"|"&TEXT(ROUND(C33/MAX(N(Tolerance),0.0001),0),"0"),IF(MatchMode="Description (exact)","S|"&LOWER(TRIM(B33)),IF(MatchMode="Reference / ID only","U|"&ROW(),"DA|"&TEXT(A33,"yyyy-mm-dd")&"|"&TEXT(ROUND(C33,2),"0.00")))))))))) | J33: =IF(I33="","",COUNTIF($I$5:I33,I33)) | K33: =IF(P33="","",IFERROR(MATCH(P33,ListB_Combo,0)+4,"")) | L33: =IF(A33="","",IF(K33="","Unmatched",IF(ABS(C33-M33)<=MAX(N(Tolerance),0),"Matched","Difference"))) | M33: =IF(K33="","",INDEX('List B'!$C$5:$C$204,K33-4)) | N33: =IF(K33="","",C33-M33) | O33: =IF(OR(A33="",K33=""),"",IF(H33<>"","Manual pair",IF(D33<>"","Reference / ID",MatchMode))) | P33: =IF(I33="","",I33&"|"&J33) | Q33: =IF(L33="Matched",COUNTIF($L$5:L33,"Matched"),"") | R33: =IF(L33="Unmatched",COUNTIF($L$5:L33,"Unmatched"),"") | S33: =IF(L33="Difference",COUNTIF($L$5:L33,"Difference"),"") | T33: =IF(L33="Difference",ABS(N33),0)
I34: =IF(A34="","",IF(H34<>"","M|"&TRIM(H34),IF(AND(MatchMode="Reference / ID only",D34=""),"U|"&ROW(),IF(D34<>"","R|"&TRIM(D34),IF(MatchMode="Amount only","A|"&TEXT(ROUND(C34,2),"0.00"),IF(MatchMode="Amount (tolerance)","T|"&TEXT(ROUND(C34/MAX(N(Tolerance),0.0001),0),"0"),IF(MatchMode="Date + amount (tolerance)","DT|"&TEXT(A34,"yyyy-mm-dd")&"|"&TEXT(ROUND(C34/MAX(N(Tolerance),0.0001),0),"0"),IF(MatchMode="Description (exact)","S|"&LOWER(TRIM(B34)),IF(MatchMode="Reference / ID only","U|"&ROW(),"DA|"&TEXT(A34,"yyyy-mm-dd")&"|"&TEXT(ROUND(C34,2),"0.00")))))))))) | J34: =IF(I34="","",COUNTIF($I$5:I34,I34)) | K34: =IF(P34="","",IFERROR(MATCH(P34,ListB_Combo,0)+4,"")) | L34: =IF(A34="","",IF(K34="","Unmatched",IF(ABS(C34-M34)<=MAX(N(Tolerance),0),"Matched","Difference"))) | M34: =IF(K34="","",INDEX('List B'!$C$5:$C$204,K34-4)) | N34: =IF(K34="","",C34-M34) | O34: =IF(OR(A34="",K34=""),"",IF(H34<>"","Manual pair",IF(D34<>"","Reference / ID",MatchMode))) | P34: =IF(I34="","",I34&"|"&J34) | Q34: =IF(L34="Matched",COUNTIF($L$5:L34,"Matched"),"") | R34: =IF(L34="Unmatched",COUNTIF($L$5:L34,"Unmatched"),"") | S34: =IF(L34="Difference",COUNTIF($L$5:L34,"Difference"),"") | T34: =IF(L34="Difference",ABS(N34),0)
I35: =IF(A35="","",IF(H35<>"","M|"&TRIM(H35),IF(AND(MatchMode="Reference / ID only",D35=""),"U|"&ROW(),IF(D35<>"","R|"&TRIM(D35),IF(MatchMode="Amount only","A|"&TEXT(ROUND(C35,2),"0.00"),IF(MatchMode="Amount (tolerance)","T|"&TEXT(ROUND(C35/MAX(N(Tolerance),0.0001),0),"0"),IF(MatchMode="Date + amount (tolerance)","DT|"&TEXT(A35,"yyyy-mm-dd")&"|"&TEXT(ROUND(C35/MAX(N(Tolerance),0.0001),0),"0"),IF(MatchMode="Description (exact)","S|"&LOWER(TRIM(B35)),IF(MatchMode="Reference / ID only","U|"&ROW(),"DA|"&TEXT(A35,"yyyy-mm-dd")&"|"&TEXT(ROUND(C35,2),"0.00")))))))))) | J35: =IF(I35="","",COUNTIF($I$5:I35,I35)) | K35: =IF(P35="","",IFERROR(MATCH(P35,ListB_Combo,0)+4,"")) | L35: =IF(A35="","",IF(K35="","Unmatched",IF(ABS(C35-M35)<=MAX(N(Tolerance),0),"Matched","Difference"))) | M35: =IF(K35="","",INDEX('List B'!$C$5:$C$204,K35-4)) | N35: =IF(K35="","",C35-M35) | O35: =IF(OR(A35="",K35=""),"",IF(H35<>"","Manual pair",IF(D35<>"","Reference / ID",MatchMode))) | P35: =IF(I35="","",I35&"|"&J35) | Q35: =IF(L35="Matched",COUNTIF($L$5:L35,"Matched"),"") | R35: =IF(L35="Unmatched",COUNTIF($L$5:L35,"Unmatched"),"") | S35: =IF(L35="Difference",COUNTIF($L$5:L35,"Difference"),"") | T35: =IF(L35="Difference",ABS(N35),0)
I36: =IF(A36="","",IF(H36<>"","M|"&TRIM(H36),IF(AND(MatchMode="Reference / ID only",D36=""),"U|"&ROW(),IF(D36<>"","R|"&TRIM(D36),IF(MatchMode="Amount only","A|"&TEXT(ROUND(C36,2),"0.00"),IF(MatchMode="Amount (tolerance)","T|"&TEXT(ROUND(C36/MAX(N(Tolerance),0.0001),0),"0"),IF(MatchMode="Date + amount (tolerance)","DT|"&TEXT(A36,"yyyy-mm-dd")&"|"&TEXT(ROUND(C36/MAX(N(Tolerance),0.0001),0),"0"),IF(MatchMode="Description (exact)","S|"&LOWER(TRIM(B36)),IF(MatchMode="Reference / ID only","U|"&ROW(),"DA|"&TEXT(A36,"yyyy-mm-dd")&"|"&TEXT(ROUND(C36,2),"0.00")))))))))) | J36: =IF(I36="","",COUNTIF($I$5:I36,I36)) | K36: =IF(P36="","",IFERROR(MATCH(P36,ListB_Combo,0)+4,"")) | L36: =IF(A36="","",IF(K36="","Unmatched",IF(ABS(C36-M36)<=MAX(N(Tolerance),0),"Matched","Difference"))) | M36: =IF(K36="","",INDEX('List B'!$C$5:$C$204,K36-4)) | N36: =IF(K36="","",C36-M36) | O36: =IF(OR(A36="",K36=""),"",IF(H36<>"","Manual pair",IF(D36<>"","Reference / ID",MatchMode))) | P36: =IF(I36="","",I36&"|"&J36) | Q36: =IF(L36="Matched",COUNTIF($L$5:L36,"Matched"),"") | R36: =IF(L36="Unmatched",COUNTIF($L$5:L36,"Unmatched"),"") | S36: =IF(L36="Difference",COUNTIF($L$5:L36,"Difference"),"") | T36: =IF(L36="Difference",ABS(N36),0)
... I204: =IF(A204="","",IF(H204<>"","M|"&TRIM(H204),IF(AND(MatchMode="Reference / ID only",D204=""),"U|"&ROW(),IF(D204<>"","R|"&TRIM(D204),IF(MatchMode="Amount only","A|"&TEXT(ROUND(C204,2),"0.00"),IF(MatchMode="Amount (tolerance)","T|"&TEXT(ROUND(C204/MAX(N(Tolerance),0.0001),0),"0"),IF(MatchMode="Date + amount (tolerance)","DT|"&TEXT(A204,"yyyy-mm-dd")&"|"&TEXT(ROUND(C204/MAX(N(Tolerance),0.0001),0),"0"),IF(MatchMode="Description (exact)","S|"&LOWER(TRIM(B204)),IF(MatchMode="Reference / ID only","U|"&ROW(),"DA|"&TEXT(A204,"yyyy-mm-dd")&"|"&TEXT(ROUND(C204,2),"0.00")))))))))) | J204: =IF(I204="","",COUNTIF($I$5:I204,I204)) | K204: =IF(P204="","",IFERROR(MATCH(P204,ListB_Combo,0)+4,"")) | L204: =IF(A204="","",IF(K204="","Unmatched",IF(ABS(C204-M204)<=MAX(N(Tolerance),0),"Matched","Difference"))) | M204: =IF(K204="","",INDEX('List B'!$C$5:$C$204,K204-4)) | N204: =IF(K204="","",C204-M204) | O204: =IF(OR(A204="",K204=""),"",IF(H204<>"","Manual pair",IF(D204<>"","Reference / ID",MatchMode))) | P204: =IF(I204="","",I204&"|"&J204) | Q204: =IF(L204="Matched",COUNTIF($L$5:L204,"Matched"),"") | R204: =IF(L204="Unmatched",COUNTIF($L$5:L204,"Unmatched"),"") | S204: =IF(L204="Difference",COUNTIF($L$5:L204,"Difference"),"") | T204: =IF(L204="Difference",ABS(N204),0)
A205: TOTAL | C205: =SUM(C5:C204)
A207: To start a new reconciliation: delete values in columns A–H only (leave gray formula columns). Or File → Save As / Make a copy first so you keep this period.

Sheet List B
A1: List B
A2: =IF(ListBName="","Paste or type transactions here.",ListBName&" · Blue = paste or type. Gray = match result. Withdrawals negative, deposits positive — same convention on both lists.")
A3: =COUNTA(A5:A204)&" items · "&COUNTIF(L5:L204,"Matched")&" matched · "&COUNTIF(L5:L204,"Difference")&" differences · "&COUNTIF(L5:L204,"Unmatched")&" unmatched · Total "&TEXT(SUM(C5:C204),"$#,##0.00")
A4: Date | B4: Description | C4: Amount | D4: Transaction ID | E4: Category | F4: Notes | G4: Reviewed? | H4: Manual pair | I4: Match key | J4: Occ. | K4: Match row | L4: Status | M4: List A amount | N4: Difference | O4: How matched
A5: 46235 | B5: Customer payment received | C5: 2500 | E5: Income | I5: =IF(A5="","",IF(H5<>"","M|"&TRIM(H5),IF(AND(MatchMode="Reference / ID only",D5=""),"U|"&ROW(),IF(D5<>"","R|"&TRIM(D5),IF(MatchMode="Amount only","A|"&TEXT(ROUND(C5,2),"0.00"),IF(MatchMode="Amount (tolerance)","T|"&TEXT(ROUND(C5/MAX(N(Tolerance),0.0001),0),"0"),IF(MatchMode="Date + amount (tolerance)","DT|"&TEXT(A5,"yyyy-mm-dd")&"|"&TEXT(ROUND(C5/MAX(N(Tolerance),0.0001),0),"0"),IF(MatchMode="Description (exact)","S|"&LOWER(TRIM(B5)),IF(MatchMode="Reference / ID only","U|"&ROW(),"DA|"&TEXT(A5,"yyyy-mm-dd")&"|"&TEXT(ROUND(C5,2),"0.00")))))))))) | J5: =IF(I5="","",COUNTIF($I$5:I5,I5)) | K5: =IF(P5="","",IFERROR(MATCH(P5,ListA_Combo,0)+4,"")) | L5: =IF(A5="","",IF(K5="","Unmatched",IF(ABS(C5-M5)<=MAX(N(Tolerance),0),"Matched","Difference"))) | M5: =IF(K5="","",INDEX('List A'!$C$5:$C$204,K5-4)) | N5: =IF(K5="","",C5-M5) | O5: =IF(OR(A5="",K5=""),"",IF(H5<>"","Manual pair",IF(D5<>"","Reference / ID",MatchMode))) | P5: =IF(I5="","",I5&"|"&J5) | Q5: =IF(L5="Matched",COUNTIF($L$5:L5,"Matched"),"") | R5: =IF(L5="Unmatched",COUNTIF($L$5:L5,"Unmatched"),"") | S5: =IF(L5="Difference",COUNTIF($L$5:L5,"Difference"),"") | T5: =IF(L5="Difference",ABS(N5),0)
A6: 46237 | B6: Office Depot — check 1041 | C6: -185 | D6: 1041 | E6: Supplies | I6: =IF(A6="","",IF(H6<>"","M|"&TRIM(H6),IF(AND(MatchMode="Reference / ID only",D6=""),"U|"&ROW(),IF(D6<>"","R|"&TRIM(D6),IF(MatchMode="Amount only","A|"&TEXT(ROUND(C6,2),"0.00"),IF(MatchMode="Amount (tolerance)","T|"&TEXT(ROUND(C6/MAX(N(Tolerance),0.0001),0),"0"),IF(MatchMode="Date + amount (tolerance)","DT|"&TEXT(A6,"yyyy-mm-dd")&"|"&TEXT(ROUND(C6/MAX(N(Tolerance),0.0001),0),"0"),IF(MatchMode="Description (exact)","S|"&LOWER(TRIM(B6)),IF(MatchMode="Reference / ID only","U|"&ROW(),"DA|"&TEXT(A6,"yyyy-mm-dd")&"|"&TEXT(ROUND(C6,2),"0.00")))))))))) | J6: =IF(I6="","",COUNTIF($I$5:I6,I6)) | K6: =IF(P6="","",IFERROR(MATCH(P6,ListA_Combo,0)+4,"")) | L6: =IF(A6="","",IF(K6="","Unmatched",IF(ABS(C6-M6)<=MAX(N(Tolerance),0),"Matched","Difference"))) | M6: =IF(K6="","",INDEX('List A'!$C$5:$C$204,K6-4)) | N6: =IF(K6="","",C6-M6) | O6: =IF(OR(A6="",K6=""),"",IF(H6<>"","Manual pair",IF(D6<>"","Reference / ID",MatchMode))) | P6: =IF(I6="","",I6&"|"&J6) | Q6: =IF(L6="Matched",COUNTIF($L$5:L6,"Matched"),"") | R6: =IF(L6="Unmatched",COUNTIF($L$5:L6,"Unmatched"),"") | S6: =IF(L6="Difference",COUNTIF($L$5:L6,"Difference"),"") | T6: =IF(L6="Difference",ABS(N6),0)
A7: 46238 | B7: Payroll 8/4 | C7: -2100 | E7: Payroll | I7: =IF(A7="","",IF(H7<>"","M|"&TRIM(H7),IF(AND(MatchMode="Reference / ID only",D7=""),"U|"&ROW(),IF(D7<>"","R|"&TRIM(D7),IF(MatchMode="Amount only","A|"&TEXT(ROUND(C7,2),"0.00"),IF(MatchMode="Amount (tolerance)","T|"&TEXT(ROUND(C7/MAX(N(Tolerance),0.0001),0),"0"),IF(MatchMode="Date + amount (tolerance)","DT|"&TEXT(A7,"yyyy-mm-dd")&"|"&TEXT(ROUND(C7/MAX(N(Tolerance),0.0001),0),"0"),IF(MatchMode="Description (exact)","S|"&LOWER(TRIM(B7)),IF(MatchMode="Reference / ID only","U|"&ROW(),"DA|"&TEXT(A7,"yyyy-mm-dd")&"|"&TEXT(ROUND(C7,2),"0.00")))))))))) | J7: =IF(I7="","",COUNTIF($I$5:I7,I7)) | K7: =IF(P7="","",IFERROR(MATCH(P7,ListA_Combo,0)+4,"")) | L7: =IF(A7="","",IF(K7="","Unmatched",IF(ABS(C7-M7)<=MAX(N(Tolerance),0),"Matched","Difference"))) | M7: =IF(K7="","",INDEX('List A'!$C$5:$C$204,K7-4)) | N7: =IF(K7="","",C7-M7) | O7: =IF(OR(A7="",K7=""),"",IF(H7<>"","Manual pair",IF(D7<>"","Reference / ID",MatchMode))) | P7: =IF(I7="","",I7&"|"&J7) | Q7: =IF(L7="Matched",COUNTIF($L$5:L7,"Matched"),"") | R7: =IF(L7="Unmatched",COUNTIF($L$5:L7,"Unmatched"),"") | S7: =IF(L7="Difference",COUNTIF($L$5:L7,"Difference"),"") | T7: =IF(L7="Difference",ABS(N7),0)
A8: 46239 | B8: Stripe batch | C8: 842.16 | D8: po_8f21 | E8: Income | I8: =IF(A8="","",IF(H8<>"","M|"&TRIM(H8),IF(AND(MatchMode="Reference / ID only",D8=""),"U|"&ROW(),IF(D8<>"","R|"&TRIM(D8),IF(MatchMode="Amount only","A|"&TEXT(ROUND(C8,2),"0.00"),IF(MatchMode="Amount (tolerance)","T|"&TEXT(ROUND(C8/MAX(N(Tolerance),0.0001),0),"0"),IF(MatchMode="Date + amount (tolerance)","DT|"&TEXT(A8,"yyyy-mm-dd")&"|"&TEXT(ROUND(C8/MAX(N(Tolerance),0.0001),0),"0"),IF(MatchMode="Description (exact)","S|"&LOWER(TRIM(B8)),IF(MatchMode="Reference / ID only","U|"&ROW(),"DA|"&TEXT(A8,"yyyy-mm-dd")&"|"&TEXT(ROUND(C8,2),"0.00")))))))))) | J8: =IF(I8="","",COUNTIF($I$5:I8,I8)) | K8: =IF(P8="","",IFERROR(MATCH(P8,ListA_Combo,0)+4,"")) | L8: =IF(A8="","",IF(K8="","Unmatched",IF(ABS(C8-M8)<=MAX(N(Tolerance),0),"Matched","Difference"))) | M8: =IF(K8="","",INDEX('List A'!$C$5:$C$204,K8-4)) | N8: =IF(K8="","",C8-M8) | O8: =IF(OR(A8="",K8=""),"",IF(H8<>"","Manual pair",IF(D8<>"","Reference / ID",MatchMode))) | P8: =IF(I8="","",I8&"|"&J8) | Q8: =IF(L8="Matched",COUNTIF($L$5:L8,"Matched"),"") | R8: =IF(L8="Unmatched",COUNTIF($L$5:L8,"Unmatched"),"") | S8: =IF(L8="Difference",COUNTIF($L$5:L8,"Difference"),"") | T8: =IF(L8="Difference",ABS(N8),0)
A9: 46240 | B9: August rent | C9: -1400 | D9: 1043 | E9: Rent | I9: =IF(A9="","",IF(H9<>"","M|"&TRIM(H9),IF(AND(MatchMode="Reference / ID only",D9=""),"U|"&ROW(),IF(D9<>"","R|"&TRIM(D9),IF(MatchMode="Amount only","A|"&TEXT(ROUND(C9,2),"0.00"),IF(MatchMode="Amount (tolerance)","T|"&TEXT(ROUND(C9/MAX(N(Tolerance),0.0001),0),"0"),IF(MatchMode="Date + amount (tolerance)","DT|"&TEXT(A9,"yyyy-mm-dd")&"|"&TEXT(ROUND(C9/MAX(N(Tolerance),0.0001),0),"0"),IF(MatchMode="Description (exact)","S|"&LOWER(TRIM(B9)),IF(MatchMode="Reference / ID only","U|"&ROW(),"DA|"&TEXT(A9,"yyyy-mm-dd")&"|"&TEXT(ROUND(C9,2),"0.00")))))))))) | J9: =IF(I9="","",COUNTIF($I$5:I9,I9)) | K9: =IF(P9="","",IFERROR(MATCH(P9,ListA_Combo,0)+4,"")) | L9: =IF(A9="","",IF(K9="","Unmatched",IF(ABS(C9-M9)<=MAX(N(Tolerance),0),"Matched","Difference"))) | M9: =IF(K9="","",INDEX('List A'!$C$5:$C$204,K9-4)) | N9: =IF(K9="","",C9-M9) | O9: =IF(OR(A9="",K9=""),"",IF(H9<>"","Manual pair",IF(D9<>"","Reference / ID",MatchMode))) | P9: =IF(I9="","",I9&"|"&J9) | Q9: =IF(L9="Matched",COUNTIF($L$5:L9,"Matched"),"") | R9: =IF(L9="Unmatched",COUNTIF($L$5:L9,"Unmatched"),"") | S9: =IF(L9="Difference",COUNTIF($L$5:L9,"Difference"),"") | T9: =IF(L9="Difference",ABS(N9),0)
A10: 46241 | B10: Adobe Creative Cloud | C10: -54.99 | E10: Software | I10: =IF(A10="","",IF(H10<>"","M|"&TRIM(H10),IF(AND(MatchMode="Reference / ID only",D10=""),"U|"&ROW(),IF(D10<>"","R|"&TRIM(D10),IF(MatchMode="Amount only","A|"&TEXT(ROUND(C10,2),"0.00"),IF(MatchMode="Amount (tolerance)","T|"&TEXT(ROUND(C10/MAX(N(Tolerance),0.0001),0),"0"),IF(MatchMode="Date + amount (tolerance)","DT|"&TEXT(A10,"yyyy-mm-dd")&"|"&TEXT(ROUND(C10/MAX(N(Tolerance),0.0001),0),"0"),IF(MatchMode="Description (exact)","S|"&LOWER(TRIM(B10)),IF(MatchMode="Reference / ID only","U|"&ROW(),"DA|"&TEXT(A10,"yyyy-mm-dd")&"|"&TEXT(ROUND(C10,2),"0.00")))))))))) | J10: =IF(I10="","",COUNTIF($I$5:I10,I10)) | K10: =IF(P10="","",IFERROR(MATCH(P10,ListA_Combo,0)+4,"")) | L10: =IF(A10="","",IF(K10="","Unmatched",IF(ABS(C10-M10)<=MAX(N(Tolerance),0),"Matched","Difference"))) | M10: =IF(K10="","",INDEX('List A'!$C$5:$C$204,K10-4)) | N10: =IF(K10="","",C10-M10) | O10: =IF(OR(A10="",K10=""),"",IF(H10<>"","Manual pair",IF(D10<>"","Reference / ID",MatchMode))) | P10: =IF(I10="","",I10&"|"&J10) | Q10: =IF(L10="Matched",COUNTIF($L$5:L10,"Matched"),"") | R10: =IF(L10="Unmatched",COUNTIF($L$5:L10,"Unmatched"),"") | S10: =IF(L10="Difference",COUNTIF($L$5:L10,"Difference"),"") | T10: =IF(L10="Difference",ABS(N10),0)
A11: 46243 | B11: Check 1042 — outstanding | C11: -500 | D11: 1042 | E11: Vendors | F11: Not yet cleared | I11: =IF(A11="","",IF(H11<>"","M|"&TRIM(H11),IF(AND(MatchMode="Reference / ID only",D11=""),"U|"&ROW(),IF(D11<>"","R|"&TRIM(D11),IF(MatchMode="Amount only","A|"&TEXT(ROUND(C11,2),"0.00"),IF(MatchMode="Amount (tolerance)","T|"&TEXT(ROUND(C11/MAX(N(Tolerance),0.0001),0),"0"),IF(MatchMode="Date + amount (tolerance)","DT|"&TEXT(A11,"yyyy-mm-dd")&"|"&TEXT(ROUND(C11/MAX(N(Tolerance),0.0001),0),"0"),IF(MatchMode="Description (exact)","S|"&LOWER(TRIM(B11)),IF(MatchMode="Reference / ID only","U|"&ROW(),"DA|"&TEXT(A11,"yyyy-mm-dd")&"|"&TEXT(ROUND(C11,2),"0.00")))))))))) | J11: =IF(I11="","",COUNTIF($I$5:I11,I11)) | K11: =IF(P11="","",IFERROR(MATCH(P11,ListA_Combo,0)+4,"")) | L11: =IF(A11="","",IF(K11="","Unmatched",IF(ABS(C11-M11)<=MAX(N(Tolerance),0),"Matched","Difference"))) | M11: =IF(K11="","",INDEX('List A'!$C$5:$C$204,K11-4)) | N11: =IF(K11="","",C11-M11) | O11: =IF(OR(A11="",K11=""),"",IF(H11<>"","Manual pair",IF(D11<>"","Reference / ID",MatchMode))) | P11: =IF(I11="","",I11&"|"&J11) | Q11: =IF(L11="Matched",COUNTIF($L$5:L11,"Matched"),"") | R11: =IF(L11="Unmatched",COUNTIF($L$5:L11,"Unmatched"),"") | S11: =IF(L11="Difference",COUNTIF($L$5:L11,"Difference"),"") | T11: =IF(L11="Difference",ABS(N11),0)
A12: 46244 | B12: Staples order | C12: -326.4 | E12: Supplies | I12: =IF(A12="","",IF(H12<>"","M|"&TRIM(H12),IF(AND(MatchMode="Reference / ID only",D12=""),"U|"&ROW(),IF(D12<>"","R|"&TRIM(D12),IF(MatchMode="Amount only","A|"&TEXT(ROUND(C12,2),"0.00"),IF(MatchMode="Amount (tolerance)","T|"&TEXT(ROUND(C12/MAX(N(Tolerance),0.0001),0),"0"),IF(MatchMode="Date + amount (tolerance)","DT|"&TEXT(A12,"yyyy-mm-dd")&"|"&TEXT(ROUND(C12/MAX(N(Tolerance),0.0001),0),"0"),IF(MatchMode="Description (exact)","S|"&LOWER(TRIM(B12)),IF(MatchMode="Reference / ID only","U|"&ROW(),"DA|"&TEXT(A12,"yyyy-mm-dd")&"|"&TEXT(ROUND(C12,2),"0.00")))))))))) | J12: =IF(I12="","",COUNTIF($I$5:I12,I12)) | K12: =IF(P12="","",IFERROR(MATCH(P12,ListA_Combo,0)+4,"")) | L12: =IF(A12="","",IF(K12="","Unmatched",IF(ABS(C12-M12)<=MAX(N(Tolerance),0),"Matched","Difference"))) | M12: =IF(K12="","",INDEX('List A'!$C$5:$C$204,K12-4)) | N12: =IF(K12="","",C12-M12) | O12: =IF(OR(A12="",K12=""),"",IF(H12<>"","Manual pair",IF(D12<>"","Reference / ID",MatchMode))) | P12: =IF(I12="","",I12&"|"&J12) | Q12: =IF(L12="Matched",COUNTIF($L$5:L12,"Matched"),"") | R12: =IF(L12="Unmatched",COUNTIF($L$5:L12,"Unmatched"),"") | S12: =IF(L12="Difference",COUNTIF($L$5:L12,"Difference"),"") | T12: =IF(L12="Difference",ABS(N12),0)
A13: 46245 | B13: Invoice 1882 paid | C13: 750 | D13: INV-1882 | E13: Income | I13: =IF(A13="","",IF(H13<>"","M|"&TRIM(H13),IF(AND(MatchMode="Reference / ID only",D13=""),"U|"&ROW(),IF(D13<>"","R|"&TRIM(D13),IF(MatchMode="Amount only","A|"&TEXT(ROUND(C13,2),"0.00"),IF(MatchMode="Amount (tolerance)","T|"&TEXT(ROUND(C13/MAX(N(Tolerance),0.0001),0),"0"),IF(MatchMode="Date + amount (tolerance)","DT|"&TEXT(A13,"yyyy-mm-dd")&"|"&TEXT(ROUND(C13/MAX(N(Tolerance),0.0001),0),"0"),IF(MatchMode="Description (exact)","S|"&LOWER(TRIM(B13)),IF(MatchMode="Reference / ID only","U|"&ROW(),"DA|"&TEXT(A13,"yyyy-mm-dd")&"|"&TEXT(ROUND(C13,2),"0.00")))))))))) | J13: =IF(I13="","",COUNTIF($I$5:I13,I13)) | K13: =IF(P13="","",IFERROR(MATCH(P13,ListA_Combo,0)+4,"")) | L13: =IF(A13="","",IF(K13="","Unmatched",IF(ABS(C13-M13)<=MAX(N(Tolerance),0),"Matched","Difference"))) | M13: =IF(K13="","",INDEX('List A'!$C$5:$C$204,K13-4)) | N13: =IF(K13="","",C13-M13) | O13: =IF(OR(A13="",K13=""),"",IF(H13<>"","Manual pair",IF(D13<>"","Reference / ID",MatchMode))) | P13: =IF(I13="","",I13&"|"&J13) | Q13: =IF(L13="Matched",COUNTIF($L$5:L13,"Matched"),"") | R13: =IF(L13="Unmatched",COUNTIF($L$5:L13,"Unmatched"),"") | S13: =IF(L13="Difference",COUNTIF($L$5:L13,"Difference"),"") | T13: =IF(L13="Difference",ABS(N13),0)
